Workbook

Sheet Resumo UF
A1: Comparativo PASSARO – PROPOSTA 2 (07/10/2026) x fretes realizados – Top 10 cidades por UF (Nordeste, Ago/2026)
A2: Valores com ICMS. Frete atual = coluna J (Valor CTe). Passaro = tabela proposta, origem SP. Diferença negativa = Passaro mais barata.
A4: UF | B4: Pedidos | C4: Peso total (kg) | D4: Valor NF total (R$) | E4: Frete atual (R$) | F4: Frete PASSARO (R$) | G4: Diferença (R$) | H4: Dif. % | I4: % frete/NF atual | J4: % frete/NF Passaro | K4: Pedidos em que Passaro é mais barata | L4: % pedidos Passaro mais barata | M4: Desconto que a Passaro precisa dar p/ empatar
A5: AL | B5: =COUNTIFS('Pedidos Top10'!$A$2:$A$1839,A5) -> 167 | C5: =SUMIFS('Pedidos Top10'!$J$2:$J$1839,'Pedidos Top10'!$A$2:$A$1839,A5) -> 8123.94 | D5: =SUMIFS('Pedidos Top10'!$K$2:$K$1839,'Pedidos Top10'!$A$2:$A$1839,A5) -> 156881.45 | E5: =SUMIFS('Pedidos Top10'!$L$2:$L$1839,'Pedidos Top10'!$A$2:$A$1839,A5) -> 29157.55 | F5: =SUMIFS('Pedidos Top10'!$AD$2:$AD$1839,'Pedidos Top10'!$A$2:$A$1839,A5) -> 25733.4 | G5: =F5-E5 -> -3424.15 | H5: =IF(E5=0,0,G5/E5) -> -0.11743614 | I5: =IF(D5=0,0,E5/D5) -> 0.18585722 | J5: =IF(D5=0,0,F5/D5) -> 0.16403087 | K5: =COUNTIFS('Pedidos Top10'!$A$2:$A$1839,A5,'Pedidos Top10'!$AG$2:$AG$1839,"PASSARO") -> 115 | L5: =IF(B5=0,0,K5/B5) -> 0.68862275 | M5: =IF(F5<=E5,0,1-E5/F5) -> 0
A6: BA | B6: =COUNTIFS('Pedidos Top10'!$A$2:$A$1839,A6) -> 501 | C6: =SUMIFS('Pedidos Top10'!$J$2:$J$1839,'Pedidos Top10'!$A$2:$A$1839,A6) -> 26699.12 | D6: =SUMIFS('Pedidos Top10'!$K$2:$K$1839,'Pedidos Top10'!$A$2:$A$1839,A6) -> 458094.85 | E6: =SUMIFS('Pedidos Top10'!$L$2:$L$1839,'Pedidos Top10'!$A$2:$A$1839,A6) -> 87126.83 | F6: =SUMIFS('Pedidos Top10'!$AD$2:$AD$1839,'Pedidos Top10'!$A$2:$A$1839,A6) -> 65815.37 | G6: =F6-E6 -> -21311.46 | H6: =IF(E6=0,0,G6/E6) -> -0.24460272 | I6: =IF(D6=0,0,E6/D6) -> 0.19019386 | J6: =IF(D6=0,0,F6/D6) -> 0.14367193 | K6: =COUNTIFS('Pedidos Top10'!$A$2:$A$1839,A6,'Pedidos Top10'!$AG$2:$AG$1839,"PASSARO") -> 439 | L6: =IF(B6=0,0,K6/B6) -> 0.8762475 | M6: =IF(F6<=E6,0,1-E6/F6) -> 0
A7: CE | B7: =COUNTIFS('Pedidos Top10'!$A$2:$A$1839,A7) -> 259 | C7: =SUMIFS('Pedidos Top10'!$J$2:$J$1839,'Pedidos Top10'!$A$2:$A$1839,A7) -> 13113.76 | D7: =SUMIFS('Pedidos Top10'!$K$2:$K$1839,'Pedidos Top10'!$A$2:$A$1839,A7) -> 239912.91 | E7: =SUMIFS('Pedidos Top10'!$L$2:$L$1839,'Pedidos Top10'!$A$2:$A$1839,A7) -> 49566.26 | F7: =SUMIFS('Pedidos Top10'!$AD$2:$AD$1839,'Pedidos Top10'!$A$2:$A$1839,A7) -> 61581.4 | G7: =F7-E7 -> 12015.14 | H7: =IF(E7=0,0,G7/E7) -> 0.24240562 | I7: =IF(D7=0,0,E7/D7) -> 0.20660105 | J7: =IF(D7=0,0,F7/D7) -> 0.25668231 | K7: =COUNTIFS('Pedidos Top10'!$A$2:$A$1839,A7,'Pedidos Top10'!$AG$2:$AG$1839,"PASSARO") -> 24 | L7: =IF(B7=0,0,K7/B7) -> 0.092664093 | M7: =IF(F7<=E7,0,1-E7/F7) -> 0.19510989
A8: MA | B8: =COUNTIFS('Pedidos Top10'!$A$2:$A$1839,A8) -> 152 | C8: =SUMIFS('Pedidos Top10'!$J$2:$J$1839,'Pedidos Top10'!$A$2:$A$1839,A8) -> 8439.19 | D8: =SUMIFS('Pedidos Top10'!$K$2:$K$1839,'Pedidos Top10'!$A$2:$A$1839,A8) -> 156324.13 | E8: =SUMIFS('Pedidos Top10'!$L$2:$L$1839,'Pedidos Top10'!$A$2:$A$1839,A8) -> 27876.98 | F8: =SUMIFS('Pedidos Top10'!$AD$2:$AD$1839,'Pedidos Top10'!$A$2:$A$1839,A8) -> 48379.73 | G8: =F8-E8 -> 20502.75 | H8: =IF(E8=0,0,G8/E8) -> 0.73547242 | I8: =IF(D8=0,0,E8/D8) -> 0.17832807 | J8: =IF(D8=0,0,F8/D8) -> 0.30948344 | K8: =COUNTIFS('Pedidos Top10'!$A$2:$A$1839,A8,'Pedidos Top10'!$AG$2:$AG$1839,"PASSARO") -> 0 | L8: =IF(B8=0,0,K8/B8) -> 0 | M8: =IF(F8<=E8,0,1-E8/F8) -> 0.42378802
A9: PB | B9: =COUNTIFS('Pedidos Top10'!$A$2:$A$1839,A9) -> 117 | C9: =SUMIFS('Pedidos Top10'!$J$2:$J$1839,'Pedidos Top10'!$A$2:$A$1839,A9) -> 5471.92 | D9: =SUMIFS('Pedidos Top10'!$K$2:$K$1839,'Pedidos Top10'!$A$2:$A$1839,A9) -> 101595.23 | E9: =SUMIFS('Pedidos Top10'!$L$2:$L$1839,'Pedidos Top10'!$A$2:$A$1839,A9) -> 20680.9 | F9: =SUMIFS('Pedidos Top10'!$AD$2:$AD$1839,'Pedidos Top10'!$A$2:$A$1839,A9) -> 18903.35 | G9: =F9-E9 -> -1777.55 | H9: =IF(E9=0,0,G9/E9) -> -0.085951288 | I9: =IF(D9=0,0,E9/D9) -> 0.20356172 | J9: =IF(D9=0,0,F9/D9) -> 0.18606533 | K9: =COUNTIFS('Pedidos Top10'!$A$2:$A$1839,A9,'Pedidos Top10'!$AG$2:$AG$1839,"PASSARO") -> 62 | L9: =IF(B9=0,0,K9/B9) -> 0.52991453 | M9: =IF(F9<=E9,0,1-E9/F9) -> 0
A10: PE | B10: =COUNTIFS('Pedidos Top10'!$A$2:$A$1839,A10) -> 349 | C10: =SUMIFS('Pedidos Top10'!$J$2:$J$1839,'Pedidos Top10'!$A$2:$A$1839,A10) -> 16860.63 | D10: =SUMIFS('Pedidos Top10'!$K$2:$K$1839,'Pedidos Top10'!$A$2:$A$1839,A10) -> 309095.04 | E10: =SUMIFS('Pedidos Top10'!$L$2:$L$1839,'Pedidos Top10'!$A$2:$A$1839,A10) -> 61261.87 | F10: =SUMIFS('Pedidos Top10'!$AD$2:$AD$1839,'Pedidos Top10'!$A$2:$A$1839,A10) -> 55213.96 | G10: =F10-E10 -> -6047.91 | H10: =IF(E10=0,0,G10/E10) -> -0.098722256 | I10: =IF(D10=0,0,E10/D10) -> 0.19819752 | J10: =IF(D10=0,0,F10/D10) -> 0.17863101 | K10: =COUNTIFS('Pedidos Top10'!$A$2:$A$1839,A10,'Pedidos Top10'!$AG$2:$AG$1839,"PASSARO") -> 229 | L10: =IF(B10=0,0,K10/B10) -> 0.65616046 | M10: =IF(F10<=E10,0,1-E10/F10) -> 0
A11: PI | B11: =COUNTIFS('Pedidos Top10'!$A$2:$A$1839,A11) -> 109 | C11: =SUMIFS('Pedidos Top10'!$J$2:$J$1839,'Pedidos Top10'!$A$2:$A$1839,A11) -> 6382.36 | D11: =SUMIFS('Pedidos Top10'!$K$2:$K$1839,'Pedidos Top10'!$A$2:$A$1839,A11) -> 121179.11 | E11: =SUMIFS('Pedidos Top10'!$L$2:$L$1839,'Pedidos Top10'!$A$2:$A$1839,A11) -> 22463.82 | F11: =SUMIFS('Pedidos Top10'!$AD$2:$AD$1839,'Pedidos Top10'!$A$2:$A$1839,A11) -> 38265.91 | G11: =F11-E11 -> 15802.09 | H11: =IF(E11=0,0,G11/E11) -> 0.70344625 | I11: =IF(D11=0,0,E11/D11) -> 0.185377 | J11: =IF(D11=0,0,F11/D11) -> 0.31577976 | K11: =COUNTIFS('Pedidos Top10'!$A$2:$A$1839,A11,'Pedidos Top10'!$AG$2:$AG$1839,"PASSARO") -> 0 | L11: =IF(B11=0,0,K11/B11) -> 0 | M11: =IF(F11<=E11,0,1-E11/F11) -> 0.41295477
A12: RN | B12: =COUNTIFS('Pedidos Top10'!$A$2:$A$1839,A12) -> 87 | C12: =SUMIFS('Pedidos Top10'!$J$2:$J$1839,'Pedidos Top10'!$A$2:$A$1839,A12) -> 3596.46 | D12: =SUMIFS('Pedidos Top10'!$K$2:$K$1839,'Pedidos Top10'!$A$2:$A$1839,A12) -> 72403.64 | E12: =SUMIFS('Pedidos Top10'!$L$2:$L$1839,'Pedidos Top10'!$A$2:$A$1839,A12) -> 15341.02 | F12: =SUMIFS('Pedidos Top10'!$AD$2:$AD$1839,'Pedidos Top10'!$A$2:$A$1839,A12) -> 17311.51 | G12: =F12-E12 -> 1970.49 | H12: =IF(E12=0,0,G12/E12) -> 0.12844583 | I12: =IF(D12=0,0,E12/D12) -> 0.21188189 | J12: =IF(D12=0,0,F12/D12) -> 0.23909723 | K12: =COUNTIFS('Pedidos Top10'!$A$2:$A$1839,A12,'Pedidos Top10'!$AG$2:$AG$1839,"PASSARO") -> 37 | L12: =IF(B12=0,0,K12/B12) -> 0.42528736 | M12: =IF(F12<=E12,0,1-E12/F12) -> 0.11382543
A13: SE | B13: =COUNTIFS('Pedidos Top10'!$A$2:$A$1839,A13) -> 97 | C13: =SUMIFS('Pedidos Top10'!$J$2:$J$1839,'Pedidos Top10'!$A$2:$A$1839,A13) -> 5118.27 | D13: =SUMIFS('Pedidos Top10'!$K$2:$K$1839,'Pedidos Top10'!$A$2:$A$1839,A13) -> 90462.68 | E13: =SUMIFS('Pedidos Top10'!$L$2:$L$1839,'Pedidos Top10'!$A$2:$A$1839,A13) -> 17913.36 | F13: =SUMIFS('Pedidos Top10'!$AD$2:$AD$1839,'Pedidos Top10'!$A$2:$A$1839,A13) -> 14694.3 | G13: =F13-E13 -> -3219.06 | H13: =IF(E13=0,0,G13/E13) -> -0.17970163 | I13: =IF(D13=0,0,E13/D13) -> 0.19801934 | J13: =IF(D13=0,0,F13/D13) -> 0.16243494 | K13: =COUNTIFS('Pedidos Top10'!$A$2:$A$1839,A13,'Pedidos Top10'!$AG$2:$AG$1839,"PASSARO") -> 72 | L13: =IF(B13=0,0,K13/B13) -> 0.74226804 | M13: =IF(F13<=E13,0,1-E13/F13) -> 0
A14: TOTAL | B14: =SUM(B5:B13) -> 1838 | C14: =SUM(C5:C13) -> 93805.65 | D14: =SUM(D5:D13) -> 1705949 | E14: =SUM(E5:E13) -> 331388.59 | F14: =SUM(F5:F13) -> 345898.93 | G14: =F14-E14 -> 14510.34 | H14: =IF(E14=0,0,G14/E14) -> 0.04378648 | I14: =IF(D14=0,0,E14/D14) -> 0.19425468 | J14: =IF(D14=0,0,F14/D14) -> 0.20276041 | K14: =SUM(K5:K13) -> 978 | L14: =IF(B14=0,0,K14/B14) -> 0.53210011 | M14: =IF(F14<=E14,0,1-E14/F14) -> 0.041949653
A17: Por transportadora atual (mesmos pedidos, Top 10 cidades)
A18: Transportadora | B18: Pedidos | C18: Peso total (kg) | D18: Valor NF total (R$) | E18: Frete atual (R$) | F18: Frete PASSARO (R$) | G18: Diferença (R$) | H18: Dif. % | I18: Ticket médio atual | J18: Ticket médio Passaro | K18: Pedidos em que Passaro é mais barata | L18: % pedidos Passaro mais barata | M18: R$/kg atual
A19: DOMINALOG | B19: =COUNTIFS('Pedidos Top10'!$D$2:$D$1839,A19) -> 1515 | C19: =SUMIFS('Pedidos Top10'!$J$2:$J$1839,'Pedidos Top10'!$D$2:$D$1839,A19) -> 80915.33 | D19: =SUMIFS('Pedidos Top10'!$K$2:$K$1839,'Pedidos Top10'!$D$2:$D$1839,A19) -> 1449016 | E19: =SUMIFS('Pedidos Top10'!$L$2:$L$1839,'Pedidos Top10'!$D$2:$D$1839,A19) -> 287729.07 | F19: =SUMIFS('Pedidos Top10'!$AD$2:$AD$1839,'Pedidos Top10'!$D$2:$D$1839,A19) -> 276618.41 | G19: =F19-E19 -> -11110.66 | H19: =IF(E19=0,0,G19/E19) -> -0.038615007 | I19: =IF(B19=0,0,E19/B19) -> 189.92018 | J19: =IF(B19=0,0,F19/B19) -> 182.58641 | K19: =COUNTIFS('Pedidos Top10'!$D$2:$D$1839,A19,'Pedidos Top10'!$AG$2:$AG$1839,"PASSARO") -> 952 | L19: =IF(B19=0,0,K19/B19) -> 0.62838284 | M19: =IF(C19=0,0,E19/C19) -> 3.5559278
A20: JADLOG | B20: =COUNTIFS('Pedidos Top10'!$D$2:$D$1839,A20) -> 193 | C20: =SUMIFS('Pedidos Top10'!$J$2:$J$1839,'Pedidos Top10'!$D$2:$D$1839,A20) -> 3725.4 | D20: =SUMIFS('Pedidos Top10'!$K$2:$K$1839,'Pedidos Top10'!$D$2:$D$1839,A20) -> 93526.9 | E20: =SUMIFS('Pedidos Top10'!$L$2:$L$1839,'Pedidos Top10'!$D$2:$D$1839,A20) -> 15437.82 | F20: =SUMIFS('Pedidos Top10'!$AD$2:$AD$1839,'Pedidos Top10'!$D$2:$D$1839,A20) -> 29194.04 | G20: =F20-E20 -> 13756.22 | H20: =IF(E20=0,0,G20/E20) -> 0.8910727 | I20: =IF(B20=0,0,E20/B20) -> 79.988705 | J20: =IF(B20=0,0,F20/B20) -> 151.26446 | K20: =COUNTIFS('Pedidos Top10'!$D$2:$D$1839,A20,'Pedidos Top10'!$AG$2:$AG$1839,"PASSARO") -> 0 | L20: =IF(B20=0,0,K20/B20) -> 0 | M20: =IF(C20=0,0,E20/C20) -> 4.1439362
A21: Bento Brasil | B21: =COUNTIFS('Pedidos Top10'!$D$2:$D$1839,A21) -> 100 | C21: =SUMIFS('Pedidos Top10'!$J$2:$J$1839,'Pedidos Top10'!$D$2:$D$1839,A21) -> 7362.73 | D21: =SUMIFS('Pedidos Top10'!$K$2:$K$1839,'Pedidos Top10'!$D$2:$D$1839,A21) -> 131134.43 | E21: =SUMIFS('Pedidos Top10'!$L$2:$L$1839,'Pedidos Top10'!$D$2:$D$1839,A21) -> 21243.1 | F21: =SUMIFS('Pedidos Top10'!$AD$2:$AD$1839,'Pedidos Top10'!$D$2:$D$1839,A21) -> 34564.99 | G21: =F21-E21 -> 13321.89 | H21: =IF(E21=0,0,G21/E21) -> 0.6271161 | I21: =IF(B21=0,0,E21/B21) -> 212.431 | J21: =IF(B21=0,0,F21/B21) -> 345.6499 | K21: =COUNTIFS('Pedidos Top10'!$D$2:$D$1839,A21,'Pedidos Top10'!$AG$2:$AG$1839,"PASSARO") -> 0 | L21: =IF(B21=0,0,K21/B21) -> 0 | M21: =IF(C21=0,0,E21/C21) -> 2.8852206
A22: Atual Cargas | B22: =COUNTIFS('Pedidos Top10'!$D$2:$D$1839,A22) -> 18 | C22: =SUMIFS('Pedidos Top10'!$J$2:$J$1839,'Pedidos Top10'!$D$2:$D$1839,A22) -> 998.13 | D22: =SUMIFS('Pedidos Top10'!$K$2:$K$1839,'Pedidos Top10'!$D$2:$D$1839,A22) -> 19241.74 | E22: =SUMIFS('Pedidos Top10'!$L$2:$L$1839,'Pedidos Top10'!$D$2:$D$1839,A22) -> 4141.87 | F22: =SUMIFS('Pedidos Top10'!$AD$2:$AD$1839,'Pedidos Top10'!$D$2:$D$1839,A22) -> 3131.26 | G22: =F22-E22 -> -1010.61 | H22: =IF(E22=0,0,G22/E22) -> -0.24399848 | I22: =IF(B22=0,0,E22/B22) -> 230.10389 | J22: =IF(B22=0,0,F22/B22) -> 173.95889 | K22: =COUNTIFS('Pedidos Top10'!$D$2:$D$1839,A22,'Pedidos Top10'!$AG$2:$AG$1839,"PASSARO") -> 15 | L22: =IF(B22=0,0,K22/B22) -> 0.83333333 | M22: =IF(C22=0,0,E22/C22) -> 4.1496298
A23: FORMATO TRANSPORTES | B23: =COUNTIFS('Pedidos Top10'!$D$2:$D$1839,A23) -> 10 | C23: =SUMIFS('Pedidos Top10'!$J$2:$J$1839,'Pedidos Top10'!$D$2:$D$1839,A23) -> 681.96 | D23: =SUMIFS('Pedidos Top10'!$K$2:$K$1839,'Pedidos Top10'!$D$2:$D$1839,A23) -> 10834.21 | E23: =SUMIFS('Pedidos Top10'!$L$2:$L$1839,'Pedidos Top10'!$D$2:$D$1839,A23) -> 2402.66 | F23: =SUMIFS('Pedidos Top10'!$AD$2:$AD$1839,'Pedidos Top10'!$D$2:$D$1839,A23) -> 2083.78 | G23: =F23-E23 -> -318.88 | H23: =IF(E23=0,0,G23/E23) -> -0.13271957 | I23: =IF(B23=0,0,E23/B23) -> 240.266 | J23: =IF(B23=0,0,F23/B23) -> 208.378 | K23: =COUNTIFS('Pedidos Top10'!$D$2:$D$1839,A23,'Pedidos Top10'!$AG$2:$AG$1839,"PASSARO") -> 9 | L23: =IF(B23=0,0,K23/B23) -> 0.9 | M23: =IF(C23=0,0,E23/C23) -> 3.5231685
A24: ZAFER | B24: =COUNTIFS('Pedidos Top10'!$D$2:$D$1839,A24) -> 2 | C24: =SUMIFS('Pedidos Top10'!$J$2:$J$1839,'Pedidos Top10'!$D$2:$D$1839,A24) -> 122.1 | D24: =SUMIFS('Pedidos Top10'!$K$2:$K$1839,'Pedidos Top10'!$D$2:$D$1839,A24) -> 2195.74 | E24: =SUMIFS('Pedidos Top10'!$L$2:$L$1839,'Pedidos Top10'!$D$2:$D$1839,A24) -> 434.07 | F24: =SUMIFS('Pedidos Top10'!$AD$2:$AD$1839,'Pedidos Top10'!$D$2:$D$1839,A24) -> 306.45 | G24: =F24-E24 -> -127.62 | H24: =IF(E24=0,0,G24/E24) -> -0.29400788 | I24: =IF(B24=0,0,E24/B24) -> 217.035 | J24: =IF(B24=0,0,F24/B24) -> 153.225 | K24: =COUNTIFS('Pedidos Top10'!$D$2:$D$1839,A24,'Pedidos Top10'!$AG$2:$AG$1839,"PASSARO") -> 2 | L24: =IF(B24=0,0,K24/B24) -> 1 | M24: =IF(C24=0,0,E24/C24) -> 3.5550369
A27: Por faixa de peso (onde a tabela Passaro é mais competitiva)
A28: Faixa de peso | B28: Pedidos | C28: Peso total (kg) | D28: Valor NF total (R$) | E28: Frete atual (R$) | F28: Frete PASSARO (R$) | G28: Diferença (R$) | H28: Dif. % | I28: Ticket médio atual | J28: Ticket médio Passaro | K28: Pedidos em que Passaro é mais barata | L28: % pedidos Passaro mais barata
A29: até 10 kg | B29: =COUNTIFS('Pedidos Top10'!$J$2:$J$1839,">"&0,'Pedidos Top10'!$J$2:$J$1839,"<="&10) -> 22 | C29: =SUMIFS('Pedidos Top10'!$J$2:$J$1839,'Pedidos Top10'!$J$2:$J$1839,">"&0,'Pedidos Top10'!$J$2:$J$1839,"<="&10) -> 132.93 | D29: =SUMIFS('Pedidos Top10'!$K$2:$K$1839,'Pedidos Top10'!$J$2:$J$1839,">"&0,'Pedidos Top10'!$J$2:$J$1839,"<="&10) -> 10157.63 | E29: =SUMIFS('Pedidos Top10'!$L$2:$L$1839,'Pedidos Top10'!$J$2:$J$1839,">"&0,'Pedidos Top10'!$J$2:$J$1839,"<="&10) -> 1364.48 | F29: =SUMIFS('Pedidos Top10'!$AD$2:$AD$1839,'Pedidos Top10'!$J$2:$J$1839,">"&0,'Pedidos Top10'!$J$2:$J$1839,"<="&10) -> 2929.13 | G29: =F29-E29 -> 1564.65 | H29: =IF(E29=0,0,G29/E29) -> 1.1467006 | I29: =IF(B29=0,0,E29/B29) -> 62.021818 | J29: =IF(B29=0,0,F29/B29) -> 133.14227 | K29: =COUNTIFS('Pedidos Top10'!$J$2:$J$1839,">"&0,'Pedidos Top10'!$J$2:$J$1839,"<="&10,'Pedidos Top10'!$AG$2:$AG$1839,"PASSARO") -> 0 | L29: =IF(B29=0,0,K29/B29) -> 0
A30: 10–30 kg | B30: =COUNTIFS('Pedidos Top10'!$J$2:$J$1839,">"&10,'Pedidos Top10'!$J$2:$J$1839,"<="&30) -> 528 | C30: =SUMIFS('Pedidos Top10'!$J$2:$J$1839,'Pedidos Top10'!$J$2:$J$1839,">"&10,'Pedidos Top10'!$J$2:$J$1839,"<="&30) -> 11946.07 | D30: =SUMIFS('Pedidos Top10'!$K$2:$K$1839,'Pedidos Top10'!$J$2:$J$1839,">"&10,'Pedidos Top10'!$J$2:$J$1839,"<="&30) -> 305423.88 | E30: =SUMIFS('Pedidos Top10'!$L$2:$L$1839,'Pedidos Top10'!$J$2:$J$1839,">"&10,'Pedidos Top10'!$J$2:$J$1839,"<="&30) -> 56316.91 | F30: =SUMIFS('Pedidos Top10'!$AD$2:$AD$1839,'Pedidos Top10'!$J$2:$J$1839,">"&10,'Pedidos Top10'!$J$2:$J$1839,"<="&30) -> 82983.09 | G30: =F30-E30 -> 26666.18 | H30: =IF(E30=0,0,G30/E30) -> 0.47350219 | I30: =IF(B30=0,0,E30/B30) -> 106.66081 | J30: =IF(B30=0,0,F30/B30) -> 157.16494 | K30: =COUNTIFS('Pedidos Top10'!$J$2:$J$1839,">"&10,'Pedidos Top10'!$J$2:$J$1839,"<="&30,'Pedidos Top10'!$AG$2:$AG$1839,"PASSARO") -> 120 | L30: =IF(B30=0,0,K30/B30) -> 0.22727273
A31: 30–50 kg | B31: =COUNTIFS('Pedidos Top10'!$J$2:$J$1839,">"&30,'Pedidos Top10'!$J$2:$J$1839,"<="&50) -> 533 | C31: =SUMIFS('Pedidos Top10'!$J$2:$J$1839,'Pedidos Top10'!$J$2:$J$1839,">"&30,'Pedidos Top10'!$J$2:$J$1839,"<="&50) -> 21075.53 | D31: =SUMIFS('Pedidos Top10'!$K$2:$K$1839,'Pedidos Top10'!$J$2:$J$1839,">"&30,'Pedidos Top10'!$J$2:$J$1839,"<="&50) -> 379477.45 | E31: =SUMIFS('Pedidos Top10'!$L$2:$L$1839,'Pedidos Top10'!$J$2:$J$1839,">"&30,'Pedidos Top10'!$J$2:$J$1839,"<="&50) -> 87391.89 | F31: =SUMIFS('Pedidos Top10'!$AD$2:$AD$1839,'Pedidos Top10'!$J$2:$J$1839,">"&30,'Pedidos Top10'!$J$2:$J$1839,"<="&50) -> 92274.79 | G31: =F31-E31 -> 4882.9 | H31: =IF(E31=0,0,G31/E31) -> 0.055873606 | I31: =IF(B31=0,0,E31/B31) -> 163.96227 | J31: =IF(B31=0,0,F31/B31) -> 173.12343 | K31: =COUNTIFS('Pedidos Top10'!$J$2:$J$1839,">"&30,'Pedidos Top10'!$J$2:$J$1839,"<="&50,'Pedidos Top10'!$AG$2:$AG$1839,"PASSARO") -> 333 | L31: =IF(B31=0,0,K31/B31) -> 0.62476548
A32: 50–70 kg | B32: =COUNTIFS('Pedidos Top10'!$J$2:$J$1839,">"&50,'Pedidos Top10'!$J$2:$J$1839,"<="&70) -> 456 | C32: =SUMIFS('Pedidos Top10'!$J$2:$J$1839,'Pedidos Top10'!$J$2:$J$1839,">"&50,'Pedidos Top10'!$J$2:$J$1839,"<="&70) -> 27589.22 | D32: =SUMIFS('Pedidos Top10'!$K$2:$K$1839,'Pedidos Top10'!$J$2:$J$1839,">"&50,'Pedidos Top10'!$J$2:$J$1839,"<="&70) -> 479901.08 | E32: =SUMIFS('Pedidos Top10'!$L$2:$L$1839,'Pedidos Top10'!$J$2:$J$1839,">"&50,'Pedidos Top10'!$J$2:$J$1839,"<="&70) -> 92754.76 | F32: =SUMIFS('Pedidos Top10'!$AD$2:$AD$1839,'Pedidos Top10'!$J$2:$J$1839,">"&50,'Pedidos Top10'!$J$2:$J$1839,"<="&70) -> 88503.04 | G32: =F32-E32 -> -4251.72 | H32: =IF(E32=0,0,G32/E32) -> -0.045838294 | I32: =IF(B32=0,0,E32/B32) -> 203.40956 | J32: =IF(B32=0,0,F32/B32) -> 194.08561 | K32: =COUNTIFS('Pedidos Top10'!$J$2:$J$1839,">"&50,'Pedidos Top10'!$J$2:$J$1839,"<="&70,'Pedidos Top10'!$AG$2:$AG$1839,"PASSARO") -> 300 | L32: =IF(B32=0,0,K32/B32) -> 0.65789474
A33: 70–100 kg | B33: =COUNTIFS('Pedidos Top10'!$J$2:$J$1839,">"&70,'Pedidos Top10'!$J$2:$J$1839,"<="&100) -> 109 | C33: =SUMIFS('Pedidos Top10'!$J$2:$J$1839,'Pedidos Top10'!$J$2:$J$1839,">"&70,'Pedidos Top10'!$J$2:$J$1839,"<="&100) -> 8662.37 | D33: =SUMIFS('Pedidos Top10'!$K$2:$K$1839,'Pedidos Top10'!$J$2:$J$1839,">"&70,'Pedidos Top10'!$J$2:$J$1839,"<="&100) -> 143464 | E33: =SUMIFS('Pedidos Top10'!$L$2:$L$1839,'Pedidos Top10'!$J$2:$J$1839,">"&70,'Pedidos Top10'!$J$2:$J$1839,"<="&100) -> 27897.63 | F33: =SUMIFS('Pedidos Top10'!$AD$2:$AD$1839,'Pedidos Top10'!$J$2:$J$1839,">"&70,'Pedidos Top10'!$J$2:$J$1839,"<="&100) -> 22871.45 | G33: =F33-E33 -> -5026.18 | H33: =IF(E33=0,0,G33/E33) -> -0.18016513 | I33: =IF(B33=0,0,E33/B33) -> 255.94156 | J33: =IF(B33=0,0,F33/B33) -> 209.82982 | K33: =COUNTIFS('Pedidos Top10'!$J$2:$J$1839,">"&70,'Pedidos Top10'!$J$2:$J$1839,"<="&100,'Pedidos Top10'!$AG$2:$AG$1839,"PASSARO") -> 87 | L33: =IF(B33=0,0,K33/B33) -> 0.79816514
A34: acima de 100 kg | B34: =COUNTIFS('Pedidos Top10'!$J$2:$J$1839,">"&100,'Pedidos Top10'!$J$2:$J$1839,"<="&1000000000) -> 190 | C34: =SUMIFS('Pedidos Top10'!$J$2:$J$1839,'Pedidos Top10'!$J$2:$J$1839,">"&100,'Pedidos Top10'!$J$2:$J$1839,"<="&1000000000) -> 24399.53 | D34: =SUMIFS('Pedidos Top10'!$K$2:$K$1839,'Pedidos Top10'!$J$2:$J$1839,">"&100,'Pedidos Top10'!$J$2:$J$1839,"<="&1000000000) -> 387525 | E34: =SUMIFS('Pedidos Top10'!$L$2:$L$1839,'Pedidos Top10'!$J$2:$J$1839,">"&100,'Pedidos Top10'!$J$2:$J$1839,"<="&1000000000) -> 65662.92 | F34: =SUMIFS('Pedidos Top10'!$AD$2:$AD$1839,'Pedidos Top10'!$J$2:$J$1839,">"&100,'Pedidos Top10'!$J$2:$J$1839,"<="&1000000000) -> 56337.43 | G34: =F34-E34 -> -9325.49 | H34: =IF(E34=0,0,G34/E34) -> -0.14202064 | I34: =IF(B34=0,0,E34/B34) -> 345.59432 | J34: =IF(B34=0,0,F34/B34) -> 296.51279 | K34: =COUNTIFS('Pedidos Top10'!$J$2:$J$1839,">"&100,'Pedidos Top10'!$J$2:$J$1839,"<="&1000000000,'Pedidos Top10'!$AG$2:$AG$1839,"PASSARO") -> 138 | L34: =IF(B34=0,0,K34/B34) -> 0.72631579
A37: Proposta 1 (com TRT/TDA) x Proposta 2 – mesmos pedidos
A38: UF | B38: Pedidos comparáveis | C38: Frete atual (R$) | D38: Passaro PROPOSTA 1 (R$) | E38: Passaro PROPOSTA 2 (R$) | F38: Variação P2 − P1 (R$) | G38: Variação % | H38: Dif. % PROPOSTA 1 x atual | I38: Dif. % PROPOSTA 2 x atual
A39: AL | B39: =COUNTIFS('Pedidos Top10'!$A$2:$A$1839,A39,'Pedidos Top10'!$AI$2:$AI$1839,"<>") -> 167 | C39: =SUMIFS('Pedidos Top10'!$L$2:$L$1839,'Pedidos Top10'!$A$2:$A$1839,A39,'Pedidos Top10'!$AI$2:$AI$1839,"<>") -> 29157.55 | D39: =SUMIFS('Pedidos Top10'!$AI$2:$AI$1839,'Pedidos Top10'!$A$2:$A$1839,A39) -> 31156.23 | E39: =SUMIFS('Pedidos Top10'!$AD$2:$AD$1839,'Pedidos Top10'!$A$2:$A$1839,A39,'Pedidos Top10'!$AI$2:$AI$1839,"<>") -> 25733.4 | F39: =E39-D39 -> -5422.83 | G39: =IF(D39=0,0,F39/D39) -> -0.17405283 | H39: =IF(C39=0,0,D39/C39-1) -> 0.068547597 | I39: =IF(C39=0,0,E39/C39-1) -> -0.11743614
A40: BA | B40: =COUNTIFS('Pedidos Top10'!$A$2:$A$1839,A40,'Pedidos Top10'!$AI$2:$AI$1839,"<>") -> 501 | C40: =SUMIFS('Pedidos Top10'!$L$2:$L$1839,'Pedidos Top10'!$A$2:$A$1839,A40,'Pedidos Top10'!$AI$2:$AI$1839,"<>") -> 87126.83 | D40: =SUMIFS('Pedidos Top10'!$AI$2:$AI$1839,'Pedidos Top10'!$A$2:$A$1839,A40) -> 81429.66 | E40: =SUMIFS('Pedidos Top10'!$AD$2:$AD$1839,'Pedidos Top10'!$A$2:$A$1839,A40,'Pedidos Top10'!$AI$2:$AI$1839,"<>") -> 65815.37 | F40: =E40-D40 -> -15614.29 | G40: =IF(D40=0,0,F40/D40) -> -0.19175188 | H40: =IF(C40=0,0,D40/C40-1) -> -0.065389387 | I40: =IF(C40=0,0,E40/C40-1) -> -0.24460272
A41: CE | B41: =COUNTIFS('Pedidos Top10'!$A$2:$A$1839,A41,'Pedidos Top10'!$AI$2:$AI$1839,"<>") -> 259 | C41: =SUMIFS('Pedidos Top10'!$L$2:$L$1839,'Pedidos Top10'!$A$2:$A$1839,A41,'Pedidos Top10'!$AI$2:$AI$1839,"<>") -> 49566.26 | D41: =SUMIFS('Pedidos Top10'!$AI$2:$AI$1839,'Pedidos Top10'!$A$2:$A$1839,A41) -> 71205.24 | E41: =SUMIFS('Pedidos Top10'!$AD$2:$AD$1839,'Pedidos Top10'!$A$2:$A$1839,A41,'Pedidos Top10'!$AI$2:$AI$1839,"<>") -> 61581.4 | F41: =E41-D41 -> -9623.84 | G41: =IF(D41=0,0,F41/D41) -> -0.13515635 | H41: =IF(C41=0,0,D41/C41-1) -> 0.43656673 | I41: =IF(C41=0,0,E41/C41-1) -> 0.24240562
A42: MA | B42: =COUNTIFS('Pedidos Top10'!$A$2:$A$1839,A42,'Pedidos Top10'!$AI$2:$AI$1839,"<>") -> 152 | C42: =SUMIFS('Pedidos Top10'!$L$2:$L$1839,'Pedidos Top10'!$A$2:$A$1839,A42,'Pedidos Top10'!$AI$2:$AI$1839,"<>") -> 27876.98 | D42: =SUMIFS('Pedidos Top10'!$AI$2:$AI$1839,'Pedidos Top10'!$A$2:$A$1839,A42) -> 54495.97 | E42: =SUMIFS('Pedidos Top10'!$AD$2:$AD$1839,'Pedidos Top10'!$A$2:$A$1839,A42,'Pedidos Top10'!$AI$2:$AI$1839,"<>") -> 48379.73 | F42: =E42-D42 -> -6116.24 | G42: =IF(D42=0,0,F42/D42) -> -0.11223289 | H42: =IF(C42=0,0,D42/C42-1) -> 0.95487352 | I42: =IF(C42=0,0,E42/C42-1) -> 0.73547242
A43: PB | B43: =COUNTIFS('Pedidos Top10'!$A$2:$A$1839,A43,'Pedidos Top10'!$AI$2:$AI$1839,"<>") -> 117 | C43: =SUMIFS('Pedidos Top10'!$L$2:$L$1839,'Pedidos Top10'!$A$2:$A$1839,A43,'Pedidos Top10'!$AI$2:$AI$1839,"<>") -> 20680.9 | D43: =SUMIFS('Pedidos Top10'!$AI$2:$AI$1839,'Pedidos Top10'!$A$2:$A$1839,A43) -> 23356.17 | E43: =SUMIFS('Pedidos Top10'!$AD$2:$AD$1839,'Pedidos Top10'!$A$2:$A$1839,A43,'Pedidos Top10'!$AI$2:$AI$1839,"<>") -> 18903.35 | F43: =E43-D43 -> -4452.82 | G43: =IF(D43=0,0,F43/D43) -> -0.19064855 | H43: =IF(C43=0,0,D43/C43-1) -> 0.12935946 | I43: =IF(C43=0,0,E43/C43-1) -> -0.085951288
A44: PE | B44: =COUNTIFS('Pedidos Top10'!$A$2:$A$1839,A44,'Pedidos Top10'!$AI$2:$AI$1839,"<>") -> 349 | C44: =SUMIFS('Pedidos Top10'!$L$2:$L$1839,'Pedidos Top10'!$A$2:$A$1839,A44,'Pedidos Top10'!$AI$2:$AI$1839,"<>") -> 61261.87 | D44: =SUMIFS('Pedidos Top10'!$AI$2:$AI$1839,'Pedidos Top10'!$A$2:$A$1839,A44) -> 67195.61 | E44: =SUMIFS('Pedidos Top10'!$AD$2:$AD$1839,'Pedidos Top10'!$A$2:$A$1839,A44,'Pedidos Top10'!$AI$2:$AI$1839,"<>") -> 55213.96 | F44: =E44-D44 -> -11981.65 | G44: =IF(D44=0,0,F44/D44) -> -0.17831001 | H44: =IF(C44=0,0,D44/C44-1) -> 0.096858617 | I44: =IF(C44=0,0,E44/C44-1) -> -0.098722256
A45: PI | B45: =COUNTIFS('Pedidos Top10'!$A$2:$A$1839,A45,'Pedidos Top10'!$AI$2:$AI$1839,"<>") -> 109 | C45: =SUMIFS('Pedidos Top10'!$L$2:$L$1839,'Pedidos Top10'!$A$2:$A$1839,A45,'Pedidos Top10'!$AI$2:$AI$1839,"<>") -> 22463.82 | D45: =SUMIFS('Pedidos Top10'!$AI$2:$AI$1839,'Pedidos Top10'!$A$2:$A$1839,A45) -> 43050.97 | E45: =SUMIFS('Pedidos Top10'!$AD$2:$AD$1839,'Pedidos Top10'!$A$2:$A$1839,A45,'Pedidos Top10'!$AI$2:$AI$1839,"<>") -> 38265.91 | F45: =E45-D45 -> -4785.06 | G45: =IF(D45=0,0,F45/D45) -> -0.11114872 | H45: =IF(C45=0,0,D45/C45-1) -> 0.91645811 | I45: =IF(C45=0,0,E45/C45-1) -> 0.70344625
A46: RN | B46: =COUNTIFS('Pedidos Top10'!$A$2:$A$1839,A46,'Pedidos Top10'!$AI$2:$AI$1839,"<>") -> 87 | C46: =SUMIFS('Pedidos Top10'!$L$2:$L$1839,'Pedidos Top10'!$A$2:$A$1839,A46,'Pedidos Top10'!$AI$2:$AI$1839,"<>") -> 15341.02 | D46: =SUMIFS('Pedidos Top10'!$AI$2:$AI$1839,'Pedidos Top10'!$A$2:$A$1839,A46) -> 20833.87 | E46: =SUMIFS('Pedidos Top10'!$AD$2:$AD$1839,'Pedidos Top10'!$A$2:$A$1839,A46,'Pedidos Top10'!$AI$2:$AI$1839,"<>") -> 17311.51 | F46: =E46-D46 -> -3522.36 | G46: =IF(D46=0,0,F46/D46) -> -0.16906892 | H46: =IF(C46=0,0,D46/C46-1) -> 0.35804986 | I46: =IF(C46=0,0,E46/C46-1) -> 0.12844583
A47: SE | B47: =COUNTIFS('Pedidos Top10'!$A$2:$A$1839,A47,'Pedidos Top10'!$AI$2:$AI$1839,"<>") -> 97 | C47: =SUMIFS('Pedidos Top10'!$L$2:$L$1839,'Pedidos Top10'!$A$2:$A$1839,A47,'Pedidos Top10'!$AI$2:$AI$1839,"<>") -> 17913.36 | D47: =SUMIFS('Pedidos Top10'!$AI$2:$AI$1839,'Pedidos Top10'!$A$2:$A$1839,A47) -> 17802.36 | E47: =SUMIFS('Pedidos Top10'!$AD$2:$AD$1839,'Pedidos Top10'!$A$2:$A$1839,A47,'Pedidos Top10'!$AI$2:$AI$1839,"<>") -> 14694.3 | F47: =E47-D47 -> -3108.06 | G47: =IF(D47=0,0,F47/D47) -> -0.17458696 | H47: =IF(C47=0,0,D47/C47-1) -> -0.0061964925 | I47: =IF(C47=0,0,E47/C47-1) -> -0.17970163
...

Sheet Top10 Cidades
A1: UF | B1: Rank | C1: Cidade | D1: Pedidos | E1: Peso total (kg) | F1: Frete atual (R$) | G1: Frete PASSARO (R$) | H1: Diferença (R$) | I1: Dif. % | J1: Ticket médio atual | K1: Ticket médio Passaro | L1: R$/kg atual | M1: R$/kg Passaro | N1: Prazo Passaro (dias) | O1: % pedidos Passaro mais barata | P1: Transportadora principal hoje | Q1: Transportadoras atuantes | R1: Veredito
A2: AL | B2: 1 | C2: MACEIO | D2: =COUNTIFS('Pedidos Top10'!$A$2:$A$1839,A2,'Pedidos Top10'!$C$2:$C$1839,C2) -> 110 | E2: =SUMIFS('Pedidos Top10'!$J$2:$J$1839,'Pedidos Top10'!$A$2:$A$1839,A2,'Pedidos Top10'!$C$2:$C$1839,C2) -> 5274.84 | F2: =SUMIFS('Pedidos Top10'!$L$2:$L$1839,'Pedidos Top10'!$A$2:$A$1839,A2,'Pedidos Top10'!$C$2:$C$1839,C2) -> 18085.24 | G2: =SUMIFS('Pedidos Top10'!$AD$2:$AD$1839,'Pedidos Top10'!$A$2:$A$1839,A2,'Pedidos Top10'!$C$2:$C$1839,C2) -> 15398.57 | H2: =G2-F2 -> -2686.67 | I2: =IF(F2=0,0,H2/F2) -> -0.14855595 | J2: =IF(D2=0,0,F2/D2) -> 164.41127 | K2: =IF(D2=0,0,G2/D2) -> 139.987 | L2: =IF(E2=0,0,F2/E2) -> 3.4285855 | M2: =IF(E2=0,0,G2/E2) -> 2.9192487 | N2: 8 | O2: =IF(D2=0,0,COUNTIFS('Pedidos Top10'!$A$2:$A$1839,A2,'Pedidos Top10'!$C$2:$C$1839,C2,'Pedidos Top10'!$AG$2:$AG$1839,"PASSARO")/D2) -> 0.78181818 | P2: DOMINALOG | Q2: DOMINALOG (90), JADLOG (19), ZAFER (1) | R2: =IF(I2<=-0.05,"Passaro mais barata",IF(I2<0.05,"Empate técnico (±5%)","Passaro mais cara")) -> Passaro mais barata
A3: AL | B3: 2 | C3: ARAPIRACA | D3: =COUNTIFS('Pedidos Top10'!$A$2:$A$1839,A3,'Pedidos Top10'!$C$2:$C$1839,C3) -> 26 | E3: =SUMIFS('Pedidos Top10'!$J$2:$J$1839,'Pedidos Top10'!$A$2:$A$1839,A3,'Pedidos Top10'!$C$2:$C$1839,C3) -> 921.45 | F3: =SUMIFS('Pedidos Top10'!$L$2:$L$1839,'Pedidos Top10'!$A$2:$A$1839,A3,'Pedidos Top10'!$C$2:$C$1839,C3) -> 3849.53 | G3: =SUMIFS('Pedidos Top10'!$AD$2:$AD$1839,'Pedidos Top10'!$A$2:$A$1839,A3,'Pedidos Top10'!$C$2:$C$1839,C3) -> 4064.41 | H3: =G3-F3 -> 214.88 | I3: =IF(F3=0,0,H3/F3) -> 0.055819801 | J3: =IF(D3=0,0,F3/D3) -> 148.05885 | K3: =IF(D3=0,0,G3/D3) -> 156.32346 | L3: =IF(E3=0,0,F3/E3) -> 4.1776873 | M3: =IF(E3=0,0,G3/E3) -> 4.410885 | N3: 10 | O3: =IF(D3=0,0,COUNTIFS('Pedidos Top10'!$A$2:$A$1839,A3,'Pedidos Top10'!$C$2:$C$1839,C3,'Pedidos Top10'!$AG$2:$AG$1839,"PASSARO")/D3) -> 0.34615385 | P3: DOMINALOG | Q3: DOMINALOG (22), JADLOG (4) | R3: =IF(I3<=-0.05,"Passaro mais barata",IF(I3<0.05,"Empate técnico (±5%)","Passaro mais cara")) -> Passaro mais cara
A4: AL | B4: 3 | C4: MARECHAL DEODORO | D4: =COUNTIFS('Pedidos Top10'!$A$2:$A$1839,A4,'Pedidos Top10'!$C$2:$C$1839,C4) -> 6 | E4: =SUMIFS('Pedidos Top10'!$J$2:$J$1839,'Pedidos Top10'!$A$2:$A$1839,A4,'Pedidos Top10'!$C$2:$C$1839,C4) -> 427 | F4: =SUMIFS('Pedidos Top10'!$L$2:$L$1839,'Pedidos Top10'!$A$2:$A$1839,A4,'Pedidos Top10'!$C$2:$C$1839,C4) -> 1414.13 | G4: =SUMIFS('Pedidos Top10'!$AD$2:$AD$1839,'Pedidos Top10'!$A$2:$A$1839,A4,'Pedidos Top10'!$C$2:$C$1839,C4) -> 1161.84 | H4: =G4-F4 -> -252.29 | I4: =IF(F4=0,0,H4/F4) -> -0.17840651 | J4: =IF(D4=0,0,F4/D4) -> 235.68833 | K4: =IF(D4=0,0,G4/D4) -> 193.64 | L4: =IF(E4=0,0,F4/E4) -> 3.3117799 | M4: =IF(E4=0,0,G4/E4) -> 2.7209368 | N4: 10 | O4: =IF(D4=0,0,COUNTIFS('Pedidos Top10'!$A$2:$A$1839,A4,'Pedidos Top10'!$C$2:$C$1839,C4,'Pedidos Top10'!$AG$2:$AG$1839,"PASSARO")/D4) -> 0.5 | P4: DOMINALOG | Q4: DOMINALOG (6) | R4: =IF(I4<=-0.05,"Passaro mais barata",IF(I4<0.05,"Empate técnico (±5%)","Passaro mais cara")) -> Passaro mais barata
A5: AL | B5: 4 | C5: RIO LARGO | D5: =COUNTIFS('Pedidos Top10'!$A$2:$A$1839,A5,'Pedidos Top10'!$C$2:$C$1839,C5) -> 6 | E5: =SUMIFS('Pedidos Top10'!$J$2:$J$1839,'Pedidos Top10'!$A$2:$A$1839,A5,'Pedidos Top10'!$C$2:$C$1839,C5) -> 277.41 | F5: =SUMIFS('Pedidos Top10'!$L$2:$L$1839,'Pedidos Top10'!$A$2:$A$1839,A5,'Pedidos Top10'!$C$2:$C$1839,C5) -> 1067.67 | G5: =SUMIFS('Pedidos Top10'!$AD$2:$AD$1839,'Pedidos Top10'!$A$2:$A$1839,A5,'Pedidos Top10'!$C$2:$C$1839,C5) -> 821.11 | H5: =G5-F5 -> -246.56 | I5: =IF(F5=0,0,H5/F5) -> -0.23093278 | J5: =IF(D5=0,0,F5/D5) -> 177.945 | K5: =IF(D5=0,0,G5/D5) -> 136.85167 | L5: =IF(E5=0,0,F5/E5) -> 3.8487077 | M5: =IF(E5=0,0,G5/E5) -> 2.9599149 | N5: 8 | O5: =IF(D5=0,0,COUNTIFS('Pedidos Top10'!$A$2:$A$1839,A5,'Pedidos Top10'!$C$2:$C$1839,C5,'Pedidos Top10'!$AG$2:$AG$1839,"PASSARO")/D5) -> 1 | P5: DOMINALOG | Q5: DOMINALOG (6) | R5: =IF(I5<=-0.05,"Passaro mais barata",IF(I5<0.05,"Empate técnico (±5%)","Passaro mais cara")) -> Passaro mais barata
A6: AL | B6: 5 | C6: MARAGOGI | D6: =COUNTIFS('Pedidos Top10'!$A$2:$A$1839,A6,'Pedidos Top10'!$C$2:$C$1839,C6) -> 4 | E6: =SUMIFS('Pedidos Top10'!$J$2:$J$1839,'Pedidos Top10'!$A$2:$A$1839,A6,'Pedidos Top10'!$C$2:$C$1839,C6) -> 134.2 | F6: =SUMIFS('Pedidos Top10'!$L$2:$L$1839,'Pedidos Top10'!$A$2:$A$1839,A6,'Pedidos Top10'!$C$2:$C$1839,C6) -> 652.13 | G6: =SUMIFS('Pedidos Top10'!$AD$2:$AD$1839,'Pedidos Top10'!$A$2:$A$1839,A6,'Pedidos Top10'!$C$2:$C$1839,C6) -> 720.53 | H6: =G6-F6 -> 68.4 | I6: =IF(F6=0,0,H6/F6) -> 0.10488706 | J6: =IF(D6=0,0,F6/D6) -> 163.0325 | K6: =IF(D6=0,0,G6/D6) -> 180.1325 | L6: =IF(E6=0,0,F6/E6) -> 4.859389 | M6: =IF(E6=0,0,G6/E6) -> 5.369076 | N6: 13 | O6: =IF(D6=0,0,COUNTIFS('Pedidos Top10'!$A$2:$A$1839,A6,'Pedidos Top10'!$C$2:$C$1839,C6,'Pedidos Top10'!$AG$2:$AG$1839,"PASSARO")/D6) -> 0.25 | P6: DOMINALOG | Q6: DOMINALOG (4) | R6: =IF(I6<=-0.05,"Passaro mais barata",IF(I6<0.05,"Empate técnico (±5%)","Passaro mais cara")) -> Passaro mais cara
A7: AL | B7: 6 | C7: DELMIRO GOUVEIA | D7: =COUNTIFS('Pedidos Top10'!$A$2:$A$1839,A7,'Pedidos Top10'!$C$2:$C$1839,C7) -> 3 | E7: =SUMIFS('Pedidos Top10'!$J$2:$J$1839,'Pedidos Top10'!$A$2:$A$1839,A7,'Pedidos Top10'!$C$2:$C$1839,C7) -> 349.7 | F7: =SUMIFS('Pedidos Top10'!$L$2:$L$1839,'Pedidos Top10'!$A$2:$A$1839,A7,'Pedidos Top10'!$C$2:$C$1839,C7) -> 1136.84 | G7: =SUMIFS('Pedidos Top10'!$AD$2:$AD$1839,'Pedidos Top10'!$A$2:$A$1839,A7,'Pedidos Top10'!$C$2:$C$1839,C7) -> 968.53 | H7: =G7-F7 -> -168.31 | I7: =IF(F7=0,0,H7/F7) -> -0.14805074 | J7: =IF(D7=0,0,F7/D7) -> 378.94667 | K7: =IF(D7=0,0,G7/D7) -> 322.84333 | L7: =IF(E7=0,0,F7/E7) -> 3.2509008 | M7: =IF(E7=0,0,G7/E7) -> 2.7696025 | N7: 13 | O7: =IF(D7=0,0,COUNTIFS('Pedidos Top10'!$A$2:$A$1839,A7,'Pedidos Top10'!$C$2:$C$1839,C7,'Pedidos Top10'!$AG$2:$AG$1839,"PASSARO")/D7) -> 0.66666667 | P7: DOMINALOG | Q7: DOMINALOG (3) | R7: =IF(I7<=-0.05,"Passaro mais barata",IF(I7<0.05,"Empate técnico (±5%)","Passaro mais cara")) -> Passaro mais barata
A8: AL | B8: 7 | C8: PIRANHAS | D8: =COUNTIFS('Pedidos Top10'!$A$2:$A$1839,A8,'Pedidos Top10'!$C$2:$C$1839,C8) -> 3 | E8: =SUMIFS('Pedidos Top10'!$J$2:$J$1839,'Pedidos Top10'!$A$2:$A$1839,A8,'Pedidos Top10'!$C$2:$C$1839,C8) -> 203.78 | F8: =SUMIFS('Pedidos Top10'!$L$2:$L$1839,'Pedidos Top10'!$A$2:$A$1839,A8,'Pedidos Top10'!$C$2:$C$1839,C8) -> 862.25 | G8: =SUMIFS('Pedidos Top10'!$AD$2:$AD$1839,'Pedidos Top10'!$A$2:$A$1839,A8,'Pedidos Top10'!$C$2:$C$1839,C8) -> 694.83 | H8: =G8-F8 -> -167.42 | I8: =IF(F8=0,0,H8/F8) -> -0.19416643 | J8: =IF(D8=0,0,F8/D8) -> 287.41667 | K8: =IF(D8=0,0,G8/D8) -> 231.61 | L8: =IF(E8=0,0,F8/E8) -> 4.2312788 | M8: =IF(E8=0,0,G8/E8) -> 3.4097065 | N8: 13 | O8: =IF(D8=0,0,COUNTIFS('Pedidos Top10'!$A$2:$A$1839,A8,'Pedidos Top10'!$C$2:$C$1839,C8,'Pedidos Top10'!$AG$2:$AG$1839,"PASSARO")/D8) -> 1 | P8: DOMINALOG | Q8: DOMINALOG (3) | R8: =IF(I8<=-0.05,"Passaro mais barata",IF(I8<0.05,"Empate técnico (±5%)","Passaro mais cara")) -> Passaro mais barata
A9: AL | B9: 8 | C9: SAO MIGUEL DOS MILAGRES | D9: =COUNTIFS('Pedidos Top10'!$A$2:$A$1839,A9,'Pedidos Top10'!$C$2:$C$1839,C9) -> 3 | E9: =SUMIFS('Pedidos Top10'!$J$2:$J$1839,'Pedidos Top10'!$A$2:$A$1839,A9,'Pedidos Top10'!$C$2:$C$1839,C9) -> 230.38 | F9: =SUMIFS('Pedidos Top10'!$L$2:$L$1839,'Pedidos Top10'!$A$2:$A$1839,A9,'Pedidos Top10'!$C$2:$C$1839,C9) -> 850.42 | G9: =SUMIFS('Pedidos Top10'!$AD$2:$AD$1839,'Pedidos Top10'!$A$2:$A$1839,A9,'Pedidos Top10'!$C$2:$C$1839,C9) -> 701.54 | H9: =G9-F9 -> -148.88 | I9: =IF(F9=0,0,H9/F9) -> -0.17506644 | J9: =IF(D9=0,0,F9/D9) -> 283.47333 | K9: =IF(D9=0,0,G9/D9) -> 233.84667 | L9: =IF(E9=0,0,F9/E9) -> 3.6913795 | M9: =IF(E9=0,0,G9/E9) -> 3.0451428 | N9: 13 | O9: =IF(D9=0,0,COUNTIFS('Pedidos Top10'!$A$2:$A$1839,A9,'Pedidos Top10'!$C$2:$C$1839,C9,'Pedidos Top10'!$AG$2:$AG$1839,"PASSARO")/D9) -> 0.66666667 | P9: DOMINALOG | Q9: DOMINALOG (2), FORMATO TRANSPORTES (1) | R9: =IF(I9<=-0.05,"Passaro mais barata",IF(I9<0.05,"Empate técnico (±5%)","Passaro mais cara")) -> Passaro mais barata
A10: AL | B10: 9 | C10: PORTO CALVO | D10: =COUNTIFS('Pedidos Top10'!$A$2:$A$1839,A10,'Pedidos Top10'!$C$2:$C$1839,C10) -> 3 | E10: =SUMIFS('Pedidos Top10'!$J$2:$J$1839,'Pedidos Top10'!$A$2:$A$1839,A10,'Pedidos Top10'!$C$2:$C$1839,C10) -> 186.48 | F10: =SUMIFS('Pedidos Top10'!$L$2:$L$1839,'Pedidos Top10'!$A$2:$A$1839,A10,'Pedidos Top10'!$C$2:$C$1839,C10) -> 686.94 | G10: =SUMIFS('Pedidos Top10'!$AD$2:$AD$1839,'Pedidos Top10'!$A$2:$A$1839,A10,'Pedidos Top10'!$C$2:$C$1839,C10) -> 633.64 | H10: =G10-F10 -> -53.3 | I10: =IF(F10=0,0,H10/F10) -> -0.077590474 | J10: =IF(D10=0,0,F10/D10) -> 228.98 | K10: =IF(D10=0,0,G10/D10) -> 211.21333 | L10: =IF(E10=0,0,F10/E10) -> 3.6837194 | M10: =IF(E10=0,0,G10/E10) -> 3.3978979 | N10: 13 | O10: =IF(D10=0,0,COUNTIFS('Pedidos Top10'!$A$2:$A$1839,A10,'Pedidos Top10'!$C$2:$C$1839,C10,'Pedidos Top10'!$AG$2:$AG$1839,"PASSARO")/D10) -> 0.66666667 | P10: DOMINALOG | Q10: DOMINALOG (3) | R10: =IF(I10<=-0.05,"Passaro mais barata",IF(I10<0.05,"Empate técnico (±5%)","Passaro mais cara")) -> Passaro mais barata
A11: AL | B11: 10 | C11: SAO LUIS DO QUITUNDE | D11: =COUNTIFS('Pedidos Top10'!$A$2:$A$1839,A11,'Pedidos Top10'!$C$2:$C$1839,C11) -> 3 | E11: =SUMIFS('Pedidos Top10'!$J$2:$J$1839,'Pedidos Top10'!$A$2:$A$1839,A11,'Pedidos Top10'!$C$2:$C$1839,C11) -> 118.7 | F11: =SUMIFS('Pedidos Top10'!$L$2:$L$1839,'Pedidos Top10'!$A$2:$A$1839,A11,'Pedidos Top10'!$C$2:$C$1839,C11) -> 552.4 | G11: =SUMIFS('Pedidos Top10'!$AD$2:$AD$1839,'Pedidos Top10'!$A$2:$A$1839,A11,'Pedidos Top10'!$C$2:$C$1839,C11) -> 568.4 | H11: =G11-F11 -> 16 | I11: =IF(F11=0,0,H11/F11) -> 0.028964518 | J11: =IF(D11=0,0,F11/D11) -> 184.13333 | K11: =IF(D11=0,0,G11/D11) -> 189.46667 | L11: =IF(E11=0,0,F11/E11) -> 4.6537489 | M11: =IF(E11=0,0,G11/E11) -> 4.7885425 | N11: 13 | O11: =IF(D11=0,0,COUNTIFS('Pedidos Top10'!$A$2:$A$1839,A11,'Pedidos Top10'!$C$2:$C$1839,C11,'Pedidos Top10'!$AG$2:$AG$1839,"PASSARO")/D11) -> 0.33333333 | P11: DOMINALOG | Q11: DOMINALOG (3) | R11: =IF(I11<=-0.05,"Passaro mais barata",IF(I11<0.05,"Empate técnico (±5%)","Passaro mais cara")) -> Empate técnico (±5%)
A12: BA | B12: 1 | C12: SALVADOR | D12: =COUNTIFS('Pedidos Top10'!$A$2:$A$1839,A12,'Pedidos Top10'!$C$2:$C$1839,C12) -> 296 | E12: =SUMIFS('Pedidos Top10'!$J$2:$J$1839,'Pedidos Top10'!$A$2:$A$1839,A12,'Pedidos Top10'!$C$2:$C$1839,C12) -> 15122.53 | F12: =SUMIFS('Pedidos Top10'!$L$2:$L$1839,'Pedidos Top10'!$A$2:$A$1839,A12,'Pedidos Top10'!$C$2:$C$1839,C12) -> 47672.61 | G12: =SUMIFS('Pedidos Top10'!$AD$2:$AD$1839,'Pedidos Top10'!$A$2:$A$1839,A12,'Pedidos Top10'!$C$2:$C$1839,C12) -> 36586.8 | H12: =G12-F12 -> -11085.81 | I12: =IF(F12=0,0,H12/F12) -> -0.23254045 | J12: =IF(D12=0,0,F12/D12) -> 161.05611 | K12: =IF(D12=0,0,G12/D12) -> 123.60405 | L12: =IF(E12=0,0,F12/E12) -> 3.1524229 | M12: =IF(E12=0,0,G12/E12) -> 2.4193571 | N12: 6 | O12: =IF(D12=0,0,COUNTIFS('Pedidos Top10'!$A$2:$A$1839,A12,'Pedidos Top10'!$C$2:$C$1839,C12,'Pedidos Top10'!$AG$2:$AG$1839,"PASSARO")/D12) -> 0.88175676 | P12: DOMINALOG | Q12: DOMINALOG (261), JADLOG (33), Atual Cargas (2) | R12: =IF(I12<=-0.05,"Passaro mais barata",IF(I12<0.05,"Empate técnico (±5%)","Passaro mais cara")) -> Passaro mais barata
A13: BA | B13: 2 | C13: FEIRA DE SANTANA | D13: =COUNTIFS('Pedidos Top10'!$A$2:$A$1839,A13,'Pedidos Top10'!$C$2:$C$1839,C13) -> 42 | E13: =SUMIFS('Pedidos Top10'!$J$2:$J$1839,'Pedidos Top10'!$A$2:$A$1839,A13,'Pedidos Top10'!$C$2:$C$1839,C13) -> 2552.96 | F13: =SUMIFS('Pedidos Top10'!$L$2:$L$1839,'Pedidos Top10'!$A$2:$A$1839,A13,'Pedidos Top10'!$C$2:$C$1839,C13) -> 8347.68 | G13: =SUMIFS('Pedidos Top10'!$AD$2:$AD$1839,'Pedidos Top10'!$A$2:$A$1839,A13,'Pedidos Top10'!$C$2:$C$1839,C13) -> 5453.87 | H13: =G13-F13 -> -2893.81 | I13: =IF(F13=0,0,H13/F13) -> -0.34666039 | J13: =IF(D13=0,0,F13/D13) -> 198.75429 | K13: =IF(D13=0,0,G13/D13) -> 129.85405 | L13: =IF(E13=0,0,F13/E13) -> 3.2698045 | M13: =IF(E13=0,0,G13/E13) -> 2.1362928 | N13: 5 | O13: =IF(D13=0,0,COUNTIFS('Pedidos Top10'!$A$2:$A$1839,A13,'Pedidos Top10'!$C$2:$C$1839,C13,'Pedidos Top10'!$AG$2:$AG$1839,"PASSARO")/D13) -> 0.9047619 | P13: DOMINALOG | Q13: DOMINALOG (39), JADLOG (3) | R13: =IF(I13<=-0.05,"Passaro mais barata",IF(I13<0.05,"Empate técnico (±5%)","Passaro mais cara")) -> Passaro mais barata
... A91: SE | B91: 10 | C91: CRISTINAPOLIS | D91: =COUNTIFS('Pedidos Top10'!$A$2:$A$1839,A91,'Pedidos Top10'!$C$2:$C$1839,C91) -> 2 | E91: =SUMIFS('Pedidos Top10'!$J$2:$J$1839,'Pedidos Top10'!$A$2:$A$1839,A91,'Pedidos Top10'!$C$2:$C$1839,C91) -> 223.9 | F91: =SUMIFS('Pedidos Top10'!$L$2:$L$1839,'Pedidos Top10'!$A$2:$A$1839,A91,'Pedidos Top10'!$C$2:$C$1839,C91) -> 712.9 | G91: =SUMIFS('Pedidos Top10'!$AD$2:$AD$1839,'Pedidos Top10'!$A$2:$A$1839,A91,'Pedidos Top10'!$C$2:$C$1839,C91) -> 559.48 | H91: =G91-F91 -> -153.42 | I91: =IF(F91=0,0,H91/F91) -> -0.2152055 | J91: =IF(D91=0,0,F91/D91) -> 356.45 | K91: =IF(D91=0,0,G91/D91) -> 279.74 | L91: =IF(E91=0,0,F91/E91) -> 3.1840107 | M91: =IF(E91=0,0,G91/E91) -> 2.4987941 | N91: 10 | O91: =IF(D91=0,0,COUNTIFS('Pedidos Top10'!$A$2:$A$1839,A91,'Pedidos Top10'!$C$2:$C$1839,C91,'Pedidos Top10'!$AG$2:$AG$1839,"PASSARO")/D91) -> 1 | P91: DOMINALOG | Q91: DOMINALOG (2) | R91: =IF(I91<=-0.05,"Passaro mais barata",IF(I91<0.05,"Empate técnico (±5%)","Passaro mais cara")) -> Passaro mais barata

Sheet Concorrência Praças
A1: UF | B1: Rank cidade | C1: Cidade | D1: Transportadora atual | E1: Pedidos | F1: Share da praça | G1: Peso total (kg) | H1: Frete atual (R$) | I1: Frete PASSARO nos mesmos pedidos (R$) | J1: Diferença (R$) | K1: Dif. % | L1: Ticket médio atual | M1: Ticket médio Passaro | N1: R$/kg atual | O1: R$/kg Passaro | P1: % pedidos Passaro mais barata | Q1: Leitura
A2: AL | B2: 1 | C2: MACEIO | D2: DOMINALOG | E2: =COUNTIFS('Pedidos Top10'!$A$2:$A$1839,A2,'Pedidos Top10'!$C$2:$C$1839,C2,'Pedidos Top10'!$D$2:$D$1839,D2) -> 90 | F2: =E2/COUNTIFS('Pedidos Top10'!$A$2:$A$1839,A2,'Pedidos Top10'!$C$2:$C$1839,C2) -> 0.81818182 | G2: =SUMIFS('Pedidos Top10'!$J$2:$J$1839,'Pedidos Top10'!$A$2:$A$1839,A2,'Pedidos Top10'!$C$2:$C$1839,C2,'Pedidos Top10'!$D$2:$D$1839,D2) -> 4819.05 | H2: =SUMIFS('Pedidos Top10'!$L$2:$L$1839,'Pedidos Top10'!$A$2:$A$1839,A2,'Pedidos Top10'!$C$2:$C$1839,C2,'Pedidos Top10'!$D$2:$D$1839,D2) -> 16352.14 | I2: =SUMIFS('Pedidos Top10'!$AD$2:$AD$1839,'Pedidos Top10'!$A$2:$A$1839,A2,'Pedidos Top10'!$C$2:$C$1839,C2,'Pedidos Top10'!$D$2:$D$1839,D2) -> 12990.97 | J2: =I2-H2 -> -3361.17 | K2: =IF(H2=0,0,J2/H2) -> -0.20554924 | L2: =IF(E2=0,0,H2/E2) -> 181.69044 | M2: =IF(E2=0,0,I2/E2) -> 144.34411 | N2: =IF(G2=0,0,H2/G2) -> 3.393229 | O2: =IF(G2=0,0,I2/G2) -> 2.6957533 | P2: =IF(E2=0,0,COUNTIFS('Pedidos Top10'!$A$2:$A$1839,A2,'Pedidos Top10'!$C$2:$C$1839,C2,'Pedidos Top10'!$D$2:$D$1839,D2,'Pedidos Top10'!$AG$2:$AG$1839,"PASSARO")/E2) -> 0.94444444 | Q2: =IF(K2<=-0.05,"Passaro compete: "&TEXT(-K2,"0%")&" abaixo de "&D2,IF(K2<0.05,"Empate técnico com "&D2,D2&" é "&TEXT(1-H2/I2,"0%")&" mais barata que a Passaro")) -> Passaro compete: 21% abaixo de DOMINALOG
A3: AL | B3: 1 | C3: MACEIO | D3: JADLOG | E3: =COUNTIFS('Pedidos Top10'!$A$2:$A$1839,A3,'Pedidos Top10'!$C$2:$C$1839,C3,'Pedidos Top10'!$D$2:$D$1839,D3) -> 19 | F3: =E3/COUNTIFS('Pedidos Top10'!$A$2:$A$1839,A3,'Pedidos Top10'!$C$2:$C$1839,C3) -> 0.17272727 | G3: =SUMIFS('Pedidos Top10'!$J$2:$J$1839,'Pedidos Top10'!$A$2:$A$1839,A3,'Pedidos Top10'!$C$2:$C$1839,C3,'Pedidos Top10'!$D$2:$D$1839,D3) -> 388.99 | H3: =SUMIFS('Pedidos Top10'!$L$2:$L$1839,'Pedidos Top10'!$A$2:$A$1839,A3,'Pedidos Top10'!$C$2:$C$1839,C3,'Pedidos Top10'!$D$2:$D$1839,D3) -> 1557.14 | I3: =SUMIFS('Pedidos Top10'!$AD$2:$AD$1839,'Pedidos Top10'!$A$2:$A$1839,A3,'Pedidos Top10'!$C$2:$C$1839,C3,'Pedidos Top10'!$D$2:$D$1839,D3) -> 2262.53 | J3: =I3-H3 -> 705.39 | K3: =IF(H3=0,0,J3/H3) -> 0.45300358 | L3: =IF(E3=0,0,H3/E3) -> 81.954737 | M3: =IF(E3=0,0,I3/E3) -> 119.08053 | N3: =IF(G3=0,0,H3/G3) -> 4.0030335 | O3: =IF(G3=0,0,I3/G3) -> 5.816422 | P3: =IF(E3=0,0,COUNTIFS('Pedidos Top10'!$A$2:$A$1839,A3,'Pedidos Top10'!$C$2:$C$1839,C3,'Pedidos Top10'!$D$2:$D$1839,D3,'Pedidos Top10'!$AG$2:$AG$1839,"PASSARO")/E3) -> 0 | Q3: =IF(K3<=-0.05,"Passaro compete: "&TEXT(-K3,"0%")&" abaixo de "&D3,IF(K3<0.05,"Empate técnico com "&D3,D3&" é "&TEXT(1-H3/I3,"0%")&" mais barata que a Passaro")) -> JADLOG é 31% mais barata que a Passaro
A4: AL | B4: 1 | C4: MACEIO | D4: ZAFER | E4: =COUNTIFS('Pedidos Top10'!$A$2:$A$1839,A4,'Pedidos Top10'!$C$2:$C$1839,C4,'Pedidos Top10'!$D$2:$D$1839,D4) -> 1 | F4: =E4/COUNTIFS('Pedidos Top10'!$A$2:$A$1839,A4,'Pedidos Top10'!$C$2:$C$1839,C4) -> 0.0090909091 | G4: =SUMIFS('Pedidos Top10'!$J$2:$J$1839,'Pedidos Top10'!$A$2:$A$1839,A4,'Pedidos Top10'!$C$2:$C$1839,C4,'Pedidos Top10'!$D$2:$D$1839,D4) -> 66.8 | H4: =SUMIFS('Pedidos Top10'!$L$2:$L$1839,'Pedidos Top10'!$A$2:$A$1839,A4,'Pedidos Top10'!$C$2:$C$1839,C4,'Pedidos Top10'!$D$2:$D$1839,D4) -> 175.96 | I4: =SUMIFS('Pedidos Top10'!$AD$2:$AD$1839,'Pedidos Top10'!$A$2:$A$1839,A4,'Pedidos Top10'!$C$2:$C$1839,C4,'Pedidos Top10'!$D$2:$D$1839,D4) -> 145.07 | J4: =I4-H4 -> -30.89 | K4: =IF(H4=0,0,J4/H4) -> -0.17555126 | L4: =IF(E4=0,0,H4/E4) -> 175.96 | M4: =IF(E4=0,0,I4/E4) -> 145.07 | N4: =IF(G4=0,0,H4/G4) -> 2.6341317 | O4: =IF(G4=0,0,I4/G4) -> 2.1717066 | P4: =IF(E4=0,0,COUNTIFS('Pedidos Top10'!$A$2:$A$1839,A4,'Pedidos Top10'!$C$2:$C$1839,C4,'Pedidos Top10'!$D$2:$D$1839,D4,'Pedidos Top10'!$AG$2:$AG$1839,"PASSARO")/E4) -> 1 | Q4: =IF(K4<=-0.05,"Passaro compete: "&TEXT(-K4,"0%")&" abaixo de "&D4,IF(K4<0.05,"Empate técnico com "&D4,D4&" é "&TEXT(1-H4/I4,"0%")&" mais barata que a Passaro")) -> Passaro compete: 18% abaixo de ZAFER
A5: AL | B5: 2 | C5: ARAPIRACA | D5: DOMINALOG | E5: =COUNTIFS('Pedidos Top10'!$A$2:$A$1839,A5,'Pedidos Top10'!$C$2:$C$1839,C5,'Pedidos Top10'!$D$2:$D$1839,D5) -> 22 | F5: =E5/COUNTIFS('Pedidos Top10'!$A$2:$A$1839,A5,'Pedidos Top10'!$C$2:$C$1839,C5) -> 0.84615385 | G5: =SUMIFS('Pedidos Top10'!$J$2:$J$1839,'Pedidos Top10'!$A$2:$A$1839,A5,'Pedidos Top10'!$C$2:$C$1839,C5,'Pedidos Top10'!$D$2:$D$1839,D5) -> 838.36 | H5: =SUMIFS('Pedidos Top10'!$L$2:$L$1839,'Pedidos Top10'!$A$2:$A$1839,A5,'Pedidos Top10'!$C$2:$C$1839,C5,'Pedidos Top10'!$D$2:$D$1839,D5) -> 3498.11 | I5: =SUMIFS('Pedidos Top10'!$AD$2:$AD$1839,'Pedidos Top10'!$A$2:$A$1839,A5,'Pedidos Top10'!$C$2:$C$1839,C5,'Pedidos Top10'!$D$2:$D$1839,D5) -> 3501.79 | J5: =I5-H5 -> 3.68 | K5: =IF(H5=0,0,J5/H5) -> 0.0010519966 | L5: =IF(E5=0,0,H5/E5) -> 159.005 | M5: =IF(E5=0,0,I5/E5) -> 159.17227 | N5: =IF(G5=0,0,H5/G5) -> 4.1725631 | O5: =IF(G5=0,0,I5/G5) -> 4.1769526 | P5: =IF(E5=0,0,COUNTIFS('Pedidos Top10'!$A$2:$A$1839,A5,'Pedidos Top10'!$C$2:$C$1839,C5,'Pedidos Top10'!$D$2:$D$1839,D5,'Pedidos Top10'!$AG$2:$AG$1839,"PASSARO")/E5) -> 0.40909091 | Q5: =IF(K5<=-0.05,"Passaro compete: "&TEXT(-K5,"0%")&" abaixo de "&D5,IF(K5<0.05,"Empate técnico com "&D5,D5&" é "&TEXT(1-H5/I5,"0%")&" mais barata que a Passaro")) -> Empate técnico com DOMINALOG
A6: AL | B6: 2 | C6: ARAPIRACA | D6: JADLOG | E6: =COUNTIFS('Pedidos Top10'!$A$2:$A$1839,A6,'Pedidos Top10'!$C$2:$C$1839,C6,'Pedidos Top10'!$D$2:$D$1839,D6) -> 4 | F6: =E6/COUNTIFS('Pedidos Top10'!$A$2:$A$1839,A6,'Pedidos Top10'!$C$2:$C$1839,C6) -> 0.15384615 | G6: =SUMIFS('Pedidos Top10'!$J$2:$J$1839,'Pedidos Top10'!$A$2:$A$1839,A6,'Pedidos Top10'!$C$2:$C$1839,C6,'Pedidos Top10'!$D$2:$D$1839,D6) -> 83.09 | H6: =SUMIFS('Pedidos Top10'!$L$2:$L$1839,'Pedidos Top10'!$A$2:$A$1839,A6,'Pedidos Top10'!$C$2:$C$1839,C6,'Pedidos Top10'!$D$2:$D$1839,D6) -> 351.42 | I6: =SUMIFS('Pedidos Top10'!$AD$2:$AD$1839,'Pedidos Top10'!$A$2:$A$1839,A6,'Pedidos Top10'!$C$2:$C$1839,C6,'Pedidos Top10'!$D$2:$D$1839,D6) -> 562.62 | J6: =I6-H6 -> 211.2 | K6: =IF(H6=0,0,J6/H6) -> 0.60099027 | L6: =IF(E6=0,0,H6/E6) -> 87.855 | M6: =IF(E6=0,0,I6/E6) -> 140.655 | N6: =IF(G6=0,0,H6/G6) -> 4.2293898 | O6: =IF(G6=0,0,I6/G6) -> 6.7712119 | P6: =IF(E6=0,0,COUNTIFS('Pedidos Top10'!$A$2:$A$1839,A6,'Pedidos Top10'!$C$2:$C$1839,C6,'Pedidos Top10'!$D$2:$D$1839,D6,'Pedidos Top10'!$AG$2:$AG$1839,"PASSARO")/E6) -> 0 | Q6: =IF(K6<=-0.05,"Passaro compete: "&TEXT(-K6,"0%")&" abaixo de "&D6,IF(K6<0.05,"Empate técnico com "&D6,D6&" é "&TEXT(1-H6/I6,"0%")&" mais barata que a Passaro")) -> JADLOG é 38% mais barata que a Passaro
A7: AL | B7: 3 | C7: MARECHAL DEODORO | D7: DOMINALOG | E7: =COUNTIFS('Pedidos Top10'!$A$2:$A$1839,A7,'Pedidos Top10'!$C$2:$C$1839,C7,'Pedidos Top10'!$D$2:$D$1839,D7) -> 6 | F7: =E7/COUNTIFS('Pedidos Top10'!$A$2:$A$1839,A7,'Pedidos Top10'!$C$2:$C$1839,C7) -> 1 | G7: =SUMIFS('Pedidos Top10'!$J$2:$J$1839,'Pedidos Top10'!$A$2:$A$1839,A7,'Pedidos Top10'!$C$2:$C$1839,C7,'Pedidos Top10'!$D$2:$D$1839,D7) -> 427 | H7: =SUMIFS('Pedidos Top10'!$L$2:$L$1839,'Pedidos Top10'!$A$2:$A$1839,A7,'Pedidos Top10'!$C$2:$C$1839,C7,'Pedidos Top10'!$D$2:$D$1839,D7) -> 1414.13 | I7: =SUMIFS('Pedidos Top10'!$AD$2:$AD$1839,'Pedidos Top10'!$A$2:$A$1839,A7,'Pedidos Top10'!$C$2:$C$1839,C7,'Pedidos Top10'!$D$2:$D$1839,D7) -> 1161.84 | J7: =I7-H7 -> -252.29 | K7: =IF(H7=0,0,J7/H7) -> -0.17840651 | L7: =IF(E7=0,0,H7/E7) -> 235.68833 | M7: =IF(E7=0,0,I7/E7) -> 193.64 | N7: =IF(G7=0,0,H7/G7) -> 3.3117799 | O7: =IF(G7=0,0,I7/G7) -> 2.7209368 | P7: =IF(E7=0,0,COUNTIFS('Pedidos Top10'!$A$2:$A$1839,A7,'Pedidos Top10'!$C$2:$C$1839,C7,'Pedidos Top10'!$D$2:$D$1839,D7,'Pedidos Top10'!$AG$2:$AG$1839,"PASSARO")/E7) -> 0.5 | Q7: =IF(K7<=-0.05,"Passaro compete: "&TEXT(-K7,"0%")&" abaixo de "&D7,IF(K7<0.05,"Empate técnico com "&D7,D7&" é "&TEXT(1-H7/I7,"0%")&" mais barata que a Passaro")) -> Passaro compete: 18% abaixo de DOMINALOG
A8: AL | B8: 4 | C8: RIO LARGO | D8: DOMINALOG | E8: =COUNTIFS('Pedidos Top10'!$A$2:$A$1839,A8,'Pedidos Top10'!$C$2:$C$1839,C8,'Pedidos Top10'!$D$2:$D$1839,D8) -> 6 | F8: =E8/COUNTIFS('Pedidos Top10'!$A$2:$A$1839,A8,'Pedidos Top10'!$C$2:$C$1839,C8) -> 1 | G8: =SUMIFS('Pedidos Top10'!$J$2:$J$1839,'Pedidos Top10'!$A$2:$A$1839,A8,'Pedidos Top10'!$C$2:$C$1839,C8,'Pedidos Top10'!$D$2:$D$1839,D8) -> 277.41 | H8: =SUMIFS('Pedidos Top10'!$L$2:$L$1839,'Pedidos Top10'!$A$2:$A$1839,A8,'Pedidos Top10'!$C$2:$C$1839,C8,'Pedidos Top10'!$D$2:$D$1839,D8) -> 1067.67 | I8: =SUMIFS('Pedidos Top10'!$AD$2:$AD$1839,'Pedidos Top10'!$A$2:$A$1839,A8,'Pedidos Top10'!$C$2:$C$1839,C8,'Pedidos Top10'!$D$2:$D$1839,D8) -> 821.11 | J8: =I8-H8 -> -246.56 | K8: =IF(H8=0,0,J8/H8) -> -0.23093278 | L8: =IF(E8=0,0,H8/E8) -> 177.945 | M8: =IF(E8=0,0,I8/E8) -> 136.85167 | N8: =IF(G8=0,0,H8/G8) -> 3.8487077 | O8: =IF(G8=0,0,I8/G8) -> 2.9599149 | P8: =IF(E8=0,0,COUNTIFS('Pedidos Top10'!$A$2:$A$1839,A8,'Pedidos Top10'!$C$2:$C$1839,C8,'Pedidos Top10'!$D$2:$D$1839,D8,'Pedidos Top10'!$AG$2:$AG$1839,"PASSARO")/E8) -> 1 | Q8: =IF(K8<=-0.05,"Passaro compete: "&TEXT(-K8,"0%")&" abaixo de "&D8,IF(K8<0.05,"Empate técnico com "&D8,D8&" é "&TEXT(1-H8/I8,"0%")&" mais barata que a Passaro")) -> Passaro compete: 23% abaixo de DOMINALOG
A9: AL | B9: 5 | C9: MARAGOGI | D9: DOMINALOG | E9: =COUNTIFS('Pedidos Top10'!$A$2:$A$1839,A9,'Pedidos Top10'!$C$2:$C$1839,C9,'Pedidos Top10'!$D$2:$D$1839,D9) -> 4 | F9: =E9/COUNTIFS('Pedidos Top10'!$A$2:$A$1839,A9,'Pedidos Top10'!$C$2:$C$1839,C9) -> 1 | G9: =SUMIFS('Pedidos Top10'!$J$2:$J$1839,'Pedidos Top10'!$A$2:$A$1839,A9,'Pedidos Top10'!$C$2:$C$1839,C9,'Pedidos Top10'!$D$2:$D$1839,D9) -> 134.2 | H9: =SUMIFS('Pedidos Top10'!$L$2:$L$1839,'Pedidos Top10'!$A$2:$A$1839,A9,'Pedidos Top10'!$C$2:$C$1839,C9,'Pedidos Top10'!$D$2:$D$1839,D9) -> 652.13 | I9: =SUMIFS('Pedidos Top10'!$AD$2:$AD$1839,'Pedidos Top10'!$A$2:$A$1839,A9,'Pedidos Top10'!$C$2:$C$1839,C9,'Pedidos Top10'!$D$2:$D$1839,D9) -> 720.53 | J9: =I9-H9 -> 68.4 | K9: =IF(H9=0,0,J9/H9) -> 0.10488706 | L9: =IF(E9=0,0,H9/E9) -> 163.0325 | M9: =IF(E9=0,0,I9/E9) -> 180.1325 | N9: =IF(G9=0,0,H9/G9) -> 4.859389 | O9: =IF(G9=0,0,I9/G9) -> 5.369076 | P9: =IF(E9=0,0,COUNTIFS('Pedidos Top10'!$A$2:$A$1839,A9,'Pedidos Top10'!$C$2:$C$1839,C9,'Pedidos Top10'!$D$2:$D$1839,D9,'Pedidos Top10'!$AG$2:$AG$1839,"PASSARO")/E9) -> 0.25 | Q9: =IF(K9<=-0.05,"Passaro compete: "&TEXT(-K9,"0%")&" abaixo de "&D9,IF(K9<0.05,"Empate técnico com "&D9,D9&" é "&TEXT(1-H9/I9,"0%")&" mais barata que a Passaro")) -> DOMINALOG é 9% mais barata que a Passaro
A10: AL | B10: 6 | C10: DELMIRO GOUVEIA | D10: DOMINALOG | E10: =COUNTIFS('Pedidos Top10'!$A$2:$A$1839,A10,'Pedidos Top10'!$C$2:$C$1839,C10,'Pedidos Top10'!$D$2:$D$1839,D10) -> 3 | F10: =E10/COUNTIFS('Pedidos Top10'!$A$2:$A$1839,A10,'Pedidos Top10'!$C$2:$C$1839,C10) -> 1 | G10: =SUMIFS('Pedidos Top10'!$J$2:$J$1839,'Pedidos Top10'!$A$2:$A$1839,A10,'Pedidos Top10'!$C$2:$C$1839,C10,'Pedidos Top10'!$D$2:$D$1839,D10) -> 349.7 | H10: =SUMIFS('Pedidos Top10'!$L$2:$L$1839,'Pedidos Top10'!$A$2:$A$1839,A10,'Pedidos Top10'!$C$2:$C$1839,C10,'Pedidos Top10'!$D$2:$D$1839,D10) -> 1136.84 | I10: =SUMIFS('Pedidos Top10'!$AD$2:$AD$1839,'Pedidos Top10'!$A$2:$A$1839,A10,'Pedidos Top10'!$C$2:$C$1839,C10,'Pedidos Top10'!$D$2:$D$1839,D10) -> 968.53 | J10: =I10-H10 -> -168.31 | K10: =IF(H10=0,0,J10/H10) -> -0.14805074 | L10: =IF(E10=0,0,H10/E10) -> 378.94667 | M10: =IF(E10=0,0,I10/E10) -> 322.84333 | N10: =IF(G10=0,0,H10/G10) -> 3.2509008 | O10: =IF(G10=0,0,I10/G10) -> 2.7696025 | P10: =IF(E10=0,0,COUNTIFS('Pedidos Top10'!$A$2:$A$1839,A10,'Pedidos Top10'!$C$2:$C$1839,C10,'Pedidos Top10'!$D$2:$D$1839,D10,'Pedidos Top10'!$AG$2:$AG$1839,"PASSARO")/E10) -> 0.66666667 | Q10: =IF(K10<=-0.05,"Passaro compete: "&TEXT(-K10,"0%")&" abaixo de "&D10,IF(K10<0.05,"Empate técnico com "&D10,D10&" é "&TEXT(1-H10/I10,"0%")&" mais barata que a Passaro")) -> Passaro compete: 15% abaixo de DOMINALOG
A11: AL | B11: 7 | C11: PIRANHAS | D11: DOMINALOG | E11: =COUNTIFS('Pedidos Top10'!$A$2:$A$1839,A11,'Pedidos Top10'!$C$2:$C$1839,C11,'Pedidos Top10'!$D$2:$D$1839,D11) -> 3 | F11: =E11/COUNTIFS('Pedidos Top10'!$A$2:$A$1839,A11,'Pedidos Top10'!$C$2:$C$1839,C11) -> 1 | G11: =SUMIFS('Pedidos Top10'!$J$2:$J$1839,'Pedidos Top10'!$A$2:$A$1839,A11,'Pedidos Top10'!$C$2:$C$1839,C11,'Pedidos Top10'!$D$2:$D$1839,D11) -> 203.78 | H11: =SUMIFS('Pedidos Top10'!$L$2:$L$1839,'Pedidos Top10'!$A$2:$A$1839,A11,'Pedidos Top10'!$C$2:$C$1839,C11,'Pedidos Top10'!$D$2:$D$1839,D11) -> 862.25 | I11: =SUMIFS('Pedidos Top10'!$AD$2:$AD$1839,'Pedidos Top10'!$A$2:$A$1839,A11,'Pedidos Top10'!$C$2:$C$1839,C11,'Pedidos Top10'!$D$2:$D$1839,D11) -> 694.83 | J11: =I11-H11 -> -167.42 | K11: =IF(H11=0,0,J11/H11) -> -0.19416643 | L11: =IF(E11=0,0,H11/E11) -> 287.41667 | M11: =IF(E11=0,0,I11/E11) -> 231.61 | N11: =IF(G11=0,0,H11/G11) -> 4.2312788 | O11: =IF(G11=0,0,I11/G11) -> 3.4097065 | P11: =IF(E11=0,0,COUNTIFS('Pedidos Top10'!$A$2:$A$1839,A11,'Pedidos Top10'!$C$2:$C$1839,C11,'Pedidos Top10'!$D$2:$D$1839,D11,'Pedidos Top10'!$AG$2:$AG$1839,"PASSARO")/E11) -> 1 | Q11: =IF(K11<=-0.05,"Passaro compete: "&TEXT(-K11,"0%")&" abaixo de "&D11,IF(K11<0.05,"Empate técnico com "&D11,D11&" é "&TEXT(1-H11/I11,"0%")&" mais barata que a Passaro")) -> Passaro compete: 19% abaixo de DOMINALOG
A12: AL | B12: 8 | C12: SAO MIGUEL DOS MILAGRES | D12: DOMINALOG | E12: =COUNTIFS('Pedidos Top10'!$A$2:$A$1839,A12,'Pedidos Top10'!$C$2:$C$1839,C12,'Pedidos Top10'!$D$2:$D$1839,D12) -> 2 | F12: =E12/COUNTIFS('Pedidos Top10'!$A$2:$A$1839,A12,'Pedidos Top10'!$C$2:$C$1839,C12) -> 0.66666667 | G12: =SUMIFS('Pedidos Top10'!$J$2:$J$1839,'Pedidos Top10'!$A$2:$A$1839,A12,'Pedidos Top10'!$C$2:$C$1839,C12,'Pedidos Top10'!$D$2:$D$1839,D12) -> 156.9 | H12: =SUMIFS('Pedidos Top10'!$L$2:$L$1839,'Pedidos Top10'!$A$2:$A$1839,A12,'Pedidos Top10'!$C$2:$C$1839,C12,'Pedidos Top10'!$D$2:$D$1839,D12) -> 583.47 | I12: =SUMIFS('Pedidos Top10'!$AD$2:$AD$1839,'Pedidos Top10'!$A$2:$A$1839,A12,'Pedidos Top10'!$C$2:$C$1839,C12,'Pedidos Top10'!$D$2:$D$1839,D12) -> 474.61 | J12: =I12-H12 -> -108.86 | K12: =IF(H12=0,0,J12/H12) -> -0.18657343 | L12: =IF(E12=0,0,H12/E12) -> 291.735 | M12: =IF(E12=0,0,I12/E12) -> 237.305 | N12: =IF(G12=0,0,H12/G12) -> 3.718738 | O12: =IF(G12=0,0,I12/G12) -> 3.0249203 | P12: =IF(E12=0,0,COUNTIFS('Pedidos Top10'!$A$2:$A$1839,A12,'Pedidos Top10'!$C$2:$C$1839,C12,'Pedidos Top10'!$D$2:$D$1839,D12,'Pedidos Top10'!$AG$2:$AG$1839,"PASSARO")/E12) -> 0.5 | Q12: =IF(K12<=-0.05,"Passaro compete: "&TEXT(-K12,"0%")&" abaixo de "&D12,IF(K12<0.05,"Empate técnico com "&D12,D12&" é "&TEXT(1-H12/I12,"0%")&" mais barata que a Passaro")) -> Passaro compete: 19% abaixo de DOMINALOG
A13: AL | B13: 8 | C13: SAO MIGUEL DOS MILAGRES | D13: FORMATO TRANSPORTES | E13: =COUNTIFS('Pedidos Top10'!$A$2:$A$1839,A13,'Pedidos Top10'!$C$2:$C$1839,C13,'Pedidos Top10'!$D$2:$D$1839,D13) -> 1 | F13: =E13/COUNTIFS('Pedidos Top10'!$A$2:$A$1839,A13,'Pedidos Top10'!$C$2:$C$1839,C13) -> 0.33333333 | G13: =SUMIFS('Pedidos Top10'!$J$2:$J$1839,'Pedidos Top10'!$A$2:$A$1839,A13,'Pedidos Top10'!$C$2:$C$1839,C13,'Pedidos Top10'!$D$2:$D$1839,D13) -> 73.48 | H13: =SUMIFS('Pedidos Top10'!$L$2:$L$1839,'Pedidos Top10'!$A$2:$A$1839,A13,'Pedidos Top10'!$C$2:$C$1839,C13,'Pedidos Top10'!$D$2:$D$1839,D13) -> 266.95 | I13: =SUMIFS('Pedidos Top10'!$AD$2:$AD$1839,'Pedidos Top10'!$A$2:$A$1839,A13,'Pedidos Top10'!$C$2:$C$1839,C13,'Pedidos Top10'!$D$2:$D$1839,D13) -> 226.93 | J13: =I13-H13 -> -40.02 | K13: =IF(H13=0,0,J13/H13) -> -0.14991571 | L13: =IF(E13=0,0,H13/E13) -> 266.95 | M13: =IF(E13=0,0,I13/E13) -> 226.93 | N13: =IF(G13=0,0,H13/G13) -> 3.6329614 | O13: =IF(G13=0,0,I13/G13) -> 3.0883234 | P13: =IF(E13=0,0,COUNTIFS('Pedidos Top10'!$A$2:$A$1839,A13,'Pedidos Top10'!$C$2:$C$1839,C13,'Pedidos Top10'!$D$2:$D$1839,D13,'Pedidos Top10'!$AG$2:$AG$1839,"PASSARO")/E13) -> 1 | Q13: =IF(K13<=-0.05,"Passaro compete: "&TEXT(-K13,"0%")&" abaixo de "&D13,IF(K13<0.05,"Empate técnico com "&D13,D13&" é "&TEXT(1-H13/I13,"0%")&" mais barata que a Passaro")) -> Passaro compete: 15% abaixo de FORMATO TRANSPORTES
... A160: SE | B160: 10 | C160: CRISTINAPOLIS | D160: DOMINALOG | E160: =COUNTIFS('Pedidos Top10'!$A$2:$A$1839,A160,'Pedidos Top10'!$C$2:$C$1839,C160,'Pedidos Top10'!$D$2:$D$1839,D160) -> 2 | F160: =E160/COUNTIFS('Pedidos Top10'!$A$2:$A$1839,A160,'Pedidos Top10'!$C$2:$C$1839,C160) -> 1 | G160: =SUMIFS('Pedidos Top10'!$J$2:$J$1839,'Pedidos Top10'!$A$2:$A$1839,A160,'Pedidos Top10'!$C$2:$C$1839,C160,'Pedidos Top10'!$D$2:$D$1839,D160) -> 223.9 | H160: =SUMIFS('Pedidos Top10'!$L$2:$L$1839,'Pedidos Top10'!$A$2:$A$1839,A160,'Pedidos Top10'!$C$2:$C$1839,C160,'Pedidos Top10'!$D$2:$D$1839,D160) -> 712.9 | I160: =SUMIFS('Pedidos Top10'!$AD$2:$AD$1839,'Pedidos Top10'!$A$2:$A$1839,A160,'Pedidos Top10'!$C$2:$C$1839,C160,'Pedidos Top10'!$D$2:$D$1839,D160) -> 559.48 | J160: =I160-H160 -> -153.42 | K160: =IF(H160=0,0,J160/H160) -> -0.2152055 | L160: =IF(E160=0,0,H160/E160) -> 356.45 | M160: =IF(E160=0,0,I160/E160) -> 279.74 | N160: =IF(G160=0,0,H160/G160) -> 3.1840107 | O160: =IF(G160=0,0,I160/G160) -> 2.4987941 | P160: =IF(E160=0,0,COUNTIFS('Pedidos Top10'!$A$2:$A$1839,A160,'Pedidos Top10'!$C$2:$C$1839,C160,'Pedidos Top10'!$D$2:$D$1839,D160,'Pedidos Top10'!$AG$2:$AG$1839,"PASSARO")/E160) -> 1 | Q160: =IF(K160<=-0.05,"Passaro compete: "&TEXT(-K160,"0%")&" abaixo de "&D160,IF(K160<0.05,"Empate técnico com "&D160,D160&" é "&TEXT(1-H160/I160,"0%")&" mais barata que a Passaro")) -> Passaro compete: 22% abaixo de DOMINALOG

Sheet Premissas
A1: Premissas e metodologia – Simulação PASSARO TRANSPORTES – PROPOSTA 2 de 07/10/2026 (origem SP capital) x fretes realizados Ago/2026 – Nordeste
A3: ICMS por UF de destino (origem SP)
A4: UF | B4: Alíquota ICMS
A5: AL | B5: 0.07 | C5: Alíquota interestadual SP → Nordeste = 7% para todas as UFs (Resolução do Senado 22/1989). Células amarelas são editáveis.
A6: BA | B6: 0.07 | C6: ICMS aplicado "por dentro": Total = Subtotal / (1 − alíquota), igual à forma como o ICMS compõe o valor do CT-e.
A7: CE | B7: 0.07
A8: MA | B8: 0.07
A9: PB | B9: 0.07
A10: PE | B10: 0.07
A11: PI | B11: 0.07
A12: RN | B12: 0.07
A13: SE | B13: 0.07
A15: Metodologia
A16: Base de pedidos | B16: 2933 CT-es no arquivo. Excluídos: 44 CT-es de redespacho (cobrem só um trecho da viagem), 24 CT-es repetidos da mesma NF (2º CT-e da mesma nota, normalmente reentrega ou complemento; mantido só o 1º emitido), 3 CT-es com CEP fora das faixas da Passaro (Porto Seguro/BA, CEPs 46xxx). Sobram 2862 pedidos atendidos pela Passaro; desses, 1838 caem nas Top 10 cidades de cada UF: 1838 com preço na proposta, que são os comparados, e 0 de São Luís/MA, sem preço. Os outros 1024 pedidos (cidades fora do Top 10) ficam fora da análise.
A17: Cruzamento por CEP | B17: O CEP de entrega (col. S) é comparado com as faixas CEPI–CEPF da Passaro. Onde duas faixas se sobrepõem (3 casos na tabela), vale a faixa mais estreita.
A18: Top 10 cidades | B18: Ranking por número de pedidos (NF) em cada UF, entre as cidades atendidas pela Passaro. Em caso de empate, desempata pelo maior valor de frete atual. PB, RN e SE têm vários empates perto da 10ª posição.
A19: Proposta 2 – como a tabela foi montada | B19: O preço por peso segue a "área de atendimento" de cada faixa de CEP, conforme a planilha de prazos/áreas da Passaro: Capital (inclui região metropolitana), Feira de Santana (só BA), Interior 1, Interior 2 e Interior 3 (só BA). As 1.794 faixas de CEP são as mesmas da tabela anterior. O prazo também foi atualizado pela planilha de áreas.
A20: ATENÇÃO – UF usada no preço | B20: 56 faixas continuam cadastradas com a UF de uma cidade homônima de outro estado (ex.: Paulista/PE aparece como "PB"). Nessas faixas usamos o preço da UF real do CEP + a área informada (ex.: Paulista/PE = Capital PE). A coluna "UF pelo CEP" da aba Tabela Passaro mostra a UF usada.
A21: ATENÇÃO – TDA | B21: A proposta diz "TDA conforme listagem em anexo", mas a listagem não veio. Mantivemos os TDAs da tabela anterior (R$ 250/400/500 em 277 faixas). Nas Top 10 isso afeta 15 pedidos. Pedir a listagem para confirmar.
A22: Taxas que saíram | B22: A Proposta 2 não tem TRT (R$ 15 nas capitais) nem a "outra taxa" de R$ 0,45/kg da proposta anterior. O despacho passou de R$ 20 para R$ 30 por CT-e.
A23: Não considerado | B23: TDE (R$ 349,83, só em entregas com dificuldade), reentrega (50%), devolução (100%), armazenagem após 7 dias (R$ 50/ton/dia + 0,20% de seguro sobre a NF), serviços adicionais (veículo dedicado, pernoite, paletização etc.) e cubagem (300 kg/m³; a base não tem dimensões, então usamos o peso bruto).
A24: Valor atual | B24: Coluna J (Valor CTe), já com impostos.
A25: Peso | B25: Peso bruto da NF (col. P).
A26: Valor da NF | B26: Valor Total da NF (col. O), base do Frete Valor (ad valorem) e do GRIS.
A27: Frete peso | B27: Faixas até 10 / 11–30 / 31–50 / 51–70 / 71–100 kg, pela UF e área da faixa de CEP. Acima de 100 kg: valor da faixa de 100 kg + (peso − 100) × Valor Excedente.
... A34: ICMS | B34: "Conforme legislação": o ICMS não está incluso nos preços, então foi somado conforme a tabela acima.

Sheet Tabela Passaro
