Workbook

Sheet Ranking Geral
A1: Quantas vezes cada transportadora foi a mais barata (26 cidades x 6 faixas = 156 cotações)
A3: Transportadora | B3: 20 kg | C3: 40 kg | D3: 60 kg | E3: 80 kg | F3: 100 kg | G3: 120 kg | H3: Total | I3: % do total | J3: Cidades cotadas | K3: Prazo médio (dias)
A4: TRANSIGA FILIAL SP | B4: =COUNTIF(B$16:B$41,$A4) | C4: =COUNTIF(C$16:C$41,$A4) | D4: =COUNTIF(D$16:D$41,$A4) | E4: =COUNTIF(E$16:E$41,$A4) | F4: =COUNTIF(F$16:F$41,$A4) | G4: =COUNTIF(G$16:G$41,$A4) | H4: =SUM(B4:G4) | I4: =H4/SUM($H$4:$H$10) | J4: 26 | K4: 7.3
A5: RAJLOG | B5: =COUNTIF(B$16:B$41,$A5) | C5: =COUNTIF(C$16:C$41,$A5) | D5: =COUNTIF(D$16:D$41,$A5) | E5: =COUNTIF(E$16:E$41,$A5) | F5: =COUNTIF(F$16:F$41,$A5) | G5: =COUNTIF(G$16:G$41,$A5) | H5: =SUM(B5:G5) | I5: =H5/SUM($H$4:$H$10) | J5: 26 | K5: 5
A6: Trans Sua Log - Standard | B6: =COUNTIF(B$16:B$41,$A6) | C6: =COUNTIF(C$16:C$41,$A6) | D6: =COUNTIF(D$16:D$41,$A6) | E6: =COUNTIF(E$16:E$41,$A6) | F6: =COUNTIF(F$16:F$41,$A6) | G6: =COUNTIF(G$16:G$41,$A6) | H6: =SUM(B6:G6) | I6: =H6/SUM($H$4:$H$10) | J6: 26 | K6: 8
A7: Transvanio | B7: =COUNTIF(B$16:B$41,$A7) | C7: =COUNTIF(C$16:C$41,$A7) | D7: =COUNTIF(D$16:D$41,$A7) | E7: =COUNTIF(E$16:E$41,$A7) | F7: =COUNTIF(F$16:F$41,$A7) | G7: =COUNTIF(G$16:G$41,$A7) | H7: =SUM(B7:G7) | I7: =H7/SUM($H$4:$H$10) | J7: 26 | K7: 4.7
A8: VM TRANSPORTES | B8: =COUNTIF(B$16:B$41,$A8) | C8: =COUNTIF(C$16:C$41,$A8) | D8: =COUNTIF(D$16:D$41,$A8) | E8: =COUNTIF(E$16:E$41,$A8) | F8: =COUNTIF(F$16:F$41,$A8) | G8: =COUNTIF(G$16:G$41,$A8) | H8: =SUM(B8:G8) | I8: =H8/SUM($H$4:$H$10) | J8: 15 | K8: 7.7
A9: Zelog Standard | B9: =COUNTIF(B$16:B$41,$A9) | C9: =COUNTIF(C$16:C$41,$A9) | D9: =COUNTIF(D$16:D$41,$A9) | E9: =COUNTIF(E$16:E$41,$A9) | F9: =COUNTIF(F$16:F$41,$A9) | G9: =COUNTIF(G$16:G$41,$A9) | H9: =SUM(B9:G9) | I9: =H9/SUM($H$4:$H$10) | J9: 13 | K9: 4
A10: Trilog Express | B10: =COUNTIF(B$16:B$41,$A10) | C10: =COUNTIF(C$16:C$41,$A10) | D10: =COUNTIF(D$16:D$41,$A10) | E10: =COUNTIF(E$16:E$41,$A10) | F10: =COUNTIF(F$16:F$41,$A10) | G10: =COUNTIF(G$16:G$41,$A10) | H10: =SUM(B10:G10) | I10: =H10/SUM($H$4:$H$10) | J10: 26 | K10: 7
A11: Cidades cotadas e prazo médio: valores fixos extraídos da planilha original.
A14: Base: transportadora mais barata por cidade e faixa
A15: Cidade | B15: 20 kg | C15: 40 kg | D15: 60 kg | E15: 80 kg | F15: 100 kg | G15: 120 kg
A16: Arujá - 07400-165 | B16: ='Comparativo por Cidade'!B12 | C16: ='Comparativo por Cidade'!C12 | D16: ='Comparativo por Cidade'!D12 | E16: ='Comparativo por Cidade'!E12 | F16: ='Comparativo por Cidade'!F12 | G16: ='Comparativo por Cidade'!G12
A17: Caieiras - 07714-600 | B17: ='Comparativo por Cidade'!B26 | C17: ='Comparativo por Cidade'!C26 | D17: ='Comparativo por Cidade'!D26 | E17: ='Comparativo por Cidade'!E26 | F17: ='Comparativo por Cidade'!F26 | G17: ='Comparativo por Cidade'!G26
A18: Cajamar - 07786-425 | B18: ='Comparativo por Cidade'!B40 | C18: ='Comparativo por Cidade'!C40 | D18: ='Comparativo por Cidade'!D40 | E18: ='Comparativo por Cidade'!E40 | F18: ='Comparativo por Cidade'!F40 | G18: ='Comparativo por Cidade'!G40
A19: Carapicuíba - 06395-360 | B19: ='Comparativo por Cidade'!B56 | C19: ='Comparativo por Cidade'!C56 | D19: ='Comparativo por Cidade'!D56 | E19: ='Comparativo por Cidade'!E56 | F19: ='Comparativo por Cidade'!F56 | G19: ='Comparativo por Cidade'!G56
A20: Cotia - 06727-185 | B20: ='Comparativo por Cidade'!B71 | C20: ='Comparativo por Cidade'!C71 | D20: ='Comparativo por Cidade'!D71 | E20: ='Comparativo por Cidade'!E71 | F20: ='Comparativo por Cidade'!F71 | G20: ='Comparativo por Cidade'!G71
A21: Embu das Artes - 06816-030 | B21: ='Comparativo por Cidade'!B86 | C21: ='Comparativo por Cidade'!C86 | D21: ='Comparativo por Cidade'!D86 | E21: ='Comparativo por Cidade'!E86 | F21: ='Comparativo por Cidade'!F86 | G21: ='Comparativo por Cidade'!G86
A22: Ferraz de Vasconcelos - 08545-210 | B22: ='Comparativo por Cidade'!B102 | C22: ='Comparativo por Cidade'!C102 | D22: ='Comparativo por Cidade'!D102 | E22: ='Comparativo por Cidade'!E102 | F22: ='Comparativo por Cidade'!F102 | G22: ='Comparativo por Cidade'!G102
A23: Francisco Morato - 07950-260 | B23: ='Comparativo por Cidade'!B116 | C23: ='Comparativo por Cidade'!C116 | D23: ='Comparativo por Cidade'!D116 | E23: ='Comparativo por Cidade'!E116 | F23: ='Comparativo por Cidade'!F116 | G23: ='Comparativo por Cidade'!G116
A24: Franco da Rocha - 07851-060 | B24: ='Comparativo por Cidade'!B130 | C24: ='Comparativo por Cidade'!C130 | D24: ='Comparativo por Cidade'!D130 | E24: ='Comparativo por Cidade'!E130 | F24: ='Comparativo por Cidade'!F130 | G24: ='Comparativo por Cidade'!G130
A25: Itaquaquecetuba - 08594-270 | B25: ='Comparativo por Cidade'!B146 | C25: ='Comparativo por Cidade'!C146 | D25: ='Comparativo por Cidade'!D146 | E25: ='Comparativo por Cidade'!E146 | F25: ='Comparativo por Cidade'!F146 | G25: ='Comparativo por Cidade'!G146
A26: Jandira - 06624-090 | B26: ='Comparativo por Cidade'!B161 | C26: ='Comparativo por Cidade'!C161 | D26: ='Comparativo por Cidade'!D161 | E26: ='Comparativo por Cidade'!E161 | F26: ='Comparativo por Cidade'!F161 | G26: ='Comparativo por Cidade'!G161
A27: Mairiporã - 07629-694 | B27: ='Comparativo por Cidade'!B175 | C27: ='Comparativo por Cidade'!C175 | D27: ='Comparativo por Cidade'!D175 | E27: ='Comparativo por Cidade'!E175 | F27: ='Comparativo por Cidade'!F175 | G27: ='Comparativo por Cidade'!G175
A28: Mauá - 09390-650 | B28: ='Comparativo por Cidade'!B190 | C28: ='Comparativo por Cidade'!C190 | D28: ='Comparativo por Cidade'!D190 | E28: ='Comparativo por Cidade'!E190 | F28: ='Comparativo por Cidade'!F190 | G28: ='Comparativo por Cidade'!G190
A29: Mogi das Cruzes - 08750-760 | B29: ='Comparativo por Cidade'!B206 | C29: ='Comparativo por Cidade'!C206 | D29: ='Comparativo por Cidade'!D206 | E29: ='Comparativo por Cidade'!E206 | F29: ='Comparativo por Cidade'!F206 | G29: ='Comparativo por Cidade'!G206
A30: Poá - 08553-240 | B30: ='Comparativo por Cidade'!B222 | C30: ='Comparativo por Cidade'!C222 | D30: ='Comparativo por Cidade'!D222 | E30: ='Comparativo por Cidade'!E222 | F30: ='Comparativo por Cidade'!F222 | G30: ='Comparativo por Cidade'!G222
A31: Suzano - 08616-260 | B31: ='Comparativo por Cidade'!B238 | C31: ='Comparativo por Cidade'!C238 | D31: ='Comparativo por Cidade'!D238 | E31: ='Comparativo por Cidade'!E238 | F31: ='Comparativo por Cidade'!F238 | G31: ='Comparativo por Cidade'!G238
A32: Barueri - 06449-080 | B32: ='Comparativo por Cidade'!B254 | C32: ='Comparativo por Cidade'!C254 | D32: ='Comparativo por Cidade'!D254 | E32: ='Comparativo por Cidade'!E254 | F32: ='Comparativo por Cidade'!F254 | G32: ='Comparativo por Cidade'!G254
A33: Diadema - 09960-750 | B33: ='Comparativo por Cidade'!B269 | C33: ='Comparativo por Cidade'!C269 | D33: ='Comparativo por Cidade'!D269 | E33: ='Comparativo por Cidade'!E269 | F33: ='Comparativo por Cidade'!F269 | G33: ='Comparativo por Cidade'!G269
A34: Guarulhos - 07240-230 | B34: ='Comparativo por Cidade'!B284 | C34: ='Comparativo por Cidade'!C284 | D34: ='Comparativo por Cidade'!D284 | E34: ='Comparativo por Cidade'!E284 | F34: ='Comparativo por Cidade'!F284 | G34: ='Comparativo por Cidade'!G284
A35: Osasco - 06140-000 | B35: ='Comparativo por Cidade'!B300 | C35: ='Comparativo por Cidade'!C300 | D35: ='Comparativo por Cidade'!D300 | E35: ='Comparativo por Cidade'!E300 | F35: ='Comparativo por Cidade'!F300 | G35: ='Comparativo por Cidade'!G300
A36: Santana de Parnaíba - 06528-305 | B36: ='Comparativo por Cidade'!B315 | C36: ='Comparativo por Cidade'!C315 | D36: ='Comparativo por Cidade'!D315 | E36: ='Comparativo por Cidade'!E315 | F36: ='Comparativo por Cidade'!F315 | G36: ='Comparativo por Cidade'!G315
A37: Santo André - 09070-010 | B37: ='Comparativo por Cidade'!B330 | C37: ='Comparativo por Cidade'!C330 | D37: ='Comparativo por Cidade'!D330 | E37: ='Comparativo por Cidade'!E330 | F37: ='Comparativo por Cidade'!F330 | G37: ='Comparativo por Cidade'!G330
A38: São Bernardo do Campo - 09840-628 | B38: ='Comparativo por Cidade'!B345 | C38: ='Comparativo por Cidade'!C345 | D38: ='Comparativo por Cidade'!D345 | E38: ='Comparativo por Cidade'!E345 | F38: ='Comparativo por Cidade'!F345 | G38: ='Comparativo por Cidade'!G345
A39: São Caetano do Sul - 09521-010 | B39: ='Comparativo por Cidade'!B360 | C39: ='Comparativo por Cidade'!C360 | D39: ='Comparativo por Cidade'!D360 | E39: ='Comparativo por Cidade'!E360 | F39: ='Comparativo por Cidade'!F360 | G39: ='Comparativo por Cidade'!G360
A40: Taboão da Serra - 06765-904 | B40: ='Comparativo por Cidade'!B375 | C40: ='Comparativo por Cidade'!C375 | D40: ='Comparativo por Cidade'!D375 | E40: ='Comparativo por Cidade'!E375 | F40: ='Comparativo por Cidade'!F375 | G40: ='Comparativo por Cidade'!G375
A41: São Paulo - 02820-030 | B41: ='Comparativo por Cidade'!B390 | C41: ='Comparativo por Cidade'!C390 | D41: ='Comparativo por Cidade'!D390 | E41: ='Comparativo por Cidade'!E390 | F41: ='Comparativo por Cidade'!F390 | G41: ='Comparativo por Cidade'!G390

Sheet Resumo RAJLOG
A1: RAJLOG x concorrente mais barato (entre as 7 selecionadas) – negativo = RAJLOG mais barata
A2: Todas as células buscam os valores da aba "Comparativo por Cidade"
A4: Cidade | B4: 20 kg | C4: 40 kg | D4: 60 kg | E4: 80 kg | F4: 100 kg | G4: 120 kg | H4: Média | I4: Nº transp. cotando
A5: Arujá - 07400-165 | B5: ='Comparativo por Cidade'!B14 | C5: ='Comparativo por Cidade'!C14 | D5: ='Comparativo por Cidade'!D14 | E5: ='Comparativo por Cidade'!E14 | F5: ='Comparativo por Cidade'!F14 | G5: ='Comparativo por Cidade'!G14 | H5: =AVERAGE(B5:G5) | I5: =COUNT('Comparativo por Cidade'!B6:B10)
A6: Caieiras - 07714-600 | B6: ='Comparativo por Cidade'!B28 | C6: ='Comparativo por Cidade'!C28 | D6: ='Comparativo por Cidade'!D28 | E6: ='Comparativo por Cidade'!E28 | F6: ='Comparativo por Cidade'!F28 | G6: ='Comparativo por Cidade'!G28 | H6: =AVERAGE(B6:G6) | I6: =COUNT('Comparativo por Cidade'!B20:B24)
A7: Cajamar - 07786-425 | B7: ='Comparativo por Cidade'!B42 | C7: ='Comparativo por Cidade'!C42 | D7: ='Comparativo por Cidade'!D42 | E7: ='Comparativo por Cidade'!E42 | F7: ='Comparativo por Cidade'!F42 | G7: ='Comparativo por Cidade'!G42 | H7: =AVERAGE(B7:G7) | I7: =COUNT('Comparativo por Cidade'!B34:B38)
A8: Carapicuíba - 06395-360 | B8: ='Comparativo por Cidade'!B58 | C8: ='Comparativo por Cidade'!C58 | D8: ='Comparativo por Cidade'!D58 | E8: ='Comparativo por Cidade'!E58 | F8: ='Comparativo por Cidade'!F58 | G8: ='Comparativo por Cidade'!G58 | H8: =AVERAGE(B8:G8) | I8: =COUNT('Comparativo por Cidade'!B48:B54)
A9: Cotia - 06727-185 | B9: ='Comparativo por Cidade'!B73 | C9: ='Comparativo por Cidade'!C73 | D9: ='Comparativo por Cidade'!D73 | E9: ='Comparativo por Cidade'!E73 | F9: ='Comparativo por Cidade'!F73 | G9: ='Comparativo por Cidade'!G73 | H9: =AVERAGE(B9:G9) | I9: =COUNT('Comparativo por Cidade'!B64:B69)
A10: Embu das Artes - 06816-030 | B10: ='Comparativo por Cidade'!B88 | C10: ='Comparativo por Cidade'!C88 | D10: ='Comparativo por Cidade'!D88 | E10: ='Comparativo por Cidade'!E88 | F10: ='Comparativo por Cidade'!F88 | G10: ='Comparativo por Cidade'!G88 | H10: =AVERAGE(B10:G10) | I10: =COUNT('Comparativo por Cidade'!B79:B84)
A11: Ferraz de Vasconcelos - 08545-210 | B11: ='Comparativo por Cidade'!B104 | C11: ='Comparativo por Cidade'!C104 | D11: ='Comparativo por Cidade'!D104 | E11: ='Comparativo por Cidade'!E104 | F11: ='Comparativo por Cidade'!F104 | G11: ='Comparativo por Cidade'!G104 | H11: =AVERAGE(B11:G11) | I11: =COUNT('Comparativo por Cidade'!B94:B100)
A12: Francisco Morato - 07950-260 | B12: ='Comparativo por Cidade'!B118 | C12: ='Comparativo por Cidade'!C118 | D12: ='Comparativo por Cidade'!D118 | E12: ='Comparativo por Cidade'!E118 | F12: ='Comparativo por Cidade'!F118 | G12: ='Comparativo por Cidade'!G118 | H12: =AVERAGE(B12:G12) | I12: =COUNT('Comparativo por Cidade'!B110:B114)
A13: Franco da Rocha - 07851-060 | B13: ='Comparativo por Cidade'!B132 | C13: ='Comparativo por Cidade'!C132 | D13: ='Comparativo por Cidade'!D132 | E13: ='Comparativo por Cidade'!E132 | F13: ='Comparativo por Cidade'!F132 | G13: ='Comparativo por Cidade'!G132 | H13: =AVERAGE(B13:G13) | I13: =COUNT('Comparativo por Cidade'!B124:B128)
A14: Itaquaquecetuba - 08594-270 | B14: ='Comparativo por Cidade'!B148 | C14: ='Comparativo por Cidade'!C148 | D14: ='Comparativo por Cidade'!D148 | E14: ='Comparativo por Cidade'!E148 | F14: ='Comparativo por Cidade'!F148 | G14: ='Comparativo por Cidade'!G148 | H14: =AVERAGE(B14:G14) | I14: =COUNT('Comparativo por Cidade'!B138:B144)
A15: Jandira - 06624-090 | B15: ='Comparativo por Cidade'!B163 | C15: ='Comparativo por Cidade'!C163 | D15: ='Comparativo por Cidade'!D163 | E15: ='Comparativo por Cidade'!E163 | F15: ='Comparativo por Cidade'!F163 | G15: ='Comparativo por Cidade'!G163 | H15: =AVERAGE(B15:G15) | I15: =COUNT('Comparativo por Cidade'!B154:B159)
A16: Mairiporã - 07629-694 | B16: ='Comparativo por Cidade'!B177 | C16: ='Comparativo por Cidade'!C177 | D16: ='Comparativo por Cidade'!D177 | E16: ='Comparativo por Cidade'!E177 | F16: ='Comparativo por Cidade'!F177 | G16: ='Comparativo por Cidade'!G177 | H16: =AVERAGE(B16:G16) | I16: =COUNT('Comparativo por Cidade'!B169:B173)
A17: Mauá - 09390-650 | B17: ='Comparativo por Cidade'!B192 | C17: ='Comparativo por Cidade'!C192 | D17: ='Comparativo por Cidade'!D192 | E17: ='Comparativo por Cidade'!E192 | F17: ='Comparativo por Cidade'!F192 | G17: ='Comparativo por Cidade'!G192 | H17: =AVERAGE(B17:G17) | I17: =COUNT('Comparativo por Cidade'!B183:B188)
A18: Mogi das Cruzes - 08750-760 | B18: ='Comparativo por Cidade'!B208 | C18: ='Comparativo por Cidade'!C208 | D18: ='Comparativo por Cidade'!D208 | E18: ='Comparativo por Cidade'!E208 | F18: ='Comparativo por Cidade'!F208 | G18: ='Comparativo por Cidade'!G208 | H18: =AVERAGE(B18:G18) | I18: =COUNT('Comparativo por Cidade'!B198:B204)
A19: Poá - 08553-240 | B19: ='Comparativo por Cidade'!B224 | C19: ='Comparativo por Cidade'!C224 | D19: ='Comparativo por Cidade'!D224 | E19: ='Comparativo por Cidade'!E224 | F19: ='Comparativo por Cidade'!F224 | G19: ='Comparativo por Cidade'!G224 | H19: =AVERAGE(B19:G19) | I19: =COUNT('Comparativo por Cidade'!B214:B220)
A20: Suzano - 08616-260 | B20: ='Comparativo por Cidade'!B240 | C20: ='Comparativo por Cidade'!C240 | D20: ='Comparativo por Cidade'!D240 | E20: ='Comparativo por Cidade'!E240 | F20: ='Comparativo por Cidade'!F240 | G20: ='Comparativo por Cidade'!G240 | H20: =AVERAGE(B20:G20) | I20: =COUNT('Comparativo por Cidade'!B230:B236)
A21: Barueri - 06449-080 | B21: ='Comparativo por Cidade'!B256 | C21: ='Comparativo por Cidade'!C256 | D21: ='Comparativo por Cidade'!D256 | E21: ='Comparativo por Cidade'!E256 | F21: ='Comparativo por Cidade'!F256 | G21: ='Comparativo por Cidade'!G256 | H21: =AVERAGE(B21:G21) | I21: =COUNT('Comparativo por Cidade'!B246:B252)
A22: Diadema - 09960-750 | B22: ='Comparativo por Cidade'!B271 | C22: ='Comparativo por Cidade'!C271 | D22: ='Comparativo por Cidade'!D271 | E22: ='Comparativo por Cidade'!E271 | F22: ='Comparativo por Cidade'!F271 | G22: ='Comparativo por Cidade'!G271 | H22: =AVERAGE(B22:G22) | I22: =COUNT('Comparativo por Cidade'!B262:B267)
A23: Guarulhos - 07240-230 | B23: ='Comparativo por Cidade'!B286 | C23: ='Comparativo por Cidade'!C286 | D23: ='Comparativo por Cidade'!D286 | E23: ='Comparativo por Cidade'!E286 | F23: ='Comparativo por Cidade'!F286 | G23: ='Comparativo por Cidade'!G286 | H23: =AVERAGE(B23:G23) | I23: =COUNT('Comparativo por Cidade'!B277:B282)
A24: Osasco - 06140-000 | B24: ='Comparativo por Cidade'!B302 | C24: ='Comparativo por Cidade'!C302 | D24: ='Comparativo por Cidade'!D302 | E24: ='Comparativo por Cidade'!E302 | F24: ='Comparativo por Cidade'!F302 | G24: ='Comparativo por Cidade'!G302 | H24: =AVERAGE(B24:G24) | I24: =COUNT('Comparativo por Cidade'!B292:B298)
A25: Santana de Parnaíba - 06528-305 | B25: ='Comparativo por Cidade'!B317 | C25: ='Comparativo por Cidade'!C317 | D25: ='Comparativo por Cidade'!D317 | E25: ='Comparativo por Cidade'!E317 | F25: ='Comparativo por Cidade'!F317 | G25: ='Comparativo por Cidade'!G317 | H25: =AVERAGE(B25:G25) | I25: =COUNT('Comparativo por Cidade'!B308:B313)
A26: Santo André - 09070-010 | B26: ='Comparativo por Cidade'!B332 | C26: ='Comparativo por Cidade'!C332 | D26: ='Comparativo por Cidade'!D332 | E26: ='Comparativo por Cidade'!E332 | F26: ='Comparativo por Cidade'!F332 | G26: ='Comparativo por Cidade'!G332 | H26: =AVERAGE(B26:G26) | I26: =COUNT('Comparativo por Cidade'!B323:B328)
A27: São Bernardo do Campo - 09840-628 | B27: ='Comparativo por Cidade'!B347 | C27: ='Comparativo por Cidade'!C347 | D27: ='Comparativo por Cidade'!D347 | E27: ='Comparativo por Cidade'!E347 | F27: ='Comparativo por Cidade'!F347 | G27: ='Comparativo por Cidade'!G347 | H27: =AVERAGE(B27:G27) | I27: =COUNT('Comparativo por Cidade'!B338:B343)
A28: São Caetano do Sul - 09521-010 | B28: ='Comparativo por Cidade'!B362 | C28: ='Comparativo por Cidade'!C362 | D28: ='Comparativo por Cidade'!D362 | E28: ='Comparativo por Cidade'!E362 | F28: ='Comparativo por Cidade'!F362 | G28: ='Comparativo por Cidade'!G362 | H28: =AVERAGE(B28:G28) | I28: =COUNT('Comparativo por Cidade'!B353:B358)
A29: Taboão da Serra - 06765-904 | B29: ='Comparativo por Cidade'!B377 | C29: ='Comparativo por Cidade'!C377 | D29: ='Comparativo por Cidade'!D377 | E29: ='Comparativo por Cidade'!E377 | F29: ='Comparativo por Cidade'!F377 | G29: ='Comparativo por Cidade'!G377 | H29: =AVERAGE(B29:G29) | I29: =COUNT('Comparativo por Cidade'!B368:B373)
A30: São Paulo - 02820-030 | B30: ='Comparativo por Cidade'!B392 | C30: ='Comparativo por Cidade'!C392 | D30: ='Comparativo por Cidade'!D392 | E30: ='Comparativo por Cidade'!E392 | F30: ='Comparativo por Cidade'!F392 | G30: ='Comparativo por Cidade'!G392 | H30: =AVERAGE(B30:G30) | I30: =COUNT('Comparativo por Cidade'!B383:B388)
A31: Média geral | B31: =AVERAGE(B5:B30) | C31: =AVERAGE(C5:C30) | D31: =AVERAGE(D5:D30) | E31: =AVERAGE(E5:E30) | F31: =AVERAGE(F5:F30) | G31: =AVERAGE(G5:G30) | H31: =AVERAGE(H5:H30)
A33: Posição da RAJLOG no ranking (1º = mais barata)
A34: Cidade | B34: 20 kg | C34: 40 kg | D34: 60 kg | E34: 80 kg | F34: 100 kg | G34: 120 kg
A35: Arujá - 07400-165 | B35: ='Comparativo por Cidade'!B13 | C35: ='Comparativo por Cidade'!C13 | D35: ='Comparativo por Cidade'!D13 | E35: ='Comparativo por Cidade'!E13 | F35: ='Comparativo por Cidade'!F13 | G35: ='Comparativo por Cidade'!G13
A36: Caieiras - 07714-600 | B36: ='Comparativo por Cidade'!B27 | C36: ='Comparativo por Cidade'!C27 | D36: ='Comparativo por Cidade'!D27 | E36: ='Comparativo por Cidade'!E27 | F36: ='Comparativo por Cidade'!F27 | G36: ='Comparativo por Cidade'!G27
A37: Cajamar - 07786-425 | B37: ='Comparativo por Cidade'!B41 | C37: ='Comparativo por Cidade'!C41 | D37: ='Comparativo por Cidade'!D41 | E37: ='Comparativo por Cidade'!E41 | F37: ='Comparativo por Cidade'!F41 | G37: ='Comparativo por Cidade'!G41
A38: Carapicuíba - 06395-360 | B38: ='Comparativo por Cidade'!B57 | C38: ='Comparativo por Cidade'!C57 | D38: ='Comparativo por Cidade'!D57 | E38: ='Comparativo por Cidade'!E57 | F38: ='Comparativo por Cidade'!F57 | G38: ='Comparativo por Cidade'!G57
A39: Cotia - 06727-185 | B39: ='Comparativo por Cidade'!B72 | C39: ='Comparativo por Cidade'!C72 | D39: ='Comparativo por Cidade'!D72 | E39: ='Comparativo por Cidade'!E72 | F39: ='Comparativo por Cidade'!F72 | G39: ='Comparativo por Cidade'!G72
A40: Embu das Artes - 06816-030 | B40: ='Comparativo por Cidade'!B87 | C40: ='Comparativo por Cidade'!C87 | D40: ='Comparativo por Cidade'!D87 | E40: ='Comparativo por Cidade'!E87 | F40: ='Comparativo por Cidade'!F87 | G40: ='Comparativo por Cidade'!G87
A41: Ferraz de Vasconcelos - 08545-210 | B41: ='Comparativo por Cidade'!B103 | C41: ='Comparativo por Cidade'!C103 | D41: ='Comparativo por Cidade'!D103 | E41: ='Comparativo por Cidade'!E103 | F41: ='Comparativo por Cidade'!F103 | G41: ='Comparativo por Cidade'!G103
A42: Francisco Morato - 07950-260 | B42: ='Comparativo por Cidade'!B117 | C42: ='Comparativo por Cidade'!C117 | D42: ='Comparativo por Cidade'!D117 | E42: ='Comparativo por Cidade'!E117 | F42: ='Comparativo por Cidade'!F117 | G42: ='Comparativo por Cidade'!G117
...

Sheet Comparativo por Cidade
A1: Comparativo de frete – somente as 7 transportadoras selecionadas (valores com ICMS)
A2: Verde = menor valor da faixa na cidade · % negativo = RAJLOG mais barata · linha amarela = RAJLOG · linhas cinza calculadas por fórmula
A4: Arujá - 07400-165
A5: Transportadora | B5: 20 kg | C5: 40 kg | D5: 60 kg | E5: 80 kg | F5: 100 kg | G5: 120 kg | H5: Prazo (dias)
A6: TRANSIGA FILIAL SP | B6: 87.9 | C6: 109.6 | D6: 138.81 | E6: 170.43 | F6: 191.42 | G6: 240.4 | H6: 7
A7: RAJLOG | B7: 53.05 | C7: 81.65 | D7: 117.47 | E7: 158.41 | F7: 168.64 | G7: 221.03 | H7: 5
A8: Trans Sua Log - Standard | B8: 80.64 | C8: 97.82 | D8: 113.18 | E8: 133.72 | F8: 158.06 | G8: 185.63 | H8: 8
A9: Transvanio | B9: 85.24 | C9: 104.55 | D9: 123.98 | E9: 143.61 | F9: 163.14 | G9: 196.72 | H9: 4
A10: Trilog Express | B10: 134.89 | C10: 151.08 | D10: 164.28 | E10: 186.45 | F10: 196.68 | G10: 233.27 | H10: 7
A11: Menor valor | B11: =MIN(B6:B10) | C11: =MIN(C6:C10) | D11: =MIN(D6:D10) | E11: =MIN(E6:E10) | F11: =MIN(F6:F10) | G11: =MIN(G6:G10)
A12: Transportadora mais barata | B12: =INDEX($A$6:$A$10,MATCH(MIN(B6:B10),B6:B10,0)) | C12: =INDEX($A$6:$A$10,MATCH(MIN(C6:C10),C6:C10,0)) | D12: =INDEX($A$6:$A$10,MATCH(MIN(D6:D10),D6:D10,0)) | E12: =INDEX($A$6:$A$10,MATCH(MIN(E6:E10),E6:E10,0)) | F12: =INDEX($A$6:$A$10,MATCH(MIN(F6:F10),F6:F10,0)) | G12: =INDEX($A$6:$A$10,MATCH(MIN(G6:G10),G6:G10,0))
A13: Posição RAJLOG | B13: =(COUNTIF(B6:B10,"<"&B7)+1)&"º de "&COUNT(B6:B10) | C13: =(COUNTIF(C6:C10,"<"&C7)+1)&"º de "&COUNT(C6:C10) | D13: =(COUNTIF(D6:D10,"<"&D7)+1)&"º de "&COUNT(D6:D10) | E13: =(COUNTIF(E6:E10,"<"&E7)+1)&"º de "&COUNT(E6:E10) | F13: =(COUNTIF(F6:F10,"<"&F7)+1)&"º de "&COUNT(F6:F10) | G13: =(COUNTIF(G6:G10,"<"&G7)+1)&"º de "&COUNT(G6:G10)
A14: RAJLOG x concorrente mais barato | B14: =B7/MIN(B6:B6,B8:B10)-1 | C14: =C7/MIN(C6:C6,C8:C10)-1 | D14: =D7/MIN(D6:D6,D8:D10)-1 | E14: =E7/MIN(E6:E6,E8:E10)-1 | F14: =F7/MIN(F6:F6,F8:F10)-1 | G14: =G7/MIN(G6:G6,G8:G10)-1
A15: RAJLOG x média das demais | B15: =B7/((SUM(B6:B10)-B7)/(COUNT(B6:B10)-1))-1 | C15: =C7/((SUM(C6:C10)-C7)/(COUNT(C6:C10)-1))-1 | D15: =D7/((SUM(D6:D10)-D7)/(COUNT(D6:D10)-1))-1 | E15: =E7/((SUM(E6:E10)-E7)/(COUNT(E6:E10)-1))-1 | F15: =F7/((SUM(F6:F10)-F7)/(COUNT(F6:F10)-1))-1 | G15: =G7/((SUM(G6:G10)-G7)/(COUNT(G6:G10)-1))-1
A18: Caieiras - 07714-600
A19: Transportadora | B19: 20 kg | C19: 40 kg | D19: 60 kg | E19: 80 kg | F19: 100 kg | G19: 120 kg | H19: Prazo (dias)
A20: TRANSIGA FILIAL SP | B20: 87.9 | C20: 119.02 | D20: 142.64 | E20: 170.92 | F20: 194.35 | G20: 235.85 | H20: 7
A21: RAJLOG | B21: 53.05 | C21: 81.65 | D21: 117.47 | E21: 158.41 | F21: 168.64 | G21: 221.03 | H21: 5
A22: Trans Sua Log - Standard | B22: 80.64 | C22: 97.82 | D22: 113.18 | E22: 133.72 | F22: 158.06 | G22: 185.63 | H22: 8
A23: Transvanio | B23: 155.69 | C23: 172.73 | D23: 192.16 | E23: 211.8 | F23: 231.32 | G23: 264.9 | H23: 6
A24: Trilog Express | B24: 134.89 | C24: 151.08 | D24: 164.28 | E24: 186.45 | F24: 196.68 | G24: 233.27 | H24: 7
A25: Menor valor | B25: =MIN(B20:B24) | C25: =MIN(C20:C24) | D25: =MIN(D20:D24) | E25: =MIN(E20:E24) | F25: =MIN(F20:F24) | G25: =MIN(G20:G24)
A26: Transportadora mais barata | B26: =INDEX($A$20:$A$24,MATCH(MIN(B20:B24),B20:B24,0)) | C26: =INDEX($A$20:$A$24,MATCH(MIN(C20:C24),C20:C24,0)) | D26: =INDEX($A$20:$A$24,MATCH(MIN(D20:D24),D20:D24,0)) | E26: =INDEX($A$20:$A$24,MATCH(MIN(E20:E24),E20:E24,0)) | F26: =INDEX($A$20:$A$24,MATCH(MIN(F20:F24),F20:F24,0)) | G26: =INDEX($A$20:$A$24,MATCH(MIN(G20:G24),G20:G24,0))
A27: Posição RAJLOG | B27: =(COUNTIF(B20:B24,"<"&B21)+1)&"º de "&COUNT(B20:B24) | C27: =(COUNTIF(C20:C24,"<"&C21)+1)&"º de "&COUNT(C20:C24) | D27: =(COUNTIF(D20:D24,"<"&D21)+1)&"º de "&COUNT(D20:D24) | E27: =(COUNTIF(E20:E24,"<"&E21)+1)&"º de "&COUNT(E20:E24) | F27: =(COUNTIF(F20:F24,"<"&F21)+1)&"º de "&COUNT(F20:F24) | G27: =(COUNTIF(G20:G24,"<"&G21)+1)&"º de "&COUNT(G20:G24)
A28: RAJLOG x concorrente mais barato | B28: =B21/MIN(B20:B20,B22:B24)-1 | C28: =C21/MIN(C20:C20,C22:C24)-1 | D28: =D21/MIN(D20:D20,D22:D24)-1 | E28: =E21/MIN(E20:E20,E22:E24)-1 | F28: =F21/MIN(F20:F20,F22:F24)-1 | G28: =G21/MIN(G20:G20,G22:G24)-1
A29: RAJLOG x média das demais | B29: =B21/((SUM(B20:B24)-B21)/(COUNT(B20:B24)-1))-1 | C29: =C21/((SUM(C20:C24)-C21)/(COUNT(C20:C24)-1))-1 | D29: =D21/((SUM(D20:D24)-D21)/(COUNT(D20:D24)-1))-1 | E29: =E21/((SUM(E20:E24)-E21)/(COUNT(E20:E24)-1))-1 | F29: =F21/((SUM(F20:F24)-F21)/(COUNT(F20:F24)-1))-1 | G29: =G21/((SUM(G20:G24)-G21)/(COUNT(G20:G24)-1))-1
A32: Cajamar - 07786-425
A33: Transportadora | B33: 20 kg | C33: 40 kg | D33: 60 kg | E33: 80 kg | F33: 100 kg | G33: 120 kg | H33: Prazo (dias)
A34: TRANSIGA FILIAL SP | B34: 87.9 | C34: 109.6 | D34: 138.81 | E34: 170.43 | F34: 191.42 | G34: 240.4 | H34: 7
A35: RAJLOG | B35: 53.05 | C35: 81.65 | D35: 117.47 | E35: 158.41 | F35: 168.64 | G35: 221.03 | H35: 5
A36: Trans Sua Log - Standard | B36: 80.64 | C36: 97.82 | D36: 113.18 | E36: 133.72 | F36: 158.06 | G36: 185.63 | H36: 8
A37: Transvanio | B37: 144.33 | C37: 161.36 | D37: 180.8 | E37: 200.43 | F37: 219.95 | G37: 253.53 | H37: 6
A38: Trilog Express | B38: 134.89 | C38: 151.08 | D38: 164.28 | E38: 186.45 | F38: 196.68 | G38: 233.27 | H38: 7
A39: Menor valor | B39: =MIN(B34:B38) | C39: =MIN(C34:C38) | D39: =MIN(D34:D38) | E39: =MIN(E34:E38) | F39: =MIN(F34:F38) | G39: =MIN(G34:G38)
A40: Transportadora mais barata | B40: =INDEX($A$34:$A$38,MATCH(MIN(B34:B38),B34:B38,0)) | C40: =INDEX($A$34:$A$38,MATCH(MIN(C34:C38),C34:C38,0)) | D40: =INDEX($A$34:$A$38,MATCH(MIN(D34:D38),D34:D38,0)) | E40: =INDEX($A$34:$A$38,MATCH(MIN(E34:E38),E34:E38,0)) | F40: =INDEX($A$34:$A$38,MATCH(MIN(F34:F38),F34:F38,0)) | G40: =INDEX($A$34:$A$38,MATCH(MIN(G34:G38),G34:G38,0))
A41: Posição RAJLOG | B41: =(COUNTIF(B34:B38,"<"&B35)+1)&"º de "&COUNT(B34:B38) | C41: =(COUNTIF(C34:C38,"<"&C35)+1)&"º de "&COUNT(C34:C38) | D41: =(COUNTIF(D34:D38,"<"&D35)+1)&"º de "&COUNT(D34:D38) | E41: =(COUNTIF(E34:E38,"<"&E35)+1)&"º de "&COUNT(E34:E38) | F41: =(COUNTIF(F34:F38,"<"&F35)+1)&"º de "&COUNT(F34:F38) | G41: =(COUNTIF(G34:G38,"<"&G35)+1)&"º de "&COUNT(G34:G38)
A42: RAJLOG x concorrente mais barato | B42: =B35/MIN(B34:B34,B36:B38)-1 | C42: =C35/MIN(C34:C34,C36:C38)-1 | D42: =D35/MIN(D34:D34,D36:D38)-1 | E42: =E35/MIN(E34:E34,E36:E38)-1 | F42: =F35/MIN(F34:F34,F36:F38)-1 | G42: =G35/MIN(G34:G34,G36:G38)-1
A43: RAJLOG x média das demais | B43: =B35/((SUM(B34:B38)-B35)/(COUNT(B34:B38)-1))-1 | C43: =C35/((SUM(C34:C38)-C35)/(COUNT(C34:C38)-1))-1 | D43: =D35/((SUM(D34:D38)-D35)/(COUNT(D34:D38)-1))-1 | E43: =E35/((SUM(E34:E38)-E35)/(COUNT(E34:E38)-1))-1 | F43: =F35/((SUM(F34:F38)-F35)/(COUNT(F34:F38)-1))-1 | G43: =G35/((SUM(G34:G38)-G35)/(COUNT(G34:G38)-1))-1
A46: Carapicuíba - 06395-360
A47: Transportadora | B47: 20 kg | C47: 40 kg | D47: 60 kg | E47: 80 kg | F47: 100 kg | G47: 120 kg | H47: Prazo (dias)
...
