Workbook

Sheet Resumo
A1: PROLOG FILIAL SP x TSL FILIAL SP — pedidos RJ com origem de cotação FILIAL SP (jul–set/2026)
A3: PREMISSAS (células em azul podem ser alteradas)
A4: Parâmetro | B4: PROLOG | C4: TSL | D4: Fonte / observação
A5: ICMS por fora (gross-up: total = subtotal / (1 − alíquota)) | B5: 0.12 | C5: 0.12 | D5: Confirmado pelo usuário: 12% por fora. Ambas as tabelas marcadas "ICMS incluso = N".
A6: Ad valorem / frete valor (% NF) | B6: 0.001 | C6: 0 | D6: Tabelas Intelipost
A7: GRIS (% NF) | B7: 0.002 | C7: 0.002 | D7: Tabelas Intelipost
A8: Seguro (% NF) | B8: 0 | C8: 0.002 | D8: Tabela TSL
A9: TAS / entrega fixo (R$ por pedido) | B9: 1 | C9: 11.9 | D9: PROLOG: TAS R$ 1,00 | TSL: entrega fixo R$ 11,90
A10: Pedágio (R$ por fração de 100 kg) | B10: 4.5 | C10: 1 | D10: Tabelas Intelipost
A11: TRT (% sobre o subtotal) | B11: 0 | C11: 0.055 | D11: TSL 5,5%. Base validada: subtotal (frete peso + taxas) — reproduz 100% das cotações reais TSL Filial SP ao centavo
A12: CTe (R$ por kg) | B12: 0.06 | C12: 0 | D12: Tabela PROLOG (faixa de 1 kg)
A13: Taxa interna (R$ por kg) — levar produto até a filial SP | B13: 0.45 | C13: 0 | D13: Confirmado pelo usuário: taxa interna obrigatória, lançada na tabela PROLOG como "outra taxa". NÃO consta na tabela TSL.
A14: Cubagem (kg/m³) | B14: 0 | C14: 300 | D14: Sem dimensões na base: simulado por peso real (as cotações TSL reais batem com peso real)
A17: VISÃO GERAL — mesmos 2.223 pedidos cotados pelas duas tabelas
A18: Indicador | B18: TSL FILIAL SP | C18: PROLOG FILIAL SP | D18: Diferença
A19: Pedidos | B19: =COUNTA(Pedidos!$A$2:$A$2224) -> 2223 | C19: =COUNTA(Pedidos!$A$2:$A$2224) -> 2223
A20: Custo total de frete | B20: =SUM(Pedidos!$T$2:$T$2224) -> 270019.88 | C20: =SUM(Pedidos!$AC$2:$AC$2224) -> 386659.64 | D20: =C20/B20-1 -> 0.43196731
A21: Custo médio por pedido | B21: =AVERAGE(Pedidos!$T$2:$T$2224) -> 121.46643 | C21: =AVERAGE(Pedidos!$AC$2:$AC$2224) -> 173.93596 | D21: =C21/B21-1 -> 0.43196731
A22: Frete / NF | B22: =SUM(Pedidos!$T$2:$T$2224)/SUM(Pedidos!$J$2:$J$2224) -> 0.18924884 | C22: =SUM(Pedidos!$AC$2:$AC$2224)/SUM(Pedidos!$J$2:$J$2224) -> 0.27099816 | D22: =C22-B22 -> 0.081749314
A23: % pedidos em que a PROLOG ganharia a cotação | C23: =COUNTIF(Pedidos!$AG$2:$AG$2224,"SIM")/B19 -> 0.0067476383
A24: PROLOG sem a taxa interna — custo médio | B24: =B21 -> 121.46643 | C24: =AVERAGE(Pedidos!$AD$2:$AD$2224) -> 148.22769 | D24: =C24/B24-1 -> 0.22031812
A25: Prazo médio (dias úteis) | B25: =AVERAGE(Pedidos!$AH$2:$AH$2224) -> 9.9518668 | C25: =AVERAGE(Pedidos!$AI$2:$AI$2224) -> 6.4669366 | D25: =C25-B25 -> -3.4849303
A26: Conferência: custo real cotado (todas transportadoras) | B26: =SUM(Pedidos!$L$2:$L$2224) -> 269909.92
A27: A tabela TSL simulada reproduz as cotações reais da TSL Filial SP (1.592 pedidos) com diferença máxima de R$ 0,01 — o motor de cálculo está validado.
A29: DE ONDE VEM A DIFERENÇA — média por pedido (R$)
A30: Componente | B30: TSL | C30: PROLOG | D30: PROLOG − TSL | E30: % da diferença
A31: Frete peso | B31: =AVERAGE(Pedidos!$M$2:$M$2224) -> 85.783608 | C31: =AVERAGE(Pedidos!$U$2:$U$2224) -> 119.69681 | D31: =C31-B31 -> 33.913198 | E31: =D31/$D$42 -> 0.64634083
A32: Ad valorem | B32: 0 | C32: =AVERAGE(Pedidos!$V$2:$V$2224) -> 0.64183448 | D32: =C32-B32 -> 0.64183448 | E32: =D32/$D$42 -> 0.012232519
A33: GRIS | B33: =AVERAGE(Pedidos!$N$2:$N$2224) -> 1.283669 | C33: =AVERAGE(Pedidos!$W$2:$W$2224) -> 1.283669 | D33: =C33-B33 -> 0 | E33: =D33/$D$42 -> 0
A34: Seguro | B34: =AVERAGE(Pedidos!$O$2:$O$2224) -> 1.283669 | C34: 0 | D34: =C34-B34 -> -1.283669 | E34: =D34/$D$42 -> -0.024465037
A35: TAS / Entrega fixo | B35: =AVERAGE(Pedidos!$Q$2:$Q$2224) -> 11.9 | C35: =AVERAGE(Pedidos!$X$2:$X$2224) -> 1 | D35: =C35-B35 -> -10.9 | E35: =D35/$D$42 -> -0.20773962
A36: Pedágio | B36: =AVERAGE(Pedidos!$P$2:$P$2224) -> 1.0670265 | C36: =AVERAGE(Pedidos!$Y$2:$Y$2224) -> 4.8016194 | D36: =C36-B36 -> 3.7345929 | E36: =D36/$D$42 -> 0.071176414
A37: TRT 5,5% | B37: =AVERAGE(Pedidos!$R$2:$R$2224) -> 5.5724885 | C37: 0 | D37: =C37-B37 -> -5.5724885 | E37: =D37/$D$42 -> -0.10620428
A38: CTe por kg | B38: 0 | C38: =AVERAGE(Pedidos!$Z$2:$Z$2224) -> 3.0164372 | D38: =C38-B38 -> 3.0164372 | E38: =D38/$D$42 -> 0.057489315
A39: Taxa interna R$ 0,45/kg | B39: 0 | C39: =AVERAGE(Pedidos!$AA$2:$AA$2224) -> 22.623279 | D39: =C39-B39 -> 22.623279 | E39: =D39/$D$42 -> 0.43116986
A40: ICMS 12% por fora | B40: =AVERAGE(Pedidos!$T$2:$T$2224)-AVERAGE(Pedidos!$S$2:$S$2224) -> 14.575972 | C40: =AVERAGE(Pedidos!$AC$2:$AC$2224)-AVERAGE(Pedidos!$AB$2:$AB$2224) -> 20.872315 | D40: =C40-B40 -> 6.2963434 | E40: =D40/$D$42 -> 0.12
A42: TOTAL | B42: =SUM(B31:B40) -> 121.46643 | C42: =SUM(C31:C40) -> 173.93596 | D42: =C42-B42 -> 52.469528 | E42: =D42/$D$42 -> 1

Sheet Comparativo Tabelas
A1: Estrutura das tabelas — principais diferenças
A3: Item | B3: PROLOG FILIAL SP | C3: TSL FILIAL SP | D3: Quem leva vantagem | E3: Comentário / oportunidade
A4: Regionalização do RJ | B4: 93 faixas de CEP, 9 níveis de preço | C4: 93 faixas de CEP, só 3 níveis: Capital, Metropolitana (10 faixas), Interior (82) | D4: — | E4: A TSL tem preço único por região; a PROLOG pode ser agressiva onde tem operação própria
A5: Frete peso — Capital (20 a 35 kg) | B5: R$ 82,21 | C5: R$ 54,10 | D5: TSL | E5: A PROLOG está 52% acima na base; é o maior gap de valor (46% dos pedidos)
A6: Frete peso — Capital (40 a 50 kg) | B6: R$ 93,97 | C6: R$ 71,00 | D6: TSL | E6: +32%
A7: Frete peso — Capital (50 a 60 kg) | B7: R$ 112,30 | C7: R$ 79,81 | D7: TSL | E7: +41%
A8: Taxa fixa por pedido | B8: TAS R$ 1,00 | C8: Entrega R$ 11,90 | D8: PROLOG | E8: R$ 10,90 a menos por pedido — vantagem forte em pedidos leves
A9: TRT | B9: não cobra | C9: 5,5% sobre o subtotal | D9: PROLOG | E9: ≈ R$ 5,57 por pedido a favor da PROLOG
A10: Ad valorem / Seguro | B10: 0,1% NF | C10: 0,2% NF | D10: PROLOG | E10: Pequeno (≈ R$ 0,64 a favor)
A11: GRIS | B11: 0,2% NF | C11: 0,2% NF | D11: Empate
A12: Pedágio | B12: R$ 4,50 / 100 kg | C12: R$ 1,00 / 100 kg | D12: TSL | E12: R$ 3,50 a mais por pedido — fácil de negociar para R$ 1,00
A13: CTe | B13: R$ 0,06 por kg | C13: não cobra | D13: TSL | E13: ≈ R$ 3,00 por pedido; pedir para transformar em fixo ou zerar
A14: Taxa interna (filial SP) | B14: R$ 0,45 por kg (na tabela) | C14: não consta | D14: TSL | E14: ≈ R$ 22,60 + ICMS = R$ 25,70 por pedido de penalidade. Se é um custo da operação da filial SP, deveria estar em TODAS as tabelas que saem da filial (inclusive TSL), senão a PROLOG concorre em desvantagem na Intelipost
A15: Cubagem | B15: não aplica (0) | C15: 300 kg/m³ | D15: PROLOG | E15: Vantagem para produtos volumosos (não medida: base sem dimensões)
A16: Excedente acima de 250 kg | B16: R$ 7,71 a 12,05 / kg | C16: R$ 0,91 a 1,28 / kg | D16: TSL | E16: Sem pedidos acima de 250 kg no período; mesmo assim, o excedente da PROLOG está fora de mercado
A17: Prazo — Capital | B17: 5 dias úteis | C17: 8 dias úteis | D17: PROLOG | E17: 3 dias mais rápido
A18: Prazo — Metropolitana | B18: 5 a 7 dias úteis | C18: 10 dias úteis | D18: PROLOG | E18: 3 a 5 dias mais rápido
A19: Prazo — Interior | B19: 6 a 11 dias úteis | C19: 13 dias úteis | D19: PROLOG | E19: 2 a 7 dias mais rápido
A20: Inconsistência na tabela TSL | B20: — | C20: Interior, faixa 170 a 200 kg = R$ 143,51 (menor que a faixa 150 a 170 kg = R$ 215,70) | D20: — | E20: Provável erro de digitação na TSL (deveria ser ~R$ 243). Hoje favorece a TSL nessa faixa

Sheet Top 20 Cidades
A1: Top 20 cidades RJ — preço final (com taxas e ICMS) PROLOG x TSL nos mesmos pedidos
A3: # | B3: Cidade | C3: Região TSL | D3: Pedidos | E3: % pedidos RJ | F3: Peso médio (kg) | G3: NF média | H3: TSL médio | I3: PROLOG médio | J3: PROLOG vs TSL | K3: PROLOG s/ taxa interna vs TSL | L3: Frete/NF TSL | M3: Frete/NF PROLOG | N3: % pedidos PROLOG ganharia | O3: Frete peso PROLOG vs TSL | P3: Prazo TSL | Q3: Prazo PROLOG | R3: Redução necessária no preço PROLOG p/ empatar | S3: Avaliação
A4: 1 | B4: Rio de Janeiro | C4: =INDEX(Pedidos!$G$2:$G$2224,MATCH($B4,Pedidos!$F$2:$F$2224,0)) -> Capital | D4: =COUNTIFS(Pedidos!$F$2:$F$2224,$B4) -> 1030 | E4: =D4/Resumo!$B$19 -> 0.46333783 | F4: =AVERAGEIFS(Pedidos!$I$2:$I$2224,Pedidos!$F$2:$F$2224,$B4) -> 47.579631 | G4: =AVERAGEIFS(Pedidos!$J$2:$J$2224,Pedidos!$F$2:$F$2224,$B4) -> 617.43493 | H4: =AVERAGEIFS(Pedidos!$T$2:$T$2224,Pedidos!$F$2:$F$2224,$B4) -> 106.76312 | I4: =AVERAGEIFS(Pedidos!$AC$2:$AC$2224,Pedidos!$F$2:$F$2224,$B4) -> 156.29299 | J4: =I4/H4-1 -> 0.46392307 | K4: =AVERAGEIFS(Pedidos!$AD$2:$AD$2224,Pedidos!$F$2:$F$2224,$B4)/H4-1 -> 0.23404986 | L4: =SUMIFS(Pedidos!$T$2:$T$2224,Pedidos!$F$2:$F$2224,$B4)/SUMIFS(Pedidos!$J$2:$J$2224,Pedidos!$F$2:$F$2224,$B4) -> 0.17291395 | M4: =SUMIFS(Pedidos!$AC$2:$AC$2224,Pedidos!$F$2:$F$2224,$B4)/SUMIFS(Pedidos!$J$2:$J$2224,Pedidos!$F$2:$F$2224,$B4) -> 0.25313273 | N4: =COUNTIFS(Pedidos!$F$2:$F$2224,$B4,Pedidos!$AG$2:$AG$2224,"SIM")/D4 -> 0 | O4: =SUMIFS(Pedidos!$U$2:$U$2224,Pedidos!$F$2:$F$2224,$B4)/SUMIFS(Pedidos!$M$2:$M$2224,Pedidos!$F$2:$F$2224,$B4)-1 -> 0.43204181 | P4: =AVERAGEIFS(Pedidos!$AH$2:$AH$2224,Pedidos!$F$2:$F$2224,$B4) -> 8 | Q4: =AVERAGEIFS(Pedidos!$AI$2:$AI$2224,Pedidos!$F$2:$F$2224,$B4) -> 5 | R4: =MAX(0,1-H4/I4) -> 0.31690399 | S4: =IF(J4<=0,"Muito bem",IF(J4<=0.32,"Melhor posição",IF(J4<=0.45,"Intermediária","Precisa melhorar"))) -> Precisa melhorar
A5: 2 | B5: São Gonçalo | C5: =INDEX(Pedidos!$G$2:$G$2224,MATCH($B5,Pedidos!$F$2:$F$2224,0)) -> Metropolitana | D5: =COUNTIFS(Pedidos!$F$2:$F$2224,$B5) -> 135 | E5: =D5/Resumo!$B$19 -> 0.060728745 | F5: =AVERAGEIFS(Pedidos!$I$2:$I$2224,Pedidos!$F$2:$F$2224,$B5) -> 50.268593 | G5: =AVERAGEIFS(Pedidos!$J$2:$J$2224,Pedidos!$F$2:$F$2224,$B5) -> 636.66911 | H5: =AVERAGEIFS(Pedidos!$T$2:$T$2224,Pedidos!$F$2:$F$2224,$B5) -> 124.74222 | I5: =AVERAGEIFS(Pedidos!$AC$2:$AC$2224,Pedidos!$F$2:$F$2224,$B5) -> 180.34462 | J5: =I5/H5-1 -> 0.44573846 | K5: =AVERAGEIFS(Pedidos!$AD$2:$AD$2224,Pedidos!$F$2:$F$2224,$B5)/H5-1 -> 0.23818923 | L5: =SUMIFS(Pedidos!$T$2:$T$2224,Pedidos!$F$2:$F$2224,$B5)/SUMIFS(Pedidos!$J$2:$J$2224,Pedidos!$F$2:$F$2224,$B5) -> 0.19592943 | M5: =SUMIFS(Pedidos!$AC$2:$AC$2224,Pedidos!$F$2:$F$2224,$B5)/SUMIFS(Pedidos!$J$2:$J$2224,Pedidos!$F$2:$F$2224,$B5) -> 0.28326272 | N5: =COUNTIFS(Pedidos!$F$2:$F$2224,$B5,Pedidos!$AG$2:$AG$2224,"SIM")/D5 -> 0 | O5: =SUMIFS(Pedidos!$U$2:$U$2224,Pedidos!$F$2:$F$2224,$B5)/SUMIFS(Pedidos!$M$2:$M$2224,Pedidos!$F$2:$F$2224,$B5)-1 -> 0.41404108 | P5: =AVERAGEIFS(Pedidos!$AH$2:$AH$2224,Pedidos!$F$2:$F$2224,$B5) -> 10 | Q5: =AVERAGEIFS(Pedidos!$AI$2:$AI$2224,Pedidos!$F$2:$F$2224,$B5) -> 7 | R5: =MAX(0,1-H5/I5) -> 0.30831196 | S5: =IF(J5<=0,"Muito bem",IF(J5<=0.32,"Melhor posição",IF(J5<=0.45,"Intermediária","Precisa melhorar"))) -> Intermediária
A6: 3 | B6: Duque de Caxias | C6: =INDEX(Pedidos!$G$2:$G$2224,MATCH($B6,Pedidos!$F$2:$F$2224,0)) -> Metropolitana | D6: =COUNTIFS(Pedidos!$F$2:$F$2224,$B6) -> 106 | E6: =D6/Resumo!$B$19 -> 0.047683311 | F6: =AVERAGEIFS(Pedidos!$I$2:$I$2224,Pedidos!$F$2:$F$2224,$B6) -> 52.422453 | G6: =AVERAGEIFS(Pedidos!$J$2:$J$2224,Pedidos!$F$2:$F$2224,$B6) -> 663.55302 | H6: =AVERAGEIFS(Pedidos!$T$2:$T$2224,Pedidos!$F$2:$F$2224,$B6) -> 128.03769 | I6: =AVERAGEIFS(Pedidos!$AC$2:$AC$2224,Pedidos!$F$2:$F$2224,$B6) -> 166.37382 | J6: =I6/H6-1 -> 0.29941283 | K6: =AVERAGEIFS(Pedidos!$AD$2:$AD$2224,Pedidos!$F$2:$F$2224,$B6)/H6-1 -> 0.088492211 | L6: =SUMIFS(Pedidos!$T$2:$T$2224,Pedidos!$F$2:$F$2224,$B6)/SUMIFS(Pedidos!$J$2:$J$2224,Pedidos!$F$2:$F$2224,$B6) -> 0.19295774 | M6: =SUMIFS(Pedidos!$AC$2:$AC$2224,Pedidos!$F$2:$F$2224,$B6)/SUMIFS(Pedidos!$J$2:$J$2224,Pedidos!$F$2:$F$2224,$B6) -> 0.25073176 | N6: =COUNTIFS(Pedidos!$F$2:$F$2224,$B6,Pedidos!$AG$2:$AG$2224,"SIM")/D6 -> 0.056603774 | O6: =SUMIFS(Pedidos!$U$2:$U$2224,Pedidos!$F$2:$F$2224,$B6)/SUMIFS(Pedidos!$M$2:$M$2224,Pedidos!$F$2:$F$2224,$B6)-1 -> 0.22424679 | P6: =AVERAGEIFS(Pedidos!$AH$2:$AH$2224,Pedidos!$F$2:$F$2224,$B6) -> 10 | Q6: =AVERAGEIFS(Pedidos!$AI$2:$AI$2224,Pedidos!$F$2:$F$2224,$B6) -> 5 | R6: =MAX(0,1-H6/I6) -> 0.23042164 | S6: =IF(J6<=0,"Muito bem",IF(J6<=0.32,"Melhor posição",IF(J6<=0.45,"Intermediária","Precisa melhorar"))) -> Melhor posição
A7: 4 | B7: Nova Iguaçu | C7: =INDEX(Pedidos!$G$2:$G$2224,MATCH($B7,Pedidos!$F$2:$F$2224,0)) -> Metropolitana | D7: =COUNTIFS(Pedidos!$F$2:$F$2224,$B7) -> 95 | E7: =D7/Resumo!$B$19 -> 0.042735043 | F7: =AVERAGEIFS(Pedidos!$I$2:$I$2224,Pedidos!$F$2:$F$2224,$B7) -> 55.083474 | G7: =AVERAGEIFS(Pedidos!$J$2:$J$2224,Pedidos!$F$2:$F$2224,$B7) -> 676.70926 | H7: =AVERAGEIFS(Pedidos!$T$2:$T$2224,Pedidos!$F$2:$F$2224,$B7) -> 130.60571 | I7: =AVERAGEIFS(Pedidos!$AC$2:$AC$2224,Pedidos!$F$2:$F$2224,$B7) -> 172.30948 | J7: =I7/H7-1 -> 0.3193104 | K7: =AVERAGEIFS(Pedidos!$AD$2:$AD$2224,Pedidos!$F$2:$F$2224,$B7)/H7-1 -> 0.10194812 | L7: =SUMIFS(Pedidos!$T$2:$T$2224,Pedidos!$F$2:$F$2224,$B7)/SUMIFS(Pedidos!$J$2:$J$2224,Pedidos!$F$2:$F$2224,$B7) -> 0.19300122 | M7: =SUMIFS(Pedidos!$AC$2:$AC$2224,Pedidos!$F$2:$F$2224,$B7)/SUMIFS(Pedidos!$J$2:$J$2224,Pedidos!$F$2:$F$2224,$B7) -> 0.25462852 | N7: =COUNTIFS(Pedidos!$F$2:$F$2224,$B7,Pedidos!$AG$2:$AG$2224,"SIM")/D7 -> 0.021052632 | O7: =SUMIFS(Pedidos!$U$2:$U$2224,Pedidos!$F$2:$F$2224,$B7)/SUMIFS(Pedidos!$M$2:$M$2224,Pedidos!$F$2:$F$2224,$B7)-1 -> 0.23727191 | P7: =AVERAGEIFS(Pedidos!$AH$2:$AH$2224,Pedidos!$F$2:$F$2224,$B7) -> 10 | Q7: =AVERAGEIFS(Pedidos!$AI$2:$AI$2224,Pedidos!$F$2:$F$2224,$B7) -> 5 | R7: =MAX(0,1-H7/I7) -> 0.24202826 | S7: =IF(J7<=0,"Muito bem",IF(J7<=0.32,"Melhor posição",IF(J7<=0.45,"Intermediária","Precisa melhorar"))) -> Melhor posição
A8: 5 | B8: Niterói | C8: =INDEX(Pedidos!$G$2:$G$2224,MATCH($B8,Pedidos!$F$2:$F$2224,0)) -> Metropolitana | D8: =COUNTIFS(Pedidos!$F$2:$F$2224,$B8) -> 68 | E8: =D8/Resumo!$B$19 -> 0.030589294 | F8: =AVERAGEIFS(Pedidos!$I$2:$I$2224,Pedidos!$F$2:$F$2224,$B8) -> 47.945882 | G8: =AVERAGEIFS(Pedidos!$J$2:$J$2224,Pedidos!$F$2:$F$2224,$B8) -> 603.64809 | H8: =AVERAGEIFS(Pedidos!$T$2:$T$2224,Pedidos!$F$2:$F$2224,$B8) -> 122.05811 | I8: =AVERAGEIFS(Pedidos!$AC$2:$AC$2224,Pedidos!$F$2:$F$2224,$B8) -> 175.73135 | J8: =I8/H8-1 -> 0.43973517 | K8: =AVERAGEIFS(Pedidos!$AD$2:$AD$2224,Pedidos!$F$2:$F$2224,$B8)/H8-1 -> 0.23716005 | L8: =SUMIFS(Pedidos!$T$2:$T$2224,Pedidos!$F$2:$F$2224,$B8)/SUMIFS(Pedidos!$J$2:$J$2224,Pedidos!$F$2:$F$2224,$B8) -> 0.20220077 | M8: =SUMIFS(Pedidos!$AC$2:$AC$2224,Pedidos!$F$2:$F$2224,$B8)/SUMIFS(Pedidos!$J$2:$J$2224,Pedidos!$F$2:$F$2224,$B8) -> 0.29111556 | N8: =COUNTIFS(Pedidos!$F$2:$F$2224,$B8,Pedidos!$AG$2:$AG$2224,"SIM")/D8 -> 0 | O8: =SUMIFS(Pedidos!$U$2:$U$2224,Pedidos!$F$2:$F$2224,$B8)/SUMIFS(Pedidos!$M$2:$M$2224,Pedidos!$F$2:$F$2224,$B8)-1 -> 0.41718327 | P8: =AVERAGEIFS(Pedidos!$AH$2:$AH$2224,Pedidos!$F$2:$F$2224,$B8) -> 10 | Q8: =AVERAGEIFS(Pedidos!$AI$2:$AI$2224,Pedidos!$F$2:$F$2224,$B8) -> 7 | R8: =MAX(0,1-H8/I8) -> 0.30542782 | S8: =IF(J8<=0,"Muito bem",IF(J8<=0.32,"Melhor posição",IF(J8<=0.45,"Intermediária","Precisa melhorar"))) -> Intermediária
A9: 6 | B9: Campos dos Goytacazes | C9: =INDEX(Pedidos!$G$2:$G$2224,MATCH($B9,Pedidos!$F$2:$F$2224,0)) -> Interior | D9: =COUNTIFS(Pedidos!$F$2:$F$2224,$B9) -> 53 | E9: =D9/Resumo!$B$19 -> 0.023841655 | F9: =AVERAGEIFS(Pedidos!$I$2:$I$2224,Pedidos!$F$2:$F$2224,$B9) -> 49.475283 | G9: =AVERAGEIFS(Pedidos!$J$2:$J$2224,Pedidos!$F$2:$F$2224,$B9) -> 649.88434 | H9: =AVERAGEIFS(Pedidos!$T$2:$T$2224,Pedidos!$F$2:$F$2224,$B9) -> 136.90877 | I9: =AVERAGEIFS(Pedidos!$AC$2:$AC$2224,Pedidos!$F$2:$F$2224,$B9) -> 218.07379 | J9: =I9/H9-1 -> 0.59284021 | K9: =AVERAGEIFS(Pedidos!$AD$2:$AD$2224,Pedidos!$F$2:$F$2224,$B9)/H9-1 -> 0.40686199 | L9: =SUMIFS(Pedidos!$T$2:$T$2224,Pedidos!$F$2:$F$2224,$B9)/SUMIFS(Pedidos!$J$2:$J$2224,Pedidos!$F$2:$F$2224,$B9) -> 0.21066636 | M9: =SUMIFS(Pedidos!$AC$2:$AC$2224,Pedidos!$F$2:$F$2224,$B9)/SUMIFS(Pedidos!$J$2:$J$2224,Pedidos!$F$2:$F$2224,$B9) -> 0.33555785 | N9: =COUNTIFS(Pedidos!$F$2:$F$2224,$B9,Pedidos!$AG$2:$AG$2224,"SIM")/D9 -> 0 | O9: =SUMIFS(Pedidos!$U$2:$U$2224,Pedidos!$F$2:$F$2224,$B9)/SUMIFS(Pedidos!$M$2:$M$2224,Pedidos!$F$2:$F$2224,$B9)-1 -> 0.60936358 | P9: =AVERAGEIFS(Pedidos!$AH$2:$AH$2224,Pedidos!$F$2:$F$2224,$B9) -> 13 | Q9: =AVERAGEIFS(Pedidos!$AI$2:$AI$2224,Pedidos!$F$2:$F$2224,$B9) -> 11 | R9: =MAX(0,1-H9/I9) -> 0.37219064 | S9: =IF(J9<=0,"Muito bem",IF(J9<=0.32,"Melhor posição",IF(J9<=0.45,"Intermediária","Precisa melhorar"))) -> Precisa melhorar
A10: 7 | B10: Belford Roxo | C10: =INDEX(Pedidos!$G$2:$G$2224,MATCH($B10,Pedidos!$F$2:$F$2224,0)) -> Metropolitana | D10: =COUNTIFS(Pedidos!$F$2:$F$2224,$B10) -> 49 | E10: =D10/Resumo!$B$19 -> 0.022042285 | F10: =AVERAGEIFS(Pedidos!$I$2:$I$2224,Pedidos!$F$2:$F$2224,$B10) -> 54.08 | G10: =AVERAGEIFS(Pedidos!$J$2:$J$2224,Pedidos!$F$2:$F$2224,$B10) -> 687.52816 | H10: =AVERAGEIFS(Pedidos!$T$2:$T$2224,Pedidos!$F$2:$F$2224,$B10) -> 128.18998 | I10: =AVERAGEIFS(Pedidos!$AC$2:$AC$2224,Pedidos!$F$2:$F$2224,$B10) -> 166.98856 | J10: =I10/H10-1 -> 0.30266472 | K10: =AVERAGEIFS(Pedidos!$AD$2:$AD$2224,Pedidos!$F$2:$F$2224,$B10)/H10-1 -> 0.08513623 | L10: =SUMIFS(Pedidos!$T$2:$T$2224,Pedidos!$F$2:$F$2224,$B10)/SUMIFS(Pedidos!$J$2:$J$2224,Pedidos!$F$2:$F$2224,$B10) -> 0.18645051 | M10: =SUMIFS(Pedidos!$AC$2:$AC$2224,Pedidos!$F$2:$F$2224,$B10)/SUMIFS(Pedidos!$J$2:$J$2224,Pedidos!$F$2:$F$2224,$B10) -> 0.2428825 | N10: =COUNTIFS(Pedidos!$F$2:$F$2224,$B10,Pedidos!$AG$2:$AG$2224,"SIM")/D10 -> 0.081632653 | O10: =SUMIFS(Pedidos!$U$2:$U$2224,Pedidos!$F$2:$F$2224,$B10)/SUMIFS(Pedidos!$M$2:$M$2224,Pedidos!$F$2:$F$2224,$B10)-1 -> 0.22020884 | P10: =AVERAGEIFS(Pedidos!$AH$2:$AH$2224,Pedidos!$F$2:$F$2224,$B10) -> 10 | Q10: =AVERAGEIFS(Pedidos!$AI$2:$AI$2224,Pedidos!$F$2:$F$2224,$B10) -> 5 | R10: =MAX(0,1-H10/I10) -> 0.23234277 | S10: =IF(J10<=0,"Muito bem",IF(J10<=0.32,"Melhor posição",IF(J10<=0.45,"Intermediária","Precisa melhorar"))) -> Melhor posição
A11: 8 | B11: Macaé | C11: =INDEX(Pedidos!$G$2:$G$2224,MATCH($B11,Pedidos!$F$2:$F$2224,0)) -> Interior | D11: =COUNTIFS(Pedidos!$F$2:$F$2224,$B11) -> 45 | E11: =D11/Resumo!$B$19 -> 0.020242915 | F11: =AVERAGEIFS(Pedidos!$I$2:$I$2224,Pedidos!$F$2:$F$2224,$B11) -> 60.060222 | G11: =AVERAGEIFS(Pedidos!$J$2:$J$2224,Pedidos!$F$2:$F$2224,$B11) -> 746.16467 | H11: =AVERAGEIFS(Pedidos!$T$2:$T$2224,Pedidos!$F$2:$F$2224,$B11) -> 151.23824 | I11: =AVERAGEIFS(Pedidos!$AC$2:$AC$2224,Pedidos!$F$2:$F$2224,$B11) -> 241.39778 | J11: =I11/H11-1 -> 0.59614254 | K11: =AVERAGEIFS(Pedidos!$AD$2:$AD$2224,Pedidos!$F$2:$F$2224,$B11)/H11-1 -> 0.39184416 | L11: =SUMIFS(Pedidos!$T$2:$T$2224,Pedidos!$F$2:$F$2224,$B11)/SUMIFS(Pedidos!$J$2:$J$2224,Pedidos!$F$2:$F$2224,$B11) -> 0.20268748 | M11: =SUMIFS(Pedidos!$AC$2:$AC$2224,Pedidos!$F$2:$F$2224,$B11)/SUMIFS(Pedidos!$J$2:$J$2224,Pedidos!$F$2:$F$2224,$B11) -> 0.32351811 | N11: =COUNTIFS(Pedidos!$F$2:$F$2224,$B11,Pedidos!$AG$2:$AG$2224,"SIM")/D11 -> 0 | O11: =SUMIFS(Pedidos!$U$2:$U$2224,Pedidos!$F$2:$F$2224,$B11)/SUMIFS(Pedidos!$M$2:$M$2224,Pedidos!$F$2:$F$2224,$B11)-1 -> 0.57333132 | P11: =AVERAGEIFS(Pedidos!$AH$2:$AH$2224,Pedidos!$F$2:$F$2224,$B11) -> 13 | Q11: =AVERAGEIFS(Pedidos!$AI$2:$AI$2224,Pedidos!$F$2:$F$2224,$B11) -> 11 | R11: =MAX(0,1-H11/I11) -> 0.37348954 | S11: =IF(J11<=0,"Muito bem",IF(J11<=0.32,"Melhor posição",IF(J11<=0.45,"Intermediária","Precisa melhorar"))) -> Precisa melhorar
A12: 9 | B12: São João de Meriti | C12: =INDEX(Pedidos!$G$2:$G$2224,MATCH($B12,Pedidos!$F$2:$F$2224,0)) -> Metropolitana | D12: =COUNTIFS(Pedidos!$F$2:$F$2224,$B12) -> 37 | E12: =D12/Resumo!$B$19 -> 0.016644175 | F12: =AVERAGEIFS(Pedidos!$I$2:$I$2224,Pedidos!$F$2:$F$2224,$B12) -> 55.930541 | G12: =AVERAGEIFS(Pedidos!$J$2:$J$2224,Pedidos!$F$2:$F$2224,$B12) -> 698.24405 | H12: =AVERAGEIFS(Pedidos!$T$2:$T$2224,Pedidos!$F$2:$F$2224,$B12) -> 133.32206 | I12: =AVERAGEIFS(Pedidos!$AC$2:$AC$2224,Pedidos!$F$2:$F$2224,$B12) -> 175.04377 | J12: =I12/H12-1 -> 0.31293922 | K12: =AVERAGEIFS(Pedidos!$AD$2:$AD$2224,Pedidos!$F$2:$F$2224,$B12)/H12-1 -> 0.097215371 | L12: =SUMIFS(Pedidos!$T$2:$T$2224,Pedidos!$F$2:$F$2224,$B12)/SUMIFS(Pedidos!$J$2:$J$2224,Pedidos!$F$2:$F$2224,$B12) -> 0.19093906 | M12: =SUMIFS(Pedidos!$AC$2:$AC$2224,Pedidos!$F$2:$F$2224,$B12)/SUMIFS(Pedidos!$J$2:$J$2224,Pedidos!$F$2:$F$2224,$B12) -> 0.25069138 | N12: =COUNTIFS(Pedidos!$F$2:$F$2224,$B12,Pedidos!$AG$2:$AG$2224,"SIM")/D12 -> 0.027027027 | O12: =SUMIFS(Pedidos!$U$2:$U$2224,Pedidos!$F$2:$F$2224,$B12)/SUMIFS(Pedidos!$M$2:$M$2224,Pedidos!$F$2:$F$2224,$B12)-1 -> 0.22920267 | P12: =AVERAGEIFS(Pedidos!$AH$2:$AH$2224,Pedidos!$F$2:$F$2224,$B12) -> 10 | Q12: =AVERAGEIFS(Pedidos!$AI$2:$AI$2224,Pedidos!$F$2:$F$2224,$B12) -> 5 | R12: =MAX(0,1-H12/I12) -> 0.23835012 | S12: =IF(J12<=0,"Muito bem",IF(J12<=0.32,"Melhor posição",IF(J12<=0.45,"Intermediária","Precisa melhorar"))) -> Melhor posição
A13: 10 | B13: Volta Redonda | C13: =INDEX(Pedidos!$G$2:$G$2224,MATCH($B13,Pedidos!$F$2:$F$2224,0)) -> Interior | D13: =COUNTIFS(Pedidos!$F$2:$F$2224,$B13) -> 37 | E13: =D13/Resumo!$B$19 -> 0.016644175 | F13: =AVERAGEIFS(Pedidos!$I$2:$I$2224,Pedidos!$F$2:$F$2224,$B13) -> 50.886757 | G13: =AVERAGEIFS(Pedidos!$J$2:$J$2224,Pedidos!$F$2:$F$2224,$B13) -> 652.92108 | H13: =AVERAGEIFS(Pedidos!$T$2:$T$2224,Pedidos!$F$2:$F$2224,$B13) -> 139.32196 | I13: =AVERAGEIFS(Pedidos!$AC$2:$AC$2224,Pedidos!$F$2:$F$2224,$B13) -> 198.53821 | J13: =I13/H13-1 -> 0.42503171 | K13: =AVERAGEIFS(Pedidos!$AD$2:$AD$2224,Pedidos!$F$2:$F$2224,$B13)/H13-1 -> 0.23655307 | L13: =SUMIFS(Pedidos!$T$2:$T$2224,Pedidos!$F$2:$F$2224,$B13)/SUMIFS(Pedidos!$J$2:$J$2224,Pedidos!$F$2:$F$2224,$B13) -> 0.21338255 | M13: =SUMIFS(Pedidos!$AC$2:$AC$2224,Pedidos!$F$2:$F$2224,$B13)/SUMIFS(Pedidos!$J$2:$J$2224,Pedidos!$F$2:$F$2224,$B13) -> 0.30407689 | N13: =COUNTIFS(Pedidos!$F$2:$F$2224,$B13,Pedidos!$AG$2:$AG$2224,"SIM")/D13 -> 0 | O13: =SUMIFS(Pedidos!$U$2:$U$2224,Pedidos!$F$2:$F$2224,$B13)/SUMIFS(Pedidos!$M$2:$M$2224,Pedidos!$F$2:$F$2224,$B13)-1 -> 0.39918634 | P13: =AVERAGEIFS(Pedidos!$AH$2:$AH$2224,Pedidos!$F$2:$F$2224,$B13) -> 13 | Q13: =AVERAGEIFS(Pedidos!$AI$2:$AI$2224,Pedidos!$F$2:$F$2224,$B13) -> 10 | R13: =MAX(0,1-H13/I13) -> 0.29826123 | S13: =IF(J13<=0,"Muito bem",IF(J13<=0.32,"Melhor posição",IF(J13<=0.45,"Intermediária","Precisa melhorar"))) -> Intermediária
A14: 11 | B14: Angra dos Reis | C14: =INDEX(Pedidos!$G$2:$G$2224,MATCH($B14,Pedidos!$F$2:$F$2224,0)) -> Interior | D14: =COUNTIFS(Pedidos!$F$2:$F$2224,$B14) -> 35 | E14: =D14/Resumo!$B$19 -> 0.015744489 | F14: =AVERAGEIFS(Pedidos!$I$2:$I$2224,Pedidos!$F$2:$F$2224,$B14) -> 44.394286 | G14: =AVERAGEIFS(Pedidos!$J$2:$J$2224,Pedidos!$F$2:$F$2224,$B14) -> 596.41771 | H14: =AVERAGEIFS(Pedidos!$T$2:$T$2224,Pedidos!$F$2:$F$2224,$B14) -> 129.13126 | I14: =AVERAGEIFS(Pedidos!$AC$2:$AC$2224,Pedidos!$F$2:$F$2224,$B14) -> 179.38259 | J14: =I14/H14-1 -> 0.38914922 | K14: =AVERAGEIFS(Pedidos!$AD$2:$AD$2224,Pedidos!$F$2:$F$2224,$B14)/H14-1 -> 0.21173989 | L14: =SUMIFS(Pedidos!$T$2:$T$2224,Pedidos!$F$2:$F$2224,$B14)/SUMIFS(Pedidos!$J$2:$J$2224,Pedidos!$F$2:$F$2224,$B14) -> 0.21651145 | M14: =SUMIFS(Pedidos!$AC$2:$AC$2224,Pedidos!$F$2:$F$2224,$B14)/SUMIFS(Pedidos!$J$2:$J$2224,Pedidos!$F$2:$F$2224,$B14) -> 0.30076671 | N14: =COUNTIFS(Pedidos!$F$2:$F$2224,$B14,Pedidos!$AG$2:$AG$2224,"SIM")/D14 -> 0 | O14: =SUMIFS(Pedidos!$U$2:$U$2224,Pedidos!$F$2:$F$2224,$B14)/SUMIFS(Pedidos!$M$2:$M$2224,Pedidos!$F$2:$F$2224,$B14)-1 -> 0.38186034 | P14: =AVERAGEIFS(Pedidos!$AH$2:$AH$2224,Pedidos!$F$2:$F$2224,$B14) -> 13 | Q14: =AVERAGEIFS(Pedidos!$AI$2:$AI$2224,Pedidos!$F$2:$F$2224,$B14) -> 10 | R14: =MAX(0,1-H14/I14) -> 0.28013493 | S14: =IF(J14<=0,"Muito bem",IF(J14<=0.32,"Melhor posição",IF(J14<=0.45,"Intermediária","Precisa melhorar"))) -> Intermediária
A15: 12 | B15: Petrópolis | C15: =INDEX(Pedidos!$G$2:$G$2224,MATCH($B15,Pedidos!$F$2:$F$2224,0)) -> Interior | D15: =COUNTIFS(Pedidos!$F$2:$F$2224,$B15) -> 32 | E15: =D15/Resumo!$B$19 -> 0.014394962 | F15: =AVERAGEIFS(Pedidos!$I$2:$I$2224,Pedidos!$F$2:$F$2224,$B15) -> 58.889375 | G15: =AVERAGEIFS(Pedidos!$J$2:$J$2224,Pedidos!$F$2:$F$2224,$B15) -> 743.8225 | H15: =AVERAGEIFS(Pedidos!$T$2:$T$2224,Pedidos!$F$2:$F$2224,$B15) -> 149.92911 | I15: =AVERAGEIFS(Pedidos!$AC$2:$AC$2224,Pedidos!$F$2:$F$2224,$B15) -> 216.62809 | J15: =I15/H15-1 -> 0.4448701 | K15: =AVERAGEIFS(Pedidos!$AD$2:$AD$2224,Pedidos!$F$2:$F$2224,$B15)/H15-1 -> 0.24257279 | L15: =SUMIFS(Pedidos!$T$2:$T$2224,Pedidos!$F$2:$F$2224,$B15)/SUMIFS(Pedidos!$J$2:$J$2224,Pedidos!$F$2:$F$2224,$B15) -> 0.20156571 | M15: =SUMIFS(Pedidos!$AC$2:$AC$2224,Pedidos!$F$2:$F$2224,$B15)/SUMIFS(Pedidos!$J$2:$J$2224,Pedidos!$F$2:$F$2224,$B15) -> 0.29123627 | N15: =COUNTIFS(Pedidos!$F$2:$F$2224,$B15,Pedidos!$AG$2:$AG$2224,"SIM")/D15 -> 0 | O15: =SUMIFS(Pedidos!$U$2:$U$2224,Pedidos!$F$2:$F$2224,$B15)/SUMIFS(Pedidos!$M$2:$M$2224,Pedidos!$F$2:$F$2224,$B15)-1 -> 0.39455971 | P15: =AVERAGEIFS(Pedidos!$AH$2:$AH$2224,Pedidos!$F$2:$F$2224,$B15) -> 13 | Q15: =AVERAGEIFS(Pedidos!$AI$2:$AI$2224,Pedidos!$F$2:$F$2224,$B15) -> 8 | R15: =MAX(0,1-H15/I15) -> 0.30789626 | S15: =IF(J15<=0,"Muito bem",IF(J15<=0.32,"Melhor posição",IF(J15<=0.45,"Intermediária","Precisa melhorar"))) -> Intermediária
... A23: 20 | B23: Rio das Ostras | C23: =INDEX(Pedidos!$G$2:$G$2224,MATCH($B23,Pedidos!$F$2:$F$2224,0)) -> Interior | D23: =COUNTIFS(Pedidos!$F$2:$F$2224,$B23) -> 18 | E23: =D23/Resumo!$B$19 -> 0.008097166 | F23: =AVERAGEIFS(Pedidos!$I$2:$I$2224,Pedidos!$F$2:$F$2224,$B23) -> 47.438889 | G23: =AVERAGEIFS(Pedidos!$J$2:$J$2224,Pedidos!$F$2:$F$2224,$B23) -> 604.15056 | H23: =AVERAGEIFS(Pedidos!$T$2:$T$2224,Pedidos!$F$2:$F$2224,$B23) -> 132.43506 | I23: =AVERAGEIFS(Pedidos!$AC$2:$AC$2224,Pedidos!$F$2:$F$2224,$B23) -> 190.52993 | J23: =I23/H23-1 -> 0.43866688 | K23: =AVERAGEIFS(Pedidos!$AD$2:$AD$2224,Pedidos!$F$2:$F$2224,$B23)/H23-1 -> 0.25461441 | L23: =SUMIFS(Pedidos!$T$2:$T$2224,Pedidos!$F$2:$F$2224,$B23)/SUMIFS(Pedidos!$J$2:$J$2224,Pedidos!$F$2:$F$2224,$B23) -> 0.2192087 | M23: =SUMIFS(Pedidos!$AC$2:$AC$2224,Pedidos!$F$2:$F$2224,$B23)/SUMIFS(Pedidos!$J$2:$J$2224,Pedidos!$F$2:$F$2224,$B23) -> 0.3153683 | N23: =COUNTIFS(Pedidos!$F$2:$F$2224,$B23,Pedidos!$AG$2:$AG$2224,"SIM")/D23 -> 0 | O23: =SUMIFS(Pedidos!$U$2:$U$2224,Pedidos!$F$2:$F$2224,$B23)/SUMIFS(Pedidos!$M$2:$M$2224,Pedidos!$F$2:$F$2224,$B23)-1 -> 0.42977503 | P23: =AVERAGEIFS(Pedidos!$AH$2:$AH$2224,Pedidos!$F$2:$F$2224,$B23) -> 13 | Q23: =AVERAGEIFS(Pedidos!$AI$2:$AI$2224,Pedidos!$F$2:$F$2224,$B23) -> 10 | R23: =MAX(0,1-H23/I23) -> 0.30491206 | S23: =IF(J23<=0,"Muito bem",IF(J23<=0.32,"Melhor posição",IF(J23<=0.45,"Intermediária","Precisa melhorar"))) -> Intermediária
B24: TOTAL TOP 20 | D24: =SUM(D4:D23) -> 1912 | E24: =D24/Resumo!$B$19 -> 0.86009897 | F24: =AVERAGEIFS(Pedidos!$I$2:$I$2224,Pedidos!$AJ$2:$AJ$2224,"SIM") -> 49.45444 | G24: =AVERAGEIFS(Pedidos!$J$2:$J$2224,Pedidos!$AJ$2:$AJ$2224,"SIM") -> 636.04536 | H24: =AVERAGEIFS(Pedidos!$T$2:$T$2224,Pedidos!$AJ$2:$AJ$2224,"SIM") -> 118.44739 | I24: =AVERAGEIFS(Pedidos!$AC$2:$AC$2224,Pedidos!$AJ$2:$AJ$2224,"SIM") -> 169.56633 | J24: =I24/H24-1 -> 0.43157508 | K24: =AVERAGEIFS(Pedidos!$AD$2:$AD$2224,Pedidos!$AJ$2:$AJ$2224,"SIM")/H24-1 -> 0.21632815 | L24: =SUMIFS(Pedidos!$T$2:$T$2224,Pedidos!$AJ$2:$AJ$2224,"SIM")/SUMIFS(Pedidos!$J$2:$J$2224,Pedidos!$AJ$2:$AJ$2224,"SIM") -> 0.18622475 | M24: =SUMIFS(Pedidos!$AC$2:$AC$2224,Pedidos!$AJ$2:$AJ$2224,"SIM")/SUMIFS(Pedidos!$J$2:$J$2224,Pedidos!$AJ$2:$AJ$2224,"SIM") -> 0.2665947 | N24: =COUNTIFS(Pedidos!$AJ$2:$AJ$2224,"SIM",Pedidos!$AG$2:$AG$2224,"SIM")/D24 -> 0.0073221757 | O24: =SUMIFS(Pedidos!$U$2:$U$2224,Pedidos!$AJ$2:$AJ$2224,"SIM")/SUMIFS(Pedidos!$M$2:$M$2224,Pedidos!$AJ$2:$AJ$2224,"SIM")-1 -> 0.39376569 | P24: =AVERAGEIFS(Pedidos!$AH$2:$AH$2224,Pedidos!$AJ$2:$AJ$2224,"SIM") -> 9.5047071 | Q24: =AVERAGEIFS(Pedidos!$AI$2:$AI$2224,Pedidos!$AJ$2:$AJ$2224,"SIM") -> 6.0690377 | R24: =MAX(0,1-H24/I24) -> 0.3014687
A26: Avaliação: "Muito bem" = PROLOG mais barata; "Melhor posição" = até +32%; "Intermediária" = +32% a +45%; "Precisa melhorar" = acima de +45%.

Sheet Faixa x Região
A1: Por faixa de peso e região TSL — preço final PROLOG x TSL (mesmos pedidos, top 20 cidades)
A3: Região: TODAS
A4: Faixa (kg) | B4: Pedidos | C4: TSL médio | D4: PROLOG médio | E4: PROLOG vs TSL | F4: PROLOG s/ taxa interna vs TSL | G4: TSL frete peso | H4: PROLOG frete peso | I4: Frete peso PROLOG vs TSL | J4: % pedidos PROLOG ganharia | K4: Redução necessária
A5: 0-20 | B5: =COUNTIFS(Pedidos!$AJ$2:$AJ$2224,"SIM",Pedidos!$H$2:$H$2224,$A5) -> 96 | C5: =IFERROR(AVERAGEIFS(Pedidos!$T$2:$T$2224,Pedidos!$AJ$2:$AJ$2224,"SIM",Pedidos!$H$2:$H$2224,$A5),"") -> 68.642848 | D5: =IFERROR(AVERAGEIFS(Pedidos!$AC$2:$AC$2224,Pedidos!$AJ$2:$AJ$2224,"SIM",Pedidos!$H$2:$H$2224,$A5),"") -> 76.075222 | E5: =IFERROR(D5/C5-1,"") -> 0.10827601 | F5: =IFERROR(AVERAGEIFS(Pedidos!$AD$2:$AD$2224,Pedidos!$AJ$2:$AJ$2224,"SIM",Pedidos!$H$2:$H$2224,$A5)/C5-1,"") -> -0.025351679 | G5: =IFERROR(AVERAGEIFS(Pedidos!$M$2:$M$2224,Pedidos!$AJ$2:$AJ$2224,"SIM",Pedidos!$H$2:$H$2224,$A5),"") -> 43.118333 | H5: =IFERROR(AVERAGEIFS(Pedidos!$U$2:$U$2224,Pedidos!$AJ$2:$AJ$2224,"SIM",Pedidos!$H$2:$H$2224,$A5),"") -> 51.369375 | I5: =IFERROR(H5/G5-1,"") -> 0.19135808 | J5: =IFERROR(COUNTIFS(Pedidos!$AJ$2:$AJ$2224,"SIM",Pedidos!$H$2:$H$2224,$A5,Pedidos!$AG$2:$AG$2224,"SIM")/B5,"") -> 0.14583333 | K5: =IFERROR(MAX(0,1-C5/D5),"") -> 0.097697694
A6: 20-35 | B6: =COUNTIFS(Pedidos!$AJ$2:$AJ$2224,"SIM",Pedidos!$H$2:$H$2224,$A6) -> 431 | C6: =IFERROR(AVERAGEIFS(Pedidos!$T$2:$T$2224,Pedidos!$AJ$2:$AJ$2224,"SIM",Pedidos!$H$2:$H$2224,$A6),"") -> 91.344054 | D6: =IFERROR(AVERAGEIFS(Pedidos!$AC$2:$AC$2224,Pedidos!$AJ$2:$AJ$2224,"SIM",Pedidos!$H$2:$H$2224,$A6),"") -> 127.44455 | E6: =IFERROR(D6/C6-1,"") -> 0.39521448 | F6: =IFERROR(AVERAGEIFS(Pedidos!$AD$2:$AD$2224,Pedidos!$AJ$2:$AJ$2224,"SIM",Pedidos!$H$2:$H$2224,$A6)/C6-1,"") -> 0.23503539 | G6: =IFERROR(AVERAGEIFS(Pedidos!$M$2:$M$2224,Pedidos!$AJ$2:$AJ$2224,"SIM",Pedidos!$H$2:$H$2224,$A6),"") -> 61.564501 | H6: =IFERROR(AVERAGEIFS(Pedidos!$U$2:$U$2224,Pedidos!$AJ$2:$AJ$2224,"SIM",Pedidos!$H$2:$H$2224,$A6),"") -> 90.763039 | I6: =IFERROR(H6/G6-1,"") -> 0.47427556 | J6: =IFERROR(COUNTIFS(Pedidos!$AJ$2:$AJ$2224,"SIM",Pedidos!$H$2:$H$2224,$A6,Pedidos!$AG$2:$AG$2224,"SIM")/B6,"") -> 0 | K6: =IFERROR(MAX(0,1-C6/D6),"") -> 0.28326432
A7: 35-40 | B7: =COUNTIFS(Pedidos!$AJ$2:$AJ$2224,"SIM",Pedidos!$H$2:$H$2224,$A7) -> 299 | C7: =IFERROR(AVERAGEIFS(Pedidos!$T$2:$T$2224,Pedidos!$AJ$2:$AJ$2224,"SIM",Pedidos!$H$2:$H$2224,$A7),"") -> 103.67513 | D7: =IFERROR(AVERAGEIFS(Pedidos!$AC$2:$AC$2224,Pedidos!$AJ$2:$AJ$2224,"SIM",Pedidos!$H$2:$H$2224,$A7),"") -> 146.77366 | E7: =IFERROR(D7/C7-1,"") -> 0.41570759 | F7: =IFERROR(AVERAGEIFS(Pedidos!$AD$2:$AD$2224,Pedidos!$AJ$2:$AJ$2224,"SIM",Pedidos!$H$2:$H$2224,$A7)/C7-1,"") -> 0.22796426 | G7: =IFERROR(AVERAGEIFS(Pedidos!$M$2:$M$2224,Pedidos!$AJ$2:$AJ$2224,"SIM",Pedidos!$H$2:$H$2224,$A7),"") -> 71.714214 | H7: =IFERROR(AVERAGEIFS(Pedidos!$U$2:$U$2224,Pedidos!$AJ$2:$AJ$2224,"SIM",Pedidos!$H$2:$H$2224,$A7),"") -> 102.8507 | I7: =IFERROR(H7/G7-1,"") -> 0.43417457 | J7: =IFERROR(COUNTIFS(Pedidos!$AJ$2:$AJ$2224,"SIM",Pedidos!$H$2:$H$2224,$A7,Pedidos!$AG$2:$AG$2224,"SIM")/B7,"") -> 0 | K7: =IFERROR(MAX(0,1-C7/D7),"") -> 0.29363944
A8: 40-50 | B8: =COUNTIFS(Pedidos!$AJ$2:$AJ$2224,"SIM",Pedidos!$H$2:$H$2224,$A8) -> 305 | C8: =IFERROR(AVERAGEIFS(Pedidos!$T$2:$T$2224,Pedidos!$AJ$2:$AJ$2224,"SIM",Pedidos!$H$2:$H$2224,$A8),"") -> 113.02112 | D8: =IFERROR(AVERAGEIFS(Pedidos!$AC$2:$AC$2224,Pedidos!$AJ$2:$AJ$2224,"SIM",Pedidos!$H$2:$H$2224,$A8),"") -> 153.47146 | E8: =IFERROR(D8/C8-1,"") -> 0.35790074 | F8: =IFERROR(AVERAGEIFS(Pedidos!$AD$2:$AD$2224,Pedidos!$AJ$2:$AJ$2224,"SIM",Pedidos!$H$2:$H$2224,$A8)/C8-1,"") -> 0.14888384 | G8: =IFERROR(AVERAGEIFS(Pedidos!$M$2:$M$2224,Pedidos!$AJ$2:$AJ$2224,"SIM",Pedidos!$H$2:$H$2224,$A8),"") -> 78.958197 | H8: =IFERROR(AVERAGEIFS(Pedidos!$U$2:$U$2224,Pedidos!$AJ$2:$AJ$2224,"SIM",Pedidos!$H$2:$H$2224,$A8),"") -> 104.18305 | I8: =IFERROR(H8/G8-1,"") -> 0.31947098 | J8: =IFERROR(COUNTIFS(Pedidos!$AJ$2:$AJ$2224,"SIM",Pedidos!$H$2:$H$2224,$A8,Pedidos!$AG$2:$AG$2224,"SIM")/B8,"") -> 0 | K8: =IFERROR(MAX(0,1-C8/D8),"") -> 0.26356915
A9: 50-60 | B9: =COUNTIFS(Pedidos!$AJ$2:$AJ$2224,"SIM",Pedidos!$H$2:$H$2224,$A9) -> 361 | C9: =IFERROR(AVERAGEIFS(Pedidos!$T$2:$T$2224,Pedidos!$AJ$2:$AJ$2224,"SIM",Pedidos!$H$2:$H$2224,$A9),"") -> 124.08632 | D9: =IFERROR(AVERAGEIFS(Pedidos!$AC$2:$AC$2224,Pedidos!$AJ$2:$AJ$2224,"SIM",Pedidos!$H$2:$H$2224,$A9),"") -> 176.4498 | E9: =IFERROR(D9/C9-1,"") -> 0.4219923 | F9: =IFERROR(AVERAGEIFS(Pedidos!$AD$2:$AD$2224,Pedidos!$AJ$2:$AJ$2224,"SIM",Pedidos!$H$2:$H$2224,$A9)/C9-1,"") -> 0.19814381 | G9: =IFERROR(AVERAGEIFS(Pedidos!$M$2:$M$2224,Pedidos!$AJ$2:$AJ$2224,"SIM",Pedidos!$H$2:$H$2224,$A9),"") -> 87.816094 | H9: =IFERROR(AVERAGEIFS(Pedidos!$U$2:$U$2224,Pedidos!$AJ$2:$AJ$2224,"SIM",Pedidos!$H$2:$H$2224,$A9),"") -> 119.98296 | I9: =IFERROR(H9/G9-1,"") -> 0.36629812 | J9: =IFERROR(COUNTIFS(Pedidos!$AJ$2:$AJ$2224,"SIM",Pedidos!$H$2:$H$2224,$A9,Pedidos!$AG$2:$AG$2224,"SIM")/B9,"") -> 0 | K9: =IFERROR(MAX(0,1-C9/D9),"") -> 0.29676131
A10: 60-70 | B10: =COUNTIFS(Pedidos!$AJ$2:$AJ$2224,"SIM",Pedidos!$H$2:$H$2224,$A10) -> 228 | C10: =IFERROR(AVERAGEIFS(Pedidos!$T$2:$T$2224,Pedidos!$AJ$2:$AJ$2224,"SIM",Pedidos!$H$2:$H$2224,$A10),"") -> 135.81146 | D10: =IFERROR(AVERAGEIFS(Pedidos!$AC$2:$AC$2224,Pedidos!$AJ$2:$AJ$2224,"SIM",Pedidos!$H$2:$H$2224,$A10),"") -> 206.19741 | E10: =IFERROR(D10/C10-1,"") -> 0.51826217 | F10: =IFERROR(AVERAGEIFS(Pedidos!$AD$2:$AD$2224,Pedidos!$AJ$2:$AJ$2224,"SIM",Pedidos!$H$2:$H$2224,$A10)/C10-1,"") -> 0.26846779 | G10: =IFERROR(AVERAGEIFS(Pedidos!$M$2:$M$2224,Pedidos!$AJ$2:$AJ$2224,"SIM",Pedidos!$H$2:$H$2224,$A10),"") -> 97.341228 | H10: =IFERROR(AVERAGEIFS(Pedidos!$U$2:$U$2224,Pedidos!$AJ$2:$AJ$2224,"SIM",Pedidos!$H$2:$H$2224,$A10),"") -> 139.83754 | I10: =IFERROR(H10/G10-1,"") -> 0.43657057 | J10: =IFERROR(COUNTIFS(Pedidos!$AJ$2:$AJ$2224,"SIM",Pedidos!$H$2:$H$2224,$A10,Pedidos!$AG$2:$AG$2224,"SIM")/B10,"") -> 0 | K10: =IFERROR(MAX(0,1-C10/D10),"") -> 0.34135223
A11: 70-80 | B11: =COUNTIFS(Pedidos!$AJ$2:$AJ$2224,"SIM",Pedidos!$H$2:$H$2224,$A11) -> 24 | C11: =IFERROR(AVERAGEIFS(Pedidos!$T$2:$T$2224,Pedidos!$AJ$2:$AJ$2224,"SIM",Pedidos!$H$2:$H$2224,$A11),"") -> 148.21552 | D11: =IFERROR(AVERAGEIFS(Pedidos!$AC$2:$AC$2224,Pedidos!$AJ$2:$AJ$2224,"SIM",Pedidos!$H$2:$H$2224,$A11),"") -> 211.16087 | E11: =IFERROR(D11/C11-1,"") -> 0.42468802 | F11: =IFERROR(AVERAGEIFS(Pedidos!$AD$2:$AD$2224,Pedidos!$AJ$2:$AJ$2224,"SIM",Pedidos!$H$2:$H$2224,$A11)/C11-1,"") -> 0.1673654 | G11: =IFERROR(AVERAGEIFS(Pedidos!$M$2:$M$2224,Pedidos!$AJ$2:$AJ$2224,"SIM",Pedidos!$H$2:$H$2224,$A11),"") -> 106.88292 | H11: =IFERROR(AVERAGEIFS(Pedidos!$U$2:$U$2224,Pedidos!$AJ$2:$AJ$2224,"SIM",Pedidos!$H$2:$H$2224,$A11),"") -> 139.39875 | I11: =IFERROR(H11/G11-1,"") -> 0.30421918 | J11: =IFERROR(COUNTIFS(Pedidos!$AJ$2:$AJ$2224,"SIM",Pedidos!$H$2:$H$2224,$A11,Pedidos!$AG$2:$AG$2224,"SIM")/B11,"") -> 0 | K11: =IFERROR(MAX(0,1-C11/D11),"") -> 0.29809194
A12: 80-100 | B12: =COUNTIFS(Pedidos!$AJ$2:$AJ$2224,"SIM",Pedidos!$H$2:$H$2224,$A12) -> 43 | C12: =IFERROR(AVERAGEIFS(Pedidos!$T$2:$T$2224,Pedidos!$AJ$2:$AJ$2224,"SIM",Pedidos!$H$2:$H$2224,$A12),"") -> 175.11375 | D12: =IFERROR(AVERAGEIFS(Pedidos!$AC$2:$AC$2224,Pedidos!$AJ$2:$AJ$2224,"SIM",Pedidos!$H$2:$H$2224,$A12),"") -> 262.07559 | E12: =IFERROR(D12/C12-1,"") -> 0.49660203 | F12: =IFERROR(AVERAGEIFS(Pedidos!$AD$2:$AD$2224,Pedidos!$AJ$2:$AJ$2224,"SIM",Pedidos!$H$2:$H$2224,$A12)/C12-1,"") -> 0.2402374 | G12: =IFERROR(AVERAGEIFS(Pedidos!$M$2:$M$2224,Pedidos!$AJ$2:$AJ$2224,"SIM",Pedidos!$H$2:$H$2224,$A12),"") -> 129.31744 | H12: =IFERROR(AVERAGEIFS(Pedidos!$U$2:$U$2224,Pedidos!$AJ$2:$AJ$2224,"SIM",Pedidos!$H$2:$H$2224,$A12),"") -> 177.46651 | I12: =IFERROR(H12/G12-1,"") -> 0.37233237 | J12: =IFERROR(COUNTIFS(Pedidos!$AJ$2:$AJ$2224,"SIM",Pedidos!$H$2:$H$2224,$A12,Pedidos!$AG$2:$AG$2224,"SIM")/B12,"") -> 0 | K12: =IFERROR(MAX(0,1-C12/D12),"") -> 0.3318197
A13: 100-120 | B13: =COUNTIFS(Pedidos!$AJ$2:$AJ$2224,"SIM",Pedidos!$H$2:$H$2224,$A13) -> 47 | C13: =IFERROR(AVERAGEIFS(Pedidos!$T$2:$T$2224,Pedidos!$AJ$2:$AJ$2224,"SIM",Pedidos!$H$2:$H$2224,$A13),"") -> 194.6799 | D13: =IFERROR(AVERAGEIFS(Pedidos!$AC$2:$AC$2224,Pedidos!$AJ$2:$AJ$2224,"SIM",Pedidos!$H$2:$H$2224,$A13),"") -> 316.24233 | E13: =IFERROR(D13/C13-1,"") -> 0.62442207 | F13: =IFERROR(AVERAGEIFS(Pedidos!$AD$2:$AD$2224,Pedidos!$AJ$2:$AJ$2224,"SIM",Pedidos!$H$2:$H$2224,$A13)/C13-1,"") -> 0.33364196 | G13: =IFERROR(AVERAGEIFS(Pedidos!$M$2:$M$2224,Pedidos!$AJ$2:$AJ$2224,"SIM",Pedidos!$H$2:$H$2224,$A13),"") -> 143.59872 | H13: =IFERROR(AVERAGEIFS(Pedidos!$U$2:$U$2224,Pedidos!$AJ$2:$AJ$2224,"SIM",Pedidos!$H$2:$H$2224,$A13),"") -> 208.16894 | I13: =IFERROR(H13/G13-1,"") -> 0.44965729 | J13: =IFERROR(COUNTIFS(Pedidos!$AJ$2:$AJ$2224,"SIM",Pedidos!$H$2:$H$2224,$A13,Pedidos!$AG$2:$AG$2224,"SIM")/B13,"") -> 0 | K13: =IFERROR(MAX(0,1-C13/D13),"") -> 0.38439644
A14: 120-150 | B14: =COUNTIFS(Pedidos!$AJ$2:$AJ$2224,"SIM",Pedidos!$H$2:$H$2224,$A14) -> 73 | C14: =IFERROR(AVERAGEIFS(Pedidos!$T$2:$T$2224,Pedidos!$AJ$2:$AJ$2224,"SIM",Pedidos!$H$2:$H$2224,$A14),"") -> 242.63268 | D14: =IFERROR(AVERAGEIFS(Pedidos!$AC$2:$AC$2224,Pedidos!$AJ$2:$AJ$2224,"SIM",Pedidos!$H$2:$H$2224,$A14),"") -> 369.59085 | E14: =IFERROR(D14/C14-1,"") -> 0.52325259 | F14: =IFERROR(AVERAGEIFS(Pedidos!$AD$2:$AD$2224,Pedidos!$AJ$2:$AJ$2224,"SIM",Pedidos!$H$2:$H$2224,$A14)/C14-1,"") -> 0.25108826 | G14: =IFERROR(AVERAGEIFS(Pedidos!$M$2:$M$2224,Pedidos!$AJ$2:$AJ$2224,"SIM",Pedidos!$H$2:$H$2224,$A14),"") -> 181.90644 | H14: =IFERROR(AVERAGEIFS(Pedidos!$U$2:$U$2224,Pedidos!$AJ$2:$AJ$2224,"SIM",Pedidos!$H$2:$H$2224,$A14),"") -> 244.44575 | I14: =IFERROR(H14/G14-1,"") -> 0.34379935 | J14: =IFERROR(COUNTIFS(Pedidos!$AJ$2:$AJ$2224,"SIM",Pedidos!$H$2:$H$2224,$A14,Pedidos!$AG$2:$AG$2224,"SIM")/B14,"") -> 0 | K14: =IFERROR(MAX(0,1-C14/D14),"") -> 0.34351006
A15: 150-170 | B15: =COUNTIFS(Pedidos!$AJ$2:$AJ$2224,"SIM",Pedidos!$H$2:$H$2224,$A15) -> 3 | C15: =IFERROR(AVERAGEIFS(Pedidos!$T$2:$T$2224,Pedidos!$AJ$2:$AJ$2224,"SIM",Pedidos!$H$2:$H$2224,$A15),"") -> 259.73784 | D15: =IFERROR(AVERAGEIFS(Pedidos!$AC$2:$AC$2224,Pedidos!$AJ$2:$AJ$2224,"SIM",Pedidos!$H$2:$H$2224,$A15),"") -> 423.50097 | E15: =IFERROR(D15/C15-1,"") -> 0.63049395 | F15: =IFERROR(AVERAGEIFS(Pedidos!$AD$2:$AD$2224,Pedidos!$AJ$2:$AJ$2224,"SIM",Pedidos!$H$2:$H$2224,$A15)/C15-1,"") -> 0.31352225 | G15: =IFERROR(AVERAGEIFS(Pedidos!$M$2:$M$2224,Pedidos!$AJ$2:$AJ$2224,"SIM",Pedidos!$H$2:$H$2224,$A15),"") -> 195.11667 | H15: =IFERROR(AVERAGEIFS(Pedidos!$U$2:$U$2224,Pedidos!$AJ$2:$AJ$2224,"SIM",Pedidos!$H$2:$H$2224,$A15),"") -> 274.84333 | I15: =IFERROR(H15/G15-1,"") -> 0.40861023 | J15: =IFERROR(COUNTIFS(Pedidos!$AJ$2:$AJ$2224,"SIM",Pedidos!$H$2:$H$2224,$A15,Pedidos!$AG$2:$AG$2224,"SIM")/B15,"") -> 0 | K15: =IFERROR(MAX(0,1-C15/D15),"") -> 0.38668892
A16: 170-200 | B16: =COUNTIFS(Pedidos!$AJ$2:$AJ$2224,"SIM",Pedidos!$H$2:$H$2224,$A16) -> 1 | C16: =IFERROR(AVERAGEIFS(Pedidos!$T$2:$T$2224,Pedidos!$AJ$2:$AJ$2224,"SIM",Pedidos!$H$2:$H$2224,$A16),"") -> 198.27526 | D16: =IFERROR(AVERAGEIFS(Pedidos!$AC$2:$AC$2224,Pedidos!$AJ$2:$AJ$2224,"SIM",Pedidos!$H$2:$H$2224,$A16),"") -> 529.025 | E16: =IFERROR(D16/C16-1,"") -> 1.6681342 | F16: =IFERROR(AVERAGEIFS(Pedidos!$AD$2:$AD$2224,Pedidos!$AJ$2:$AJ$2224,"SIM",Pedidos!$H$2:$H$2224,$A16)/C16-1,"") -> 1.180692 | G16: =IFERROR(AVERAGEIFS(Pedidos!$M$2:$M$2224,Pedidos!$AJ$2:$AJ$2224,"SIM",Pedidos!$H$2:$H$2224,$A16),"") -> 143.51 | H16: =IFERROR(AVERAGEIFS(Pedidos!$U$2:$U$2224,Pedidos!$AJ$2:$AJ$2224,"SIM",Pedidos!$H$2:$H$2224,$A16),"") -> 353.17 | I16: =IFERROR(H16/G16-1,"") -> 1.4609435 | J16: =IFERROR(COUNTIFS(Pedidos!$AJ$2:$AJ$2224,"SIM",Pedidos!$H$2:$H$2224,$A16,Pedidos!$AG$2:$AG$2224,"SIM")/B16,"") -> 0 | K16: =IFERROR(MAX(0,1-C16/D16),"") -> 0.62520625
A17: 200-250 | B17: =COUNTIFS(Pedidos!$AJ$2:$AJ$2224,"SIM",Pedidos!$H$2:$H$2224,$A17) -> 1 | C17: =IFERROR(AVERAGEIFS(Pedidos!$T$2:$T$2224,Pedidos!$AJ$2:$AJ$2224,"SIM",Pedidos!$H$2:$H$2224,$A17),"") -> 355.2278 | D17: =IFERROR(AVERAGEIFS(Pedidos!$AC$2:$AC$2224,Pedidos!$AJ$2:$AJ$2224,"SIM",Pedidos!$H$2:$H$2224,$A17),"") -> 593.32707 | E17: =IFERROR(D17/C17-1,"") -> 0.67027204 | F17: =IFERROR(AVERAGEIFS(Pedidos!$AD$2:$AD$2224,Pedidos!$AJ$2:$AJ$2224,"SIM",Pedidos!$H$2:$H$2224,$A17)/C17-1,"") -> 0.38092507 | G17: =IFERROR(AVERAGEIFS(Pedidos!$M$2:$M$2224,Pedidos!$AJ$2:$AJ$2224,"SIM",Pedidos!$H$2:$H$2224,$A17),"") -> 272.9 | H17: =IFERROR(AVERAGEIFS(Pedidos!$U$2:$U$2224,Pedidos!$AJ$2:$AJ$2224,"SIM",Pedidos!$H$2:$H$2224,$A17),"") -> 398.74 | I17: =IFERROR(H17/G17-1,"") -> 0.46112129 | J17: =IFERROR(COUNTIFS(Pedidos!$AJ$2:$AJ$2224,"SIM",Pedidos!$H$2:$H$2224,$A17,Pedidos!$AG$2:$AG$2224,"SIM")/B17,"") -> 0 | K17: =IFERROR(MAX(0,1-C17/D17),"") -> 0.40129513
A18: TOTAL | B18: =COUNTIFS(Pedidos!$AJ$2:$AJ$2224,"SIM") -> 1912 | C18: =IFERROR(AVERAGEIFS(Pedidos!$T$2:$T$2224,Pedidos!$AJ$2:$AJ$2224,"SIM"),"") -> 118.44739 | D18: =IFERROR(AVERAGEIFS(Pedidos!$AC$2:$AC$2224,Pedidos!$AJ$2:$AJ$2224,"SIM"),"") -> 169.56633 | E18: =IFERROR(D18/C18-1,"") -> 0.43157508 | F18: =IFERROR(AVERAGEIFS(Pedidos!$AD$2:$AD$2224,Pedidos!$AJ$2:$AJ$2224,"SIM")/C18-1,"") -> 0.21632815 | G18: =IFERROR(AVERAGEIFS(Pedidos!$M$2:$M$2224,Pedidos!$AJ$2:$AJ$2224,"SIM"),"") -> 83.289634 | H18: =IFERROR(AVERAGEIFS(Pedidos!$U$2:$U$2224,Pedidos!$AJ$2:$AJ$2224,"SIM"),"") -> 116.08623 | I18: =IFERROR(H18/G18-1,"") -> 0.39376569 | J18: =IFERROR(COUNTIFS(Pedidos!$AJ$2:$AJ$2224,"SIM",Pedidos!$AG$2:$AG$2224,"SIM")/B18,"") -> 0.0073221757 | K18: =IFERROR(MAX(0,1-C18/D18),"") -> 0.3014687
A20: Região: Capital
A21: Faixa (kg) | B21: Pedidos | C21: TSL médio | D21: PROLOG médio | E21: PROLOG vs TSL | F21: PROLOG s/ taxa interna vs TSL | G21: TSL frete peso | H21: PROLOG frete peso | I21: Frete peso PROLOG vs TSL | J21: % pedidos PROLOG ganharia | K21: Redução necessária
A22: 0-20 | B22: =COUNTIFS(Pedidos!$AJ$2:$AJ$2224,"SIM",Pedidos!$G$2:$G$2224,"Capital",Pedidos!$H$2:$H$2224,$A22) -> 64 | C22: =IFERROR(AVERAGEIFS(Pedidos!$T$2:$T$2224,Pedidos!$AJ$2:$AJ$2224,"SIM",Pedidos!$G$2:$G$2224,"Capital",Pedidos!$H$2:$H$2224,$A22),"") -> 64.649099 | D22: =IFERROR(AVERAGEIFS(Pedidos!$AC$2:$AC$2224,Pedidos!$AJ$2:$AJ$2224,"SIM",Pedidos!$G$2:$G$2224,"Capital",Pedidos!$H$2:$H$2224,$A22),"") -> 70.923919 | E22: =IFERROR(D22/C22-1,"") -> 0.097059663 | F22: =IFERROR(AVERAGEIFS(Pedidos!$AD$2:$AD$2224,Pedidos!$AJ$2:$AJ$2224,"SIM",Pedidos!$G$2:$G$2224,"Capital",Pedidos!$H$2:$H$2224,$A22)/C22-1,"") -> -0.043092706 | G22: =IFERROR(AVERAGEIFS(Pedidos!$M$2:$M$2224,Pedidos!$AJ$2:$AJ$2224,"SIM",Pedidos!$G$2:$G$2224,"Capital",Pedidos!$H$2:$H$2224,$A22),"") -> 39.83 | H22: =IFERROR(AVERAGEIFS(Pedidos!$U$2:$U$2224,Pedidos!$AJ$2:$AJ$2224,"SIM",Pedidos!$G$2:$G$2224,"Capital",Pedidos!$H$2:$H$2224,$A22),"") -> 46.98 | I22: =IFERROR(H22/G22-1,"") -> 0.17951293 | J22: =IFERROR(COUNTIFS(Pedidos!$AJ$2:$AJ$2224,"SIM",Pedidos!$G$2:$G$2224,"Capital",Pedidos!$H$2:$H$2224,$A22,Pedidos!$AG$2:$AG$2224,"SIM")/B22,"") -> 0 | K22: =IFERROR(MAX(0,1-C22/D22),"") -> 0.088472548
A23: 20-35 | B23: =COUNTIFS(Pedidos!$AJ$2:$AJ$2224,"SIM",Pedidos!$G$2:$G$2224,"Capital",Pedidos!$H$2:$H$2224,$A23) -> 263 | C23: =IFERROR(AVERAGEIFS(Pedidos!$T$2:$T$2224,Pedidos!$AJ$2:$AJ$2224,"SIM",Pedidos!$G$2:$G$2224,"Capital",Pedidos!$H$2:$H$2224,$A23),"") -> 82.379886 | D23: =IFERROR(AVERAGEIFS(Pedidos!$AC$2:$AC$2224,Pedidos!$AJ$2:$AJ$2224,"SIM",Pedidos!$G$2:$G$2224,"Capital",Pedidos!$H$2:$H$2224,$A23),"") -> 117.40343 | E23: =IFERROR(D23/C23-1,"") -> 0.42514675 | F23: =IFERROR(AVERAGEIFS(Pedidos!$AD$2:$AD$2224,Pedidos!$AJ$2:$AJ$2224,"SIM",Pedidos!$G$2:$G$2224,"Capital",Pedidos!$H$2:$H$2224,$A23)/C23-1,"") -> 0.25086793 | G23: =IFERROR(AVERAGEIFS(Pedidos!$M$2:$M$2224,Pedidos!$AJ$2:$AJ$2224,"SIM",Pedidos!$G$2:$G$2224,"Capital",Pedidos!$H$2:$H$2224,$A23),"") -> 54.1 | H23: =IFERROR(AVERAGEIFS(Pedidos!$U$2:$U$2224,Pedidos!$AJ$2:$AJ$2224,"SIM",Pedidos!$G$2:$G$2224,"Capital",Pedidos!$H$2:$H$2224,$A23),"") -> 82.21 | I23: =IFERROR(H23/G23-1,"") -> 0.51959335 | J23: =IFERROR(COUNTIFS(Pedidos!$AJ$2:$AJ$2224,"SIM",Pedidos!$G$2:$G$2224,"Capital",Pedidos!$H$2:$H$2224,$A23,Pedidos!$AG$2:$AG$2224,"SIM")/B23,"") -> 0 | K23: =IFERROR(MAX(0,1-C23/D23),"") -> 0.29831787
A24: 35-40 | B24: =COUNTIFS(Pedidos!$AJ$2:$AJ$2224,"SIM",Pedidos!$G$2:$G$2224,"Capital",Pedidos!$H$2:$H$2224,$A24) -> 163 | C24: =IFERROR(AVERAGEIFS(Pedidos!$T$2:$T$2224,Pedidos!$AJ$2:$AJ$2224,"SIM",Pedidos!$G$2:$G$2224,"Capital",Pedidos!$H$2:$H$2224,$A24),"") -> 92.068014 | D24: =IFERROR(AVERAGEIFS(Pedidos!$AC$2:$AC$2224,Pedidos!$AJ$2:$AJ$2224,"SIM",Pedidos!$G$2:$G$2224,"Capital",Pedidos!$H$2:$H$2224,$A24),"") -> 136.60884 | E24: =IFERROR(D24/C24-1,"") -> 0.48378175 | F24: =IFERROR(AVERAGEIFS(Pedidos!$AD$2:$AD$2224,Pedidos!$AJ$2:$AJ$2224,"SIM",Pedidos!$G$2:$G$2224,"Capital",Pedidos!$H$2:$H$2224,$A24)/C24-1,"") -> 0.27292682 | G24: =IFERROR(AVERAGEIFS(Pedidos!$M$2:$M$2224,Pedidos!$AJ$2:$AJ$2224,"SIM",Pedidos!$G$2:$G$2224,"Capital",Pedidos!$H$2:$H$2224,$A24),"") -> 62.05 | H24: =IFERROR(AVERAGEIFS(Pedidos!$U$2:$U$2224,Pedidos!$AJ$2:$AJ$2224,"SIM",Pedidos!$G$2:$G$2224,"Capital",Pedidos!$H$2:$H$2224,$A24),"") -> 93.97 | I24: =IFERROR(H24/G24-1,"") -> 0.51442385 | J24: =IFERROR(COUNTIFS(Pedidos!$AJ$2:$AJ$2224,"SIM",Pedidos!$G$2:$G$2224,"Capital",Pedidos!$H$2:$H$2224,$A24,Pedidos!$AG$2:$AG$2224,"SIM")/B24,"") -> 0 | K24: =IFERROR(MAX(0,1-C24/D24),"") -> 0.32604644
A25: 40-50 | B25: =COUNTIFS(Pedidos!$AJ$2:$AJ$2224,"SIM",Pedidos!$G$2:$G$2224,"Capital",Pedidos!$H$2:$H$2224,$A25) -> 154 | C25: =IFERROR(AVERAGEIFS(Pedidos!$T$2:$T$2224,Pedidos!$AJ$2:$AJ$2224,"SIM",Pedidos!$G$2:$G$2224,"Capital",Pedidos!$H$2:$H$2224,$A25),"") -> 103.46131 | D25: =IFERROR(AVERAGEIFS(Pedidos!$AC$2:$AC$2224,Pedidos!$AJ$2:$AJ$2224,"SIM",Pedidos!$G$2:$G$2224,"Capital",Pedidos!$H$2:$H$2224,$A25),"") -> 141.78335 | E25: =IFERROR(D25/C25-1,"") -> 0.37039977 | F25: =IFERROR(AVERAGEIFS(Pedidos!$AD$2:$AD$2224,Pedidos!$AJ$2:$AJ$2224,"SIM",Pedidos!$G$2:$G$2224,"Capital",Pedidos!$H$2:$H$2224,$A25)/C25-1,"") -> 0.14265691 | G25: =IFERROR(AVERAGEIFS(Pedidos!$M$2:$M$2224,Pedidos!$AJ$2:$AJ$2224,"SIM",Pedidos!$G$2:$G$2224,"Capital",Pedidos!$H$2:$H$2224,$A25),"") -> 71 | H25: =IFERROR(AVERAGEIFS(Pedidos!$U$2:$U$2224,Pedidos!$AJ$2:$AJ$2224,"SIM",Pedidos!$G$2:$G$2224,"Capital",Pedidos!$H$2:$H$2224,$A25),"") -> 93.97 | I25: =IFERROR(H25/G25-1,"") -> 0.32352113 | J25: =IFERROR(COUNTIFS(Pedidos!$AJ$2:$AJ$2224,"SIM",Pedidos!$G$2:$G$2224,"Capital",Pedidos!$H$2:$H$2224,$A25,Pedidos!$AG$2:$AG$2224,"SIM")/B25,"") -> 0 | K25: =IFERROR(MAX(0,1-C25/D25),"") -> 0.27028593
A26: 50-60 | B26: =COUNTIFS(Pedidos!$AJ$2:$AJ$2224,"SIM",Pedidos!$G$2:$G$2224,"Capital",Pedidos!$H$2:$H$2224,$A26) -> 181 | C26: =IFERROR(AVERAGEIFS(Pedidos!$T$2:$T$2224,Pedidos!$AJ$2:$AJ$2224,"SIM",Pedidos!$G$2:$G$2224,"Capital",Pedidos!$H$2:$H$2224,$A26),"") -> 114.45303 | D26: =IFERROR(AVERAGEIFS(Pedidos!$AC$2:$AC$2224,Pedidos!$AJ$2:$AJ$2224,"SIM",Pedidos!$G$2:$G$2224,"Capital",Pedidos!$H$2:$H$2224,$A26),"") -> 167.53521 | E26: =IFERROR(D26/C26-1,"") -> 0.46379014 | F26: =IFERROR(AVERAGEIFS(Pedidos!$AD$2:$AD$2224,Pedidos!$AJ$2:$AJ$2224,"SIM",Pedidos!$G$2:$G$2224,"Capital",Pedidos!$H$2:$H$2224,$A26)/C26-1,"") -> 0.22232656 | G26: =IFERROR(AVERAGEIFS(Pedidos!$M$2:$M$2224,Pedidos!$AJ$2:$AJ$2224,"SIM",Pedidos!$G$2:$G$2224,"Capital",Pedidos!$H$2:$H$2224,$A26),"") -> 79.81 | H26: =IFERROR(AVERAGEIFS(Pedidos!$U$2:$U$2224,Pedidos!$AJ$2:$AJ$2224,"SIM",Pedidos!$G$2:$G$2224,"Capital",Pedidos!$H$2:$H$2224,$A26),"") -> 112.3 | I26: =IFERROR(H26/G26-1,"") -> 0.40709184 | J26: =IFERROR(COUNTIFS(Pedidos!$AJ$2:$AJ$2224,"SIM",Pedidos!$G$2:$G$2224,"Capital",Pedidos!$H$2:$H$2224,$A26,Pedidos!$AG$2:$AG$2224,"SIM")/B26,"") -> 0 | K26: =IFERROR(MAX(0,1-C26/D26),"") -> 0.31684196
A27: 60-70 | B27: =COUNTIFS(Pedidos!$AJ$2:$AJ$2224,"SIM",Pedidos!$G$2:$G$2224,"Capital",Pedidos!$H$2:$H$2224,$A27) -> 112 | C27: =IFERROR(AVERAGEIFS(Pedidos!$T$2:$T$2224,Pedidos!$AJ$2:$AJ$2224,"SIM",Pedidos!$G$2:$G$2224,"Capital",Pedidos!$H$2:$H$2224,$A27),"") -> 124.87712 | D27: =IFERROR(AVERAGEIFS(Pedidos!$AC$2:$AC$2224,Pedidos!$AJ$2:$AJ$2224,"SIM",Pedidos!$G$2:$G$2224,"Capital",Pedidos!$H$2:$H$2224,$A27),"") -> 196.26069 | E27: =IFERROR(D27/C27-1,"") -> 0.57163054 | F27: =IFERROR(AVERAGEIFS(Pedidos!$AD$2:$AD$2224,Pedidos!$AJ$2:$AJ$2224,"SIM",Pedidos!$G$2:$G$2224,"Capital",Pedidos!$H$2:$H$2224,$A27)/C27-1,"") -> 0.2995002 | G27: =IFERROR(AVERAGEIFS(Pedidos!$M$2:$M$2224,Pedidos!$AJ$2:$AJ$2224,"SIM",Pedidos!$G$2:$G$2224,"Capital",Pedidos!$H$2:$H$2224,$A27),"") -> 88.2 | H27: =IFERROR(AVERAGEIFS(Pedidos!$U$2:$U$2224,Pedidos!$AJ$2:$AJ$2224,"SIM",Pedidos!$G$2:$G$2224,"Capital",Pedidos!$H$2:$H$2224,$A27),"") -> 131.02 | I27: =IFERROR(H27/G27-1,"") -> 0.48548753 | J27: =IFERROR(COUNTIFS(Pedidos!$AJ$2:$AJ$2224,"SIM",Pedidos!$G$2:$G$2224,"Capital",Pedidos!$H$2:$H$2224,$A27,Pedidos!$AG$2:$AG$2224,"SIM")/B27,"") -> 0 | K27: =IFERROR(MAX(0,1-C27/D27),"") -> 0.36371814
A28: 70-80 | B28: =COUNTIFS(Pedidos!$AJ$2:$AJ$2224,"SIM",Pedidos!$G$2:$G$2224,"Capital",Pedidos!$H$2:$H$2224,$A28) -> 11 | C28: =IFERROR(AVERAGEIFS(Pedidos!$T$2:$T$2224,Pedidos!$AJ$2:$AJ$2224,"SIM",Pedidos!$G$2:$G$2224,"Capital",Pedidos!$H$2:$H$2224,$A28),"") -> 137.68127 | D28: =IFERROR(AVERAGEIFS(Pedidos!$AC$2:$AC$2224,Pedidos!$AJ$2:$AJ$2224,"SIM",Pedidos!$G$2:$G$2224,"Capital",Pedidos!$H$2:$H$2224,$A28),"") -> 207.02902 | E28: =IFERROR(D28/C28-1,"") -> 0.50368327 | F28: =IFERROR(AVERAGEIFS(Pedidos!$AD$2:$AD$2224,Pedidos!$AJ$2:$AJ$2224,"SIM",Pedidos!$G$2:$G$2224,"Capital",Pedidos!$H$2:$H$2224,$A28)/C28-1,"") -> 0.21938489 | G28: =IFERROR(AVERAGEIFS(Pedidos!$M$2:$M$2224,Pedidos!$AJ$2:$AJ$2224,"SIM",Pedidos!$G$2:$G$2224,"Capital",Pedidos!$H$2:$H$2224,$A28),"") -> 97.6 | H28: =IFERROR(AVERAGEIFS(Pedidos!$U$2:$U$2224,Pedidos!$AJ$2:$AJ$2224,"SIM",Pedidos!$G$2:$G$2224,"Capital",Pedidos!$H$2:$H$2224,$A28),"") -> 134.39 | I28: =IFERROR(H28/G28-1,"") -> 0.37694672 | J28: =IFERROR(COUNTIFS(Pedidos!$AJ$2:$AJ$2224,"SIM",Pedidos!$G$2:$G$2224,"Capital",Pedidos!$H$2:$H$2224,$A28,Pedidos!$AG$2:$AG$2224,"SIM")/B28,"") -> 0 | K28: =IFERROR(MAX(0,1-C28/D28),"") -> 0.33496633
A29: 80-100 | B29: =COUNTIFS(Pedidos!$AJ$2:$AJ$2224,"SIM",Pedidos!$G$2:$G$2224,"Capital",Pedidos!$H$2:$H$2224,$A29) -> 19 | C29: =IFERROR(AVERAGEIFS(Pedidos!$T$2:$T$2224,Pedidos!$AJ$2:$AJ$2224,"SIM",Pedidos!$G$2:$G$2224,"Capital",Pedidos!$H$2:$H$2224,$A29),"") -> 163.75881 | D29: =IFERROR(AVERAGEIFS(Pedidos!$AC$2:$AC$2224,Pedidos!$AJ$2:$AJ$2224,"SIM",Pedidos!$G$2:$G$2224,"Capital",Pedidos!$H$2:$H$2224,$A29),"") -> 251.89439 | E29: =IFERROR(D29/C29-1,"") -> 0.53820355 | F29: =IFERROR(AVERAGEIFS(Pedidos!$AD$2:$AD$2224,Pedidos!$AJ$2:$AJ$2224,"SIM",Pedidos!$G$2:$G$2224,"Capital",Pedidos!$H$2:$H$2224,$A29)/C29-1,"") -> 0.26110827 | G29: =IFERROR(AVERAGEIFS(Pedidos!$M$2:$M$2224,Pedidos!$AJ$2:$AJ$2224,"SIM",Pedidos!$G$2:$G$2224,"Capital",Pedidos!$H$2:$H$2224,$A29),"") -> 119.8 | H29: =IFERROR(AVERAGEIFS(Pedidos!$U$2:$U$2224,Pedidos!$AJ$2:$AJ$2224,"SIM",Pedidos!$G$2:$G$2224,"Capital",Pedidos!$H$2:$H$2224,$A29),"") -> 167.99 | I29: =IFERROR(H29/G29-1,"") -> 0.40225376 | J29: =IFERROR(COUNTIFS(Pedidos!$AJ$2:$AJ$2224,"SIM",Pedidos!$G$2:$G$2224,"Capital",Pedidos!$H$2:$H$2224,$A29,Pedidos!$AG$2:$AG$2224,"SIM")/B29,"") -> 0 | K29: =IFERROR(MAX(0,1-C29/D29),"") -> 0.34989098
A30: 100-120 | B30: =COUNTIFS(Pedidos!$AJ$2:$AJ$2224,"SIM",Pedidos!$G$2:$G$2224,"Capital",Pedidos!$H$2:$H$2224,$A30) -> 21 | C30: =IFERROR(AVERAGEIFS(Pedidos!$T$2:$T$2224,Pedidos!$AJ$2:$AJ$2224,"SIM",Pedidos!$G$2:$G$2224,"Capital",Pedidos!$H$2:$H$2224,$A30),"") -> 185.62398 | D30: =IFERROR(AVERAGEIFS(Pedidos!$AC$2:$AC$2224,Pedidos!$AJ$2:$AJ$2224,"SIM",Pedidos!$G$2:$G$2224,"Capital",Pedidos!$H$2:$H$2224,$A30),"") -> 309.11115 | E30: =IFERROR(D30/C30-1,"") -> 0.66525442 | F30: =IFERROR(AVERAGEIFS(Pedidos!$AD$2:$AD$2224,Pedidos!$AJ$2:$AJ$2224,"SIM",Pedidos!$G$2:$G$2224,"Capital",Pedidos!$H$2:$H$2224,$A30)/C30-1,"") -> 0.35907406 | G30: =IFERROR(AVERAGEIFS(Pedidos!$M$2:$M$2224,Pedidos!$AJ$2:$AJ$2224,"SIM",Pedidos!$G$2:$G$2224,"Capital",Pedidos!$H$2:$H$2224,$A30),"") -> 135.94 | H30: =IFERROR(AVERAGEIFS(Pedidos!$U$2:$U$2224,Pedidos!$AJ$2:$AJ$2224,"SIM",Pedidos!$G$2:$G$2224,"Capital",Pedidos!$H$2:$H$2224,$A30),"") -> 201.59 | I30: =IFERROR(H30/G30-1,"") -> 0.48293365 | J30: =IFERROR(COUNTIFS(Pedidos!$AJ$2:$AJ$2224,"SIM",Pedidos!$G$2:$G$2224,"Capital",Pedidos!$H$2:$H$2224,$A30,Pedidos!$AG$2:$AG$2224,"SIM")/B30,"") -> 0 | K30: =IFERROR(MAX(0,1-C30/D30),"") -> 0.39949116
A31: 120-150 | B31: =COUNTIFS(Pedidos!$AJ$2:$AJ$2224,"SIM",Pedidos!$G$2:$G$2224,"Capital",Pedidos!$H$2:$H$2224,$A31) -> 39 | C31: =IFERROR(AVERAGEIFS(Pedidos!$T$2:$T$2224,Pedidos!$AJ$2:$AJ$2224,"SIM",Pedidos!$G$2:$G$2224,"Capital",Pedidos!$H$2:$H$2224,$A31),"") -> 234.088 | D31: =IFERROR(AVERAGEIFS(Pedidos!$AC$2:$AC$2224,Pedidos!$AJ$2:$AJ$2224,"SIM",Pedidos!$G$2:$G$2224,"Capital",Pedidos!$H$2:$H$2224,$A31),"") -> 363.47249 | E31: =IFERROR(D31/C31-1,"") -> 0.55271733 | F31: =IFERROR(AVERAGEIFS(Pedidos!$AD$2:$AD$2224,Pedidos!$AJ$2:$AJ$2224,"SIM",Pedidos!$G$2:$G$2224,"Capital",Pedidos!$H$2:$H$2224,$A31)/C31-1,"") -> 0.27119777 | G31: =IFERROR(AVERAGEIFS(Pedidos!$M$2:$M$2224,Pedidos!$AJ$2:$AJ$2224,"SIM",Pedidos!$G$2:$G$2224,"Capital",Pedidos!$H$2:$H$2224,$A31),"") -> 174.85 | H31: =IFERROR(AVERAGEIFS(Pedidos!$U$2:$U$2224,Pedidos!$AJ$2:$AJ$2224,"SIM",Pedidos!$G$2:$G$2224,"Capital",Pedidos!$H$2:$H$2224,$A31),"") -> 239.25 | I31: =IFERROR(H31/G31-1,"") -> 0.3683157 | J31: =IFERROR(COUNTIFS(Pedidos!$AJ$2:$AJ$2224,"SIM",Pedidos!$G$2:$G$2224,"Capital",Pedidos!$H$2:$H$2224,$A31,Pedidos!$AG$2:$AG$2224,"SIM")/B31,"") -> 0 | K31: =IFERROR(MAX(0,1-C31/D31),"") -> 0.35596777
A32: 150-170 | B32: =COUNTIFS(Pedidos!$AJ$2:$AJ$2224,"SIM",Pedidos!$G$2:$G$2224,"Capital",Pedidos!$H$2:$H$2224,$A32) -> 2 | C32: =IFERROR(AVERAGEIFS(Pedidos!$T$2:$T$2224,Pedidos!$AJ$2:$AJ$2224,"SIM",Pedidos!$G$2:$G$2224,"Capital",Pedidos!$H$2:$H$2224,$A32),"") -> 255.75965 | D32: =IFERROR(AVERAGEIFS(Pedidos!$AC$2:$AC$2224,Pedidos!$AJ$2:$AJ$2224,"SIM",Pedidos!$G$2:$G$2224,"Capital",Pedidos!$H$2:$H$2224,$A32),"") -> 417.59806 | E32: =IFERROR(D32/C32-1,"") -> 0.63277542 | F32: =IFERROR(AVERAGEIFS(Pedidos!$AD$2:$AD$2224,Pedidos!$AJ$2:$AJ$2224,"SIM",Pedidos!$G$2:$G$2224,"Capital",Pedidos!$H$2:$H$2224,$A32)/C32-1,"") -> 0.31587188 | G32: =IFERROR(AVERAGEIFS(Pedidos!$M$2:$M$2224,Pedidos!$AJ$2:$AJ$2224,"SIM",Pedidos!$G$2:$G$2224,"Capital",Pedidos!$H$2:$H$2224,$A32),"") -> 192.1 | H32: =IFERROR(AVERAGEIFS(Pedidos!$U$2:$U$2224,Pedidos!$AJ$2:$AJ$2224,"SIM",Pedidos!$G$2:$G$2224,"Capital",Pedidos!$H$2:$H$2224,$A32),"") -> 271.15 | I32: =IFERROR(H32/G32-1,"") -> 0.41150442 | J32: =IFERROR(COUNTIFS(Pedidos!$AJ$2:$AJ$2224,"SIM",Pedidos!$G$2:$G$2224,"Capital",Pedidos!$H$2:$H$2224,$A32,Pedidos!$AG$2:$AG$2224,"SIM")/B32,"") -> 0 | K32: =IFERROR(MAX(0,1-C32/D32),"") -> 0.3875459
A33: 170-200 | B33: =COUNTIFS(Pedidos!$AJ$2:$AJ$2224,"SIM",Pedidos!$G$2:$G$2224,"Capital",Pedidos!$H$2:$H$2224,$A33) -> 0 | C33: =IFERROR(AVERAGEIFS(Pedidos!$T$2:$T$2224,Pedidos!$AJ$2:$AJ$2224,"SIM",Pedidos!$G$2:$G$2224,"Capital",Pedidos!$H$2:$H$2224,$A33),"") | D33: =IFERROR(AVERAGEIFS(Pedidos!$AC$2:$AC$2224,Pedidos!$AJ$2:$AJ$2224,"SIM",Pedidos!$G$2:$G$2224,"Capital",Pedidos!$H$2:$H$2224,$A33),"") | E33: =IFERROR(D33/C33-1,"") | F33: =IFERROR(AVERAGEIFS(Pedidos!$AD$2:$AD$2224,Pedidos!$AJ$2:$AJ$2224,"SIM",Pedidos!$G$2:$G$2224,"Capital",Pedidos!$H$2:$H$2224,$A33)/C33-1,"") | G33: =IFERROR(AVERAGEIFS(Pedidos!$M$2:$M$2224,Pedidos!$AJ$2:$AJ$2224,"SIM",Pedidos!$G$2:$G$2224,"Capital",Pedidos!$H$2:$H$2224,$A33),"") | H33: =IFERROR(AVERAGEIFS(Pedidos!$U$2:$U$2224,Pedidos!$AJ$2:$AJ$2224,"SIM",Pedidos!$G$2:$G$2224,"Capital",Pedidos!$H$2:$H$2224,$A33),"") | I33: =IFERROR(H33/G33-1,"") | J33: =IFERROR(COUNTIFS(Pedidos!$AJ$2:$AJ$2224,"SIM",Pedidos!$G$2:$G$2224,"Capital",Pedidos!$H$2:$H$2224,$A33,Pedidos!$AG$2:$AG$2224,"SIM")/B33,"") | K33: =IFERROR(MAX(0,1-C33/D33),"")
A34: 200-250 | B34: =COUNTIFS(Pedidos!$AJ$2:$AJ$2224,"SIM",Pedidos!$G$2:$G$2224,"Capital",Pedidos!$H$2:$H$2224,$A34) -> 1 | C34: =IFERROR(AVERAGEIFS(Pedidos!$T$2:$T$2224,Pedidos!$AJ$2:$AJ$2224,"SIM",Pedidos!$G$2:$G$2224,"Capital",Pedidos!$H$2:$H$2224,$A34),"") -> 355.2278 | D34: =IFERROR(AVERAGEIFS(Pedidos!$AC$2:$AC$2224,Pedidos!$AJ$2:$AJ$2224,"SIM",Pedidos!$G$2:$G$2224,"Capital",Pedidos!$H$2:$H$2224,$A34),"") -> 593.32707 | E34: =IFERROR(D34/C34-1,"") -> 0.67027204 | F34: =IFERROR(AVERAGEIFS(Pedidos!$AD$2:$AD$2224,Pedidos!$AJ$2:$AJ$2224,"SIM",Pedidos!$G$2:$G$2224,"Capital",Pedidos!$H$2:$H$2224,$A34)/C34-1,"") -> 0.38092507 | G34: =IFERROR(AVERAGEIFS(Pedidos!$M$2:$M$2224,Pedidos!$AJ$2:$AJ$2224,"SIM",Pedidos!$G$2:$G$2224,"Capital",Pedidos!$H$2:$H$2224,$A34),"") -> 272.9 | H34: =IFERROR(AVERAGEIFS(Pedidos!$U$2:$U$2224,Pedidos!$AJ$2:$AJ$2224,"SIM",Pedidos!$G$2:$G$2224,"Capital",Pedidos!$H$2:$H$2224,$A34),"") -> 398.74 | I34: =IFERROR(H34/G34-1,"") -> 0.46112129 | J34: =IFERROR(COUNTIFS(Pedidos!$AJ$2:$AJ$2224,"SIM",Pedidos!$G$2:$G$2224,"Capital",Pedidos!$H$2:$H$2224,$A34,Pedidos!$AG$2:$AG$2224,"SIM")/B34,"") -> 0 | K34: =IFERROR(MAX(0,1-C34/D34),"") -> 0.40129513
A35: TOTAL | B35: =COUNTIFS(Pedidos!$AJ$2:$AJ$2224,"SIM",Pedidos!$G$2:$G$2224,"Capital") -> 1030 | C35: =IFERROR(AVERAGEIFS(Pedidos!$T$2:$T$2224,Pedidos!$AJ$2:$AJ$2224,"SIM",Pedidos!$G$2:$G$2224,"Capital"),"") -> 106.76312 | D35: =IFERROR(AVERAGEIFS(Pedidos!$AC$2:$AC$2224,Pedidos!$AJ$2:$AJ$2224,"SIM",Pedidos!$G$2:$G$2224,"Capital"),"") -> 156.29299 | E35: =IFERROR(D35/C35-1,"") -> 0.46392307 | F35: =IFERROR(AVERAGEIFS(Pedidos!$AD$2:$AD$2224,Pedidos!$AJ$2:$AJ$2224,"SIM",Pedidos!$G$2:$G$2224,"Capital")/C35-1,"") -> 0.23404986 | G35: =IFERROR(AVERAGEIFS(Pedidos!$M$2:$M$2224,Pedidos!$AJ$2:$AJ$2224,"SIM",Pedidos!$G$2:$G$2224,"Capital"),"") -> 73.621718 | H35: =IFERROR(AVERAGEIFS(Pedidos!$U$2:$U$2224,Pedidos!$AJ$2:$AJ$2224,"SIM",Pedidos!$G$2:$G$2224,"Capital"),"") -> 105.42938 | I35: =IFERROR(H35/G35-1,"") -> 0.43204181 | J35: =IFERROR(COUNTIFS(Pedidos!$AJ$2:$AJ$2224,"SIM",Pedidos!$G$2:$G$2224,"Capital",Pedidos!$AG$2:$AG$2224,"SIM")/B35,"") -> 0 | K35: =IFERROR(MAX(0,1-C35/D35),"") -> 0.31690399
A37: Região: Metropolitana
A38: Faixa (kg) | B38: Pedidos | C38: TSL médio | D38: PROLOG médio | E38: PROLOG vs TSL | F38: PROLOG s/ taxa interna vs TSL | G38: TSL frete peso | H38: PROLOG frete peso | I38: Frete peso PROLOG vs TSL | J38: % pedidos PROLOG ganharia | K38: Redução necessária
A39: 0-20 | B39: =COUNTIFS(Pedidos!$AJ$2:$AJ$2224,"SIM",Pedidos!$G$2:$G$2224,"Metropolitana",Pedidos!$H$2:$H$2224,$A39) -> 24 | C39: =IFERROR(AVERAGEIFS(Pedidos!$T$2:$T$2224,Pedidos!$AJ$2:$AJ$2224,"SIM",Pedidos!$G$2:$G$2224,"Metropolitana",Pedidos!$H$2:$H$2224,$A39),"") -> 75.475687 | D39: =IFERROR(AVERAGEIFS(Pedidos!$AC$2:$AC$2224,Pedidos!$AJ$2:$AJ$2224,"SIM",Pedidos!$G$2:$G$2224,"Metropolitana",Pedidos!$H$2:$H$2224,$A39),"") -> 76.658069 | E39: =IFERROR(D39/C39-1,"") -> 0.015665734 | F39: =IFERROR(AVERAGEIFS(Pedidos!$AD$2:$AD$2224,Pedidos!$AJ$2:$AJ$2224,"SIM",Pedidos!$G$2:$G$2224,"Metropolitana",Pedidos!$H$2:$H$2224,$A39)/C39-1,"") -> -0.11165176 | G39: =IFERROR(AVERAGEIFS(Pedidos!$M$2:$M$2224,Pedidos!$AJ$2:$AJ$2224,"SIM",Pedidos!$G$2:$G$2224,"Metropolitana",Pedidos!$H$2:$H$2224,$A39),"") -> 48.69 | H39: =IFERROR(AVERAGEIFS(Pedidos!$U$2:$U$2224,Pedidos!$AJ$2:$AJ$2224,"SIM",Pedidos!$G$2:$G$2224,"Metropolitana",Pedidos!$H$2:$H$2224,$A39),"") -> 51.350833 | I39: =IFERROR(H39/G39-1,"") -> 0.054648456 | J39: =IFERROR(COUNTIFS(Pedidos!$AJ$2:$AJ$2224,"SIM",Pedidos!$G$2:$G$2224,"Metropolitana",Pedidos!$H$2:$H$2224,$A39,Pedidos!$AG$2:$AG$2224,"SIM")/B39,"") -> 0.58333333 | K39: =IFERROR(MAX(0,1-C39/D39),"") -> 0.015424104
