Workbook

Sheet Painel
B1: COMPETITIVIDADE DA TABELA PROLOG FILIAL SP — RIO DE JANEIRO
B2: Base: 2.223 pedidos reais do RJ (jul–set/2026), saída filial SP, cotados pela tabela PROLOG e pela tabela de OUTRO PARCEIRO. Preços finais com ICMS 12% por fora e todas as taxas.
B4: PREÇO PROLOG vs OUTRO PARCEIRO | E4: COTAÇÕES QUE A PROLOG GANHARIA HOJE | H4: FRETE PESO PROLOG vs OUTRO PARCEIRO | K4: REDUÇÃO NECESSÁRIA NO FRETE PESO
B5: =SUM(Pedidos!$AB$2:$AB$2224)/SUM(Pedidos!$S$2:$S$2224)-1 -> 0.4347729 | E5: =COUNTIF(Pedidos!$AE$2:$AE$2224,"SIM")/COUNTA(Pedidos!$D$2:$D$2224) -> 0.0067506751 | H5: =SUM(Pedidos!$T$2:$T$2224)/SUM(Pedidos!$I$2:$I$2224)-1 -> 0.79476785 | K5: =1-(SUM(Pedidos!$R$2:$R$2224)-(SUM(Pedidos!$AA$2:$AA$2224)-SUM(Pedidos!$T$2:$T$2224)))/SUM(Pedidos!$T$2:$T$2224) -> 0.3874974
B7: preço final médio por pedido | E7: pedidos em que a PROLOG seria a mais barata | H7: principal causa da diferença | K7: para empatar, mantendo as taxas atuais
B9: QUADRO 1 — Competitividade por região
B10: Região | C10: Pedidos | D10: % do volume | E10: Preço médio PROLOG | F10: Preço médio OUTRO PARCEIRO | G10: PROLOG vs OUTRO PARCEIRO | H10: Frete peso PROLOG vs OUTRO PARCEIRO | I10: Redução necessária no frete peso | J10: Prazo PROLOG (du) | K10: Prazo OUTRO PARCEIRO (du) | L10: Situação
B11: Capital | C11: =COUNTIFS(Pedidos!$E$2:$E$2224,"Capital") -> 1030 | D11: =C11/COUNTA(Pedidos!$D$2:$D$2224) -> 0.46354635 | E11: =AVERAGEIFS(Pedidos!$AB$2:$AB$2224,Pedidos!$E$2:$E$2224,"Capital") -> 156.29299 | F11: =AVERAGEIFS(Pedidos!$S$2:$S$2224,Pedidos!$E$2:$E$2224,"Capital") -> 106.44612 | G11: =E11/F11-1 -> 0.46828261 | H11: =SUMIFS(Pedidos!$T$2:$T$2224,Pedidos!$E$2:$E$2224,"Capital")/SUMIFS(Pedidos!$I$2:$I$2224,Pedidos!$E$2:$E$2224,"Capital")-1 -> 0.923291 | I11: =1-(SUMIFS(Pedidos!$R$2:$R$2224,Pedidos!$E$2:$E$2224,"Capital")-(SUMIFS(Pedidos!$AA$2:$AA$2224,Pedidos!$E$2:$E$2224,"Capital")-SUMIFS(Pedidos!$T$2:$T$2224,Pedidos!$E$2:$E$2224,"Capital")))/SUMIFS(Pedidos!$T$2:$T$2224,Pedidos!$E$2:$E$2224,"Capital") -> 0.41606281 | J11: =AVERAGEIFS(Pedidos!$AG$2:$AG$2224,Pedidos!$E$2:$E$2224,"Capital") -> 5 | K11: =AVERAGEIFS(Pedidos!$AF$2:$AF$2224,Pedidos!$E$2:$E$2224,"Capital") -> 2 | L11: =IF(G11<=0,"COMPETITIVO",IF(G11<=0.25,"AJUSTE MODERADO","AJUSTE FORTE")) -> AJUSTE FORTE
B12: Metropolitana | C12: =COUNTIFS(Pedidos!$E$2:$E$2224,"Metropolitana") -> 542 | D12: =C12/COUNTA(Pedidos!$D$2:$D$2224) -> 0.24392439 | E12: =AVERAGEIFS(Pedidos!$AB$2:$AB$2224,Pedidos!$E$2:$E$2224,"Metropolitana") -> 172.71587 | F12: =AVERAGEIFS(Pedidos!$S$2:$S$2224,Pedidos!$E$2:$E$2224,"Metropolitana") -> 127.2607 | G12: =E12/F12-1 -> 0.35718152 | H12: =SUMIFS(Pedidos!$T$2:$T$2224,Pedidos!$E$2:$E$2224,"Metropolitana")/SUMIFS(Pedidos!$I$2:$I$2224,Pedidos!$E$2:$E$2224,"Metropolitana")-1 -> 0.65576215 | I12: =1-(SUMIFS(Pedidos!$R$2:$R$2224,Pedidos!$E$2:$E$2224,"Metropolitana")-(SUMIFS(Pedidos!$AA$2:$AA$2224,Pedidos!$E$2:$E$2224,"Metropolitana")-SUMIFS(Pedidos!$T$2:$T$2224,Pedidos!$E$2:$E$2224,"Metropolitana")))/SUMIFS(Pedidos!$T$2:$T$2224,Pedidos!$E$2:$E$2224,"Metropolitana") -> 0.3407957 | J12: =AVERAGEIFS(Pedidos!$AG$2:$AG$2224,Pedidos!$E$2:$E$2224,"Metropolitana") -> 5.7490775 | K12: =AVERAGEIFS(Pedidos!$AF$2:$AF$2224,Pedidos!$E$2:$E$2224,"Metropolitana") -> 2 | L12: =IF(G12<=0,"COMPETITIVO",IF(G12<=0.25,"AJUSTE MODERADO","AJUSTE FORTE")) -> AJUSTE FORTE
B13: Interior | C13: =COUNTIFS(Pedidos!$E$2:$E$2224,"Interior") -> 651 | D13: =C13/COUNTA(Pedidos!$D$2:$D$2224) -> 0.2929793 | E13: =AVERAGEIFS(Pedidos!$AB$2:$AB$2224,Pedidos!$E$2:$E$2224,"Interior") -> 202.86615 | F13: =AVERAGEIFS(Pedidos!$S$2:$S$2224,Pedidos!$E$2:$E$2224,"Interior") -> 139.59612 | G13: =E13/F13-1 -> 0.4532363 | H13: =SUMIFS(Pedidos!$T$2:$T$2224,Pedidos!$E$2:$E$2224,"Interior")/SUMIFS(Pedidos!$I$2:$I$2224,Pedidos!$E$2:$E$2224,"Interior")-1 -> 0.75887282 | I13: =1-(SUMIFS(Pedidos!$R$2:$R$2224,Pedidos!$E$2:$E$2224,"Interior")-(SUMIFS(Pedidos!$AA$2:$AA$2224,Pedidos!$E$2:$E$2224,"Interior")-SUMIFS(Pedidos!$T$2:$T$2224,Pedidos!$E$2:$E$2224,"Interior")))/SUMIFS(Pedidos!$T$2:$T$2224,Pedidos!$E$2:$E$2224,"Interior") -> 0.38610223 | J13: =AVERAGEIFS(Pedidos!$AG$2:$AG$2224,Pedidos!$E$2:$E$2224,"Interior") -> 9.3855607 | K13: =AVERAGEIFS(Pedidos!$AF$2:$AF$2224,Pedidos!$E$2:$E$2224,"Interior") -> 13 | L13: =IF(G13<=0,"COMPETITIVO",IF(G13<=0.25,"AJUSTE MODERADO","AJUSTE FORTE")) -> AJUSTE FORTE
B14: TOTAL | C14: =COUNTIFS(Pedidos!$E$2:$E$2224,"<>") -> 2223 | D14: =C14/COUNTA(Pedidos!$D$2:$D$2224) -> 1.00045 | E14: =AVERAGEIFS(Pedidos!$AB$2:$AB$2224,Pedidos!$E$2:$E$2224,"<>") -> 173.93596 | F14: =AVERAGEIFS(Pedidos!$S$2:$S$2224,Pedidos!$E$2:$E$2224,"<>") -> 121.22891 | G14: =E14/F14-1 -> 0.4347729 | H14: =SUMIFS(Pedidos!$T$2:$T$2224,Pedidos!$E$2:$E$2224,"<>")/SUMIFS(Pedidos!$I$2:$I$2224,Pedidos!$E$2:$E$2224,"<>")-1 -> 0.79476785 | I14: =1-(SUMIFS(Pedidos!$R$2:$R$2224,Pedidos!$E$2:$E$2224,"<>")-(SUMIFS(Pedidos!$AA$2:$AA$2224,Pedidos!$E$2:$E$2224,"<>")-SUMIFS(Pedidos!$T$2:$T$2224,Pedidos!$E$2:$E$2224,"<>")))/SUMIFS(Pedidos!$T$2:$T$2224,Pedidos!$E$2:$E$2224,"<>") -> 0.3874974 | J14: =AVERAGEIFS(Pedidos!$AG$2:$AG$2224,Pedidos!$E$2:$E$2224,"<>") -> 6.4669366 | K14: =AVERAGEIFS(Pedidos!$AF$2:$AF$2224,Pedidos!$E$2:$E$2224,"<>") -> 5.2213225 | L14: =IF(G14<=0,"COMPETITIVO",IF(G14<=0.25,"AJUSTE MODERADO","AJUSTE FORTE")) -> AJUSTE FORTE
B15: Capital = CEPs 20000-001 a 23799-999 (município do Rio). Metropolitana = Niterói, São Gonçalo, Duque de Caxias, São João de Meriti, Nova Iguaçu, Belford Roxo, Queimados, Nilópolis e Mesquita. Interior = demais.
B17: QUADRO 2 — PROLOG vs OUTRO PARCEIRO por faixa de peso (preço final) | H17: verde = PROLOG competitiva · vermelho = precisa reduzir
B18: Região | C18: 0-20 kg | D18: 20-35 kg | E18: 35-40 kg | F18: 40-50 kg | G18: 50-60 kg | H18: 60-70 kg | I18: 70-80 kg | J18: 80-100 kg | K18: 100-120 kg | L18: 120-150 kg | M18: Total
B19: Capital | C19: =IFERROR(SUMIFS(Pedidos!$AB$2:$AB$2224,Pedidos!$E$2:$E$2224,"Capital",Pedidos!$F$2:$F$2224,"0-20")/SUMIFS(Pedidos!$S$2:$S$2224,Pedidos!$E$2:$E$2224,"Capital",Pedidos!$F$2:$F$2224,"0-20")-1,"") -> 0.090212475 | D19: =IFERROR(SUMIFS(Pedidos!$AB$2:$AB$2224,Pedidos!$E$2:$E$2224,"Capital",Pedidos!$F$2:$F$2224,"20-35")/SUMIFS(Pedidos!$S$2:$S$2224,Pedidos!$E$2:$E$2224,"Capital",Pedidos!$F$2:$F$2224,"20-35")-1,"") -> 0.45217647 | E19: =IFERROR(SUMIFS(Pedidos!$AB$2:$AB$2224,Pedidos!$E$2:$E$2224,"Capital",Pedidos!$F$2:$F$2224,"35-40")/SUMIFS(Pedidos!$S$2:$S$2224,Pedidos!$E$2:$E$2224,"Capital",Pedidos!$F$2:$F$2224,"35-40")-1,"") -> 0.46655029 | F19: =IFERROR(SUMIFS(Pedidos!$AB$2:$AB$2224,Pedidos!$E$2:$E$2224,"Capital",Pedidos!$F$2:$F$2224,"40-50")/SUMIFS(Pedidos!$S$2:$S$2224,Pedidos!$E$2:$E$2224,"Capital",Pedidos!$F$2:$F$2224,"40-50")-1,"") -> 0.36502388 | G19: =IFERROR(SUMIFS(Pedidos!$AB$2:$AB$2224,Pedidos!$E$2:$E$2224,"Capital",Pedidos!$F$2:$F$2224,"50-60")/SUMIFS(Pedidos!$S$2:$S$2224,Pedidos!$E$2:$E$2224,"Capital",Pedidos!$F$2:$F$2224,"50-60")-1,"") -> 0.46820634 | H19: =IFERROR(SUMIFS(Pedidos!$AB$2:$AB$2224,Pedidos!$E$2:$E$2224,"Capital",Pedidos!$F$2:$F$2224,"60-70")/SUMIFS(Pedidos!$S$2:$S$2224,Pedidos!$E$2:$E$2224,"Capital",Pedidos!$F$2:$F$2224,"60-70")-1,"") -> 0.55690899 | I19: =IFERROR(SUMIFS(Pedidos!$AB$2:$AB$2224,Pedidos!$E$2:$E$2224,"Capital",Pedidos!$F$2:$F$2224,"70-80")/SUMIFS(Pedidos!$S$2:$S$2224,Pedidos!$E$2:$E$2224,"Capital",Pedidos!$F$2:$F$2224,"70-80")-1,"") -> 0.48740184 | J19: =IFERROR(SUMIFS(Pedidos!$AB$2:$AB$2224,Pedidos!$E$2:$E$2224,"Capital",Pedidos!$F$2:$F$2224,"80-100")/SUMIFS(Pedidos!$S$2:$S$2224,Pedidos!$E$2:$E$2224,"Capital",Pedidos!$F$2:$F$2224,"80-100")-1,"") -> 0.55652654 | K19: =IFERROR(SUMIFS(Pedidos!$AB$2:$AB$2224,Pedidos!$E$2:$E$2224,"Capital",Pedidos!$F$2:$F$2224,"100-120")/SUMIFS(Pedidos!$S$2:$S$2224,Pedidos!$E$2:$E$2224,"Capital",Pedidos!$F$2:$F$2224,"100-120")-1,"") -> 0.66629369 | L19: =IFERROR(SUMIFS(Pedidos!$AB$2:$AB$2224,Pedidos!$E$2:$E$2224,"Capital",Pedidos!$F$2:$F$2224,"120-150")/SUMIFS(Pedidos!$S$2:$S$2224,Pedidos!$E$2:$E$2224,"Capital",Pedidos!$F$2:$F$2224,"120-150")-1,"") -> 0.59080036 | M19: =IFERROR(SUMIFS(Pedidos!$AB$2:$AB$2224,Pedidos!$E$2:$E$2224,"Capital")/SUMIFS(Pedidos!$S$2:$S$2224,Pedidos!$E$2:$E$2224,"Capital")-1,"") -> 0.46828261
B20: Metropolitana | C20: =IFERROR(SUMIFS(Pedidos!$AB$2:$AB$2224,Pedidos!$E$2:$E$2224,"Metropolitana",Pedidos!$F$2:$F$2224,"0-20")/SUMIFS(Pedidos!$S$2:$S$2224,Pedidos!$E$2:$E$2224,"Metropolitana",Pedidos!$F$2:$F$2224,"0-20")-1,"") -> 0.0011116464 | D20: =IFERROR(SUMIFS(Pedidos!$AB$2:$AB$2224,Pedidos!$E$2:$E$2224,"Metropolitana",Pedidos!$F$2:$F$2224,"20-35")/SUMIFS(Pedidos!$S$2:$S$2224,Pedidos!$E$2:$E$2224,"Metropolitana",Pedidos!$F$2:$F$2224,"20-35")-1,"") -> 0.2693548 | E20: =IFERROR(SUMIFS(Pedidos!$AB$2:$AB$2224,Pedidos!$E$2:$E$2224,"Metropolitana",Pedidos!$F$2:$F$2224,"35-40")/SUMIFS(Pedidos!$S$2:$S$2224,Pedidos!$E$2:$E$2224,"Metropolitana",Pedidos!$F$2:$F$2224,"35-40")-1,"") -> 0.27306231 | F20: =IFERROR(SUMIFS(Pedidos!$AB$2:$AB$2224,Pedidos!$E$2:$E$2224,"Metropolitana",Pedidos!$F$2:$F$2224,"40-50")/SUMIFS(Pedidos!$S$2:$S$2224,Pedidos!$E$2:$E$2224,"Metropolitana",Pedidos!$F$2:$F$2224,"40-50")-1,"") -> 0.28870004 | G20: =IFERROR(SUMIFS(Pedidos!$AB$2:$AB$2224,Pedidos!$E$2:$E$2224,"Metropolitana",Pedidos!$F$2:$F$2224,"50-60")/SUMIFS(Pedidos!$S$2:$S$2224,Pedidos!$E$2:$E$2224,"Metropolitana",Pedidos!$F$2:$F$2224,"50-60")-1,"") -> 0.35816794 | H20: =IFERROR(SUMIFS(Pedidos!$AB$2:$AB$2224,Pedidos!$E$2:$E$2224,"Metropolitana",Pedidos!$F$2:$F$2224,"60-70")/SUMIFS(Pedidos!$S$2:$S$2224,Pedidos!$E$2:$E$2224,"Metropolitana",Pedidos!$F$2:$F$2224,"60-70")-1,"") -> 0.44290558 | I20: =IFERROR(SUMIFS(Pedidos!$AB$2:$AB$2224,Pedidos!$E$2:$E$2224,"Metropolitana",Pedidos!$F$2:$F$2224,"70-80")/SUMIFS(Pedidos!$S$2:$S$2224,Pedidos!$E$2:$E$2224,"Metropolitana",Pedidos!$F$2:$F$2224,"70-80")-1,"") -> 0.3642043 | J20: =IFERROR(SUMIFS(Pedidos!$AB$2:$AB$2224,Pedidos!$E$2:$E$2224,"Metropolitana",Pedidos!$F$2:$F$2224,"80-100")/SUMIFS(Pedidos!$S$2:$S$2224,Pedidos!$E$2:$E$2224,"Metropolitana",Pedidos!$F$2:$F$2224,"80-100")-1,"") -> 0.49142215 | K20: =IFERROR(SUMIFS(Pedidos!$AB$2:$AB$2224,Pedidos!$E$2:$E$2224,"Metropolitana",Pedidos!$F$2:$F$2224,"100-120")/SUMIFS(Pedidos!$S$2:$S$2224,Pedidos!$E$2:$E$2224,"Metropolitana",Pedidos!$F$2:$F$2224,"100-120")-1,"") -> 0.59793507 | L20: =IFERROR(SUMIFS(Pedidos!$AB$2:$AB$2224,Pedidos!$E$2:$E$2224,"Metropolitana",Pedidos!$F$2:$F$2224,"120-150")/SUMIFS(Pedidos!$S$2:$S$2224,Pedidos!$E$2:$E$2224,"Metropolitana",Pedidos!$F$2:$F$2224,"120-150")-1,"") -> 0.53347538 | M20: =IFERROR(SUMIFS(Pedidos!$AB$2:$AB$2224,Pedidos!$E$2:$E$2224,"Metropolitana")/SUMIFS(Pedidos!$S$2:$S$2224,Pedidos!$E$2:$E$2224,"Metropolitana")-1,"") -> 0.35718152
B21: Interior | C21: =IFERROR(SUMIFS(Pedidos!$AB$2:$AB$2224,Pedidos!$E$2:$E$2224,"Interior",Pedidos!$F$2:$F$2224,"0-20")/SUMIFS(Pedidos!$S$2:$S$2224,Pedidos!$E$2:$E$2224,"Interior",Pedidos!$F$2:$F$2224,"0-20")-1,"") -> 0.53003614 | D21: =IFERROR(SUMIFS(Pedidos!$AB$2:$AB$2224,Pedidos!$E$2:$E$2224,"Interior",Pedidos!$F$2:$F$2224,"20-35")/SUMIFS(Pedidos!$S$2:$S$2224,Pedidos!$E$2:$E$2224,"Interior",Pedidos!$F$2:$F$2224,"20-35")-1,"") -> 0.45279877 | E21: =IFERROR(SUMIFS(Pedidos!$AB$2:$AB$2224,Pedidos!$E$2:$E$2224,"Interior",Pedidos!$F$2:$F$2224,"35-40")/SUMIFS(Pedidos!$S$2:$S$2224,Pedidos!$E$2:$E$2224,"Interior",Pedidos!$F$2:$F$2224,"35-40")-1,"") -> 0.40457711 | F21: =IFERROR(SUMIFS(Pedidos!$AB$2:$AB$2224,Pedidos!$E$2:$E$2224,"Interior",Pedidos!$F$2:$F$2224,"40-50")/SUMIFS(Pedidos!$S$2:$S$2224,Pedidos!$E$2:$E$2224,"Interior",Pedidos!$F$2:$F$2224,"40-50")-1,"") -> 0.40459217 | G21: =IFERROR(SUMIFS(Pedidos!$AB$2:$AB$2224,Pedidos!$E$2:$E$2224,"Interior",Pedidos!$F$2:$F$2224,"50-60")/SUMIFS(Pedidos!$S$2:$S$2224,Pedidos!$E$2:$E$2224,"Interior",Pedidos!$F$2:$F$2224,"50-60")-1,"") -> 0.42464002 | H21: =IFERROR(SUMIFS(Pedidos!$AB$2:$AB$2224,Pedidos!$E$2:$E$2224,"Interior",Pedidos!$F$2:$F$2224,"60-70")/SUMIFS(Pedidos!$S$2:$S$2224,Pedidos!$E$2:$E$2224,"Interior",Pedidos!$F$2:$F$2224,"60-70")-1,"") -> 0.48279866 | I21: =IFERROR(SUMIFS(Pedidos!$AB$2:$AB$2224,Pedidos!$E$2:$E$2224,"Interior",Pedidos!$F$2:$F$2224,"70-80")/SUMIFS(Pedidos!$S$2:$S$2224,Pedidos!$E$2:$E$2224,"Interior",Pedidos!$F$2:$F$2224,"70-80")-1,"") -> 0.38567155 | J21: =IFERROR(SUMIFS(Pedidos!$AB$2:$AB$2224,Pedidos!$E$2:$E$2224,"Interior",Pedidos!$F$2:$F$2224,"80-100")/SUMIFS(Pedidos!$S$2:$S$2224,Pedidos!$E$2:$E$2224,"Interior",Pedidos!$F$2:$F$2224,"80-100")-1,"") -> 0.46611946 | K21: =IFERROR(SUMIFS(Pedidos!$AB$2:$AB$2224,Pedidos!$E$2:$E$2224,"Interior",Pedidos!$F$2:$F$2224,"100-120")/SUMIFS(Pedidos!$S$2:$S$2224,Pedidos!$E$2:$E$2224,"Interior",Pedidos!$F$2:$F$2224,"100-120")-1,"") -> 0.58503505 | L21: =IFERROR(SUMIFS(Pedidos!$AB$2:$AB$2224,Pedidos!$E$2:$E$2224,"Interior",Pedidos!$F$2:$F$2224,"120-150")/SUMIFS(Pedidos!$S$2:$S$2224,Pedidos!$E$2:$E$2224,"Interior",Pedidos!$F$2:$F$2224,"120-150")-1,"") -> 0.52391223 | M21: =IFERROR(SUMIFS(Pedidos!$AB$2:$AB$2224,Pedidos!$E$2:$E$2224,"Interior")/SUMIFS(Pedidos!$S$2:$S$2224,Pedidos!$E$2:$E$2224,"Interior")-1,"") -> 0.4532363
B22: TODAS | C22: =IFERROR(SUMIFS(Pedidos!$AB$2:$AB$2224,Pedidos!$E$2:$E$2224,"<>",Pedidos!$F$2:$F$2224,"0-20")/SUMIFS(Pedidos!$S$2:$S$2224,Pedidos!$E$2:$E$2224,"<>",Pedidos!$F$2:$F$2224,"0-20")-1,"") -> 0.15272413 | D22: =IFERROR(SUMIFS(Pedidos!$AB$2:$AB$2224,Pedidos!$E$2:$E$2224,"<>",Pedidos!$F$2:$F$2224,"20-35")/SUMIFS(Pedidos!$S$2:$S$2224,Pedidos!$E$2:$E$2224,"<>",Pedidos!$F$2:$F$2224,"20-35")-1,"") -> 0.41664093 | E22: =IFERROR(SUMIFS(Pedidos!$AB$2:$AB$2224,Pedidos!$E$2:$E$2224,"<>",Pedidos!$F$2:$F$2224,"35-40")/SUMIFS(Pedidos!$S$2:$S$2224,Pedidos!$E$2:$E$2224,"<>",Pedidos!$F$2:$F$2224,"35-40")-1,"") -> 0.39811542 | F22: =IFERROR(SUMIFS(Pedidos!$AB$2:$AB$2224,Pedidos!$E$2:$E$2224,"<>",Pedidos!$F$2:$F$2224,"40-50")/SUMIFS(Pedidos!$S$2:$S$2224,Pedidos!$E$2:$E$2224,"<>",Pedidos!$F$2:$F$2224,"40-50")-1,"") -> 0.35665037 | G22: =IFERROR(SUMIFS(Pedidos!$AB$2:$AB$2224,Pedidos!$E$2:$E$2224,"<>",Pedidos!$F$2:$F$2224,"50-60")/SUMIFS(Pedidos!$S$2:$S$2224,Pedidos!$E$2:$E$2224,"<>",Pedidos!$F$2:$F$2224,"50-60")-1,"") -> 0.42227189 | H22: =IFERROR(SUMIFS(Pedidos!$AB$2:$AB$2224,Pedidos!$E$2:$E$2224,"<>",Pedidos!$F$2:$F$2224,"60-70")/SUMIFS(Pedidos!$S$2:$S$2224,Pedidos!$E$2:$E$2224,"<>",Pedidos!$F$2:$F$2224,"60-70")-1,"") -> 0.49929853 | I22: =IFERROR(SUMIFS(Pedidos!$AB$2:$AB$2224,Pedidos!$E$2:$E$2224,"<>",Pedidos!$F$2:$F$2224,"70-80")/SUMIFS(Pedidos!$S$2:$S$2224,Pedidos!$E$2:$E$2224,"<>",Pedidos!$F$2:$F$2224,"70-80")-1,"") -> 0.41262021 | J22: =IFERROR(SUMIFS(Pedidos!$AB$2:$AB$2224,Pedidos!$E$2:$E$2224,"<>",Pedidos!$F$2:$F$2224,"80-100")/SUMIFS(Pedidos!$S$2:$S$2224,Pedidos!$E$2:$E$2224,"<>",Pedidos!$F$2:$F$2224,"80-100")-1,"") -> 0.49933513 | K22: =IFERROR(SUMIFS(Pedidos!$AB$2:$AB$2224,Pedidos!$E$2:$E$2224,"<>",Pedidos!$F$2:$F$2224,"100-120")/SUMIFS(Pedidos!$S$2:$S$2224,Pedidos!$E$2:$E$2224,"<>",Pedidos!$F$2:$F$2224,"100-120")-1,"") -> 0.61970309 | L22: =IFERROR(SUMIFS(Pedidos!$AB$2:$AB$2224,Pedidos!$E$2:$E$2224,"<>",Pedidos!$F$2:$F$2224,"120-150")/SUMIFS(Pedidos!$S$2:$S$2224,Pedidos!$E$2:$E$2224,"<>",Pedidos!$F$2:$F$2224,"120-150")-1,"") -> 0.55509108 | M22: =IFERROR(SUMIFS(Pedidos!$AB$2:$AB$2224,Pedidos!$E$2:$E$2224,"<>")/SUMIFS(Pedidos!$S$2:$S$2224,Pedidos!$E$2:$E$2224,"<>")-1,"") -> 0.4347729
B23: % do volume | C23: =COUNTIFS(Pedidos!$F$2:$F$2224,"0-20")/COUNTA(Pedidos!$D$2:$D$2224) -> 0.048154815 | D23: =COUNTIFS(Pedidos!$F$2:$F$2224,"20-35")/COUNTA(Pedidos!$D$2:$D$2224) -> 0.22277228 | E23: =COUNTIFS(Pedidos!$F$2:$F$2224,"35-40")/COUNTA(Pedidos!$D$2:$D$2224) -> 0.15976598 | F23: =COUNTIFS(Pedidos!$F$2:$F$2224,"40-50")/COUNTA(Pedidos!$D$2:$D$2224) -> 0.15481548 | G23: =COUNTIFS(Pedidos!$F$2:$F$2224,"50-60")/COUNTA(Pedidos!$D$2:$D$2224) -> 0.18721872 | H23: =COUNTIFS(Pedidos!$F$2:$F$2224,"60-70")/COUNTA(Pedidos!$D$2:$D$2224) -> 0.12286229 | I23: =COUNTIFS(Pedidos!$F$2:$F$2224,"70-80")/COUNTA(Pedidos!$D$2:$D$2224) -> 0.01350135 | J23: =COUNTIFS(Pedidos!$F$2:$F$2224,"80-100")/COUNTA(Pedidos!$D$2:$D$2224) -> 0.025652565 | K23: =COUNTIFS(Pedidos!$F$2:$F$2224,"100-120")/COUNTA(Pedidos!$D$2:$D$2224) -> 0.023852385 | L23: =COUNTIFS(Pedidos!$F$2:$F$2224,"120-150")/COUNTA(Pedidos!$D$2:$D$2224) -> 0.03870387 | M23: =SUM(C23:L23) -> 0.99729973
B25: QUADRO 3 — Frete peso da tabela: ATUAL x ALVO para empatar (faixas com 80% do volume) | H25: alvo = valor máximo de frete peso para empatar; para ganhar a cotação, ficar alguns % abaixo
B26: Cidade | C26: 0-20 kg | E26: 20-35 kg | G26: 35-40 kg | I26: 40-50 kg | K26: 50-60 kg | M26: 60-70 kg
C27: Atual | D27: Alvo | E27: Atual | F27: Alvo | G27: Atual | H27: Alvo | I27: Atual | J27: Alvo | K27: Atual | L27: Alvo | M27: Atual | N27: Alvo
B28: Rio de Janeiro | C28: =INDEX('Proposta Tabela PROLOG'!H:H,MATCH($B28,'Proposta Tabela PROLOG'!$B:$B,0)) -> 46.98 | D28: =INDEX('Proposta Tabela PROLOG'!AH:AH,MATCH($B28,'Proposta Tabela PROLOG'!$B:$B,0)) -> 41.817887 | E28: =INDEX('Proposta Tabela PROLOG'!I:I,MATCH($B28,'Proposta Tabela PROLOG'!$B:$B,0)) -> 82.21 | F28: =INDEX('Proposta Tabela PROLOG'!AI:AI,MATCH($B28,'Proposta Tabela PROLOG'!$B:$B,0)) -> 49.991357 | G28: =INDEX('Proposta Tabela PROLOG'!J:J,MATCH($B28,'Proposta Tabela PROLOG'!$B:$B,0)) -> 93.97 | H28: =INDEX('Proposta Tabela PROLOG'!AJ:AJ,MATCH($B28,'Proposta Tabela PROLOG'!$B:$B,0)) -> 55.728132 | I28: =INDEX('Proposta Tabela PROLOG'!K:K,MATCH($B28,'Proposta Tabela PROLOG'!$B:$B,0)) -> 93.97 | J28: =INDEX('Proposta Tabela PROLOG'!AK:AK,MATCH($B28,'Proposta Tabela PROLOG'!$B:$B,0)) -> 60.613696 | K28: =INDEX('Proposta Tabela PROLOG'!L:L,MATCH($B28,'Proposta Tabela PROLOG'!$B:$B,0)) -> 112.3 | L28: =INDEX('Proposta Tabela PROLOG'!AL:AL,MATCH($B28,'Proposta Tabela PROLOG'!$B:$B,0)) -> 65.29338 | M28: =INDEX('Proposta Tabela PROLOG'!M:M,MATCH($B28,'Proposta Tabela PROLOG'!$B:$B,0)) -> 131.02 | N28: =INDEX('Proposta Tabela PROLOG'!AM:AM,MATCH($B28,'Proposta Tabela PROLOG'!$B:$B,0)) -> 69.201232
B29: São Gonçalo | C29: =INDEX('Proposta Tabela PROLOG'!H:H,MATCH($B29,'Proposta Tabela PROLOG'!$B:$B,0)) -> 57.47 | D29: =INDEX('Proposta Tabela PROLOG'!AH:AH,MATCH($B29,'Proposta Tabela PROLOG'!$B:$B,0)) -> 51.117887 | E29: =INDEX('Proposta Tabela PROLOG'!I:I,MATCH($B29,'Proposta Tabela PROLOG'!$B:$B,0)) -> 100.58 | F29: =INDEX('Proposta Tabela PROLOG'!AI:AI,MATCH($B29,'Proposta Tabela PROLOG'!$B:$B,0)) -> 66.681357 | G29: =INDEX('Proposta Tabela PROLOG'!J:J,MATCH($B29,'Proposta Tabela PROLOG'!$B:$B,0)) -> 114.95 | H29: =INDEX('Proposta Tabela PROLOG'!AJ:AJ,MATCH($B29,'Proposta Tabela PROLOG'!$B:$B,0)) -> 74.208132 | I29: =INDEX('Proposta Tabela PROLOG'!K:K,MATCH($B29,'Proposta Tabela PROLOG'!$B:$B,0)) -> 114.95 | J29: =INDEX('Proposta Tabela PROLOG'!AK:AK,MATCH($B29,'Proposta Tabela PROLOG'!$B:$B,0)) -> 72.423696 | K29: =INDEX('Proposta Tabela PROLOG'!L:L,MATCH($B29,'Proposta Tabela PROLOG'!$B:$B,0)) -> 128.14 | L29: =INDEX('Proposta Tabela PROLOG'!AL:AL,MATCH($B29,'Proposta Tabela PROLOG'!$B:$B,0)) -> 77.67338 | M29: =INDEX('Proposta Tabela PROLOG'!M:M,MATCH($B29,'Proposta Tabela PROLOG'!$B:$B,0)) -> 149.5 | N29: =INDEX('Proposta Tabela PROLOG'!AM:AM,MATCH($B29,'Proposta Tabela PROLOG'!$B:$B,0)) -> 82.541232
B30: Duque de Caxias | C30: =INDEX('Proposta Tabela PROLOG'!H:H,MATCH($B30,'Proposta Tabela PROLOG'!$B:$B,0)) -> 46.98 | D30: =INDEX('Proposta Tabela PROLOG'!AH:AH,MATCH($B30,'Proposta Tabela PROLOG'!$B:$B,0)) -> 51.117887 | E30: =INDEX('Proposta Tabela PROLOG'!I:I,MATCH($B30,'Proposta Tabela PROLOG'!$B:$B,0)) -> 82.21 | F30: =INDEX('Proposta Tabela PROLOG'!AI:AI,MATCH($B30,'Proposta Tabela PROLOG'!$B:$B,0)) -> 66.681357 | G30: =INDEX('Proposta Tabela PROLOG'!J:J,MATCH($B30,'Proposta Tabela PROLOG'!$B:$B,0)) -> 93.97 | H30: =INDEX('Proposta Tabela PROLOG'!AJ:AJ,MATCH($B30,'Proposta Tabela PROLOG'!$B:$B,0)) -> 74.208132 | I30: =INDEX('Proposta Tabela PROLOG'!K:K,MATCH($B30,'Proposta Tabela PROLOG'!$B:$B,0)) -> 93.97 | J30: =INDEX('Proposta Tabela PROLOG'!AK:AK,MATCH($B30,'Proposta Tabela PROLOG'!$B:$B,0)) -> 72.423696 | K30: =INDEX('Proposta Tabela PROLOG'!L:L,MATCH($B30,'Proposta Tabela PROLOG'!$B:$B,0)) -> 112.3 | L30: =INDEX('Proposta Tabela PROLOG'!AL:AL,MATCH($B30,'Proposta Tabela PROLOG'!$B:$B,0)) -> 77.67338 | M30: =INDEX('Proposta Tabela PROLOG'!M:M,MATCH($B30,'Proposta Tabela PROLOG'!$B:$B,0)) -> 131.02 | N30: =INDEX('Proposta Tabela PROLOG'!AM:AM,MATCH($B30,'Proposta Tabela PROLOG'!$B:$B,0)) -> 82.541232
B31: Nova Iguaçu | C31: =INDEX('Proposta Tabela PROLOG'!H:H,MATCH($B31,'Proposta Tabela PROLOG'!$B:$B,0)) -> 46.98 | D31: =INDEX('Proposta Tabela PROLOG'!AH:AH,MATCH($B31,'Proposta Tabela PROLOG'!$B:$B,0)) -> 51.117887 | E31: =INDEX('Proposta Tabela PROLOG'!I:I,MATCH($B31,'Proposta Tabela PROLOG'!$B:$B,0)) -> 82.21 | F31: =INDEX('Proposta Tabela PROLOG'!AI:AI,MATCH($B31,'Proposta Tabela PROLOG'!$B:$B,0)) -> 66.681357 | G31: =INDEX('Proposta Tabela PROLOG'!J:J,MATCH($B31,'Proposta Tabela PROLOG'!$B:$B,0)) -> 93.97 | H31: =INDEX('Proposta Tabela PROLOG'!AJ:AJ,MATCH($B31,'Proposta Tabela PROLOG'!$B:$B,0)) -> 74.208132 | I31: =INDEX('Proposta Tabela PROLOG'!K:K,MATCH($B31,'Proposta Tabela PROLOG'!$B:$B,0)) -> 93.97 | J31: =INDEX('Proposta Tabela PROLOG'!AK:AK,MATCH($B31,'Proposta Tabela PROLOG'!$B:$B,0)) -> 72.423696 | K31: =INDEX('Proposta Tabela PROLOG'!L:L,MATCH($B31,'Proposta Tabela PROLOG'!$B:$B,0)) -> 112.3 | L31: =INDEX('Proposta Tabela PROLOG'!AL:AL,MATCH($B31,'Proposta Tabela PROLOG'!$B:$B,0)) -> 77.67338 | M31: =INDEX('Proposta Tabela PROLOG'!M:M,MATCH($B31,'Proposta Tabela PROLOG'!$B:$B,0)) -> 131.02 | N31: =INDEX('Proposta Tabela PROLOG'!AM:AM,MATCH($B31,'Proposta Tabela PROLOG'!$B:$B,0)) -> 82.541232
B32: Niterói | C32: =INDEX('Proposta Tabela PROLOG'!H:H,MATCH($B32,'Proposta Tabela PROLOG'!$B:$B,0)) -> 57.47 | D32: =INDEX('Proposta Tabela PROLOG'!AH:AH,MATCH($B32,'Proposta Tabela PROLOG'!$B:$B,0)) -> 51.117887 | E32: =INDEX('Proposta Tabela PROLOG'!I:I,MATCH($B32,'Proposta Tabela PROLOG'!$B:$B,0)) -> 100.58 | F32: =INDEX('Proposta Tabela PROLOG'!AI:AI,MATCH($B32,'Proposta Tabela PROLOG'!$B:$B,0)) -> 66.681357 | G32: =INDEX('Proposta Tabela PROLOG'!J:J,MATCH($B32,'Proposta Tabela PROLOG'!$B:$B,0)) -> 114.95 | H32: =INDEX('Proposta Tabela PROLOG'!AJ:AJ,MATCH($B32,'Proposta Tabela PROLOG'!$B:$B,0)) -> 74.208132 | I32: =INDEX('Proposta Tabela PROLOG'!K:K,MATCH($B32,'Proposta Tabela PROLOG'!$B:$B,0)) -> 114.95 | J32: =INDEX('Proposta Tabela PROLOG'!AK:AK,MATCH($B32,'Proposta Tabela PROLOG'!$B:$B,0)) -> 72.423696 | K32: =INDEX('Proposta Tabela PROLOG'!L:L,MATCH($B32,'Proposta Tabela PROLOG'!$B:$B,0)) -> 128.14 | L32: =INDEX('Proposta Tabela PROLOG'!AL:AL,MATCH($B32,'Proposta Tabela PROLOG'!$B:$B,0)) -> 77.67338 | M32: =INDEX('Proposta Tabela PROLOG'!M:M,MATCH($B32,'Proposta Tabela PROLOG'!$B:$B,0)) -> 149.5 | N32: =INDEX('Proposta Tabela PROLOG'!AM:AM,MATCH($B32,'Proposta Tabela PROLOG'!$B:$B,0)) -> 82.541232
B33: Campos dos Goytacazes | C33: =INDEX('Proposta Tabela PROLOG'!H:H,MATCH($B33,'Proposta Tabela PROLOG'!$B:$B,0)) -> 124.04 | D33: =INDEX('Proposta Tabela PROLOG'!AH:AH,MATCH($B33,'Proposta Tabela PROLOG'!$B:$B,0)) -> 55.347887 | E33: =INDEX('Proposta Tabela PROLOG'!I:I,MATCH($B33,'Proposta Tabela PROLOG'!$B:$B,0)) -> 138.29 | F33: =INDEX('Proposta Tabela PROLOG'!AI:AI,MATCH($B33,'Proposta Tabela PROLOG'!$B:$B,0)) -> 73.511357 | G33: =INDEX('Proposta Tabela PROLOG'!J:J,MATCH($B33,'Proposta Tabela PROLOG'!$B:$B,0)) -> 143.04 | H33: =INDEX('Proposta Tabela PROLOG'!AJ:AJ,MATCH($B33,'Proposta Tabela PROLOG'!$B:$B,0)) -> 82.348132 | I33: =INDEX('Proposta Tabela PROLOG'!K:K,MATCH($B33,'Proposta Tabela PROLOG'!$B:$B,0)) -> 152.54 | J33: =INDEX('Proposta Tabela PROLOG'!AK:AK,MATCH($B33,'Proposta Tabela PROLOG'!$B:$B,0)) -> 84.763696 | K33: =INDEX('Proposta Tabela PROLOG'!L:L,MATCH($B33,'Proposta Tabela PROLOG'!$B:$B,0)) -> 162.04 | L33: =INDEX('Proposta Tabela PROLOG'!AL:AL,MATCH($B33,'Proposta Tabela PROLOG'!$B:$B,0)) -> 90.27338 | M33: =INDEX('Proposta Tabela PROLOG'!M:M,MATCH($B33,'Proposta Tabela PROLOG'!$B:$B,0)) -> 171.54 | N33: =INDEX('Proposta Tabela PROLOG'!AM:AM,MATCH($B33,'Proposta Tabela PROLOG'!$B:$B,0)) -> 96.191232
B34: Belford Roxo | C34: =INDEX('Proposta Tabela PROLOG'!H:H,MATCH($B34,'Proposta Tabela PROLOG'!$B:$B,0)) -> 46.98 | D34: =INDEX('Proposta Tabela PROLOG'!AH:AH,MATCH($B34,'Proposta Tabela PROLOG'!$B:$B,0)) -> 51.117887 | E34: =INDEX('Proposta Tabela PROLOG'!I:I,MATCH($B34,'Proposta Tabela PROLOG'!$B:$B,0)) -> 82.21 | F34: =INDEX('Proposta Tabela PROLOG'!AI:AI,MATCH($B34,'Proposta Tabela PROLOG'!$B:$B,0)) -> 66.681357 | G34: =INDEX('Proposta Tabela PROLOG'!J:J,MATCH($B34,'Proposta Tabela PROLOG'!$B:$B,0)) -> 93.97 | H34: =INDEX('Proposta Tabela PROLOG'!AJ:AJ,MATCH($B34,'Proposta Tabela PROLOG'!$B:$B,0)) -> 74.208132 | I34: =INDEX('Proposta Tabela PROLOG'!K:K,MATCH($B34,'Proposta Tabela PROLOG'!$B:$B,0)) -> 93.97 | J34: =INDEX('Proposta Tabela PROLOG'!AK:AK,MATCH($B34,'Proposta Tabela PROLOG'!$B:$B,0)) -> 72.423696 | K34: =INDEX('Proposta Tabela PROLOG'!L:L,MATCH($B34,'Proposta Tabela PROLOG'!$B:$B,0)) -> 112.3 | L34: =INDEX('Proposta Tabela PROLOG'!AL:AL,MATCH($B34,'Proposta Tabela PROLOG'!$B:$B,0)) -> 77.67338 | M34: =INDEX('Proposta Tabela PROLOG'!M:M,MATCH($B34,'Proposta Tabela PROLOG'!$B:$B,0)) -> 131.02 | N34: =INDEX('Proposta Tabela PROLOG'!AM:AM,MATCH($B34,'Proposta Tabela PROLOG'!$B:$B,0)) -> 82.541232
B35: Macaé | C35: =INDEX('Proposta Tabela PROLOG'!H:H,MATCH($B35,'Proposta Tabela PROLOG'!$B:$B,0)) -> 124.04 | D35: =INDEX('Proposta Tabela PROLOG'!AH:AH,MATCH($B35,'Proposta Tabela PROLOG'!$B:$B,0)) -> 55.347887 | E35: =INDEX('Proposta Tabela PROLOG'!I:I,MATCH($B35,'Proposta Tabela PROLOG'!$B:$B,0)) -> 138.29 | F35: =INDEX('Proposta Tabela PROLOG'!AI:AI,MATCH($B35,'Proposta Tabela PROLOG'!$B:$B,0)) -> 73.511357 | G35: =INDEX('Proposta Tabela PROLOG'!J:J,MATCH($B35,'Proposta Tabela PROLOG'!$B:$B,0)) -> 143.04 | H35: =INDEX('Proposta Tabela PROLOG'!AJ:AJ,MATCH($B35,'Proposta Tabela PROLOG'!$B:$B,0)) -> 82.348132 | I35: =INDEX('Proposta Tabela PROLOG'!K:K,MATCH($B35,'Proposta Tabela PROLOG'!$B:$B,0)) -> 152.54 | J35: =INDEX('Proposta Tabela PROLOG'!AK:AK,MATCH($B35,'Proposta Tabela PROLOG'!$B:$B,0)) -> 84.763696 | K35: =INDEX('Proposta Tabela PROLOG'!L:L,MATCH($B35,'Proposta Tabela PROLOG'!$B:$B,0)) -> 162.04 | L35: =INDEX('Proposta Tabela PROLOG'!AL:AL,MATCH($B35,'Proposta Tabela PROLOG'!$B:$B,0)) -> 90.27338 | M35: =INDEX('Proposta Tabela PROLOG'!M:M,MATCH($B35,'Proposta Tabela PROLOG'!$B:$B,0)) -> 171.54 | N35: =INDEX('Proposta Tabela PROLOG'!AM:AM,MATCH($B35,'Proposta Tabela PROLOG'!$B:$B,0)) -> 96.191232
B36: Tabela completa (93 faixas de CEP × 13 faixas de peso) na aba "Proposta Tabela PROLOG".
B38: QUADRO 4 — SIMULADOR DE PROPOSTA (altere as células amarelas) | H38: o resultado recalcula sobre os 2.223 pedidos
B39: Parâmetro da proposta | C39: Valor | E39: Região | F39: Preço médio PROPOSTA | G39: PROPOSTA vs OUTRO PARCEIRO | H39: Cotações ganhas
B40: Redução linear no frete peso (%) | C40: 0.33 | E40: Capital | F40: =AVERAGEIFS(Pedidos!$AI$2:$AI$2224,Pedidos!$E$2:$E$2224,"Capital") -> 109.32065 | G40: =SUMIFS(Pedidos!$AI$2:$AI$2224,Pedidos!$E$2:$E$2224,"Capital")/SUMIFS(Pedidos!$S$2:$S$2224,Pedidos!$E$2:$E$2224,"Capital")-1 -> 0.02700456 | H40: =COUNTIFS(Pedidos!$E$2:$E$2224,"Capital",Pedidos!$AJ$2:$AJ$2224,"SIM")/COUNTIFS(Pedidos!$E$2:$E$2224,"Capital") -> 0.37961165
B41: TAS (R$ por pedido) — hoje R$ 1,00 | C41: 1 | E41: Metropolitana | F41: =AVERAGEIFS(Pedidos!$AI$2:$AI$2224,Pedidos!$E$2:$E$2224,"Metropolitana") -> 120.91249 | G41: =SUMIFS(Pedidos!$AI$2:$AI$2224,Pedidos!$E$2:$E$2224,"Metropolitana")/SUMIFS(Pedidos!$S$2:$S$2224,Pedidos!$E$2:$E$2224,"Metropolitana")-1 -> -0.049883525 | H41: =COUNTIFS(Pedidos!$E$2:$E$2224,"Metropolitana",Pedidos!$AJ$2:$AJ$2224,"SIM")/COUNTIFS(Pedidos!$E$2:$E$2224,"Metropolitana") -> 0.77490775
B42: Pedágio (R$ por 100 kg) — hoje R$ 4,50 | C42: 1.05 | E42: Interior | F42: =AVERAGEIFS(Pedidos!$AI$2:$AI$2224,Pedidos!$E$2:$E$2224,"Interior") -> 141.04962 | G42: =SUMIFS(Pedidos!$AI$2:$AI$2224,Pedidos!$E$2:$E$2224,"Interior")/SUMIFS(Pedidos!$S$2:$S$2224,Pedidos!$E$2:$E$2224,"Interior")-1 -> 0.01041218 | H42: =COUNTIFS(Pedidos!$E$2:$E$2224,"Interior",Pedidos!$AJ$2:$AJ$2224,"SIM")/COUNTIFS(Pedidos!$E$2:$E$2224,"Interior") -> 0.56989247
B43: CTe (R$ por kg) — hoje R$ 0,06 | C43: 0 | E43: TOTAL | F43: =AVERAGEIFS(Pedidos!$AI$2:$AI$2224,Pedidos!$E$2:$E$2224,"<>") -> 121.43866 | G43: =SUMIFS(Pedidos!$AI$2:$AI$2224,Pedidos!$E$2:$E$2224,"<>")/SUMIFS(Pedidos!$S$2:$S$2224,Pedidos!$E$2:$E$2224,"<>")-1 -> 0.0017301598 | H43: =COUNTIFS(Pedidos!$E$2:$E$2224,"<>",Pedidos!$AJ$2:$AJ$2224,"SIM")/COUNTIFS(Pedidos!$E$2:$E$2224,"<>") -> 0.5317139
B44: A taxa interna do embarcador (R$ 0,45/kg) e o ICMS 12% são mantidos — iguais para todos os parceiros.
B46: Cenários prontos de redução do frete peso (com TAS, pedágio e CTe do simulador)
B47: Redução no frete peso | C47: PROLOG vs OUTRO PARCEIRO | D47: Cotações ganhas
...

Sheet Resumo
A1: PROLOG FILIAL SP x OUTRO PARCEIRO — pedidos RJ, origem FILIAL SP, jul–set/2026
A3: PREMISSAS (células em azul podem ser alteradas — todas as abas recalculam)
A4: Parâmetro | B4: PROLOG | C4: OUTRO PARCEIRO | D4: Fonte / observação
A5: ICMS por fora (total = subtotal / (1 − alíquota)) | B5: 0.12 | C5: 0.12 | D5: Confirmado: 12% por fora. Ambas as tabelas com "ICMS incluso = N".
A6: Ad valorem / frete valor (% NF) | B6: 0.001 | C6: 0 | D6: Tabelas Intelipost
A7: GRIS (% NF) | B7: 0.002 | C7: 0.0021 | D7: Tabelas Intelipost
A8: Seguro (% NF) | B8: 0 | C8: 0.0021 | D8: Tabela OUTRO PARCEIRO
A9: TAS / entrega fixo (R$ por pedido) | B9: 1 | C9: 0 | D9: PROLOG: TAS R$ 1,00
A10: Pedágio (R$ por fração de 100 kg) | B10: 4.5 | C10: 1.05 | D10: Tabelas Intelipost
A11: TRT (% sobre o subtotal) | B11: 0 | C11: 0 | D11: Nenhuma das duas tabelas cobra TRT
A12: CTe por kg (R$/kg) | B12: 0.06 | C12: 0 | D12: PROLOG: CTE FIXO 0,06 com faixa de 1 kg
A13: CTe fixo (R$ por pedido) | B13: 0 | C13: 13.55 | D13: OUTRO PARCEIRO: CTE VALOR FIXO R$ 13,55
A14: Taxa interna (R$ por kg) — levar o produto até a filial SP | B14: 0.45 | C14: 0.45 | D14: Taxa do embarcador, obrigatória e IGUAL para todos os parceiros (não negociável) — lançada como "outra taxa"
A15: Cubagem (kg/m³) | B15: 0 | C15: 300 | D15: Sem dimensões na base: simulado por peso real
A18: VISÃO GERAL — os mesmos 2.223 pedidos cotados pelas duas tabelas
A19: Indicador | B19: OUTRO PARCEIRO | C19: PROLOG FILIAL SP | D19: Diferença
A20: Pedidos | B20: =COUNTA(Pedidos!$D$2:$D$2224) -> 2222 | C20: =COUNTA(Pedidos!$D$2:$D$2224) -> 2222
A21: Custo total de frete | B21: =SUM(Pedidos!$S$2:$S$2224) -> 269491.88 | C21: =SUM(Pedidos!$AB$2:$AB$2224) -> 386659.64 | D21: =C21/B21-1 -> 0.4347729
A22: Custo médio por pedido | B22: =AVERAGE(Pedidos!$S$2:$S$2224) -> 121.22891 | C22: =AVERAGE(Pedidos!$AB$2:$AB$2224) -> 173.93596 | D22: =C22/B22-1 -> 0.4347729
A23: Frete / NF | B23: =SUM(Pedidos!$S$2:$S$2224)/SUM(Pedidos!$H$2:$H$2224) -> 0.18887878 | C23: =SUM(Pedidos!$AB$2:$AB$2224)/SUM(Pedidos!$H$2:$H$2224) -> 0.27099816 | D23: =C23-B23 -> 0.082119375
A24: % pedidos em que a PROLOG ganharia a cotação | C24: =COUNTIF(Pedidos!$AE$2:$AE$2224,"SIM")/B20 -> 0.0067506751
A25: Prazo médio (dias úteis) | B25: =AVERAGE(Pedidos!$AF$2:$AF$2224) -> 5.2213225 | C25: =AVERAGE(Pedidos!$AG$2:$AG$2224) -> 6.4669366 | D25: =C25-B25 -> 1.245614
A30: DE ONDE VEM A DIFERENÇA — média por pedido (R$)
A31: Componente | B31: OUTRO PARCEIRO | C31: PROLOG | D31: PROLOG − OUTRO PARCEIRO | E31: % da diferença
A32: Frete peso | B32: =AVERAGE(Pedidos!$I$2:$I$2224) -> 66.692083 | C32: =AVERAGE(Pedidos!$T$2:$T$2224) -> 119.69681 | D32: =C32-B32 -> 53.004723 | E32: =D32/$D$43 -> 1.0056478
A33: Ad valorem | B33: =AVERAGE(Pedidos!$J$2:$J$2224) -> 0 | C33: =AVERAGE(Pedidos!$U$2:$U$2224) -> 0.64183448 | D33: =C33-B33 -> 0.64183448 | E33: =D33/$D$43 -> 0.012177394
A34: GRIS | B34: =AVERAGE(Pedidos!$K$2:$K$2224) -> 1.3478524 | C34: =AVERAGE(Pedidos!$V$2:$V$2224) -> 1.283669 | D34: =C34-B34 -> -0.064183448 | E34: =D34/$D$43 -> -0.0012177394
A35: Seguro | B35: =AVERAGE(Pedidos!$L$2:$L$2224) -> 1.3478524 | C35: 0 | D35: =C35-B35 -> -1.3478524 | E35: =D35/$D$43 -> -0.025572528
A36: TAS / entrega | B36: =AVERAGE(Pedidos!$N$2:$N$2224) -> 0 | C36: =AVERAGE(Pedidos!$W$2:$W$2224) -> 1 | D36: =C36-B36 -> 1 | E36: =D36/$D$43 -> 0.018972795
A37: Pedágio | B37: =AVERAGE(Pedidos!$M$2:$M$2224) -> 1.1203779 | C37: =AVERAGE(Pedidos!$X$2:$X$2224) -> 4.8016194 | D37: =C37-B37 -> 3.6812416 | E37: =D37/$D$43 -> 0.069843443
A38: CTe (OUTRO PARCEIRO fixo R$ 13,55 / PROLOG R$ 0,06 por kg) | B38: =AVERAGE(Pedidos!$O$2:$O$2224) -> 13.55 | C38: =AVERAGE(Pedidos!$Y$2:$Y$2224) -> 3.0164372 | D38: =C38-B38 -> -10.533563 | E38: =D38/$D$43 -> -0.19985113
A39: Taxa interna R$ 0,45/kg | B39: =AVERAGE(Pedidos!$P$2:$P$2224) -> 22.623279 | C39: =AVERAGE(Pedidos!$Z$2:$Z$2224) -> 22.623279 | D39: =C39-B39 -> 0 | E39: =D39/$D$43 -> 0
A40: TRT | B40: =AVERAGE(Pedidos!$Q$2:$Q$2224) -> 0 | C40: 0 | D40: =C40-B40 -> 0 | E40: =D40/$D$43 -> 0
A41: ICMS 12% por fora | B41: =AVERAGE(Pedidos!$S$2:$S$2224)-AVERAGE(Pedidos!$R$2:$R$2224) -> 14.54747 | C41: =AVERAGE(Pedidos!$AB$2:$AB$2224)-AVERAGE(Pedidos!$AA$2:$AA$2224) -> 20.872315 | D41: =C41-B41 -> 6.3248456 | E41: =D41/$D$43 -> 0.12
A43: TOTAL | B43: =SUM(B32:B41) -> 121.22891 | C43: =SUM(C32:C41) -> 173.93596 | D43: =C43-B43 -> 52.707046 | E43: =D43/$D$43 -> 1

Sheet Comparativo Tabelas
A1: Estrutura das tabelas — principais diferenças (OUTRO PARCEIRO = tabela atualizada 17/07/2026)
A3: Item | B3: PROLOG FILIAL SP | C3: OUTRO PARCEIRO | D3: Quem leva vantagem | E3: Comentário / oportunidade
A4: Regionalização do RJ | B4: 93 faixas de CEP, 9 níveis de preço | C4: 93 faixas de CEP, 3 níveis: Capital, Metropolitana (10 faixas), Interior (82) | D4: — | E4: OUTRO PARCEIRO tem preço único por região; a PROLOG pode ser agressiva onde tem operação própria
A5: Frete peso — Capital até 20 kg | B5: R$ 46,98 | C5: R$ 33,42 | D5: OUTRO PARCEIRO | E5: +41%
A6: Frete peso — Capital 20 a 35 kg | B6: R$ 82,21 | C6: R$ 42,11 | D6: OUTRO PARCEIRO | E6: +95% — maior gap de valor (faixa mais vendida da capital)
A7: Frete peso — Capital 40 a 50 kg | B7: R$ 93,97 | C7: R$ 53,55 | D7: OUTRO PARCEIRO | E7: +75%
A8: Frete peso — Capital 50 a 60 kg | B8: R$ 112,30 | C8: R$ 58,60 | D8: OUTRO PARCEIRO | E8: +92%
A9: Frete peso — Capital 60 a 70 kg | B9: R$ 131,02 | C9: R$ 63,21 | D9: OUTRO PARCEIRO | E9: +107%
A10: Taxa fixa por pedido | B10: TAS R$ 1,00 | C10: CTe fixo R$ 13,55 | D10: PROLOG | E10: R$ 12,55 a menos por pedido — é a única vantagem relevante da PROLOG em taxas
A11: CTe por kg | B11: R$ 0,06 / kg | C11: não cobra | D11: OUTRO PARCEIRO | E11: ≈ R$ 3,00 por pedido; trocar por fixo ou zerar
A12: Taxa interna do embarcador | B12: R$ 0,45 / kg | C12: R$ 0,45 / kg | D12: Empate | E12: Igual para todos os parceiros, não negociável
A13: Ad valorem / Seguro | B13: 0,10% NF (ad valorem) | C13: 0,21% NF (seguro) | D13: PROLOG | E13: ≈ R$ 0,70 a favor
A14: GRIS | B14: 0,20% NF | C14: 0,21% NF | D14: PROLOG | E14: Pequeno
A15: TRT | B15: não cobra | C15: não cobra | D15: Empate
A16: Pedágio | B16: R$ 4,50 / 100 kg | C16: R$ 1,05 / 100 kg | D16: OUTRO PARCEIRO | E16: R$ 3,45 a mais por pedido — fácil de negociar
A17: Cubagem | B17: não aplica (0) | C17: 300 kg/m³ | D17: PROLOG | E17: Vantagem para volumosos (não medida: base sem dimensões)
A18: Excedente acima de 250 kg | B18: R$ 7,71 a 12,05 / kg | C18: R$ 0,96 a 1,34 / kg | D18: OUTRO PARCEIRO | E18: Sem pedidos acima de 250 kg; ainda assim fora de mercado
A19: Prazo — Capital e Metropolitana | B19: 5 a 7 dias úteis | C19: 2 dias úteis | D19: OUTRO PARCEIRO | E19: O OUTRO PARCEIRO oferece 2 du: a PROLOG perdeu a vantagem de prazo nas regiões de maior volume
A20: Prazo — Interior | B20: 6 a 11 dias úteis | C20: 13 dias úteis | D20: PROLOG | E20: 2 a 7 dias mais rápido

Sheet Top 20 Cidades
A1: Top 20 cidades RJ — preço final (com taxas e ICMS) PROLOG x OUTRO PARCEIRO nos mesmos pedidos
A3: # | B3: Cidade | C3: Região OUTRO PARCEIRO | D3: Pedidos | E3: % pedidos RJ | F3: Peso médio (kg) | G3: NF média | H3: OUTRO PARCEIRO médio | I3: PROLOG médio | J3: PROLOG vs OUTRO PARCEIRO | K3: Frete/NF OUTRO PARCEIRO | L3: Frete/NF PROLOG | M3: % pedidos PROLOG ganharia | N3: Frete peso PROLOG vs OUTRO PARCEIRO | O3: Prazo OUTRO PARCEIRO | P3: Prazo PROLOG | Q3: Redução necessária no preço PROLOG p/ empatar | R3: Avaliação
A4: 1 | B4: Rio de Janeiro | C4: =INDEX(Pedidos!$E$2:$E$2224,MATCH($B4,Pedidos!$D$2:$D$2224,0)) -> Capital | D4: =COUNTIFS(Pedidos!$D$2:$D$2224,$B4) -> 1030 | E4: =D4/Resumo!$B$20 -> 0.46354635 | F4: =AVERAGEIFS(Pedidos!$G$2:$G$2224,Pedidos!$D$2:$D$2224,$B4) -> 47.579631 | G4: =AVERAGEIFS(Pedidos!$H$2:$H$2224,Pedidos!$D$2:$D$2224,$B4) -> 617.43493 | H4: =AVERAGEIFS(Pedidos!$S$2:$S$2224,Pedidos!$D$2:$D$2224,$B4) -> 106.44612 | I4: =AVERAGEIFS(Pedidos!$AB$2:$AB$2224,Pedidos!$D$2:$D$2224,$B4) -> 156.29299 | J4: =I4/H4-1 -> 0.46828261 | K4: =SUMIFS(Pedidos!$S$2:$S$2224,Pedidos!$D$2:$D$2224,$B4)/SUMIFS(Pedidos!$H$2:$H$2224,Pedidos!$D$2:$D$2224,$B4) -> 0.17240055 | L4: =SUMIFS(Pedidos!$AB$2:$AB$2224,Pedidos!$D$2:$D$2224,$B4)/SUMIFS(Pedidos!$H$2:$H$2224,Pedidos!$D$2:$D$2224,$B4) -> 0.25313273 | M4: =COUNTIFS(Pedidos!$D$2:$D$2224,$B4,Pedidos!$AE$2:$AE$2224,"SIM")/D4 -> 0 | N4: =SUMIFS(Pedidos!$T$2:$T$2224,Pedidos!$D$2:$D$2224,$B4)/SUMIFS(Pedidos!$I$2:$I$2224,Pedidos!$D$2:$D$2224,$B4)-1 -> 0.923291 | O4: =AVERAGEIFS(Pedidos!$AF$2:$AF$2224,Pedidos!$D$2:$D$2224,$B4) -> 2 | P4: =AVERAGEIFS(Pedidos!$AG$2:$AG$2224,Pedidos!$D$2:$D$2224,$B4) -> 5 | Q4: =MAX(0,1-H4/I4) -> 0.31893221 | R4: =IF(J4<=0,"Muito bem",IF(J4<=0.32,"Melhor posição",IF(J4<=0.45,"Intermediária","Precisa melhorar"))) -> Precisa melhorar
A5: 2 | B5: São Gonçalo | C5: =INDEX(Pedidos!$E$2:$E$2224,MATCH($B5,Pedidos!$D$2:$D$2224,0)) -> Metropolitana | D5: =COUNTIFS(Pedidos!$D$2:$D$2224,$B5) -> 135 | E5: =D5/Resumo!$B$20 -> 0.060756076 | F5: =AVERAGEIFS(Pedidos!$G$2:$G$2224,Pedidos!$D$2:$D$2224,$B5) -> 50.268593 | G5: =AVERAGEIFS(Pedidos!$H$2:$H$2224,Pedidos!$D$2:$D$2224,$B5) -> 636.66911 | H5: =AVERAGEIFS(Pedidos!$S$2:$S$2224,Pedidos!$D$2:$D$2224,$B5) -> 124.74227 | I5: =AVERAGEIFS(Pedidos!$AB$2:$AB$2224,Pedidos!$D$2:$D$2224,$B5) -> 180.34462 | J5: =I5/H5-1 -> 0.44573788 | K5: =SUMIFS(Pedidos!$S$2:$S$2224,Pedidos!$D$2:$D$2224,$B5)/SUMIFS(Pedidos!$H$2:$H$2224,Pedidos!$D$2:$D$2224,$B5) -> 0.19592951 | L5: =SUMIFS(Pedidos!$AB$2:$AB$2224,Pedidos!$D$2:$D$2224,$B5)/SUMIFS(Pedidos!$H$2:$H$2224,Pedidos!$D$2:$D$2224,$B5) -> 0.28326272 | M5: =COUNTIFS(Pedidos!$D$2:$D$2224,$B5,Pedidos!$AE$2:$AE$2224,"SIM")/D5 -> 0 | N5: =SUMIFS(Pedidos!$T$2:$T$2224,Pedidos!$D$2:$D$2224,$B5)/SUMIFS(Pedidos!$I$2:$I$2224,Pedidos!$D$2:$D$2224,$B5)-1 -> 0.79754425 | O5: =AVERAGEIFS(Pedidos!$AF$2:$AF$2224,Pedidos!$D$2:$D$2224,$B5) -> 2 | P5: =AVERAGEIFS(Pedidos!$AG$2:$AG$2224,Pedidos!$D$2:$D$2224,$B5) -> 7 | Q5: =MAX(0,1-H5/I5) -> 0.30831168 | R5: =IF(J5<=0,"Muito bem",IF(J5<=0.32,"Melhor posição",IF(J5<=0.45,"Intermediária","Precisa melhorar"))) -> Intermediária
A6: 3 | B6: Duque de Caxias | C6: =INDEX(Pedidos!$E$2:$E$2224,MATCH($B6,Pedidos!$D$2:$D$2224,0)) -> Metropolitana | D6: =COUNTIFS(Pedidos!$D$2:$D$2224,$B6) -> 106 | E6: =D6/Resumo!$B$20 -> 0.04770477 | F6: =AVERAGEIFS(Pedidos!$G$2:$G$2224,Pedidos!$D$2:$D$2224,$B6) -> 52.422453 | G6: =AVERAGEIFS(Pedidos!$H$2:$H$2224,Pedidos!$D$2:$D$2224,$B6) -> 663.55302 | H6: =AVERAGEIFS(Pedidos!$S$2:$S$2224,Pedidos!$D$2:$D$2224,$B6) -> 127.67403 | I6: =AVERAGEIFS(Pedidos!$AB$2:$AB$2224,Pedidos!$D$2:$D$2224,$B6) -> 166.37382 | J6: =I6/H6-1 -> 0.30311399 | K6: =SUMIFS(Pedidos!$S$2:$S$2224,Pedidos!$D$2:$D$2224,$B6)/SUMIFS(Pedidos!$H$2:$H$2224,Pedidos!$D$2:$D$2224,$B6) -> 0.19240969 | L6: =SUMIFS(Pedidos!$AB$2:$AB$2224,Pedidos!$D$2:$D$2224,$B6)/SUMIFS(Pedidos!$H$2:$H$2224,Pedidos!$D$2:$D$2224,$B6) -> 0.25073176 | M6: =COUNTIFS(Pedidos!$D$2:$D$2224,$B6,Pedidos!$AE$2:$AE$2224,"SIM")/D6 -> 0.056603774 | N6: =SUMIFS(Pedidos!$T$2:$T$2224,Pedidos!$D$2:$D$2224,$B6)/SUMIFS(Pedidos!$I$2:$I$2224,Pedidos!$D$2:$D$2224,$B6)-1 -> 0.56939029 | O6: =AVERAGEIFS(Pedidos!$AF$2:$AF$2224,Pedidos!$D$2:$D$2224,$B6) -> 2 | P6: =AVERAGEIFS(Pedidos!$AG$2:$AG$2224,Pedidos!$D$2:$D$2224,$B6) -> 5 | Q6: =MAX(0,1-H6/I6) -> 0.23260743 | R6: =IF(J6<=0,"Muito bem",IF(J6<=0.32,"Melhor posição",IF(J6<=0.45,"Intermediária","Precisa melhorar"))) -> Melhor posição
A7: 4 | B7: Nova Iguaçu | C7: =INDEX(Pedidos!$E$2:$E$2224,MATCH($B7,Pedidos!$D$2:$D$2224,0)) -> Metropolitana | D7: =COUNTIFS(Pedidos!$D$2:$D$2224,$B7) -> 95 | E7: =D7/Resumo!$B$20 -> 0.042754275 | F7: =AVERAGEIFS(Pedidos!$G$2:$G$2224,Pedidos!$D$2:$D$2224,$B7) -> 55.083474 | G7: =AVERAGEIFS(Pedidos!$H$2:$H$2224,Pedidos!$D$2:$D$2224,$B7) -> 676.70926 | H7: =AVERAGEIFS(Pedidos!$S$2:$S$2224,Pedidos!$D$2:$D$2224,$B7) -> 130.8124 | I7: =AVERAGEIFS(Pedidos!$AB$2:$AB$2224,Pedidos!$D$2:$D$2224,$B7) -> 172.30948 | J7: =I7/H7-1 -> 0.31722581 | K7: =SUMIFS(Pedidos!$S$2:$S$2224,Pedidos!$D$2:$D$2224,$B7)/SUMIFS(Pedidos!$H$2:$H$2224,Pedidos!$D$2:$D$2224,$B7) -> 0.19330666 | L7: =SUMIFS(Pedidos!$AB$2:$AB$2224,Pedidos!$D$2:$D$2224,$B7)/SUMIFS(Pedidos!$H$2:$H$2224,Pedidos!$D$2:$D$2224,$B7) -> 0.25462852 | M7: =COUNTIFS(Pedidos!$D$2:$D$2224,$B7,Pedidos!$AE$2:$AE$2224,"SIM")/D7 -> 0.021052632 | N7: =SUMIFS(Pedidos!$T$2:$T$2224,Pedidos!$D$2:$D$2224,$B7)/SUMIFS(Pedidos!$I$2:$I$2224,Pedidos!$D$2:$D$2224,$B7)-1 -> 0.58921342 | O7: =AVERAGEIFS(Pedidos!$AF$2:$AF$2224,Pedidos!$D$2:$D$2224,$B7) -> 2 | P7: =AVERAGEIFS(Pedidos!$AG$2:$AG$2224,Pedidos!$D$2:$D$2224,$B7) -> 5 | Q7: =MAX(0,1-H7/I7) -> 0.24082872 | R7: =IF(J7<=0,"Muito bem",IF(J7<=0.32,"Melhor posição",IF(J7<=0.45,"Intermediária","Precisa melhorar"))) -> Melhor posição
A8: 5 | B8: Niterói | C8: =INDEX(Pedidos!$E$2:$E$2224,MATCH($B8,Pedidos!$D$2:$D$2224,0)) -> Metropolitana | D8: =COUNTIFS(Pedidos!$D$2:$D$2224,$B8) -> 68 | E8: =D8/Resumo!$B$20 -> 0.03060306 | F8: =AVERAGEIFS(Pedidos!$G$2:$G$2224,Pedidos!$D$2:$D$2224,$B8) -> 47.945882 | G8: =AVERAGEIFS(Pedidos!$H$2:$H$2224,Pedidos!$D$2:$D$2224,$B8) -> 603.64809 | H8: =AVERAGEIFS(Pedidos!$S$2:$S$2224,Pedidos!$D$2:$D$2224,$B8) -> 122.03111 | I8: =AVERAGEIFS(Pedidos!$AB$2:$AB$2224,Pedidos!$D$2:$D$2224,$B8) -> 175.73135 | J8: =I8/H8-1 -> 0.44005367 | K8: =SUMIFS(Pedidos!$S$2:$S$2224,Pedidos!$D$2:$D$2224,$B8)/SUMIFS(Pedidos!$H$2:$H$2224,Pedidos!$D$2:$D$2224,$B8) -> 0.20215605 | L8: =SUMIFS(Pedidos!$AB$2:$AB$2224,Pedidos!$D$2:$D$2224,$B8)/SUMIFS(Pedidos!$H$2:$H$2224,Pedidos!$D$2:$D$2224,$B8) -> 0.29111556 | M8: =COUNTIFS(Pedidos!$D$2:$D$2224,$B8,Pedidos!$AE$2:$AE$2224,"SIM")/D8 -> 0 | N8: =SUMIFS(Pedidos!$T$2:$T$2224,Pedidos!$D$2:$D$2224,$B8)/SUMIFS(Pedidos!$I$2:$I$2224,Pedidos!$D$2:$D$2224,$B8)-1 -> 0.78989311 | O8: =AVERAGEIFS(Pedidos!$AF$2:$AF$2224,Pedidos!$D$2:$D$2224,$B8) -> 2 | P8: =AVERAGEIFS(Pedidos!$AG$2:$AG$2224,Pedidos!$D$2:$D$2224,$B8) -> 7 | Q8: =MAX(0,1-H8/I8) -> 0.30558143 | R8: =IF(J8<=0,"Muito bem",IF(J8<=0.32,"Melhor posição",IF(J8<=0.45,"Intermediária","Precisa melhorar"))) -> Intermediária
A9: 6 | B9: Campos dos Goytacazes | C9: =INDEX(Pedidos!$E$2:$E$2224,MATCH($B9,Pedidos!$D$2:$D$2224,0)) -> Interior | D9: =COUNTIFS(Pedidos!$D$2:$D$2224,$B9) -> 53 | E9: =D9/Resumo!$B$20 -> 0.023852385 | F9: =AVERAGEIFS(Pedidos!$G$2:$G$2224,Pedidos!$D$2:$D$2224,$B9) -> 49.475283 | G9: =AVERAGEIFS(Pedidos!$H$2:$H$2224,Pedidos!$D$2:$D$2224,$B9) -> 649.88434 | H9: =AVERAGEIFS(Pedidos!$S$2:$S$2224,Pedidos!$D$2:$D$2224,$B9) -> 136.62809 | I9: =AVERAGEIFS(Pedidos!$AB$2:$AB$2224,Pedidos!$D$2:$D$2224,$B9) -> 218.07379 | J9: =I9/H9-1 -> 0.59611238 | K9: =SUMIFS(Pedidos!$S$2:$S$2224,Pedidos!$D$2:$D$2224,$B9)/SUMIFS(Pedidos!$H$2:$H$2224,Pedidos!$D$2:$D$2224,$B9) -> 0.21023447 | L9: =SUMIFS(Pedidos!$AB$2:$AB$2224,Pedidos!$D$2:$D$2224,$B9)/SUMIFS(Pedidos!$H$2:$H$2224,Pedidos!$D$2:$D$2224,$B9) -> 0.33555785 | M9: =COUNTIFS(Pedidos!$D$2:$D$2224,$B9,Pedidos!$AE$2:$AE$2224,"SIM")/D9 -> 0 | N9: =SUMIFS(Pedidos!$T$2:$T$2224,Pedidos!$D$2:$D$2224,$B9)/SUMIFS(Pedidos!$I$2:$I$2224,Pedidos!$D$2:$D$2224,$B9)-1 -> 0.973722 | O9: =AVERAGEIFS(Pedidos!$AF$2:$AF$2224,Pedidos!$D$2:$D$2224,$B9) -> 13 | P9: =AVERAGEIFS(Pedidos!$AG$2:$AG$2224,Pedidos!$D$2:$D$2224,$B9) -> 11 | Q9: =MAX(0,1-H9/I9) -> 0.3734777 | R9: =IF(J9<=0,"Muito bem",IF(J9<=0.32,"Melhor posição",IF(J9<=0.45,"Intermediária","Precisa melhorar"))) -> Precisa melhorar
A10: 7 | B10: Belford Roxo | C10: =INDEX(Pedidos!$E$2:$E$2224,MATCH($B10,Pedidos!$D$2:$D$2224,0)) -> Metropolitana | D10: =COUNTIFS(Pedidos!$D$2:$D$2224,$B10) -> 49 | E10: =D10/Resumo!$B$20 -> 0.022052205 | F10: =AVERAGEIFS(Pedidos!$G$2:$G$2224,Pedidos!$D$2:$D$2224,$B10) -> 54.08 | G10: =AVERAGEIFS(Pedidos!$H$2:$H$2224,Pedidos!$D$2:$D$2224,$B10) -> 687.52816 | H10: =AVERAGEIFS(Pedidos!$S$2:$S$2224,Pedidos!$D$2:$D$2224,$B10) -> 128.46784 | I10: =AVERAGEIFS(Pedidos!$AB$2:$AB$2224,Pedidos!$D$2:$D$2224,$B10) -> 166.98856 | J10: =I10/H10-1 -> 0.29984716 | K10: =SUMIFS(Pedidos!$S$2:$S$2224,Pedidos!$D$2:$D$2224,$B10)/SUMIFS(Pedidos!$H$2:$H$2224,Pedidos!$D$2:$D$2224,$B10) -> 0.18685466 | L10: =SUMIFS(Pedidos!$AB$2:$AB$2224,Pedidos!$D$2:$D$2224,$B10)/SUMIFS(Pedidos!$H$2:$H$2224,Pedidos!$D$2:$D$2224,$B10) -> 0.2428825 | M10: =COUNTIFS(Pedidos!$D$2:$D$2224,$B10,Pedidos!$AE$2:$AE$2224,"SIM")/D10 -> 0.081632653 | N10: =SUMIFS(Pedidos!$T$2:$T$2224,Pedidos!$D$2:$D$2224,$B10)/SUMIFS(Pedidos!$I$2:$I$2224,Pedidos!$D$2:$D$2224,$B10)-1 -> 0.56848399 | O10: =AVERAGEIFS(Pedidos!$AF$2:$AF$2224,Pedidos!$D$2:$D$2224,$B10) -> 2 | P10: =AVERAGEIFS(Pedidos!$AG$2:$AG$2224,Pedidos!$D$2:$D$2224,$B10) -> 5 | Q10: =MAX(0,1-H10/I10) -> 0.23067878 | R10: =IF(J10<=0,"Muito bem",IF(J10<=0.32,"Melhor posição",IF(J10<=0.45,"Intermediária","Precisa melhorar"))) -> Melhor posição
A11: 8 | B11: Macaé | C11: =INDEX(Pedidos!$E$2:$E$2224,MATCH($B11,Pedidos!$D$2:$D$2224,0)) -> Interior | D11: =COUNTIFS(Pedidos!$D$2:$D$2224,$B11) -> 45 | E11: =D11/Resumo!$B$20 -> 0.020252025 | F11: =AVERAGEIFS(Pedidos!$G$2:$G$2224,Pedidos!$D$2:$D$2224,$B11) -> 60.060222 | G11: =AVERAGEIFS(Pedidos!$H$2:$H$2224,Pedidos!$D$2:$D$2224,$B11) -> 746.16467 | H11: =AVERAGEIFS(Pedidos!$S$2:$S$2224,Pedidos!$D$2:$D$2224,$B11) -> 149.95366 | I11: =AVERAGEIFS(Pedidos!$AB$2:$AB$2224,Pedidos!$D$2:$D$2224,$B11) -> 241.39778 | J11: =I11/H11-1 -> 0.60981583 | K11: =SUMIFS(Pedidos!$S$2:$S$2224,Pedidos!$D$2:$D$2224,$B11)/SUMIFS(Pedidos!$H$2:$H$2224,Pedidos!$D$2:$D$2224,$B11) -> 0.20096591 | L11: =SUMIFS(Pedidos!$AB$2:$AB$2224,Pedidos!$D$2:$D$2224,$B11)/SUMIFS(Pedidos!$H$2:$H$2224,Pedidos!$D$2:$D$2224,$B11) -> 0.32351811 | M11: =COUNTIFS(Pedidos!$D$2:$D$2224,$B11,Pedidos!$AE$2:$AE$2224,"SIM")/D11 -> 0 | N11: =SUMIFS(Pedidos!$T$2:$T$2224,Pedidos!$D$2:$D$2224,$B11)/SUMIFS(Pedidos!$I$2:$I$2224,Pedidos!$D$2:$D$2224,$B11)-1 -> 0.99407972 | O11: =AVERAGEIFS(Pedidos!$AF$2:$AF$2224,Pedidos!$D$2:$D$2224,$B11) -> 13 | P11: =AVERAGEIFS(Pedidos!$AG$2:$AG$2224,Pedidos!$D$2:$D$2224,$B11) -> 11 | Q11: =MAX(0,1-H11/I11) -> 0.37881093 | R11: =IF(J11<=0,"Muito bem",IF(J11<=0.32,"Melhor posição",IF(J11<=0.45,"Intermediária","Precisa melhorar"))) -> Precisa melhorar
A12: 9 | B12: São João de Meriti | C12: =INDEX(Pedidos!$E$2:$E$2224,MATCH($B12,Pedidos!$D$2:$D$2224,0)) -> Metropolitana | D12: =COUNTIFS(Pedidos!$D$2:$D$2224,$B12) -> 37 | E12: =D12/Resumo!$B$20 -> 0.016651665 | F12: =AVERAGEIFS(Pedidos!$G$2:$G$2224,Pedidos!$D$2:$D$2224,$B12) -> 55.930541 | G12: =AVERAGEIFS(Pedidos!$H$2:$H$2224,Pedidos!$D$2:$D$2224,$B12) -> 698.24405 | H12: =AVERAGEIFS(Pedidos!$S$2:$S$2224,Pedidos!$D$2:$D$2224,$B12) -> 132.91637 | I12: =AVERAGEIFS(Pedidos!$AB$2:$AB$2224,Pedidos!$D$2:$D$2224,$B12) -> 175.04377 | J12: =I12/H12-1 -> 0.31694661 | K12: =SUMIFS(Pedidos!$S$2:$S$2224,Pedidos!$D$2:$D$2224,$B12)/SUMIFS(Pedidos!$H$2:$H$2224,Pedidos!$D$2:$D$2224,$B12) -> 0.19035805 | L12: =SUMIFS(Pedidos!$AB$2:$AB$2224,Pedidos!$D$2:$D$2224,$B12)/SUMIFS(Pedidos!$H$2:$H$2224,Pedidos!$D$2:$D$2224,$B12) -> 0.25069138 | M12: =COUNTIFS(Pedidos!$D$2:$D$2224,$B12,Pedidos!$AE$2:$AE$2224,"SIM")/D12 -> 0.027027027 | N12: =SUMIFS(Pedidos!$T$2:$T$2224,Pedidos!$D$2:$D$2224,$B12)/SUMIFS(Pedidos!$I$2:$I$2224,Pedidos!$D$2:$D$2224,$B12)-1 -> 0.58454207 | O12: =AVERAGEIFS(Pedidos!$AF$2:$AF$2224,Pedidos!$D$2:$D$2224,$B12) -> 2 | P12: =AVERAGEIFS(Pedidos!$AG$2:$AG$2224,Pedidos!$D$2:$D$2224,$B12) -> 5 | Q12: =MAX(0,1-H12/I12) -> 0.24066778 | R12: =IF(J12<=0,"Muito bem",IF(J12<=0.32,"Melhor posição",IF(J12<=0.45,"Intermediária","Precisa melhorar"))) -> Melhor posição
A13: 10 | B13: Volta Redonda | C13: =INDEX(Pedidos!$E$2:$E$2224,MATCH($B13,Pedidos!$D$2:$D$2224,0)) -> Interior | D13: =COUNTIFS(Pedidos!$D$2:$D$2224,$B13) -> 37 | E13: =D13/Resumo!$B$20 -> 0.016651665 | F13: =AVERAGEIFS(Pedidos!$G$2:$G$2224,Pedidos!$D$2:$D$2224,$B13) -> 50.886757 | G13: =AVERAGEIFS(Pedidos!$H$2:$H$2224,Pedidos!$D$2:$D$2224,$B13) -> 652.92108 | H13: =AVERAGEIFS(Pedidos!$S$2:$S$2224,Pedidos!$D$2:$D$2224,$B13) -> 139.16228 | I13: =AVERAGEIFS(Pedidos!$AB$2:$AB$2224,Pedidos!$D$2:$D$2224,$B13) -> 198.53821 | J13: =I13/H13-1 -> 0.42666683 | K13: =SUMIFS(Pedidos!$S$2:$S$2224,Pedidos!$D$2:$D$2224,$B13)/SUMIFS(Pedidos!$H$2:$H$2224,Pedidos!$D$2:$D$2224,$B13) -> 0.21313798 | L13: =SUMIFS(Pedidos!$AB$2:$AB$2224,Pedidos!$D$2:$D$2224,$B13)/SUMIFS(Pedidos!$H$2:$H$2224,Pedidos!$D$2:$D$2224,$B13) -> 0.30407689 | M13: =COUNTIFS(Pedidos!$D$2:$D$2224,$B13,Pedidos!$AE$2:$AE$2224,"SIM")/D13 -> 0 | N13: =SUMIFS(Pedidos!$T$2:$T$2224,Pedidos!$D$2:$D$2224,$B13)/SUMIFS(Pedidos!$I$2:$I$2224,Pedidos!$D$2:$D$2224,$B13)-1 -> 0.71827553 | O13: =AVERAGEIFS(Pedidos!$AF$2:$AF$2224,Pedidos!$D$2:$D$2224,$B13) -> 13 | P13: =AVERAGEIFS(Pedidos!$AG$2:$AG$2224,Pedidos!$D$2:$D$2224,$B13) -> 10 | Q13: =MAX(0,1-H13/I13) -> 0.2990655 | R13: =IF(J13<=0,"Muito bem",IF(J13<=0.32,"Melhor posição",IF(J13<=0.45,"Intermediária","Precisa melhorar"))) -> Intermediária
A14: 11 | B14: Angra dos Reis | C14: =INDEX(Pedidos!$E$2:$E$2224,MATCH($B14,Pedidos!$D$2:$D$2224,0)) -> Interior | D14: =COUNTIFS(Pedidos!$D$2:$D$2224,$B14) -> 35 | E14: =D14/Resumo!$B$20 -> 0.015751575 | F14: =AVERAGEIFS(Pedidos!$G$2:$G$2224,Pedidos!$D$2:$D$2224,$B14) -> 44.394286 | G14: =AVERAGEIFS(Pedidos!$H$2:$H$2224,Pedidos!$D$2:$D$2224,$B14) -> 596.41771 | H14: =AVERAGEIFS(Pedidos!$S$2:$S$2224,Pedidos!$D$2:$D$2224,$B14) -> 129.0381 | I14: =AVERAGEIFS(Pedidos!$AB$2:$AB$2224,Pedidos!$D$2:$D$2224,$B14) -> 179.38259 | J14: =I14/H14-1 -> 0.39015218 | K14: =SUMIFS(Pedidos!$S$2:$S$2224,Pedidos!$D$2:$D$2224,$B14)/SUMIFS(Pedidos!$H$2:$H$2224,Pedidos!$D$2:$D$2224,$B14) -> 0.21635524 | L14: =SUMIFS(Pedidos!$AB$2:$AB$2224,Pedidos!$D$2:$D$2224,$B14)/SUMIFS(Pedidos!$H$2:$H$2224,Pedidos!$D$2:$D$2224,$B14) -> 0.30076671 | M14: =COUNTIFS(Pedidos!$D$2:$D$2224,$B14,Pedidos!$AE$2:$AE$2224,"SIM")/D14 -> 0 | N14: =SUMIFS(Pedidos!$T$2:$T$2224,Pedidos!$D$2:$D$2224,$B14)/SUMIFS(Pedidos!$I$2:$I$2224,Pedidos!$D$2:$D$2224,$B14)-1 -> 0.67416202 | O14: =AVERAGEIFS(Pedidos!$AF$2:$AF$2224,Pedidos!$D$2:$D$2224,$B14) -> 13 | P14: =AVERAGEIFS(Pedidos!$AG$2:$AG$2224,Pedidos!$D$2:$D$2224,$B14) -> 10 | Q14: =MAX(0,1-H14/I14) -> 0.2806543 | R14: =IF(J14<=0,"Muito bem",IF(J14<=0.32,"Melhor posição",IF(J14<=0.45,"Intermediária","Precisa melhorar"))) -> Intermediária
A15: 12 | B15: Petrópolis | C15: =INDEX(Pedidos!$E$2:$E$2224,MATCH($B15,Pedidos!$D$2:$D$2224,0)) -> Interior | D15: =COUNTIFS(Pedidos!$D$2:$D$2224,$B15) -> 32 | E15: =D15/Resumo!$B$20 -> 0.01440144 | F15: =AVERAGEIFS(Pedidos!$G$2:$G$2224,Pedidos!$D$2:$D$2224,$B15) -> 58.889375 | G15: =AVERAGEIFS(Pedidos!$H$2:$H$2224,Pedidos!$D$2:$D$2224,$B15) -> 743.8225 | H15: =AVERAGEIFS(Pedidos!$S$2:$S$2224,Pedidos!$D$2:$D$2224,$B15) -> 149.95063 | I15: =AVERAGEIFS(Pedidos!$AB$2:$AB$2224,Pedidos!$D$2:$D$2224,$B15) -> 216.62809 | J15: =I15/H15-1 -> 0.44466274 | K15: =SUMIFS(Pedidos!$S$2:$S$2224,Pedidos!$D$2:$D$2224,$B15)/SUMIFS(Pedidos!$H$2:$H$2224,Pedidos!$D$2:$D$2224,$B15) -> 0.20159464 | L15: =SUMIFS(Pedidos!$AB$2:$AB$2224,Pedidos!$D$2:$D$2224,$B15)/SUMIFS(Pedidos!$H$2:$H$2224,Pedidos!$D$2:$D$2224,$B15) -> 0.29123627 | M15: =COUNTIFS(Pedidos!$D$2:$D$2224,$B15,Pedidos!$AE$2:$AE$2224,"SIM")/D15 -> 0 | N15: =SUMIFS(Pedidos!$T$2:$T$2224,Pedidos!$D$2:$D$2224,$B15)/SUMIFS(Pedidos!$I$2:$I$2224,Pedidos!$D$2:$D$2224,$B15)-1 -> 0.73994151 | O15: =AVERAGEIFS(Pedidos!$AF$2:$AF$2224,Pedidos!$D$2:$D$2224,$B15) -> 13 | P15: =AVERAGEIFS(Pedidos!$AG$2:$AG$2224,Pedidos!$D$2:$D$2224,$B15) -> 8 | Q15: =MAX(0,1-H15/I15) -> 0.30779692 | R15: =IF(J15<=0,"Muito bem",IF(J15<=0.32,"Melhor posição",IF(J15<=0.45,"Intermediária","Precisa melhorar"))) -> Intermediária
... A23: 20 | B23: Rio das Ostras | C23: =INDEX(Pedidos!$E$2:$E$2224,MATCH($B23,Pedidos!$D$2:$D$2224,0)) -> Interior | D23: =COUNTIFS(Pedidos!$D$2:$D$2224,$B23) -> 18 | E23: =D23/Resumo!$B$20 -> 0.0081008101 | F23: =AVERAGEIFS(Pedidos!$G$2:$G$2224,Pedidos!$D$2:$D$2224,$B23) -> 47.438889 | G23: =AVERAGEIFS(Pedidos!$H$2:$H$2224,Pedidos!$D$2:$D$2224,$B23) -> 604.15056 | H23: =AVERAGEIFS(Pedidos!$S$2:$S$2224,Pedidos!$D$2:$D$2224,$B23) -> 132.72499 | I23: =AVERAGEIFS(Pedidos!$AB$2:$AB$2224,Pedidos!$D$2:$D$2224,$B23) -> 190.52993 | J23: =I23/H23-1 -> 0.43552422 | K23: =SUMIFS(Pedidos!$S$2:$S$2224,Pedidos!$D$2:$D$2224,$B23)/SUMIFS(Pedidos!$H$2:$H$2224,Pedidos!$D$2:$D$2224,$B23) -> 0.21968859 | L23: =SUMIFS(Pedidos!$AB$2:$AB$2224,Pedidos!$D$2:$D$2224,$B23)/SUMIFS(Pedidos!$H$2:$H$2224,Pedidos!$D$2:$D$2224,$B23) -> 0.3153683 | M23: =COUNTIFS(Pedidos!$D$2:$D$2224,$B23,Pedidos!$AE$2:$AE$2224,"SIM")/D23 -> 0 | N23: =SUMIFS(Pedidos!$T$2:$T$2224,Pedidos!$D$2:$D$2224,$B23)/SUMIFS(Pedidos!$I$2:$I$2224,Pedidos!$D$2:$D$2224,$B23)-1 -> 0.73945688 | O23: =AVERAGEIFS(Pedidos!$AF$2:$AF$2224,Pedidos!$D$2:$D$2224,$B23) -> 13 | P23: =AVERAGEIFS(Pedidos!$AG$2:$AG$2224,Pedidos!$D$2:$D$2224,$B23) -> 10 | Q23: =MAX(0,1-H23/I23) -> 0.30339037 | R23: =IF(J23<=0,"Muito bem",IF(J23<=0.32,"Melhor posição",IF(J23<=0.45,"Intermediária","Precisa melhorar"))) -> Intermediária
B24: TOTAL TOP 20 | D24: =SUM(D4:D23) -> 1912 | E24: =D24/Resumo!$B$20 -> 0.86048605 | F24: =AVERAGEIFS(Pedidos!$G$2:$G$2224,Pedidos!$AH$2:$AH$2224,"SIM") -> 49.45444 | G24: =AVERAGEIFS(Pedidos!$H$2:$H$2224,Pedidos!$AH$2:$AH$2224,"SIM") -> 636.04536 | H24: =AVERAGEIFS(Pedidos!$S$2:$S$2224,Pedidos!$AH$2:$AH$2224,"SIM") -> 118.21998 | I24: =AVERAGEIFS(Pedidos!$AB$2:$AB$2224,Pedidos!$AH$2:$AH$2224,"SIM") -> 169.56633 | J24: =I24/H24-1 -> 0.43432883 | K24: =SUMIFS(Pedidos!$S$2:$S$2224,Pedidos!$AH$2:$AH$2224,"SIM")/SUMIFS(Pedidos!$H$2:$H$2224,Pedidos!$AH$2:$AH$2224,"SIM") -> 0.18586721 | L24: =SUMIFS(Pedidos!$AB$2:$AB$2224,Pedidos!$AH$2:$AH$2224,"SIM")/SUMIFS(Pedidos!$H$2:$H$2224,Pedidos!$AH$2:$AH$2224,"SIM") -> 0.2665947 | M24: =COUNTIFS(Pedidos!$AH$2:$AH$2224,"SIM",Pedidos!$AE$2:$AE$2224,"SIM")/D24 -> 0.0073221757 | N24: =SUMIFS(Pedidos!$T$2:$T$2224,Pedidos!$AH$2:$AH$2224,"SIM")/SUMIFS(Pedidos!$I$2:$I$2224,Pedidos!$AH$2:$AH$2224,"SIM")-1 -> 0.80659243 | O24: =AVERAGEIFS(Pedidos!$AF$2:$AF$2224,Pedidos!$AH$2:$AH$2224,"SIM") -> 4.1344142 | P24: =AVERAGEIFS(Pedidos!$AG$2:$AG$2224,Pedidos!$AH$2:$AH$2224,"SIM") -> 6.0690377 | Q24: =MAX(0,1-H24/I24) -> 0.3028098
A26: Avaliação: "Muito bem" = PROLOG mais barata; "Melhor posição" = até +32%; "Intermediária" = +32% a +45%; "Precisa melhorar" = acima de +45%.

Sheet Frete Peso Top 20
A1: Frete peso por faixa (valor de tabela, antes de taxas e ICMS) — PROLOG x OUTRO PARCEIRO nas top 20 cidades
A4: 1) PROLOG — frete peso (R$)
A5: Cidade | B5: Região OUTRO PARCEIRO | C5: 0-20 | D5: 20-35 | E5: 35-40 | F5: 40-50 | G5: 50-60 | H5: 60-70 | I5: 70-80 | J5: 80-100 | K5: 100-120 | L5: 120-150 | M5: 150-170 | N5: 170-200 | O5: 200-250
A6: Rio de Janeiro | B6: Capital | C6: 46.98 | D6: 82.21 | E6: 93.97 | F6: 93.97 | G6: 112.3 | H6: 131.02 | I6: 134.39 | J6: 167.99 | K6: 201.59 | L6: 239.25 | M6: 271.15 | N6: 319 | O6: 398.74
A7: São Gonçalo | B7: Metropolitana | C7: 57.47 | D7: 100.58 | E7: 114.95 | F7: 114.95 | G7: 128.14 | H7: 149.5 | I7: 142.74 | J7: 178.42 | K7: 214.11 | L7: 249.03 | M7: 282.23 | N7: 332.05 | O7: 415.05
A8: Duque de Caxias | B8: Metropolitana | C8: 46.98 | D8: 82.21 | E8: 93.97 | F8: 93.97 | G8: 112.3 | H8: 131.02 | I8: 134.39 | J8: 167.99 | K8: 201.59 | L8: 239.25 | M8: 271.15 | N8: 319 | O8: 398.74
A9: Nova Iguaçu | B9: Metropolitana | C9: 46.98 | D9: 82.21 | E9: 93.97 | F9: 93.97 | G9: 112.3 | H9: 131.02 | I9: 134.39 | J9: 167.99 | K9: 201.59 | L9: 239.25 | M9: 271.15 | N9: 319 | O9: 398.74
A10: Niterói | B10: Metropolitana | C10: 57.47 | D10: 100.58 | E10: 114.95 | F10: 114.95 | G10: 128.14 | H10: 149.5 | I10: 142.74 | J10: 178.42 | K10: 214.11 | L10: 249.03 | M10: 282.23 | N10: 332.05 | O10: 415.05
A11: Campos dos Goytacazes | B11: Interior | C11: 124.04 | D11: 138.29 | E11: 143.04 | F11: 152.54 | G11: 162.04 | H11: 171.54 | I11: 181.04 | J11: 200.04 | K11: 236.82 | L11: 264.84 | M11: 300.15 | N11: 353.17 | O11: 441.4
A12: Belford Roxo | B12: Metropolitana | C12: 46.98 | D12: 82.21 | E12: 93.97 | F12: 93.97 | G12: 112.3 | H12: 131.02 | I12: 134.39 | J12: 167.99 | K12: 201.59 | L12: 239.25 | M12: 271.15 | N12: 319 | O12: 398.74
A13: Macaé | B13: Interior | C13: 124.04 | D13: 138.29 | E13: 143.04 | F13: 152.54 | G13: 162.04 | H13: 171.54 | I13: 181.04 | J13: 200.04 | K13: 236.82 | L13: 264.84 | M13: 300.15 | N13: 353.17 | O13: 441.4
A14: São João de Meriti | B14: Metropolitana | C14: 46.98 | D14: 82.21 | E14: 93.97 | F14: 93.97 | G14: 112.3 | H14: 131.02 | I14: 134.39 | J14: 167.99 | K14: 201.59 | L14: 239.25 | M14: 271.15 | N14: 319 | O14: 398.74
A15: Volta Redonda | B15: Interior | C15: 77.35 | D15: 108.83 | E15: 124.38 | F15: 124.38 | G15: 142.32 | H15: 166.05 | I15: 157.88 | J15: 197.35 | K15: 236.82 | L15: 264.84 | M15: 300.15 | N15: 353.12 | O15: 441.4
A16: Angra dos Reis | B16: Interior | C16: 77.35 | D16: 108.83 | E16: 124.38 | F16: 124.38 | G16: 142.32 | H16: 166.05 | I16: 157.88 | J16: 197.35 | K16: 236.82 | L16: 264.84 | M16: 300.15 | N16: 353.12 | O16: 441.4
A17: Petrópolis | B17: Interior | C17: 89.03 | D17: 108.83 | E17: 124.38 | F17: 124.38 | G17: 142.32 | H17: 166.05 | I17: 166.05 | J17: 197.35 | K17: 236.82 | L17: 264.84 | M17: 300.15 | N17: 353.12 | O17: 441.4
... A25: Rio das Ostras | B25: Interior | C25: 100.7 | D25: 114.95 | E25: 124.38 | F25: 129.29 | G25: 142.32 | H25: 166.05 | I25: 166.05 | J25: 197.35 | K25: 236.82 | L25: 264.84 | M25: 300.15 | N25: 353.12 | O25: 441.4
A27: 2) OUTRO PARCEIRO — frete peso (R$)
A28: Cidade | B28: Região OUTRO PARCEIRO | C28: 0-20 | D28: 20-35 | E28: 35-40 | F28: 40-50 | G28: 50-60 | H28: 60-70 | I28: 70-80 | J28: 80-100 | K28: 100-120 | L28: 120-150 | M28: 150-170 | N28: 170-200 | O28: 200-250
A29: Rio de Janeiro | B29: Capital | C29: 33.42 | D29: 42.11 | E29: 48.35 | F29: 53.55 | G29: 58.6 | H29: 63.21 | I29: 68.88 | J29: 83.79 | K29: 92.34 | L29: 120.59 | M29: 130.31 | N29: 144.9 | O29: 181.55
A30: São Gonçalo | B30: Metropolitana | C30: 42.72 | D30: 58.8 | E30: 66.83 | F30: 65.36 | G30: 70.98 | H30: 76.55 | I30: 82.48 | J30: 92.32 | K30: 101.26 | L30: 129.62 | M30: 139.81 | N30: 155.09 | O30: 194.34
A31: Duque de Caxias | B31: Metropolitana | C31: 42.72 | D31: 58.8 | E31: 66.83 | F31: 65.36 | G31: 70.98 | H31: 76.55 | I31: 82.48 | J31: 92.32 | K31: 101.26 | L31: 129.62 | M31: 139.81 | N31: 155.09 | O31: 194.34
A32: Nova Iguaçu | B32: Metropolitana | C32: 42.72 | D32: 58.8 | E32: 66.83 | F32: 65.36 | G32: 70.98 | H32: 76.55 | I32: 82.48 | J32: 92.32 | K32: 101.26 | L32: 129.62 | M32: 139.81 | N32: 155.09 | O32: 194.34
A33: Niterói | B33: Metropolitana | C33: 42.72 | D33: 58.8 | E33: 66.83 | F33: 65.36 | G33: 70.98 | H33: 76.55 | I33: 82.48 | J33: 92.32 | K33: 101.26 | L33: 129.62 | M33: 139.81 | N33: 155.09 | O33: 194.34
A34: Campos dos Goytacazes | B34: Interior | C34: 46.95 | D34: 65.63 | E34: 74.97 | F34: 77.7 | G34: 83.58 | H34: 90.2 | I34: 96.77 | J34: 109.63 | K34: 119.5 | L34: 144.24 | M34: 155.09 | N34: 66.69 | O34: 214.88
A35: Belford Roxo | B35: Metropolitana | C35: 42.72 | D35: 58.8 | E35: 66.83 | F35: 65.36 | G35: 70.98 | H35: 76.55 | I35: 82.48 | J35: 92.32 | K35: 101.26 | L35: 129.62 | M35: 139.81 | N35: 155.09 | O35: 194.34
