Workbook

Sheet Resumo
A1: Simulação PROLOG FILIAL SP — Pedidos RJ com origem de cotação FILIAL SP (jul–set/2026)
A3: PREMISSAS
A5: Parâmetro | C5: Valor | D5: Fonte / observação
A6: Alíquota ICMS SP→RJ (gross-up, tabela marcada "ICMS já calculado? = N") | C6: 0.12 | D6: Interestadual SP→RJ 12%. Intelipost soma o ICMS por dentro: total = subtotal / (1 − alíquota).
A7: Ad valorem (% NF) | C7: 0.001 | D7: Da tabela: FRETE VALOR (%) = 0,1
A8: GRIS (% NF) | C8: 0.002 | D8: Da tabela: GRIS (%) = 0,2
A9: TAS (R$ por pedido) | C9: 1 | D9: Da tabela
A10: Pedágio (R$ por fração de 100 kg) | C10: 4.5 | D10: Da tabela: 4,50 / faixa 100 kg
A11: CTe (R$ por kg) | C11: 0.06 | D11: Da tabela: CTE FIXO 0,06 com faixa de 1 kg → cobrado por kg
A12: Outra taxa (R$ por kg) | C12: 0.45 | D12: Da tabela: OUTRA TAXA FIXO 0,45 com faixa de 1 kg → cobrado por kg
A13: Cubagem | C13: Não aplicada | D13: Fator de cubagem = 0 na tabela; usado PESO ITENS
A14: Peso > 250 kg | C14: Faixa 250 + excedente/kg | D14: Nenhum pedido no recorte passa de 250 kg
A16: Obs.: as taxas (exceto ICMS) estão calculadas por pedido na aba Pedidos (colunas K–Q); a célula C6 recalcula o total.
A18: VISÃO GERAL
A19: Indicador | C19: Atual (transportadoras cotadas) | D19: PROLOG FILIAL SP (simulado) | E19: Diferença
A20: Pedidos | C20: =COUNTA(Pedidos!$A$2:$A$2224) -> 2223 | D20: =COUNTA(Pedidos!$A$2:$A$2224) -> 2223
A21: Custo total de frete | C21: =SUM(Pedidos!$J$2:$J$2224) -> 269909.92 | D21: =SUM(Pedidos!$S$2:$S$2224) -> 386659.7 | E21: =D21/C21-1 -> 0.43255089
A22: Custo médio por pedido | C22: =AVERAGE(Pedidos!$J$2:$J$2224) -> 121.41697 | D22: =AVERAGE(Pedidos!$S$2:$S$2224) -> 173.93599 | E22: =D22/C22-1 -> 0.43255089
A23: Valor de NF total | C23: =SUM(Pedidos!$H$2:$H$2224) -> 1426798.1 | D23: =SUM(Pedidos!$H$2:$H$2224) -> 1426798.1
A24: Frete / NF (participação no custo) | C24: =C21/C23 -> 0.18917178 | D24: =D21/D23 -> 0.2709982 | E24: =D24-C24 -> 0.08182642
A25: % de pedidos em que PROLOG seria mais barata | D25: =COUNTIF(Pedidos!$V$2:$V$2224,"SIM")/C20 -> 0.0067476383
A27: DECOMPOSIÇÃO DO PREÇO MÉDIO PROLOG (por pedido)
A28: Componente | C28: R$ médio/pedido | D28: % do total PROLOG
A29: Frete peso | C29: =AVERAGE(Pedidos!$K$2:$K$2224) -> 119.69681 | D29: =C29/$C$37 -> 0.68816585
A30: Ad valorem | C30: =AVERAGE(Pedidos!$L$2:$L$2224) -> 0.64184197 | D30: =C30/$C$37 -> 0.0036901045
A31: GRIS | C31: =AVERAGE(Pedidos!$M$2:$M$2224) -> 1.2836836 | D31: =C31/$C$37 -> 0.007380207
A32: TAS | C32: =AVERAGE(Pedidos!$N$2:$N$2224) -> 1 | D32: =C32/$C$37 -> 0.0057492416
A33: Pedágio | C33: =AVERAGE(Pedidos!$O$2:$O$2224) -> 4.8016194 | D33: =C33/$C$37 -> 0.02760567
A34: CTe (R$/kg) | C34: =AVERAGE(Pedidos!$P$2:$P$2224) -> 3.0164372 | D34: =C34/$C$37 -> 0.017342226
A35: Outra taxa (R$/kg) | C35: =AVERAGE(Pedidos!$Q$2:$Q$2224) -> 22.623279 | D35: =C35/$C$37 -> 0.1300667
A36: ICMS 12% (gross-up) | C36: =AVERAGE(Pedidos!$S$2:$S$2224)-AVERAGE(Pedidos!$R$2:$R$2224) -> 20.872318 | D36: =C36/$C$37 -> 0.12
A37: TOTAL PROLOG | C37: =SUM(C29:C36) -> 173.93599 | D37: =C37/$C$37 -> 1
A38: Custo médio atual (comparação) | C38: =C22 -> 121.41697
A40: SENSIBILIDADE — quanto cada premissa pesa (diferença do custo total PROLOG vs atual)
A41: Cenário | C41: Custo total PROLOG | D41: vs atual | E41: % pedidos PROLOG mais barata
A42: A) Tabela literal (taxas por kg + ICMS 12%) | C42: =SUM(Pedidos!$S$2:$S$2224) -> 386659.7 | D42: =C42/$C$21-1 -> 0.43255089 | E42: =SUMPRODUCT(--(Pedidos!$S$2:$S$2224<Pedidos!$J$2:$J$2224))/C20 -> 0.0067476383
A43: B) Sem ICMS gross-up | C43: =SUM(Pedidos!$R$2:$R$2224) -> 340260.53 | D43: =C43/$C$21-1 -> 0.26064479 | E43: =SUMPRODUCT(--(Pedidos!$R$2:$R$2224<Pedidos!$J$2:$J$2224))/C20 -> 0.048582996
A44: C) Sem as taxas por kg (CTe e outra taxa) + ICMS | C44: =(SUM(Pedidos!$R$2:$R$2224)-SUM(Pedidos!$P$2:$P$2224)-SUM(Pedidos!$Q$2:$Q$2224))/(1-$C$6) -> 321890.28 | D44: =C44/$C$21-1 -> 0.19258409 | E44: =SUMPRODUCT(--((Pedidos!$R$2:$R$2224-Pedidos!$P$2:$P$2224-Pedidos!$Q$2:$Q$2224)/(1-$C$6)<Pedidos!$J$2:$J$2224))/C20 -> 0.093567251
A45: D) Sem taxas por kg e sem ICMS | C45: =SUM(Pedidos!$R$2:$R$2224)-SUM(Pedidos!$P$2:$P$2224)-SUM(Pedidos!$Q$2:$Q$2224) -> 283263.44 | D45: =C45/$C$21-1 -> 0.049474 | E45: =SUMPRODUCT(--((Pedidos!$R$2:$R$2224-Pedidos!$P$2:$P$2224-Pedidos!$Q$2:$Q$2224)<Pedidos!$J$2:$J$2224))/C20 -> 0.28205128
A46: E) Somente frete peso | C46: =SUM(Pedidos!$K$2:$K$2224) -> 266086 | D46: =C46/$C$21-1 -> -0.014167393 | E46: =SUMPRODUCT(--(Pedidos!$K$2:$K$2224<Pedidos!$J$2:$J$2224))/C20 -> 0.5465587

Sheet Top 20 Cidades
A1: Top 20 cidades do RJ (por nº de pedidos) — custo atual x PROLOG FILIAL SP simulado
A3: # | B3: Cidade | C3: Pedidos | D3: % dos pedidos RJ | E3: Peso médio (kg) | F3: NF média (R$) | G3: Custo médio atual (R$) | H3: PROLOG médio (R$) | I3: Diferença média (R$) | J3: PROLOG vs atual (%) | K3: Frete/NF atual | L3: Frete/NF PROLOG | M3: % pedidos PROLOG mais barata | N3: PROLOG só frete peso (R$) | O3: Frete peso vs atual (%) | P3: Desconto necessário p/ empatar | Q3: Prazo PROLOG (du) | R3: Avaliação
A4: 1 | B4: Rio de Janeiro | C4: =COUNTIFS(Pedidos!$E$2:$E$2224,$B4) -> 1030 | D4: =C4/Resumo!$C$20 -> 0.46333783 | E4: =AVERAGEIFS(Pedidos!$G$2:$G$2224,Pedidos!$E$2:$E$2224,$B4) -> 47.579631 | F4: =AVERAGEIFS(Pedidos!$H$2:$H$2224,Pedidos!$E$2:$E$2224,$B4) -> 617.43493 | G4: =AVERAGEIFS(Pedidos!$J$2:$J$2224,Pedidos!$E$2:$E$2224,$B4) -> 106.83918 | H4: =AVERAGEIFS(Pedidos!$S$2:$S$2224,Pedidos!$E$2:$E$2224,$B4) -> 156.29301 | I4: =H4-G4 -> 49.453828 | J4: =H4/G4-1 -> 0.46288099 | K4: =SUMIFS(Pedidos!$J$2:$J$2224,Pedidos!$E$2:$E$2224,$B4)/SUMIFS(Pedidos!$H$2:$H$2224,Pedidos!$E$2:$E$2224,$B4) -> 0.17303716 | L4: =SUMIFS(Pedidos!$S$2:$S$2224,Pedidos!$E$2:$E$2224,$B4)/SUMIFS(Pedidos!$H$2:$H$2224,Pedidos!$E$2:$E$2224,$B4) -> 0.25313277 | M4: =COUNTIFS(Pedidos!$E$2:$E$2224,$B4,Pedidos!$V$2:$V$2224,"SIM")/C4 -> 0 | N4: =AVERAGEIFS(Pedidos!$K$2:$K$2224,Pedidos!$E$2:$E$2224,$B4) -> 105.42938 | O4: =N4/G4-1 -> -0.013195588 | P4: =MAX(0,1-G4/H4) -> 0.31641739 | Q4: =AVERAGEIFS(Pedidos!$W$2:$W$2224,Pedidos!$E$2:$E$2224,$B4) -> 5 | R4: =IF(J4<=0,"Muito bem",IF(J4<=0.32,"Melhor posição relativa",IF(J4<=0.45,"Intermediária","Precisa melhorar"))) -> Precisa melhorar
A5: 2 | B5: São Gonçalo | C5: =COUNTIFS(Pedidos!$E$2:$E$2224,$B5) -> 135 | D5: =C5/Resumo!$C$20 -> 0.060728745 | E5: =AVERAGEIFS(Pedidos!$G$2:$G$2224,Pedidos!$E$2:$E$2224,$B5) -> 50.268593 | F5: =AVERAGEIFS(Pedidos!$H$2:$H$2224,Pedidos!$E$2:$E$2224,$B5) -> 636.66911 | G5: =AVERAGEIFS(Pedidos!$J$2:$J$2224,Pedidos!$E$2:$E$2224,$B5) -> 124.5983 | H5: =AVERAGEIFS(Pedidos!$S$2:$S$2224,Pedidos!$E$2:$E$2224,$B5) -> 180.34465 | I5: =H5-G5 -> 55.746352 | J5: =H5/G5-1 -> 0.44740862 | K5: =SUMIFS(Pedidos!$J$2:$J$2224,Pedidos!$E$2:$E$2224,$B5)/SUMIFS(Pedidos!$H$2:$H$2224,Pedidos!$E$2:$E$2224,$B5) -> 0.19570338 | L5: =SUMIFS(Pedidos!$S$2:$S$2224,Pedidos!$E$2:$E$2224,$B5)/SUMIFS(Pedidos!$H$2:$H$2224,Pedidos!$E$2:$E$2224,$B5) -> 0.28326276 | M5: =COUNTIFS(Pedidos!$E$2:$E$2224,$B5,Pedidos!$V$2:$V$2224,"SIM")/C5 -> 0 | N5: =AVERAGEIFS(Pedidos!$K$2:$K$2224,Pedidos!$E$2:$E$2224,$B5) -> 125.20548 | O5: =N5/G5-1 -> 0.004873142 | P5: =MAX(0,1-G5/H5) -> 0.3091101 | Q5: =AVERAGEIFS(Pedidos!$W$2:$W$2224,Pedidos!$E$2:$E$2224,$B5) -> 7 | R5: =IF(J5<=0,"Muito bem",IF(J5<=0.32,"Melhor posição relativa",IF(J5<=0.45,"Intermediária","Precisa melhorar"))) -> Intermediária
A6: 3 | B6: Duque de Caxias | C6: =COUNTIFS(Pedidos!$E$2:$E$2224,$B6) -> 106 | D6: =C6/Resumo!$C$20 -> 0.047683311 | E6: =AVERAGEIFS(Pedidos!$G$2:$G$2224,Pedidos!$E$2:$E$2224,$B6) -> 52.422453 | F6: =AVERAGEIFS(Pedidos!$H$2:$H$2224,Pedidos!$E$2:$E$2224,$B6) -> 663.55302 | G6: =AVERAGEIFS(Pedidos!$J$2:$J$2224,Pedidos!$E$2:$E$2224,$B6) -> 128.07689 | H6: =AVERAGEIFS(Pedidos!$S$2:$S$2224,Pedidos!$E$2:$E$2224,$B6) -> 166.37385 | I6: =H6-G6 -> 38.296959 | J6: =H6/G6-1 -> 0.29901538 | K6: =SUMIFS(Pedidos!$J$2:$J$2224,Pedidos!$E$2:$E$2224,$B6)/SUMIFS(Pedidos!$H$2:$H$2224,Pedidos!$E$2:$E$2224,$B6) -> 0.19301681 | L6: =SUMIFS(Pedidos!$S$2:$S$2224,Pedidos!$E$2:$E$2224,$B6)/SUMIFS(Pedidos!$H$2:$H$2224,Pedidos!$E$2:$E$2224,$B6) -> 0.2507318 | M6: =COUNTIFS(Pedidos!$E$2:$E$2224,$B6,Pedidos!$V$2:$V$2224,"SIM")/C6 -> 0.056603774 | N6: =AVERAGEIFS(Pedidos!$K$2:$K$2224,Pedidos!$E$2:$E$2224,$B6) -> 111.60245 | O6: =N6/G6-1 -> -0.12862925 | P6: =MAX(0,1-G6/H6) -> 0.23018617 | Q6: =AVERAGEIFS(Pedidos!$W$2:$W$2224,Pedidos!$E$2:$E$2224,$B6) -> 5 | R6: =IF(J6<=0,"Muito bem",IF(J6<=0.32,"Melhor posição relativa",IF(J6<=0.45,"Intermediária","Precisa melhorar"))) -> Melhor posição relativa
A7: 4 | B7: Nova Iguaçu | C7: =COUNTIFS(Pedidos!$E$2:$E$2224,$B7) -> 95 | D7: =C7/Resumo!$C$20 -> 0.042735043 | E7: =AVERAGEIFS(Pedidos!$G$2:$G$2224,Pedidos!$E$2:$E$2224,$B7) -> 55.083474 | F7: =AVERAGEIFS(Pedidos!$H$2:$H$2224,Pedidos!$E$2:$E$2224,$B7) -> 676.70926 | G7: =AVERAGEIFS(Pedidos!$J$2:$J$2224,Pedidos!$E$2:$E$2224,$B7) -> 130.55305 | H7: =AVERAGEIFS(Pedidos!$S$2:$S$2224,Pedidos!$E$2:$E$2224,$B7) -> 172.3095 | I7: =H7-G7 -> 41.756451 | J7: =H7/G7-1 -> 0.31984278 | K7: =SUMIFS(Pedidos!$J$2:$J$2224,Pedidos!$E$2:$E$2224,$B7)/SUMIFS(Pedidos!$H$2:$H$2224,Pedidos!$E$2:$E$2224,$B7) -> 0.1929234 | L7: =SUMIFS(Pedidos!$S$2:$S$2224,Pedidos!$E$2:$E$2224,$B7)/SUMIFS(Pedidos!$H$2:$H$2224,Pedidos!$E$2:$E$2224,$B7) -> 0.25462856 | M7: =COUNTIFS(Pedidos!$E$2:$E$2224,$B7,Pedidos!$V$2:$V$2224,"SIM")/C7 -> 0.021052632 | N7: =AVERAGEIFS(Pedidos!$K$2:$K$2224,Pedidos!$E$2:$E$2224,$B7) -> 115.36284 | O7: =N7/G7-1 -> -0.11635278 | P7: =MAX(0,1-G7/H7) -> 0.242334 | Q7: =AVERAGEIFS(Pedidos!$W$2:$W$2224,Pedidos!$E$2:$E$2224,$B7) -> 5 | R7: =IF(J7<=0,"Muito bem",IF(J7<=0.32,"Melhor posição relativa",IF(J7<=0.45,"Intermediária","Precisa melhorar"))) -> Melhor posição relativa
A8: 5 | B8: Niterói | C8: =COUNTIFS(Pedidos!$E$2:$E$2224,$B8) -> 68 | D8: =C8/Resumo!$C$20 -> 0.030589294 | E8: =AVERAGEIFS(Pedidos!$G$2:$G$2224,Pedidos!$E$2:$E$2224,$B8) -> 47.945882 | F8: =AVERAGEIFS(Pedidos!$H$2:$H$2224,Pedidos!$E$2:$E$2224,$B8) -> 603.64809 | G8: =AVERAGEIFS(Pedidos!$J$2:$J$2224,Pedidos!$E$2:$E$2224,$B8) -> 122.04441 | H8: =AVERAGEIFS(Pedidos!$S$2:$S$2224,Pedidos!$E$2:$E$2224,$B8) -> 175.73137 | I8: =H8-G8 -> 53.686962 | J8: =H8/G8-1 -> 0.43989693 | K8: =SUMIFS(Pedidos!$J$2:$J$2224,Pedidos!$E$2:$E$2224,$B8)/SUMIFS(Pedidos!$H$2:$H$2224,Pedidos!$E$2:$E$2224,$B8) -> 0.20217808 | L8: =SUMIFS(Pedidos!$S$2:$S$2224,Pedidos!$E$2:$E$2224,$B8)/SUMIFS(Pedidos!$H$2:$H$2224,Pedidos!$E$2:$E$2224,$B8) -> 0.2911156 | M8: =COUNTIFS(Pedidos!$E$2:$E$2224,$B8,Pedidos!$V$2:$V$2224,"SIM")/C8 -> 0 | N8: =AVERAGEIFS(Pedidos!$K$2:$K$2224,Pedidos!$E$2:$E$2224,$B8) -> 122.54029 | O8: =N8/G8-1 -> 0.0040631303 | P8: =MAX(0,1-G8/H8) -> 0.30550585 | Q8: =AVERAGEIFS(Pedidos!$W$2:$W$2224,Pedidos!$E$2:$E$2224,$B8) -> 7 | R8: =IF(J8<=0,"Muito bem",IF(J8<=0.32,"Melhor posição relativa",IF(J8<=0.45,"Intermediária","Precisa melhorar"))) -> Intermediária
A9: 6 | B9: Campos dos Goytacazes | C9: =COUNTIFS(Pedidos!$E$2:$E$2224,$B9) -> 53 | D9: =C9/Resumo!$C$20 -> 0.023841655 | E9: =AVERAGEIFS(Pedidos!$G$2:$G$2224,Pedidos!$E$2:$E$2224,$B9) -> 49.475283 | F9: =AVERAGEIFS(Pedidos!$H$2:$H$2224,Pedidos!$E$2:$E$2224,$B9) -> 649.88434 | G9: =AVERAGEIFS(Pedidos!$J$2:$J$2224,Pedidos!$E$2:$E$2224,$B9) -> 136.86038 | H9: =AVERAGEIFS(Pedidos!$S$2:$S$2224,Pedidos!$E$2:$E$2224,$B9) -> 218.07381 | I9: =H9-G9 -> 81.213435 | J9: =H9/G9-1 -> 0.59340356 | K9: =SUMIFS(Pedidos!$J$2:$J$2224,Pedidos!$E$2:$E$2224,$B9)/SUMIFS(Pedidos!$H$2:$H$2224,Pedidos!$E$2:$E$2224,$B9) -> 0.2105919 | L9: =SUMIFS(Pedidos!$S$2:$S$2224,Pedidos!$E$2:$E$2224,$B9)/SUMIFS(Pedidos!$H$2:$H$2224,Pedidos!$E$2:$E$2224,$B9) -> 0.33555788 | M9: =COUNTIFS(Pedidos!$E$2:$E$2224,$B9,Pedidos!$V$2:$V$2224,"SIM")/C9 -> 0 | N9: =AVERAGEIFS(Pedidos!$K$2:$K$2224,Pedidos!$E$2:$E$2224,$B9) -> 158.72151 | O9: =N9/G9-1 -> 0.1597331 | P9: =MAX(0,1-G9/H9) -> 0.3724126 | Q9: =AVERAGEIFS(Pedidos!$W$2:$W$2224,Pedidos!$E$2:$E$2224,$B9) -> 11 | R9: =IF(J9<=0,"Muito bem",IF(J9<=0.32,"Melhor posição relativa",IF(J9<=0.45,"Intermediária","Precisa melhorar"))) -> Precisa melhorar
A10: 7 | B10: Belford Roxo | C10: =COUNTIFS(Pedidos!$E$2:$E$2224,$B10) -> 49 | D10: =C10/Resumo!$C$20 -> 0.022042285 | E10: =AVERAGEIFS(Pedidos!$G$2:$G$2224,Pedidos!$E$2:$E$2224,$B10) -> 54.08 | F10: =AVERAGEIFS(Pedidos!$H$2:$H$2224,Pedidos!$E$2:$E$2224,$B10) -> 687.52816 | G10: =AVERAGEIFS(Pedidos!$J$2:$J$2224,Pedidos!$E$2:$E$2224,$B10) -> 128.08959 | H10: =AVERAGEIFS(Pedidos!$S$2:$S$2224,Pedidos!$E$2:$E$2224,$B10) -> 166.98858 | I10: =H10-G10 -> 38.898989 | J10: =H10/G10-1 -> 0.30368579 | K10: =SUMIFS(Pedidos!$J$2:$J$2224,Pedidos!$E$2:$E$2224,$B10)/SUMIFS(Pedidos!$H$2:$H$2224,Pedidos!$E$2:$E$2224,$B10) -> 0.1863045 | L10: =SUMIFS(Pedidos!$S$2:$S$2224,Pedidos!$E$2:$E$2224,$B10)/SUMIFS(Pedidos!$H$2:$H$2224,Pedidos!$E$2:$E$2224,$B10) -> 0.24288253 | M10: =COUNTIFS(Pedidos!$E$2:$E$2224,$B10,Pedidos!$V$2:$V$2224,"SIM")/C10 -> 0.081632653 | N10: =AVERAGEIFS(Pedidos!$K$2:$K$2224,Pedidos!$E$2:$E$2224,$B10) -> 111.30122 | O10: =N10/G10-1 -> -0.13106738 | P10: =MAX(0,1-G10/H10) -> 0.23294401 | Q10: =AVERAGEIFS(Pedidos!$W$2:$W$2224,Pedidos!$E$2:$E$2224,$B10) -> 5 | R10: =IF(J10<=0,"Muito bem",IF(J10<=0.32,"Melhor posição relativa",IF(J10<=0.45,"Intermediária","Precisa melhorar"))) -> Melhor posição relativa
A11: 8 | B11: Macaé | C11: =COUNTIFS(Pedidos!$E$2:$E$2224,$B11) -> 45 | D11: =C11/Resumo!$C$20 -> 0.020242915 | E11: =AVERAGEIFS(Pedidos!$G$2:$G$2224,Pedidos!$E$2:$E$2224,$B11) -> 60.060222 | F11: =AVERAGEIFS(Pedidos!$H$2:$H$2224,Pedidos!$E$2:$E$2224,$B11) -> 746.16467 | G11: =AVERAGEIFS(Pedidos!$J$2:$J$2224,Pedidos!$E$2:$E$2224,$B11) -> 150.53156 | H11: =AVERAGEIFS(Pedidos!$S$2:$S$2224,Pedidos!$E$2:$E$2224,$B11) -> 241.39782 | I11: =H11-G11 -> 90.86626 | J11: =H11/G11-1 -> 0.60363596 | K11: =SUMIFS(Pedidos!$J$2:$J$2224,Pedidos!$E$2:$E$2224,$B11)/SUMIFS(Pedidos!$H$2:$H$2224,Pedidos!$E$2:$E$2224,$B11) -> 0.2017404 | L11: =SUMIFS(Pedidos!$S$2:$S$2224,Pedidos!$E$2:$E$2224,$B11)/SUMIFS(Pedidos!$H$2:$H$2224,Pedidos!$E$2:$E$2224,$B11) -> 0.32351815 | M11: =COUNTIFS(Pedidos!$E$2:$E$2224,$B11,Pedidos!$V$2:$V$2224,"SIM")/C11 -> 0 | N11: =AVERAGEIFS(Pedidos!$K$2:$K$2224,Pedidos!$E$2:$E$2224,$B11) -> 173.27622 | O11: =N11/G11-1 -> 0.15109567 | P11: =MAX(0,1-G11/H11) -> 0.37641708 | Q11: =AVERAGEIFS(Pedidos!$W$2:$W$2224,Pedidos!$E$2:$E$2224,$B11) -> 11 | R11: =IF(J11<=0,"Muito bem",IF(J11<=0.32,"Melhor posição relativa",IF(J11<=0.45,"Intermediária","Precisa melhorar"))) -> Precisa melhorar
A12: 9 | B12: São João de Meriti | C12: =COUNTIFS(Pedidos!$E$2:$E$2224,$B12) -> 37 | D12: =C12/Resumo!$C$20 -> 0.016644175 | E12: =AVERAGEIFS(Pedidos!$G$2:$G$2224,Pedidos!$E$2:$E$2224,$B12) -> 55.930541 | F12: =AVERAGEIFS(Pedidos!$H$2:$H$2224,Pedidos!$E$2:$E$2224,$B12) -> 698.24405 | G12: =AVERAGEIFS(Pedidos!$J$2:$J$2224,Pedidos!$E$2:$E$2224,$B12) -> 131.78351 | H12: =AVERAGEIFS(Pedidos!$S$2:$S$2224,Pedidos!$E$2:$E$2224,$B12) -> 175.0438 | I12: =H12-G12 -> 43.260283 | J12: =H12/G12-1 -> 0.32826779 | K12: =SUMIFS(Pedidos!$J$2:$J$2224,Pedidos!$E$2:$E$2224,$B12)/SUMIFS(Pedidos!$H$2:$H$2224,Pedidos!$E$2:$E$2224,$B12) -> 0.1887356 | L12: =SUMIFS(Pedidos!$S$2:$S$2224,Pedidos!$E$2:$E$2224,$B12)/SUMIFS(Pedidos!$H$2:$H$2224,Pedidos!$E$2:$E$2224,$B12) -> 0.25069142 | M12: =COUNTIFS(Pedidos!$E$2:$E$2224,$B12,Pedidos!$V$2:$V$2224,"SIM")/C12 -> 0.027027027 | N12: =AVERAGEIFS(Pedidos!$K$2:$K$2224,Pedidos!$E$2:$E$2224,$B12) -> 117.27324 | O12: =N12/G12-1 -> -0.11010687 | P12: =MAX(0,1-G12/H12) -> 0.24713976 | Q12: =AVERAGEIFS(Pedidos!$W$2:$W$2224,Pedidos!$E$2:$E$2224,$B12) -> 5 | R12: =IF(J12<=0,"Muito bem",IF(J12<=0.32,"Melhor posição relativa",IF(J12<=0.45,"Intermediária","Precisa melhorar"))) -> Intermediária
A13: 10 | B13: Volta Redonda | C13: =COUNTIFS(Pedidos!$E$2:$E$2224,$B13) -> 37 | D13: =C13/Resumo!$C$20 -> 0.016644175 | E13: =AVERAGEIFS(Pedidos!$G$2:$G$2224,Pedidos!$E$2:$E$2224,$B13) -> 50.886757 | F13: =AVERAGEIFS(Pedidos!$H$2:$H$2224,Pedidos!$E$2:$E$2224,$B13) -> 652.92108 | G13: =AVERAGEIFS(Pedidos!$J$2:$J$2224,Pedidos!$E$2:$E$2224,$B13) -> 139.23459 | H13: =AVERAGEIFS(Pedidos!$S$2:$S$2224,Pedidos!$E$2:$E$2224,$B13) -> 198.53824 | I13: =H13-G13 -> 59.303643 | J13: =H13/G13-1 -> 0.42592606 | K13: =SUMIFS(Pedidos!$J$2:$J$2224,Pedidos!$E$2:$E$2224,$B13)/SUMIFS(Pedidos!$H$2:$H$2224,Pedidos!$E$2:$E$2224,$B13) -> 0.21324873 | L13: =SUMIFS(Pedidos!$S$2:$S$2224,Pedidos!$E$2:$E$2224,$B13)/SUMIFS(Pedidos!$H$2:$H$2224,Pedidos!$E$2:$E$2224,$B13) -> 0.30407693 | M13: =COUNTIFS(Pedidos!$E$2:$E$2224,$B13,Pedidos!$V$2:$V$2224,"SIM")/C13 -> 0 | N13: =AVERAGEIFS(Pedidos!$K$2:$K$2224,Pedidos!$E$2:$E$2224,$B13) -> 140.82243 | O13: =N13/G13-1 -> 0.011404047 | P13: =MAX(0,1-G13/H13) -> 0.29870137 | Q13: =AVERAGEIFS(Pedidos!$W$2:$W$2224,Pedidos!$E$2:$E$2224,$B13) -> 10 | R13: =IF(J13<=0,"Muito bem",IF(J13<=0.32,"Melhor posição relativa",IF(J13<=0.45,"Intermediária","Precisa melhorar"))) -> Intermediária
A14: 11 | B14: Angra dos Reis | C14: =COUNTIFS(Pedidos!$E$2:$E$2224,$B14) -> 35 | D14: =C14/Resumo!$C$20 -> 0.015744489 | E14: =AVERAGEIFS(Pedidos!$G$2:$G$2224,Pedidos!$E$2:$E$2224,$B14) -> 44.394286 | F14: =AVERAGEIFS(Pedidos!$H$2:$H$2224,Pedidos!$E$2:$E$2224,$B14) -> 596.41771 | G14: =AVERAGEIFS(Pedidos!$J$2:$J$2224,Pedidos!$E$2:$E$2224,$B14) -> 129.24743 | H14: =AVERAGEIFS(Pedidos!$S$2:$S$2224,Pedidos!$E$2:$E$2224,$B14) -> 179.38262 | I14: =H14-G14 -> 50.135188 | J14: =H14/G14-1 -> 0.38790086 | K14: =SUMIFS(Pedidos!$J$2:$J$2224,Pedidos!$E$2:$E$2224,$B14)/SUMIFS(Pedidos!$H$2:$H$2224,Pedidos!$E$2:$E$2224,$B14) -> 0.21670622 | L14: =SUMIFS(Pedidos!$S$2:$S$2224,Pedidos!$E$2:$E$2224,$B14)/SUMIFS(Pedidos!$H$2:$H$2224,Pedidos!$E$2:$E$2224,$B14) -> 0.30076675 | M14: =COUNTIFS(Pedidos!$E$2:$E$2224,$B14,Pedidos!$V$2:$V$2224,"SIM")/C14 -> 0 | N14: =AVERAGEIFS(Pedidos!$K$2:$K$2224,Pedidos!$E$2:$E$2224,$B14) -> 127.71943 | O14: =N14/G14-1 -> -0.011822285 | P14: =MAX(0,1-G14/H14) -> 0.27948744 | Q14: =AVERAGEIFS(Pedidos!$W$2:$W$2224,Pedidos!$E$2:$E$2224,$B14) -> 10 | R14: =IF(J14<=0,"Muito bem",IF(J14<=0.32,"Melhor posição relativa",IF(J14<=0.45,"Intermediária","Precisa melhorar"))) -> Intermediária
A15: 12 | B15: Petrópolis | C15: =COUNTIFS(Pedidos!$E$2:$E$2224,$B15) -> 32 | D15: =C15/Resumo!$C$20 -> 0.014394962 | E15: =AVERAGEIFS(Pedidos!$G$2:$G$2224,Pedidos!$E$2:$E$2224,$B15) -> 58.889375 | F15: =AVERAGEIFS(Pedidos!$H$2:$H$2224,Pedidos!$E$2:$E$2224,$B15) -> 743.8225 | G15: =AVERAGEIFS(Pedidos!$J$2:$J$2224,Pedidos!$E$2:$E$2224,$B15) -> 149.76844 | H15: =AVERAGEIFS(Pedidos!$S$2:$S$2224,Pedidos!$E$2:$E$2224,$B15) -> 216.62811 | I15: =H15-G15 -> 66.859677 | J15: =H15/G15-1 -> 0.44642034 | K15: =SUMIFS(Pedidos!$J$2:$J$2224,Pedidos!$E$2:$E$2224,$B15)/SUMIFS(Pedidos!$H$2:$H$2224,Pedidos!$E$2:$E$2224,$B15) -> 0.2013497 | L15: =SUMIFS(Pedidos!$S$2:$S$2224,Pedidos!$E$2:$E$2224,$B15)/SUMIFS(Pedidos!$H$2:$H$2224,Pedidos!$E$2:$E$2224,$B15) -> 0.2912363 | M15: =COUNTIFS(Pedidos!$E$2:$E$2224,$B15,Pedidos!$V$2:$V$2224,"SIM")/C15 -> 0 | N15: =AVERAGEIFS(Pedidos!$K$2:$K$2224,Pedidos!$E$2:$E$2224,$B15) -> 152.08937 | O15: =N15/G15-1 -> 0.01549684 | P15: =MAX(0,1-G15/H15) -> 0.30863804 | Q15: =AVERAGEIFS(Pedidos!$W$2:$W$2224,Pedidos!$E$2:$E$2224,$B15) -> 8 | R15: =IF(J15<=0,"Muito bem",IF(J15<=0.32,"Melhor posição relativa",IF(J15<=0.45,"Intermediária","Precisa melhorar"))) -> Intermediária
... A23: 20 | B23: Rio das Ostras | C23: =COUNTIFS(Pedidos!$E$2:$E$2224,$B23) -> 18 | D23: =C23/Resumo!$C$20 -> 0.008097166 | E23: =AVERAGEIFS(Pedidos!$G$2:$G$2224,Pedidos!$E$2:$E$2224,$B23) -> 47.438889 | F23: =AVERAGEIFS(Pedidos!$H$2:$H$2224,Pedidos!$E$2:$E$2224,$B23) -> 604.15056 | G23: =AVERAGEIFS(Pedidos!$J$2:$J$2224,Pedidos!$E$2:$E$2224,$B23) -> 132.50556 | H23: =AVERAGEIFS(Pedidos!$S$2:$S$2224,Pedidos!$E$2:$E$2224,$B23) -> 190.52996 | I23: =H23-G23 -> 58.024407 | J23: =H23/G23-1 -> 0.43790169 | K23: =SUMIFS(Pedidos!$J$2:$J$2224,Pedidos!$E$2:$E$2224,$B23)/SUMIFS(Pedidos!$H$2:$H$2224,Pedidos!$E$2:$E$2224,$B23) -> 0.21932539 | L23: =SUMIFS(Pedidos!$S$2:$S$2224,Pedidos!$E$2:$E$2224,$B23)/SUMIFS(Pedidos!$H$2:$H$2224,Pedidos!$E$2:$E$2224,$B23) -> 0.31536835 | M23: =COUNTIFS(Pedidos!$E$2:$E$2224,$B23,Pedidos!$V$2:$V$2224,"SIM")/C23 -> 0 | N23: =AVERAGEIFS(Pedidos!$K$2:$K$2224,Pedidos!$E$2:$E$2224,$B23) -> 136.04389 | O23: =N23/G23-1 -> 0.026703283 | P23: =MAX(0,1-G23/H23) -> 0.30454216 | Q23: =AVERAGEIFS(Pedidos!$W$2:$W$2224,Pedidos!$E$2:$E$2224,$B23) -> 10 | R23: =IF(J23<=0,"Muito bem",IF(J23<=0.32,"Melhor posição relativa",IF(J23<=0.45,"Intermediária","Precisa melhorar"))) -> Intermediária
B24: TOTAL TOP 20 | C24: =SUM(C4:C23) -> 1912 | D24: =C24/Resumo!$C$20 -> 0.86009897 | E24: =AVERAGEIFS(Pedidos!$G$2:$G$2224,Pedidos!$X$2:$X$2224,"SIM") -> 49.45444 | F24: =AVERAGEIFS(Pedidos!$H$2:$H$2224,Pedidos!$X$2:$X$2224,"SIM") -> 636.04536 | G24: =AVERAGEIFS(Pedidos!$J$2:$J$2224,Pedidos!$X$2:$X$2224,"SIM") -> 118.41855 | H24: =AVERAGEIFS(Pedidos!$S$2:$S$2224,Pedidos!$X$2:$X$2224,"SIM") -> 169.56635 | I24: =H24-G24 -> 51.147804 | J24: =H24/G24-1 -> 0.43192393 | K24: =SUMIFS(Pedidos!$J$2:$J$2224,Pedidos!$X$2:$X$2224,"SIM")/SUMIFS(Pedidos!$H$2:$H$2224,Pedidos!$X$2:$X$2224,"SIM") -> 0.1861794 | L24: =SUMIFS(Pedidos!$S$2:$S$2224,Pedidos!$X$2:$X$2224,"SIM")/SUMIFS(Pedidos!$H$2:$H$2224,Pedidos!$X$2:$X$2224,"SIM") -> 0.26659474 | M24: =COUNTIFS(Pedidos!$X$2:$X$2224,"SIM",Pedidos!$V$2:$V$2224,"SIM")/C24 -> 0.0073221757 | N24: =AVERAGEIFS(Pedidos!$K$2:$K$2224,Pedidos!$X$2:$X$2224,"SIM") -> 116.08623 | O24: =N24/G24-1 -> -0.019695494 | P24: =MAX(0,1-G24/H24) -> 0.30163888 | Q24: =AVERAGEIFS(Pedidos!$W$2:$W$2224,Pedidos!$X$2:$X$2224,"SIM") -> 6.0690377
A26: Avaliação (coluna R): "Muito bem" = PROLOG mais barata que o atual; "Melhor posição relativa" = até +32%; "Intermediária" = +32% a +45%; "Precisa melhorar" = acima de +45%. Faixas definidas pela distribuição observada (média RJ ≈ +43%).
A27: "PROLOG só frete peso" = valor da faixa de peso da tabela, sem ad valorem, GRIS, TAS, pedágio, taxas por kg e ICMS — mostra onde a base da tabela é competitiva e o peso das taxas adicionais.

Sheet Faixa x Transportadora
A1: Top 20 cidades — por faixa de peso: transportadoras atuais x PROLOG simulado nos MESMOS pedidos
A3: Transportadora atual: TODAS
A4: Faixa (kg) | B4: Pedidos | C4: Peso médio | D4: Custo médio atual (R$) | E4: PROLOG médio (R$) | F4: PROLOG vs atual (%) | G4: Frete/NF atual | H4: Frete/NF PROLOG | I4: % pedidos PROLOG mais barata | J4: PROLOG só frete peso (R$) | K4: Desconto necessário p/ empatar
A5: 0-20 | B5: =COUNTIFS(Pedidos!$X$2:$X$2224,"SIM",Pedidos!$F$2:$F$2224,$A5) -> 96 | C5: =IFERROR(AVERAGEIFS(Pedidos!$G$2:$G$2224,Pedidos!$X$2:$X$2224,"SIM",Pedidos!$F$2:$F$2224,$A5),"") -> 17.503438 | D5: =IFERROR(AVERAGEIFS(Pedidos!$J$2:$J$2224,Pedidos!$X$2:$X$2224,"SIM",Pedidos!$F$2:$F$2224,$A5),"") -> 69.142083 | E5: =IFERROR(AVERAGEIFS(Pedidos!$S$2:$S$2224,Pedidos!$X$2:$X$2224,"SIM",Pedidos!$F$2:$F$2224,$A5),"") -> 76.075249 | F5: =IFERROR(E5/D5-1,"") -> 0.10027417 | G5: =IFERROR(SUMIFS(Pedidos!$J$2:$J$2224,Pedidos!$X$2:$X$2224,"SIM",Pedidos!$F$2:$F$2224,$A5)/SUMIFS(Pedidos!$H$2:$H$2224,Pedidos!$X$2:$X$2224,"SIM",Pedidos!$F$2:$F$2224,$A5),"") -> 0.22335232 | H5: =IFERROR(SUMIFS(Pedidos!$S$2:$S$2224,Pedidos!$X$2:$X$2224,"SIM",Pedidos!$F$2:$F$2224,$A5)/SUMIFS(Pedidos!$H$2:$H$2224,Pedidos!$X$2:$X$2224,"SIM",Pedidos!$F$2:$F$2224,$A5),"") -> 0.24574879 | I5: =IFERROR(COUNTIFS(Pedidos!$X$2:$X$2224,"SIM",Pedidos!$F$2:$F$2224,$A5,Pedidos!$V$2:$V$2224,"SIM")/B5,"") -> 0.14583333 | J5: =IFERROR(AVERAGEIFS(Pedidos!$K$2:$K$2224,Pedidos!$X$2:$X$2224,"SIM",Pedidos!$F$2:$F$2224,$A5),"") -> 51.369375 | K5: =IFERROR(MAX(0,1-D5/E5),"") -> 0.091135624
A6: 20-35 | B6: =COUNTIFS(Pedidos!$X$2:$X$2224,"SIM",Pedidos!$F$2:$F$2224,$A6) -> 431 | C6: =IFERROR(AVERAGEIFS(Pedidos!$G$2:$G$2224,Pedidos!$X$2:$X$2224,"SIM",Pedidos!$F$2:$F$2224,$A6),"") -> 28.263202 | D6: =IFERROR(AVERAGEIFS(Pedidos!$J$2:$J$2224,Pedidos!$X$2:$X$2224,"SIM",Pedidos!$F$2:$F$2224,$A6),"") -> 90.953759 | E6: =IFERROR(AVERAGEIFS(Pedidos!$S$2:$S$2224,Pedidos!$X$2:$X$2224,"SIM",Pedidos!$F$2:$F$2224,$A6),"") -> 127.44457 | F6: =IFERROR(E6/D6-1,"") -> 0.40120182 | G6: =IFERROR(SUMIFS(Pedidos!$J$2:$J$2224,Pedidos!$X$2:$X$2224,"SIM",Pedidos!$F$2:$F$2224,$A6)/SUMIFS(Pedidos!$H$2:$H$2224,Pedidos!$X$2:$X$2224,"SIM",Pedidos!$F$2:$F$2224,$A6),"") -> 0.21057819 | H6: =IFERROR(SUMIFS(Pedidos!$S$2:$S$2224,Pedidos!$X$2:$X$2224,"SIM",Pedidos!$F$2:$F$2224,$A6)/SUMIFS(Pedidos!$H$2:$H$2224,Pedidos!$X$2:$X$2224,"SIM",Pedidos!$F$2:$F$2224,$A6),"") -> 0.29506255 | I6: =IFERROR(COUNTIFS(Pedidos!$X$2:$X$2224,"SIM",Pedidos!$F$2:$F$2224,$A6,Pedidos!$V$2:$V$2224,"SIM")/B6,"") -> 0 | J6: =IFERROR(AVERAGEIFS(Pedidos!$K$2:$K$2224,Pedidos!$X$2:$X$2224,"SIM",Pedidos!$F$2:$F$2224,$A6),"") -> 90.763039 | K6: =IFERROR(MAX(0,1-D6/E6),"") -> 0.28632694
A7: 35-40 | B7: =COUNTIFS(Pedidos!$X$2:$X$2224,"SIM",Pedidos!$F$2:$F$2224,$A7) -> 299 | C7: =IFERROR(AVERAGEIFS(Pedidos!$G$2:$G$2224,Pedidos!$X$2:$X$2224,"SIM",Pedidos!$F$2:$F$2224,$A7),"") -> 37.708027 | D7: =IFERROR(AVERAGEIFS(Pedidos!$J$2:$J$2224,Pedidos!$X$2:$X$2224,"SIM",Pedidos!$F$2:$F$2224,$A7),"") -> 103.90311 | E7: =IFERROR(AVERAGEIFS(Pedidos!$S$2:$S$2224,Pedidos!$X$2:$X$2224,"SIM",Pedidos!$F$2:$F$2224,$A7),"") -> 146.77369 | F7: =IFERROR(E7/D7-1,"") -> 0.41260147 | G7: =IFERROR(SUMIFS(Pedidos!$J$2:$J$2224,Pedidos!$X$2:$X$2224,"SIM",Pedidos!$F$2:$F$2224,$A7)/SUMIFS(Pedidos!$H$2:$H$2224,Pedidos!$X$2:$X$2224,"SIM",Pedidos!$F$2:$F$2224,$A7),"") -> 0.22301406 | H7: =IFERROR(SUMIFS(Pedidos!$S$2:$S$2224,Pedidos!$X$2:$X$2224,"SIM",Pedidos!$F$2:$F$2224,$A7)/SUMIFS(Pedidos!$H$2:$H$2224,Pedidos!$X$2:$X$2224,"SIM",Pedidos!$F$2:$F$2224,$A7),"") -> 0.31503 | I7: =IFERROR(COUNTIFS(Pedidos!$X$2:$X$2224,"SIM",Pedidos!$F$2:$F$2224,$A7,Pedidos!$V$2:$V$2224,"SIM")/B7,"") -> 0 | J7: =IFERROR(AVERAGEIFS(Pedidos!$K$2:$K$2224,Pedidos!$X$2:$X$2224,"SIM",Pedidos!$F$2:$F$2224,$A7),"") -> 102.8507 | K7: =IFERROR(MAX(0,1-D7/E7),"") -> 0.29208626
A8: 40-50 | B8: =COUNTIFS(Pedidos!$X$2:$X$2224,"SIM",Pedidos!$F$2:$F$2224,$A8) -> 305 | C8: =IFERROR(AVERAGEIFS(Pedidos!$G$2:$G$2224,Pedidos!$X$2:$X$2224,"SIM",Pedidos!$F$2:$F$2224,$A8),"") -> 45.845246 | D8: =IFERROR(AVERAGEIFS(Pedidos!$J$2:$J$2224,Pedidos!$X$2:$X$2224,"SIM",Pedidos!$F$2:$F$2224,$A8),"") -> 113.34272 | E8: =IFERROR(AVERAGEIFS(Pedidos!$S$2:$S$2224,Pedidos!$X$2:$X$2224,"SIM",Pedidos!$F$2:$F$2224,$A8),"") -> 153.47148 | F8: =IFERROR(E8/D8-1,"") -> 0.35404797 | G8: =IFERROR(SUMIFS(Pedidos!$J$2:$J$2224,Pedidos!$X$2:$X$2224,"SIM",Pedidos!$F$2:$F$2224,$A8)/SUMIFS(Pedidos!$H$2:$H$2224,Pedidos!$X$2:$X$2224,"SIM",Pedidos!$F$2:$F$2224,$A8),"") -> 0.1877047 | H8: =IFERROR(SUMIFS(Pedidos!$S$2:$S$2224,Pedidos!$X$2:$X$2224,"SIM",Pedidos!$F$2:$F$2224,$A8)/SUMIFS(Pedidos!$H$2:$H$2224,Pedidos!$X$2:$X$2224,"SIM",Pedidos!$F$2:$F$2224,$A8),"") -> 0.25416117 | I8: =IFERROR(COUNTIFS(Pedidos!$X$2:$X$2224,"SIM",Pedidos!$F$2:$F$2224,$A8,Pedidos!$V$2:$V$2224,"SIM")/B8,"") -> 0 | J8: =IFERROR(AVERAGEIFS(Pedidos!$K$2:$K$2224,Pedidos!$X$2:$X$2224,"SIM",Pedidos!$F$2:$F$2224,$A8),"") -> 104.18305 | K8: =IFERROR(MAX(0,1-D8/E8),"") -> 0.26147373
A9: 50-60 | B9: =COUNTIFS(Pedidos!$X$2:$X$2224,"SIM",Pedidos!$F$2:$F$2224,$A9) -> 361 | C9: =IFERROR(AVERAGEIFS(Pedidos!$G$2:$G$2224,Pedidos!$X$2:$X$2224,"SIM",Pedidos!$F$2:$F$2224,$A9),"") -> 53.752382 | D9: =IFERROR(AVERAGEIFS(Pedidos!$J$2:$J$2224,Pedidos!$X$2:$X$2224,"SIM",Pedidos!$F$2:$F$2224,$A9),"") -> 124.19161 | E9: =IFERROR(AVERAGEIFS(Pedidos!$S$2:$S$2224,Pedidos!$X$2:$X$2224,"SIM",Pedidos!$F$2:$F$2224,$A9),"") -> 176.44982 | F9: =IFERROR(E9/D9-1,"") -> 0.42078699 | G9: =IFERROR(SUMIFS(Pedidos!$J$2:$J$2224,Pedidos!$X$2:$X$2224,"SIM",Pedidos!$F$2:$F$2224,$A9)/SUMIFS(Pedidos!$H$2:$H$2224,Pedidos!$X$2:$X$2224,"SIM",Pedidos!$F$2:$F$2224,$A9),"") -> 0.17823196 | H9: =IFERROR(SUMIFS(Pedidos!$S$2:$S$2224,Pedidos!$X$2:$X$2224,"SIM",Pedidos!$F$2:$F$2224,$A9)/SUMIFS(Pedidos!$H$2:$H$2224,Pedidos!$X$2:$X$2224,"SIM",Pedidos!$F$2:$F$2224,$A9),"") -> 0.25322965 | I9: =IFERROR(COUNTIFS(Pedidos!$X$2:$X$2224,"SIM",Pedidos!$F$2:$F$2224,$A9,Pedidos!$V$2:$V$2224,"SIM")/B9,"") -> 0 | J9: =IFERROR(AVERAGEIFS(Pedidos!$K$2:$K$2224,Pedidos!$X$2:$X$2224,"SIM",Pedidos!$F$2:$F$2224,$A9),"") -> 119.98296 | K9: =IFERROR(MAX(0,1-D9/E9),"") -> 0.29616473
A10: 60-70 | B10: =COUNTIFS(Pedidos!$X$2:$X$2224,"SIM",Pedidos!$F$2:$F$2224,$A10) -> 228 | C10: =IFERROR(AVERAGEIFS(Pedidos!$G$2:$G$2224,Pedidos!$X$2:$X$2224,"SIM",Pedidos!$F$2:$F$2224,$A10),"") -> 66.008026 | D10: =IFERROR(AVERAGEIFS(Pedidos!$J$2:$J$2224,Pedidos!$X$2:$X$2224,"SIM",Pedidos!$F$2:$F$2224,$A10),"") -> 135.94289 | E10: =IFERROR(AVERAGEIFS(Pedidos!$S$2:$S$2224,Pedidos!$X$2:$X$2224,"SIM",Pedidos!$F$2:$F$2224,$A10),"") -> 206.19743 | F10: =IFERROR(E10/D10-1,"") -> 0.51679448 | G10: =IFERROR(SUMIFS(Pedidos!$J$2:$J$2224,Pedidos!$X$2:$X$2224,"SIM",Pedidos!$F$2:$F$2224,$A10)/SUMIFS(Pedidos!$H$2:$H$2224,Pedidos!$X$2:$X$2224,"SIM",Pedidos!$F$2:$F$2224,$A10),"") -> 0.17873894 | H10: =IFERROR(SUMIFS(Pedidos!$S$2:$S$2224,Pedidos!$X$2:$X$2224,"SIM",Pedidos!$F$2:$F$2224,$A10)/SUMIFS(Pedidos!$H$2:$H$2224,Pedidos!$X$2:$X$2224,"SIM",Pedidos!$F$2:$F$2224,$A10),"") -> 0.27111024 | I10: =IFERROR(COUNTIFS(Pedidos!$X$2:$X$2224,"SIM",Pedidos!$F$2:$F$2224,$A10,Pedidos!$V$2:$V$2224,"SIM")/B10,"") -> 0 | J10: =IFERROR(AVERAGEIFS(Pedidos!$K$2:$K$2224,Pedidos!$X$2:$X$2224,"SIM",Pedidos!$F$2:$F$2224,$A10),"") -> 139.83754 | K10: =IFERROR(MAX(0,1-D10/E10),"") -> 0.3407149
A11: 70-80 | B11: =COUNTIFS(Pedidos!$X$2:$X$2224,"SIM",Pedidos!$F$2:$F$2224,$A11) -> 24 | C11: =IFERROR(AVERAGEIFS(Pedidos!$G$2:$G$2224,Pedidos!$X$2:$X$2224,"SIM",Pedidos!$F$2:$F$2224,$A11),"") -> 74.3625 | D11: =IFERROR(AVERAGEIFS(Pedidos!$J$2:$J$2224,Pedidos!$X$2:$X$2224,"SIM",Pedidos!$F$2:$F$2224,$A11),"") -> 148.41333 | E11: =IFERROR(AVERAGEIFS(Pedidos!$S$2:$S$2224,Pedidos!$X$2:$X$2224,"SIM",Pedidos!$F$2:$F$2224,$A11),"") -> 211.16089 | F11: =IFERROR(E11/D11-1,"") -> 0.42278925 | G11: =IFERROR(SUMIFS(Pedidos!$J$2:$J$2224,Pedidos!$X$2:$X$2224,"SIM",Pedidos!$F$2:$F$2224,$A11)/SUMIFS(Pedidos!$H$2:$H$2224,Pedidos!$X$2:$X$2224,"SIM",Pedidos!$F$2:$F$2224,$A11),"") -> 0.15431244 | H11: =IFERROR(SUMIFS(Pedidos!$S$2:$S$2224,Pedidos!$X$2:$X$2224,"SIM",Pedidos!$F$2:$F$2224,$A11)/SUMIFS(Pedidos!$H$2:$H$2224,Pedidos!$X$2:$X$2224,"SIM",Pedidos!$F$2:$F$2224,$A11),"") -> 0.21955408 | I11: =IFERROR(COUNTIFS(Pedidos!$X$2:$X$2224,"SIM",Pedidos!$F$2:$F$2224,$A11,Pedidos!$V$2:$V$2224,"SIM")/B11,"") -> 0 | J11: =IFERROR(AVERAGEIFS(Pedidos!$K$2:$K$2224,Pedidos!$X$2:$X$2224,"SIM",Pedidos!$F$2:$F$2224,$A11),"") -> 139.39875 | K11: =IFERROR(MAX(0,1-D11/E11),"") -> 0.29715522
A12: 80-100 | B12: =COUNTIFS(Pedidos!$X$2:$X$2224,"SIM",Pedidos!$F$2:$F$2224,$A12) -> 43 | C12: =IFERROR(AVERAGEIFS(Pedidos!$G$2:$G$2224,Pedidos!$X$2:$X$2224,"SIM",Pedidos!$F$2:$F$2224,$A12),"") -> 87.476744 | D12: =IFERROR(AVERAGEIFS(Pedidos!$J$2:$J$2224,Pedidos!$X$2:$X$2224,"SIM",Pedidos!$F$2:$F$2224,$A12),"") -> 174.62372 | E12: =IFERROR(AVERAGEIFS(Pedidos!$S$2:$S$2224,Pedidos!$X$2:$X$2224,"SIM",Pedidos!$F$2:$F$2224,$A12),"") -> 262.07562 | F12: =IFERROR(E12/D12-1,"") -> 0.50080194 | G12: =IFERROR(SUMIFS(Pedidos!$J$2:$J$2224,Pedidos!$X$2:$X$2224,"SIM",Pedidos!$F$2:$F$2224,$A12)/SUMIFS(Pedidos!$H$2:$H$2224,Pedidos!$X$2:$X$2224,"SIM",Pedidos!$F$2:$F$2224,$A12),"") -> 0.18147433 | H12: =IFERROR(SUMIFS(Pedidos!$S$2:$S$2224,Pedidos!$X$2:$X$2224,"SIM",Pedidos!$F$2:$F$2224,$A12)/SUMIFS(Pedidos!$H$2:$H$2224,Pedidos!$X$2:$X$2224,"SIM",Pedidos!$F$2:$F$2224,$A12),"") -> 0.27235703 | I12: =IFERROR(COUNTIFS(Pedidos!$X$2:$X$2224,"SIM",Pedidos!$F$2:$F$2224,$A12,Pedidos!$V$2:$V$2224,"SIM")/B12,"") -> 0 | J12: =IFERROR(AVERAGEIFS(Pedidos!$K$2:$K$2224,Pedidos!$X$2:$X$2224,"SIM",Pedidos!$F$2:$F$2224,$A12),"") -> 177.46651 | K12: =IFERROR(MAX(0,1-D12/E12),"") -> 0.33368956
A13: 100-120 | B13: =COUNTIFS(Pedidos!$X$2:$X$2224,"SIM",Pedidos!$F$2:$F$2224,$A13) -> 47 | C13: =IFERROR(AVERAGEIFS(Pedidos!$G$2:$G$2224,Pedidos!$X$2:$X$2224,"SIM",Pedidos!$F$2:$F$2224,$A13),"") -> 110.29234 | D13: =IFERROR(AVERAGEIFS(Pedidos!$J$2:$J$2224,Pedidos!$X$2:$X$2224,"SIM",Pedidos!$F$2:$F$2224,$A13),"") -> 194.59979 | E13: =IFERROR(AVERAGEIFS(Pedidos!$S$2:$S$2224,Pedidos!$X$2:$X$2224,"SIM",Pedidos!$F$2:$F$2224,$A13),"") -> 316.24235 | F13: =IFERROR(E13/D13-1,"") -> 0.62509093 | G13: =IFERROR(SUMIFS(Pedidos!$J$2:$J$2224,Pedidos!$X$2:$X$2224,"SIM",Pedidos!$F$2:$F$2224,$A13)/SUMIFS(Pedidos!$H$2:$H$2224,Pedidos!$X$2:$X$2224,"SIM",Pedidos!$F$2:$F$2224,$A13),"") -> 0.15923706 | H13: =IFERROR(SUMIFS(Pedidos!$S$2:$S$2224,Pedidos!$X$2:$X$2224,"SIM",Pedidos!$F$2:$F$2224,$A13)/SUMIFS(Pedidos!$H$2:$H$2224,Pedidos!$X$2:$X$2224,"SIM",Pedidos!$F$2:$F$2224,$A13),"") -> 0.25877471 | I13: =IFERROR(COUNTIFS(Pedidos!$X$2:$X$2224,"SIM",Pedidos!$F$2:$F$2224,$A13,Pedidos!$V$2:$V$2224,"SIM")/B13,"") -> 0 | J13: =IFERROR(AVERAGEIFS(Pedidos!$K$2:$K$2224,Pedidos!$X$2:$X$2224,"SIM",Pedidos!$F$2:$F$2224,$A13),"") -> 208.16894 | K13: =IFERROR(MAX(0,1-D13/E13),"") -> 0.38464982
A14: 120-150 | B14: =COUNTIFS(Pedidos!$X$2:$X$2224,"SIM",Pedidos!$F$2:$F$2224,$A14) -> 73 | C14: =IFERROR(AVERAGEIFS(Pedidos!$G$2:$G$2224,Pedidos!$X$2:$X$2224,"SIM",Pedidos!$F$2:$F$2224,$A14),"") -> 128.52932 | D14: =IFERROR(AVERAGEIFS(Pedidos!$J$2:$J$2224,Pedidos!$X$2:$X$2224,"SIM",Pedidos!$F$2:$F$2224,$A14),"") -> 240.82521 | E14: =IFERROR(AVERAGEIFS(Pedidos!$S$2:$S$2224,Pedidos!$X$2:$X$2224,"SIM",Pedidos!$F$2:$F$2224,$A14),"") -> 369.59088 | F14: =IFERROR(E14/D14-1,"") -> 0.53468522 | G14: =IFERROR(SUMIFS(Pedidos!$J$2:$J$2224,Pedidos!$X$2:$X$2224,"SIM",Pedidos!$F$2:$F$2224,$A14)/SUMIFS(Pedidos!$H$2:$H$2224,Pedidos!$X$2:$X$2224,"SIM",Pedidos!$F$2:$F$2224,$A14),"") -> 0.14641807 | H14: =IFERROR(SUMIFS(Pedidos!$S$2:$S$2224,Pedidos!$X$2:$X$2224,"SIM",Pedidos!$F$2:$F$2224,$A14)/SUMIFS(Pedidos!$H$2:$H$2224,Pedidos!$X$2:$X$2224,"SIM",Pedidos!$F$2:$F$2224,$A14),"") -> 0.22470564 | I14: =IFERROR(COUNTIFS(Pedidos!$X$2:$X$2224,"SIM",Pedidos!$F$2:$F$2224,$A14,Pedidos!$V$2:$V$2224,"SIM")/B14,"") -> 0 | J14: =IFERROR(AVERAGEIFS(Pedidos!$K$2:$K$2224,Pedidos!$X$2:$X$2224,"SIM",Pedidos!$F$2:$F$2224,$A14),"") -> 244.44575 | K14: =IFERROR(MAX(0,1-D14/E14),"") -> 0.34840058
A15: 150-170 | B15: =COUNTIFS(Pedidos!$X$2:$X$2224,"SIM",Pedidos!$F$2:$F$2224,$A15) -> 3 | C15: =IFERROR(AVERAGEIFS(Pedidos!$G$2:$G$2224,Pedidos!$X$2:$X$2224,"SIM",Pedidos!$F$2:$F$2224,$A15),"") -> 160.63333 | D15: =IFERROR(AVERAGEIFS(Pedidos!$J$2:$J$2224,Pedidos!$X$2:$X$2224,"SIM",Pedidos!$F$2:$F$2224,$A15),"") -> 259.73 | E15: =IFERROR(AVERAGEIFS(Pedidos!$S$2:$S$2224,Pedidos!$X$2:$X$2224,"SIM",Pedidos!$F$2:$F$2224,$A15),"") -> 423.50102 | F15: =IFERROR(E15/D15-1,"") -> 0.63054334 | G15: =IFERROR(SUMIFS(Pedidos!$J$2:$J$2224,Pedidos!$X$2:$X$2224,"SIM",Pedidos!$F$2:$F$2224,$A15)/SUMIFS(Pedidos!$H$2:$H$2224,Pedidos!$X$2:$X$2224,"SIM",Pedidos!$F$2:$F$2224,$A15),"") -> 0.13604317 | H15: =IFERROR(SUMIFS(Pedidos!$S$2:$S$2224,Pedidos!$X$2:$X$2224,"SIM",Pedidos!$F$2:$F$2224,$A15)/SUMIFS(Pedidos!$H$2:$H$2224,Pedidos!$X$2:$X$2224,"SIM",Pedidos!$F$2:$F$2224,$A15),"") -> 0.22182429 | I15: =IFERROR(COUNTIFS(Pedidos!$X$2:$X$2224,"SIM",Pedidos!$F$2:$F$2224,$A15,Pedidos!$V$2:$V$2224,"SIM")/B15,"") -> 0 | J15: =IFERROR(AVERAGEIFS(Pedidos!$K$2:$K$2224,Pedidos!$X$2:$X$2224,"SIM",Pedidos!$F$2:$F$2224,$A15),"") -> 274.84333 | K15: =IFERROR(MAX(0,1-D15/E15),"") -> 0.3867075
A16: 170-200 | B16: =COUNTIFS(Pedidos!$X$2:$X$2224,"SIM",Pedidos!$F$2:$F$2224,$A16) -> 1 | C16: =IFERROR(AVERAGEIFS(Pedidos!$G$2:$G$2224,Pedidos!$X$2:$X$2224,"SIM",Pedidos!$F$2:$F$2224,$A16),"") -> 188.4 | D16: =IFERROR(AVERAGEIFS(Pedidos!$J$2:$J$2224,Pedidos!$X$2:$X$2224,"SIM",Pedidos!$F$2:$F$2224,$A16),"") -> 198.28 | E16: =IFERROR(AVERAGEIFS(Pedidos!$S$2:$S$2224,Pedidos!$X$2:$X$2224,"SIM",Pedidos!$F$2:$F$2224,$A16),"") -> 529.025 | F16: =IFERROR(E16/D16-1,"") -> 1.6680704 | G16: =IFERROR(SUMIFS(Pedidos!$J$2:$J$2224,Pedidos!$X$2:$X$2224,"SIM",Pedidos!$F$2:$F$2224,$A16)/SUMIFS(Pedidos!$H$2:$H$2224,Pedidos!$X$2:$X$2224,"SIM",Pedidos!$F$2:$F$2224,$A16),"") -> 0.099438315 | H16: =IFERROR(SUMIFS(Pedidos!$S$2:$S$2224,Pedidos!$X$2:$X$2224,"SIM",Pedidos!$F$2:$F$2224,$A16)/SUMIFS(Pedidos!$H$2:$H$2224,Pedidos!$X$2:$X$2224,"SIM",Pedidos!$F$2:$F$2224,$A16),"") -> 0.26530843 | I16: =IFERROR(COUNTIFS(Pedidos!$X$2:$X$2224,"SIM",Pedidos!$F$2:$F$2224,$A16,Pedidos!$V$2:$V$2224,"SIM")/B16,"") -> 0 | J16: =IFERROR(AVERAGEIFS(Pedidos!$K$2:$K$2224,Pedidos!$X$2:$X$2224,"SIM",Pedidos!$F$2:$F$2224,$A16),"") -> 353.17 | K16: =IFERROR(MAX(0,1-D16/E16),"") -> 0.6251973
... A18: >250 | B18: =COUNTIFS(Pedidos!$X$2:$X$2224,"SIM",Pedidos!$F$2:$F$2224,$A18) -> 0 | C18: =IFERROR(AVERAGEIFS(Pedidos!$G$2:$G$2224,Pedidos!$X$2:$X$2224,"SIM",Pedidos!$F$2:$F$2224,$A18),"") | D18: =IFERROR(AVERAGEIFS(Pedidos!$J$2:$J$2224,Pedidos!$X$2:$X$2224,"SIM",Pedidos!$F$2:$F$2224,$A18),"") | E18: =IFERROR(AVERAGEIFS(Pedidos!$S$2:$S$2224,Pedidos!$X$2:$X$2224,"SIM",Pedidos!$F$2:$F$2224,$A18),"") | F18: =IFERROR(E18/D18-1,"") | G18: =IFERROR(SUMIFS(Pedidos!$J$2:$J$2224,Pedidos!$X$2:$X$2224,"SIM",Pedidos!$F$2:$F$2224,$A18)/SUMIFS(Pedidos!$H$2:$H$2224,Pedidos!$X$2:$X$2224,"SIM",Pedidos!$F$2:$F$2224,$A18),"") | H18: =IFERROR(SUMIFS(Pedidos!$S$2:$S$2224,Pedidos!$X$2:$X$2224,"SIM",Pedidos!$F$2:$F$2224,$A18)/SUMIFS(Pedidos!$H$2:$H$2224,Pedidos!$X$2:$X$2224,"SIM",Pedidos!$F$2:$F$2224,$A18),"") | I18: =IFERROR(COUNTIFS(Pedidos!$X$2:$X$2224,"SIM",Pedidos!$F$2:$F$2224,$A18,Pedidos!$V$2:$V$2224,"SIM")/B18,"") | J18: =IFERROR(AVERAGEIFS(Pedidos!$K$2:$K$2224,Pedidos!$X$2:$X$2224,"SIM",Pedidos!$F$2:$F$2224,$A18),"") | K18: =IFERROR(MAX(0,1-D18/E18),"")
A19: TOTAL | B19: =COUNTIFS(Pedidos!$X$2:$X$2224,"SIM") -> 1912 | C19: =IFERROR(AVERAGEIFS(Pedidos!$G$2:$G$2224,Pedidos!$X$2:$X$2224,"SIM"),"") -> 49.45444 | D19: =IFERROR(AVERAGEIFS(Pedidos!$J$2:$J$2224,Pedidos!$X$2:$X$2224,"SIM"),"") -> 118.41855 | E19: =IFERROR(AVERAGEIFS(Pedidos!$S$2:$S$2224,Pedidos!$X$2:$X$2224,"SIM"),"") -> 169.56635 | F19: =IFERROR(E19/D19-1,"") -> 0.43192393 | G19: =IFERROR(SUMIFS(Pedidos!$J$2:$J$2224,Pedidos!$X$2:$X$2224,"SIM")/SUMIFS(Pedidos!$H$2:$H$2224,Pedidos!$X$2:$X$2224,"SIM"),"") -> 0.1861794 | H19: =IFERROR(SUMIFS(Pedidos!$S$2:$S$2224,Pedidos!$X$2:$X$2224,"SIM")/SUMIFS(Pedidos!$H$2:$H$2224,Pedidos!$X$2:$X$2224,"SIM"),"") -> 0.26659474 | I19: =IFERROR(COUNTIFS(Pedidos!$X$2:$X$2224,"SIM",Pedidos!$V$2:$V$2224,"SIM")/B19,"") -> 0.0073221757 | J19: =IFERROR(AVERAGEIFS(Pedidos!$K$2:$K$2224,Pedidos!$X$2:$X$2224,"SIM"),"") -> 116.08623 | K19: =IFERROR(MAX(0,1-D19/E19),"") -> 0.30163888
A21: Transportadora atual: Tsl Filial Sp
A22: Faixa (kg) | B22: Pedidos | C22: Peso médio | D22: Custo médio atual (R$) | E22: PROLOG médio (R$) | F22: PROLOG vs atual (%) | G22: Frete/NF atual | H22: Frete/NF PROLOG | I22: % pedidos PROLOG mais barata | J22: PROLOG só frete peso (R$) | K22: Desconto necessário p/ empatar
A23: 0-20 | B23: =COUNTIFS(Pedidos!$X$2:$X$2224,"SIM",Pedidos!$I$2:$I$2224,"Tsl Filial Sp",Pedidos!$F$2:$F$2224,$A23) -> 60 | C23: =IFERROR(AVERAGEIFS(Pedidos!$G$2:$G$2224,Pedidos!$X$2:$X$2224,"SIM",Pedidos!$I$2:$I$2224,"Tsl Filial Sp",Pedidos!$F$2:$F$2224,$A23),"") -> 16.952167 | D23: =IFERROR(AVERAGEIFS(Pedidos!$J$2:$J$2224,Pedidos!$X$2:$X$2224,"SIM",Pedidos!$I$2:$I$2224,"Tsl Filial Sp",Pedidos!$F$2:$F$2224,$A23),"") -> 68.086 | E23: =IFERROR(AVERAGEIFS(Pedidos!$S$2:$S$2224,Pedidos!$X$2:$X$2224,"SIM",Pedidos!$I$2:$I$2224,"Tsl Filial Sp",Pedidos!$F$2:$F$2224,$A23),"") -> 76.187824 | F23: =IFERROR(E23/D23-1,"") -> 0.11899398 | G23: =IFERROR(SUMIFS(Pedidos!$J$2:$J$2224,Pedidos!$X$2:$X$2224,"SIM",Pedidos!$I$2:$I$2224,"Tsl Filial Sp",Pedidos!$F$2:$F$2224,$A23)/SUMIFS(Pedidos!$H$2:$H$2224,Pedidos!$X$2:$X$2224,"SIM",Pedidos!$I$2:$I$2224,"Tsl Filial Sp",Pedidos!$F$2:$F$2224,$A23),"") -> 0.22374005 | H23: =IFERROR(SUMIFS(Pedidos!$S$2:$S$2224,Pedidos!$X$2:$X$2224,"SIM",Pedidos!$I$2:$I$2224,"Tsl Filial Sp",Pedidos!$F$2:$F$2224,$A23)/SUMIFS(Pedidos!$H$2:$H$2224,Pedidos!$X$2:$X$2224,"SIM",Pedidos!$I$2:$I$2224,"Tsl Filial Sp",Pedidos!$F$2:$F$2224,$A23),"") -> 0.25036377 | I23: =IFERROR(COUNTIFS(Pedidos!$X$2:$X$2224,"SIM",Pedidos!$I$2:$I$2224,"Tsl Filial Sp",Pedidos!$F$2:$F$2224,$A23,Pedidos!$V$2:$V$2224,"SIM")/B23,"") -> 0.13333333 | J23: =IFERROR(AVERAGEIFS(Pedidos!$K$2:$K$2224,Pedidos!$X$2:$X$2224,"SIM",Pedidos!$I$2:$I$2224,"Tsl Filial Sp",Pedidos!$F$2:$F$2224,$A23),"") -> 51.766833 | K23: =IFERROR(MAX(0,1-D23/E23),"") -> 0.10634014
A24: 20-35 | B24: =COUNTIFS(Pedidos!$X$2:$X$2224,"SIM",Pedidos!$I$2:$I$2224,"Tsl Filial Sp",Pedidos!$F$2:$F$2224,$A24) -> 347 | C24: =IFERROR(AVERAGEIFS(Pedidos!$G$2:$G$2224,Pedidos!$X$2:$X$2224,"SIM",Pedidos!$I$2:$I$2224,"Tsl Filial Sp",Pedidos!$F$2:$F$2224,$A24),"") -> 28.226138 | D24: =IFERROR(AVERAGEIFS(Pedidos!$J$2:$J$2224,Pedidos!$X$2:$X$2224,"SIM",Pedidos!$I$2:$I$2224,"Tsl Filial Sp",Pedidos!$F$2:$F$2224,$A24),"") -> 90.233487 | E24: =IFERROR(AVERAGEIFS(Pedidos!$S$2:$S$2224,Pedidos!$X$2:$X$2224,"SIM",Pedidos!$I$2:$I$2224,"Tsl Filial Sp",Pedidos!$F$2:$F$2224,$A24),"") -> 126.04516 | F24: =IFERROR(E24/D24-1,"") -> 0.39687787 | G24: =IFERROR(SUMIFS(Pedidos!$J$2:$J$2224,Pedidos!$X$2:$X$2224,"SIM",Pedidos!$I$2:$I$2224,"Tsl Filial Sp",Pedidos!$F$2:$F$2224,$A24)/SUMIFS(Pedidos!$H$2:$H$2224,Pedidos!$X$2:$X$2224,"SIM",Pedidos!$I$2:$I$2224,"Tsl Filial Sp",Pedidos!$F$2:$F$2224,$A24),"") -> 0.2080639 | H24: =IFERROR(SUMIFS(Pedidos!$S$2:$S$2224,Pedidos!$X$2:$X$2224,"SIM",Pedidos!$I$2:$I$2224,"Tsl Filial Sp",Pedidos!$F$2:$F$2224,$A24)/SUMIFS(Pedidos!$H$2:$H$2224,Pedidos!$X$2:$X$2224,"SIM",Pedidos!$I$2:$I$2224,"Tsl Filial Sp",Pedidos!$F$2:$F$2224,$A24),"") -> 0.29063986 | I24: =IFERROR(COUNTIFS(Pedidos!$X$2:$X$2224,"SIM",Pedidos!$I$2:$I$2224,"Tsl Filial Sp",Pedidos!$F$2:$F$2224,$A24,Pedidos!$V$2:$V$2224,"SIM")/B24,"") -> 0 | J24: =IFERROR(AVERAGEIFS(Pedidos!$K$2:$K$2224,Pedidos!$X$2:$X$2224,"SIM",Pedidos!$I$2:$I$2224,"Tsl Filial Sp",Pedidos!$F$2:$F$2224,$A24),"") -> 89.543256 | K24: =IFERROR(MAX(0,1-D24/E24),"") -> 0.2841178
A25: 35-40 | B25: =COUNTIFS(Pedidos!$X$2:$X$2224,"SIM",Pedidos!$I$2:$I$2224,"Tsl Filial Sp",Pedidos!$F$2:$F$2224,$A25) -> 231 | C25: =IFERROR(AVERAGEIFS(Pedidos!$G$2:$G$2224,Pedidos!$X$2:$X$2224,"SIM",Pedidos!$I$2:$I$2224,"Tsl Filial Sp",Pedidos!$F$2:$F$2224,$A25),"") -> 37.73645 | D25: =IFERROR(AVERAGEIFS(Pedidos!$J$2:$J$2224,Pedidos!$X$2:$X$2224,"SIM",Pedidos!$I$2:$I$2224,"Tsl Filial Sp",Pedidos!$F$2:$F$2224,$A25),"") -> 102.1158 | E25: =IFERROR(AVERAGEIFS(Pedidos!$S$2:$S$2224,Pedidos!$X$2:$X$2224,"SIM",Pedidos!$I$2:$I$2224,"Tsl Filial Sp",Pedidos!$F$2:$F$2224,$A25),"") -> 144.7635 | F25: =IFERROR(E25/D25-1,"") -> 0.41764052 | G25: =IFERROR(SUMIFS(Pedidos!$J$2:$J$2224,Pedidos!$X$2:$X$2224,"SIM",Pedidos!$I$2:$I$2224,"Tsl Filial Sp",Pedidos!$F$2:$F$2224,$A25)/SUMIFS(Pedidos!$H$2:$H$2224,Pedidos!$X$2:$X$2224,"SIM",Pedidos!$I$2:$I$2224,"Tsl Filial Sp",Pedidos!$F$2:$F$2224,$A25),"") -> 0.2187463 | H25: =IFERROR(SUMIFS(Pedidos!$S$2:$S$2224,Pedidos!$X$2:$X$2224,"SIM",Pedidos!$I$2:$I$2224,"Tsl Filial Sp",Pedidos!$F$2:$F$2224,$A25)/SUMIFS(Pedidos!$H$2:$H$2224,Pedidos!$X$2:$X$2224,"SIM",Pedidos!$I$2:$I$2224,"Tsl Filial Sp",Pedidos!$F$2:$F$2224,$A25),"") -> 0.31010362 | I25: =IFERROR(COUNTIFS(Pedidos!$X$2:$X$2224,"SIM",Pedidos!$I$2:$I$2224,"Tsl Filial Sp",Pedidos!$F$2:$F$2224,$A25,Pedidos!$V$2:$V$2224,"SIM")/B25,"") -> 0 | J25: =IFERROR(AVERAGEIFS(Pedidos!$K$2:$K$2224,Pedidos!$X$2:$X$2224,"SIM",Pedidos!$I$2:$I$2224,"Tsl Filial Sp",Pedidos!$F$2:$F$2224,$A25),"") -> 101.06502 | K25: =IFERROR(MAX(0,1-D25/E25),"") -> 0.29460255
A26: 40-50 | B26: =COUNTIFS(Pedidos!$X$2:$X$2224,"SIM",Pedidos!$I$2:$I$2224,"Tsl Filial Sp",Pedidos!$F$2:$F$2224,$A26) -> 230 | C26: =IFERROR(AVERAGEIFS(Pedidos!$G$2:$G$2224,Pedidos!$X$2:$X$2224,"SIM",Pedidos!$I$2:$I$2224,"Tsl Filial Sp",Pedidos!$F$2:$F$2224,$A26),"") -> 46.013478 | D26: =IFERROR(AVERAGEIFS(Pedidos!$J$2:$J$2224,Pedidos!$X$2:$X$2224,"SIM",Pedidos!$I$2:$I$2224,"Tsl Filial Sp",Pedidos!$F$2:$F$2224,$A26),"") -> 111.57261 | E26: =IFERROR(AVERAGEIFS(Pedidos!$S$2:$S$2224,Pedidos!$X$2:$X$2224,"SIM",Pedidos!$I$2:$I$2224,"Tsl Filial Sp",Pedidos!$F$2:$F$2224,$A26),"") -> 151.21398 | F26: =IFERROR(E26/D26-1,"") -> 0.3552966 | G26: =IFERROR(SUMIFS(Pedidos!$J$2:$J$2224,Pedidos!$X$2:$X$2224,"SIM",Pedidos!$I$2:$I$2224,"Tsl Filial Sp",Pedidos!$F$2:$F$2224,$A26)/SUMIFS(Pedidos!$H$2:$H$2224,Pedidos!$X$2:$X$2224,"SIM",Pedidos!$I$2:$I$2224,"Tsl Filial Sp",Pedidos!$F$2:$F$2224,$A26),"") -> 0.18307816 | H26: =IFERROR(SUMIFS(Pedidos!$S$2:$S$2224,Pedidos!$X$2:$X$2224,"SIM",Pedidos!$I$2:$I$2224,"Tsl Filial Sp",Pedidos!$F$2:$F$2224,$A26)/SUMIFS(Pedidos!$H$2:$H$2224,Pedidos!$X$2:$X$2224,"SIM",Pedidos!$I$2:$I$2224,"Tsl Filial Sp",Pedidos!$F$2:$F$2224,$A26),"") -> 0.24812521 | I26: =IFERROR(COUNTIFS(Pedidos!$X$2:$X$2224,"SIM",Pedidos!$I$2:$I$2224,"Tsl Filial Sp",Pedidos!$F$2:$F$2224,$A26,Pedidos!$V$2:$V$2224,"SIM")/B26,"") -> 0 | J26: =IFERROR(AVERAGEIFS(Pedidos!$K$2:$K$2224,Pedidos!$X$2:$X$2224,"SIM",Pedidos!$I$2:$I$2224,"Tsl Filial Sp",Pedidos!$F$2:$F$2224,$A26),"") -> 102.09596 | K26: =IFERROR(MAX(0,1-D26/E26),"") -> 0.26215413
A27: 50-60 | B27: =COUNTIFS(Pedidos!$X$2:$X$2224,"SIM",Pedidos!$I$2:$I$2224,"Tsl Filial Sp",Pedidos!$F$2:$F$2224,$A27) -> 230 | C27: =IFERROR(AVERAGEIFS(Pedidos!$G$2:$G$2224,Pedidos!$X$2:$X$2224,"SIM",Pedidos!$I$2:$I$2224,"Tsl Filial Sp",Pedidos!$F$2:$F$2224,$A27),"") -> 53.869435 | D27: =IFERROR(AVERAGEIFS(Pedidos!$J$2:$J$2224,Pedidos!$X$2:$X$2224,"SIM",Pedidos!$I$2:$I$2224,"Tsl Filial Sp",Pedidos!$F$2:$F$2224,$A27),"") -> 122.18887 | E27: =IFERROR(AVERAGEIFS(Pedidos!$S$2:$S$2224,Pedidos!$X$2:$X$2224,"SIM",Pedidos!$I$2:$I$2224,"Tsl Filial Sp",Pedidos!$F$2:$F$2224,$A27),"") -> 174.17349 | F27: =IFERROR(E27/D27-1,"") -> 0.42544478 | G27: =IFERROR(SUMIFS(Pedidos!$J$2:$J$2224,Pedidos!$X$2:$X$2224,"SIM",Pedidos!$I$2:$I$2224,"Tsl Filial Sp",Pedidos!$F$2:$F$2224,$A27)/SUMIFS(Pedidos!$H$2:$H$2224,Pedidos!$X$2:$X$2224,"SIM",Pedidos!$I$2:$I$2224,"Tsl Filial Sp",Pedidos!$F$2:$F$2224,$A27),"") -> 0.17585563 | H27: =IFERROR(SUMIFS(Pedidos!$S$2:$S$2224,Pedidos!$X$2:$X$2224,"SIM",Pedidos!$I$2:$I$2224,"Tsl Filial Sp",Pedidos!$F$2:$F$2224,$A27)/SUMIFS(Pedidos!$H$2:$H$2224,Pedidos!$X$2:$X$2224,"SIM",Pedidos!$I$2:$I$2224,"Tsl Filial Sp",Pedidos!$F$2:$F$2224,$A27),"") -> 0.25067248 | I27: =IFERROR(COUNTIFS(Pedidos!$X$2:$X$2224,"SIM",Pedidos!$I$2:$I$2224,"Tsl Filial Sp",Pedidos!$F$2:$F$2224,$A27,Pedidos!$V$2:$V$2224,"SIM")/B27,"") -> 0 | J27: =IFERROR(AVERAGEIFS(Pedidos!$K$2:$K$2224,Pedidos!$X$2:$X$2224,"SIM",Pedidos!$I$2:$I$2224,"Tsl Filial Sp",Pedidos!$F$2:$F$2224,$A27),"") -> 117.93309 | K27: =IFERROR(MAX(0,1-D27/E27),"") -> 0.29846458
A28: 60-70 | B28: =COUNTIFS(Pedidos!$X$2:$X$2224,"SIM",Pedidos!$I$2:$I$2224,"Tsl Filial Sp",Pedidos!$F$2:$F$2224,$A28) -> 178 | C28: =IFERROR(AVERAGEIFS(Pedidos!$G$2:$G$2224,Pedidos!$X$2:$X$2224,"SIM",Pedidos!$I$2:$I$2224,"Tsl Filial Sp",Pedidos!$F$2:$F$2224,$A28),"") -> 66.23809 | D28: =IFERROR(AVERAGEIFS(Pedidos!$J$2:$J$2224,Pedidos!$X$2:$X$2224,"SIM",Pedidos!$I$2:$I$2224,"Tsl Filial Sp",Pedidos!$F$2:$F$2224,$A28),"") -> 133.63685 | E28: =IFERROR(AVERAGEIFS(Pedidos!$S$2:$S$2224,Pedidos!$X$2:$X$2224,"SIM",Pedidos!$I$2:$I$2224,"Tsl Filial Sp",Pedidos!$F$2:$F$2224,$A28),"") -> 203.43675 | F28: =IFERROR(E28/D28-1,"") -> 0.52231026 | G28: =IFERROR(SUMIFS(Pedidos!$J$2:$J$2224,Pedidos!$X$2:$X$2224,"SIM",Pedidos!$I$2:$I$2224,"Tsl Filial Sp",Pedidos!$F$2:$F$2224,$A28)/SUMIFS(Pedidos!$H$2:$H$2224,Pedidos!$X$2:$X$2224,"SIM",Pedidos!$I$2:$I$2224,"Tsl Filial Sp",Pedidos!$F$2:$F$2224,$A28),"") -> 0.17527255 | H28: =IFERROR(SUMIFS(Pedidos!$S$2:$S$2224,Pedidos!$X$2:$X$2224,"SIM",Pedidos!$I$2:$I$2224,"Tsl Filial Sp",Pedidos!$F$2:$F$2224,$A28)/SUMIFS(Pedidos!$H$2:$H$2224,Pedidos!$X$2:$X$2224,"SIM",Pedidos!$I$2:$I$2224,"Tsl Filial Sp",Pedidos!$F$2:$F$2224,$A28),"") -> 0.26681921 | I28: =IFERROR(COUNTIFS(Pedidos!$X$2:$X$2224,"SIM",Pedidos!$I$2:$I$2224,"Tsl Filial Sp",Pedidos!$F$2:$F$2224,$A28,Pedidos!$V$2:$V$2224,"SIM")/B28,"") -> 0 | J28: =IFERROR(AVERAGEIFS(Pedidos!$K$2:$K$2224,Pedidos!$X$2:$X$2224,"SIM",Pedidos!$I$2:$I$2224,"Tsl Filial Sp",Pedidos!$F$2:$F$2224,$A28),"") -> 137.27899 | K28: =IFERROR(MAX(0,1-D28/E28),"") -> 0.34310368
A29: 70-80 | B29: =COUNTIFS(Pedidos!$X$2:$X$2224,"SIM",Pedidos!$I$2:$I$2224,"Tsl Filial Sp",Pedidos!$F$2:$F$2224,$A29) -> 19 | C29: =IFERROR(AVERAGEIFS(Pedidos!$G$2:$G$2224,Pedidos!$X$2:$X$2224,"SIM",Pedidos!$I$2:$I$2224,"Tsl Filial Sp",Pedidos!$F$2:$F$2224,$A29),"") -> 74.105263 | D29: =IFERROR(AVERAGEIFS(Pedidos!$J$2:$J$2224,Pedidos!$X$2:$X$2224,"SIM",Pedidos!$I$2:$I$2224,"Tsl Filial Sp",Pedidos!$F$2:$F$2224,$A29),"") -> 147.00842 | E29: =IFERROR(AVERAGEIFS(Pedidos!$S$2:$S$2224,Pedidos!$X$2:$X$2224,"SIM",Pedidos!$I$2:$I$2224,"Tsl Filial Sp",Pedidos!$F$2:$F$2224,$A29),"") -> 211.5 | F29: =IFERROR(E29/D29-1,"") -> 0.43869309 | G29: =IFERROR(SUMIFS(Pedidos!$J$2:$J$2224,Pedidos!$X$2:$X$2224,"SIM",Pedidos!$I$2:$I$2224,"Tsl Filial Sp",Pedidos!$F$2:$F$2224,$A29)/SUMIFS(Pedidos!$H$2:$H$2224,Pedidos!$X$2:$X$2224,"SIM",Pedidos!$I$2:$I$2224,"Tsl Filial Sp",Pedidos!$F$2:$F$2224,$A29),"") -> 0.15307905 | H29: =IFERROR(SUMIFS(Pedidos!$S$2:$S$2224,Pedidos!$X$2:$X$2224,"SIM",Pedidos!$I$2:$I$2224,"Tsl Filial Sp",Pedidos!$F$2:$F$2224,$A29)/SUMIFS(Pedidos!$H$2:$H$2224,Pedidos!$X$2:$X$2224,"SIM",Pedidos!$I$2:$I$2224,"Tsl Filial Sp",Pedidos!$F$2:$F$2224,$A29),"") -> 0.22023378 | I29: =IFERROR(COUNTIFS(Pedidos!$X$2:$X$2224,"SIM",Pedidos!$I$2:$I$2224,"Tsl Filial Sp",Pedidos!$F$2:$F$2224,$A29,Pedidos!$V$2:$V$2224,"SIM")/B29,"") -> 0 | J29: =IFERROR(AVERAGEIFS(Pedidos!$K$2:$K$2224,Pedidos!$X$2:$X$2224,"SIM",Pedidos!$I$2:$I$2224,"Tsl Filial Sp",Pedidos!$F$2:$F$2224,$A29),"") -> 139.83789 | K29: =IFERROR(MAX(0,1-D29/E29),"") -> 0.30492472
A30: 80-100 | B30: =COUNTIFS(Pedidos!$X$2:$X$2224,"SIM",Pedidos!$I$2:$I$2224,"Tsl Filial Sp",Pedidos!$F$2:$F$2224,$A30) -> 38 | C30: =IFERROR(AVERAGEIFS(Pedidos!$G$2:$G$2224,Pedidos!$X$2:$X$2224,"SIM",Pedidos!$I$2:$I$2224,"Tsl Filial Sp",Pedidos!$F$2:$F$2224,$A30),"") -> 87.921053 | D30: =IFERROR(AVERAGEIFS(Pedidos!$J$2:$J$2224,Pedidos!$X$2:$X$2224,"SIM",Pedidos!$I$2:$I$2224,"Tsl Filial Sp",Pedidos!$F$2:$F$2224,$A30),"") -> 174.32053 | E30: =IFERROR(AVERAGEIFS(Pedidos!$S$2:$S$2224,Pedidos!$X$2:$X$2224,"SIM",Pedidos!$I$2:$I$2224,"Tsl Filial Sp",Pedidos!$F$2:$F$2224,$A30),"") -> 262.49897 | F30: =IFERROR(E30/D30-1,"") -> 0.50584084 | G30: =IFERROR(SUMIFS(Pedidos!$J$2:$J$2224,Pedidos!$X$2:$X$2224,"SIM",Pedidos!$I$2:$I$2224,"Tsl Filial Sp",Pedidos!$F$2:$F$2224,$A30)/SUMIFS(Pedidos!$H$2:$H$2224,Pedidos!$X$2:$X$2224,"SIM",Pedidos!$I$2:$I$2224,"Tsl Filial Sp",Pedidos!$F$2:$F$2224,$A30),"") -> 0.18016082 | H30: =IFERROR(SUMIFS(Pedidos!$S$2:$S$2224,Pedidos!$X$2:$X$2224,"SIM",Pedidos!$I$2:$I$2224,"Tsl Filial Sp",Pedidos!$F$2:$F$2224,$A30)/SUMIFS(Pedidos!$H$2:$H$2224,Pedidos!$X$2:$X$2224,"SIM",Pedidos!$I$2:$I$2224,"Tsl Filial Sp",Pedidos!$F$2:$F$2224,$A30),"") -> 0.27129352 | I30: =IFERROR(COUNTIFS(Pedidos!$X$2:$X$2224,"SIM",Pedidos!$I$2:$I$2224,"Tsl Filial Sp",Pedidos!$F$2:$F$2224,$A30,Pedidos!$V$2:$V$2224,"SIM")/B30,"") -> 0 | J30: =IFERROR(AVERAGEIFS(Pedidos!$K$2:$K$2224,Pedidos!$X$2:$X$2224,"SIM",Pedidos!$I$2:$I$2224,"Tsl Filial Sp",Pedidos!$F$2:$F$2224,$A30),"") -> 177.59553 | K30: =IFERROR(MAX(0,1-D30/E30),"") -> 0.33591919
A31: 100-120 | B31: =COUNTIFS(Pedidos!$X$2:$X$2224,"SIM",Pedidos!$I$2:$I$2224,"Tsl Filial Sp",Pedidos!$F$2:$F$2224,$A31) -> 35 | C31: =IFERROR(AVERAGEIFS(Pedidos!$G$2:$G$2224,Pedidos!$X$2:$X$2224,"SIM",Pedidos!$I$2:$I$2224,"Tsl Filial Sp",Pedidos!$F$2:$F$2224,$A31),"") -> 110.18971 | D31: =IFERROR(AVERAGEIFS(Pedidos!$J$2:$J$2224,Pedidos!$X$2:$X$2224,"SIM",Pedidos!$I$2:$I$2224,"Tsl Filial Sp",Pedidos!$F$2:$F$2224,$A31),"") -> 192.25486 | E31: =IFERROR(AVERAGEIFS(Pedidos!$S$2:$S$2224,Pedidos!$X$2:$X$2224,"SIM",Pedidos!$I$2:$I$2224,"Tsl Filial Sp",Pedidos!$F$2:$F$2224,$A31),"") -> 313.39016 | F31: =IFERROR(E31/D31-1,"") -> 0.6300767 | G31: =IFERROR(SUMIFS(Pedidos!$J$2:$J$2224,Pedidos!$X$2:$X$2224,"SIM",Pedidos!$I$2:$I$2224,"Tsl Filial Sp",Pedidos!$F$2:$F$2224,$A31)/SUMIFS(Pedidos!$H$2:$H$2224,Pedidos!$X$2:$X$2224,"SIM",Pedidos!$I$2:$I$2224,"Tsl Filial Sp",Pedidos!$F$2:$F$2224,$A31),"") -> 0.15673408 | H31: =IFERROR(SUMIFS(Pedidos!$S$2:$S$2224,Pedidos!$X$2:$X$2224,"SIM",Pedidos!$I$2:$I$2224,"Tsl Filial Sp",Pedidos!$F$2:$F$2224,$A31)/SUMIFS(Pedidos!$H$2:$H$2224,Pedidos!$X$2:$X$2224,"SIM",Pedidos!$I$2:$I$2224,"Tsl Filial Sp",Pedidos!$F$2:$F$2224,$A31),"") -> 0.25548857 | I31: =IFERROR(COUNTIFS(Pedidos!$X$2:$X$2224,"SIM",Pedidos!$I$2:$I$2224,"Tsl Filial Sp",Pedidos!$F$2:$F$2224,$A31,Pedidos!$V$2:$V$2224,"SIM")/B31,"") -> 0 | J31: =IFERROR(AVERAGEIFS(Pedidos!$K$2:$K$2224,Pedidos!$X$2:$X$2224,"SIM",Pedidos!$I$2:$I$2224,"Tsl Filial Sp",Pedidos!$F$2:$F$2224,$A31),"") -> 205.68286 | K31: =IFERROR(MAX(0,1-D31/E31),"") -> 0.38653193
A32: 120-150 | B32: =COUNTIFS(Pedidos!$X$2:$X$2224,"SIM",Pedidos!$I$2:$I$2224,"Tsl Filial Sp",Pedidos!$F$2:$F$2224,$A32) -> 48 | C32: =IFERROR(AVERAGEIFS(Pedidos!$G$2:$G$2224,Pedidos!$X$2:$X$2224,"SIM",Pedidos!$I$2:$I$2224,"Tsl Filial Sp",Pedidos!$F$2:$F$2224,$A32),"") -> 128.26542 | D32: =IFERROR(AVERAGEIFS(Pedidos!$J$2:$J$2224,Pedidos!$X$2:$X$2224,"SIM",Pedidos!$I$2:$I$2224,"Tsl Filial Sp",Pedidos!$F$2:$F$2224,$A32),"") -> 239.57979 | E32: =IFERROR(AVERAGEIFS(Pedidos!$S$2:$S$2224,Pedidos!$X$2:$X$2224,"SIM",Pedidos!$I$2:$I$2224,"Tsl Filial Sp",Pedidos!$F$2:$F$2224,$A32),"") -> 366.89616 | F32: =IFERROR(E32/D32-1,"") -> 0.53141529 | G32: =IFERROR(SUMIFS(Pedidos!$J$2:$J$2224,Pedidos!$X$2:$X$2224,"SIM",Pedidos!$I$2:$I$2224,"Tsl Filial Sp",Pedidos!$F$2:$F$2224,$A32)/SUMIFS(Pedidos!$H$2:$H$2224,Pedidos!$X$2:$X$2224,"SIM",Pedidos!$I$2:$I$2224,"Tsl Filial Sp",Pedidos!$F$2:$F$2224,$A32),"") -> 0.14535132 | H32: =IFERROR(SUMIFS(Pedidos!$S$2:$S$2224,Pedidos!$X$2:$X$2224,"SIM",Pedidos!$I$2:$I$2224,"Tsl Filial Sp",Pedidos!$F$2:$F$2224,$A32)/SUMIFS(Pedidos!$H$2:$H$2224,Pedidos!$X$2:$X$2224,"SIM",Pedidos!$I$2:$I$2224,"Tsl Filial Sp",Pedidos!$F$2:$F$2224,$A32),"") -> 0.22259323 | I32: =IFERROR(COUNTIFS(Pedidos!$X$2:$X$2224,"SIM",Pedidos!$I$2:$I$2224,"Tsl Filial Sp",Pedidos!$F$2:$F$2224,$A32,Pedidos!$V$2:$V$2224,"SIM")/B32,"") -> 0 | J32: =IFERROR(AVERAGEIFS(Pedidos!$K$2:$K$2224,Pedidos!$X$2:$X$2224,"SIM",Pedidos!$I$2:$I$2224,"Tsl Filial Sp",Pedidos!$F$2:$F$2224,$A32),"") -> 242.1975 | K32: =IFERROR(MAX(0,1-D32/E32),"") -> 0.34700926
A33: 150-170 | B33: =COUNTIFS(Pedidos!$X$2:$X$2224,"SIM",Pedidos!$I$2:$I$2224,"Tsl Filial Sp",Pedidos!$F$2:$F$2224,$A33) -> 3 | C33: =IFERROR(AVERAGEIFS(Pedidos!$G$2:$G$2224,Pedidos!$X$2:$X$2224,"SIM",Pedidos!$I$2:$I$2224,"Tsl Filial Sp",Pedidos!$F$2:$F$2224,$A33),"") -> 160.63333 | D33: =IFERROR(AVERAGEIFS(Pedidos!$J$2:$J$2224,Pedidos!$X$2:$X$2224,"SIM",Pedidos!$I$2:$I$2224,"Tsl Filial Sp",Pedidos!$F$2:$F$2224,$A33),"") -> 259.73 | E33: =IFERROR(AVERAGEIFS(Pedidos!$S$2:$S$2224,Pedidos!$X$2:$X$2224,"SIM",Pedidos!$I$2:$I$2224,"Tsl Filial Sp",Pedidos!$F$2:$F$2224,$A33),"") -> 423.50102 | F33: =IFERROR(E33/D33-1,"") -> 0.63054334 | G33: =IFERROR(SUMIFS(Pedidos!$J$2:$J$2224,Pedidos!$X$2:$X$2224,"SIM",Pedidos!$I$2:$I$2224,"Tsl Filial Sp",Pedidos!$F$2:$F$2224,$A33)/SUMIFS(Pedidos!$H$2:$H$2224,Pedidos!$X$2:$X$2224,"SIM",Pedidos!$I$2:$I$2224,"Tsl Filial Sp",Pedidos!$F$2:$F$2224,$A33),"") -> 0.13604317 | H33: =IFERROR(SUMIFS(Pedidos!$S$2:$S$2224,Pedidos!$X$2:$X$2224,"SIM",Pedidos!$I$2:$I$2224,"Tsl Filial Sp",Pedidos!$F$2:$F$2224,$A33)/SUMIFS(Pedidos!$H$2:$H$2224,Pedidos!$X$2:$X$2224,"SIM",Pedidos!$I$2:$I$2224,"Tsl Filial Sp",Pedidos!$F$2:$F$2224,$A33),"") -> 0.22182429 | I33: =IFERROR(COUNTIFS(Pedidos!$X$2:$X$2224,"SIM",Pedidos!$I$2:$I$2224,"Tsl Filial Sp",Pedidos!$F$2:$F$2224,$A33,Pedidos!$V$2:$V$2224,"SIM")/B33,"") -> 0 | J33: =IFERROR(AVERAGEIFS(Pedidos!$K$2:$K$2224,Pedidos!$X$2:$X$2224,"SIM",Pedidos!$I$2:$I$2224,"Tsl Filial Sp",Pedidos!$F$2:$F$2224,$A33),"") -> 274.84333 | K33: =IFERROR(MAX(0,1-D33/E33),"") -> 0.3867075
A34: 170-200 | B34: =COUNTIFS(Pedidos!$X$2:$X$2224,"SIM",Pedidos!$I$2:$I$2224,"Tsl Filial Sp",Pedidos!$F$2:$F$2224,$A34) -> 1 | C34: =IFERROR(AVERAGEIFS(Pedidos!$G$2:$G$2224,Pedidos!$X$2:$X$2224,"SIM",Pedidos!$I$2:$I$2224,"Tsl Filial Sp",Pedidos!$F$2:$F$2224,$A34),"") -> 188.4 | D34: =IFERROR(AVERAGEIFS(Pedidos!$J$2:$J$2224,Pedidos!$X$2:$X$2224,"SIM",Pedidos!$I$2:$I$2224,"Tsl Filial Sp",Pedidos!$F$2:$F$2224,$A34),"") -> 198.28 | E34: =IFERROR(AVERAGEIFS(Pedidos!$S$2:$S$2224,Pedidos!$X$2:$X$2224,"SIM",Pedidos!$I$2:$I$2224,"Tsl Filial Sp",Pedidos!$F$2:$F$2224,$A34),"") -> 529.025 | F34: =IFERROR(E34/D34-1,"") -> 1.6680704 | G34: =IFERROR(SUMIFS(Pedidos!$J$2:$J$2224,Pedidos!$X$2:$X$2224,"SIM",Pedidos!$I$2:$I$2224,"Tsl Filial Sp",Pedidos!$F$2:$F$2224,$A34)/SUMIFS(Pedidos!$H$2:$H$2224,Pedidos!$X$2:$X$2224,"SIM",Pedidos!$I$2:$I$2224,"Tsl Filial Sp",Pedidos!$F$2:$F$2224,$A34),"") -> 0.099438315 | H34: =IFERROR(SUMIFS(Pedidos!$S$2:$S$2224,Pedidos!$X$2:$X$2224,"SIM",Pedidos!$I$2:$I$2224,"Tsl Filial Sp",Pedidos!$F$2:$F$2224,$A34)/SUMIFS(Pedidos!$H$2:$H$2224,Pedidos!$X$2:$X$2224,"SIM",Pedidos!$I$2:$I$2224,"Tsl Filial Sp",Pedidos!$F$2:$F$2224,$A34),"") -> 0.26530843 | I34: =IFERROR(COUNTIFS(Pedidos!$X$2:$X$2224,"SIM",Pedidos!$I$2:$I$2224,"Tsl Filial Sp",Pedidos!$F$2:$F$2224,$A34,Pedidos!$V$2:$V$2224,"SIM")/B34,"") -> 0 | J34: =IFERROR(AVERAGEIFS(Pedidos!$K$2:$K$2224,Pedidos!$X$2:$X$2224,"SIM",Pedidos!$I$2:$I$2224,"Tsl Filial Sp",Pedidos!$F$2:$F$2224,$A34),"") -> 353.17 | K34: =IFERROR(MAX(0,1-D34/E34),"") -> 0.6251973
... A36: >250 | B36: =COUNTIFS(Pedidos!$X$2:$X$2224,"SIM",Pedidos!$I$2:$I$2224,"Tsl Filial Sp",Pedidos!$F$2:$F$2224,$A36) -> 0 | C36: =IFERROR(AVERAGEIFS(Pedidos!$G$2:$G$2224,Pedidos!$X$2:$X$2224,"SIM",Pedidos!$I$2:$I$2224,"Tsl Filial Sp",Pedidos!$F$2:$F$2224,$A36),"") | D36: =IFERROR(AVERAGEIFS(Pedidos!$J$2:$J$2224,Pedidos!$X$2:$X$2224,"SIM",Pedidos!$I$2:$I$2224,"Tsl Filial Sp",Pedidos!$F$2:$F$2224,$A36),"") | E36: =IFERROR(AVERAGEIFS(Pedidos!$S$2:$S$2224,Pedidos!$X$2:$X$2224,"SIM",Pedidos!$I$2:$I$2224,"Tsl Filial Sp",Pedidos!$F$2:$F$2224,$A36),"") | F36: =IFERROR(E36/D36-1,"") | G36: =IFERROR(SUMIFS(Pedidos!$J$2:$J$2224,Pedidos!$X$2:$X$2224,"SIM",Pedidos!$I$2:$I$2224,"Tsl Filial Sp",Pedidos!$F$2:$F$2224,$A36)/SUMIFS(Pedidos!$H$2:$H$2224,Pedidos!$X$2:$X$2224,"SIM",Pedidos!$I$2:$I$2224,"Tsl Filial Sp",Pedidos!$F$2:$F$2224,$A36),"") | H36: =IFERROR(SUMIFS(Pedidos!$S$2:$S$2224,Pedidos!$X$2:$X$2224,"SIM",Pedidos!$I$2:$I$2224,"Tsl Filial Sp",Pedidos!$F$2:$F$2224,$A36)/SUMIFS(Pedidos!$H$2:$H$2224,Pedidos!$X$2:$X$2224,"SIM",Pedidos!$I$2:$I$2224,"Tsl Filial Sp",Pedidos!$F$2:$F$2224,$A36),"") | I36: =IFERROR(COUNTIFS(Pedidos!$X$2:$X$2224,"SIM",Pedidos!$I$2:$I$2224,"Tsl Filial Sp",Pedidos!$F$2:$F$2224,$A36,Pedidos!$V$2:$V$2224,"SIM")/B36,"") | J36: =IFERROR(AVERAGEIFS(Pedidos!$K$2:$K$2224,Pedidos!$X$2:$X$2224,"SIM",Pedidos!$I$2:$I$2224,"Tsl Filial Sp",Pedidos!$F$2:$F$2224,$A36),"") | K36: =IFERROR(MAX(0,1-D36/E36),"")
A37: TOTAL | B37: =COUNTIFS(Pedidos!$X$2:$X$2224,"SIM",Pedidos!$I$2:$I$2224,"Tsl Filial Sp") -> 1420 | C37: =IFERROR(AVERAGEIFS(Pedidos!$G$2:$G$2224,Pedidos!$X$2:$X$2224,"SIM",Pedidos!$I$2:$I$2224,"Tsl Filial Sp"),"") -> 49.102007 | D37: =IFERROR(AVERAGEIFS(Pedidos!$J$2:$J$2224,Pedidos!$X$2:$X$2224,"SIM",Pedidos!$I$2:$I$2224,"Tsl Filial Sp"),"") -> 116.31056 | E37: =IFERROR(AVERAGEIFS(Pedidos!$S$2:$S$2224,Pedidos!$X$2:$X$2224,"SIM",Pedidos!$I$2:$I$2224,"Tsl Filial Sp"),"") -> 167.02312 | F37: =IFERROR(E37/D37-1,"") -> 0.43600996 | G37: =IFERROR(SUMIFS(Pedidos!$J$2:$J$2224,Pedidos!$X$2:$X$2224,"SIM",Pedidos!$I$2:$I$2224,"Tsl Filial Sp")/SUMIFS(Pedidos!$H$2:$H$2224,Pedidos!$X$2:$X$2224,"SIM",Pedidos!$I$2:$I$2224,"Tsl Filial Sp"),"") -> 0.18411323 | H37: =IFERROR(SUMIFS(Pedidos!$S$2:$S$2224,Pedidos!$X$2:$X$2224,"SIM",Pedidos!$I$2:$I$2224,"Tsl Filial Sp")/SUMIFS(Pedidos!$H$2:$H$2224,Pedidos!$X$2:$X$2224,"SIM",Pedidos!$I$2:$I$2224,"Tsl Filial Sp"),"") -> 0.26438844 | I37: =IFERROR(COUNTIFS(Pedidos!$X$2:$X$2224,"SIM",Pedidos!$I$2:$I$2224,"Tsl Filial Sp",Pedidos!$V$2:$V$2224,"SIM")/B37,"") -> 0.0056338028 | J37: =IFERROR(AVERAGEIFS(Pedidos!$K$2:$K$2224,Pedidos!$X$2:$X$2224,"SIM",Pedidos!$I$2:$I$2224,"Tsl Filial Sp"),"") -> 114.06585 | K37: =IFERROR(MAX(0,1-D37/E37),"") -> 0.303626
